Workbook

Sheet Cover
B2: PORTFOLIO PROJECT 04
B3: Cost Accounting Report
B4: Sampaguita Foods & Distribution Corporation (SFDC)
B5: Activity-based product costing, break-even and CVP analysis for FY2025, reconciled to the Project 1 financial statements
B7: Prepared by Bengie Hirnani | Version 1.0 | PHP in thousands (unless otherwise stated)
B10: Model status | C10: =Model_Status -> ✔ All 20 integrity checks passed
B11: Scope | C11: Product-category costing with activity-based and traditional allocation side by side; per-case unit economics; contribution margin, break-even, margin of safety, operating leverage and target-profit analysis; cost-behaviour regression; what-if grids; interactive dashboard. A Word report (separate file) presents the findings.
B12: Data notice | C12: The company, drivers and volumes are fictional. Sales, costs and profit tie to the Project 1 workbook (control totals on Checks). Cost-driver data are illustrative management inputs.
B14: NAVIGATION - click a button to jump to a sheet
B15: DASHBOARD
B16: =HYPERLINK("#Dashboard!A1","Dashboard") -> Dashboard | C16: KPI cards, insights and four charts
B18: COSTING AND CVP
B19: =HYPERLINK("#Product_Costing!A1","Product Costing") -> Product Costing | C19: Gross profit, ABC and traditional operating profit, per-case economics
B20: =HYPERLINK("#ABC_Allocation!A1","ABC Allocation") -> ABC Allocation | C20: Cost drivers and allocation of every cost pool
B21: =HYPERLINK("#CVP_BreakEven!A1","CVP BreakEven") -> CVP BreakEven | C21: Contribution margin, break-even, margin of safety, target profit, Project 1 reconciliation
B22: =HYPERLINK("#Cost_Behaviour!A1","Cost Behaviour") -> Cost Behaviour | C22: High-low and regression tests of fixed/variable classification
B23: =HYPERLINK("#Sensitivity!A1","Sensitivity") -> Sensitivity | C23: Scenario analysis and two sensitivity grids
B25: DATA AND CONTROLS
B26: =HYPERLINK("#Inputs!A1","Inputs") -> Inputs | C26: Volumes, driver data and parameters
B27: =HYPERLINK("#FS_Data!A1","FS Data") -> FS Data | C27: Project 1 control totals
B28: =HYPERLINK("#Data_Sales!A1","Data Sales") -> Data Sales | C28: Monthly sales ledger (Project 1)
B29: =HYPERLINK("#Data_Expenses!A1","Data Expenses") -> Data Expenses | C29: Monthly expense ledger (Project 1)
B30: =HYPERLINK("#Chart_Data!A1","Chart Data") -> Chart Data | C30: Helper tables for charts
B31: =HYPERLINK("#Checks!A1","Checks") -> Checks | C31: Model integrity checks
B32: =HYPERLINK("#Documentation!A1","Documentation") -> Documentation | C32: Purpose, method, conventions

Sheet Documentation
B1: Cost Accounting Documentation
B2: Sampaguita Foods & Distribution Corporation (SFDC) | Documentation
B3: =HYPERLINK("#Cover!A1","◄ Back to Cover") -> ◄ Back to Cover
B5: 1. PURPOSE
B6: Objective | C6: Show how a distributor can move from a single profit figure to product-category profitability, using activity-based costing, and use cost-volume-profit analysis to answer break-even and target-profit questions.
B7: Link to Project 1 | C7: Net sales, cost of sales and operating expenses come from the Project 1 ledgers. Total operating profit of PHP 58.7 million and the Project 1 break-even (PHP 686.9 million) are reproduced exactly.
B9: 2. METHOD
B10: Costing | C10: Cost of sales is traced directly to categories from the sales ledger. Operating costs (13 ledger lines plus depreciation by asset class) are pooled and allocated with the driver named on ABC_Allocation. Traditional costing spreads the same total on net sales.
B11: CVP | C11: Variable costs = cost of sales plus the four variable expense lines of the Project 1 chart of accounts (commissions, advertising, freight, bad debts). Fixed costs = all other expenses plus depreciation. Break-even = fixed costs / contribution margin ratio.
B12: Mix | C12: Category break-even at the current sales mix = company break-even x category share of net sales. Stand-alone break-even uses each category's own allocated fixed costs.
B14: 3. CONVENTIONS
B15: Colours | C15: Blue = input; black = same-sheet formula; green = link to another sheet; yellow fill = key assumption.
B16: Units | C16: PHP '000 unless stated; cases in thousands; per-case figures in PHP.
B18: 4. LIMITATIONS
B19: Driver data | C19: Cases, cube, pallet, order-line, promotion and credit-sales data are fictional. In practice they come from the WMS, order system and promotion calendar.
B20: Behaviour | C20: Fixed/variable classification is binary; semi-variable costs are tested on Cost_Behaviour but not split in the CVP. Fixed costs are assumed fixed within the relevant range.
B21: Joint effects | C21: Category stand-alone break-even ignores shared-cost relief if a category is dropped; do not read it as a drop decision on its own.
B23: 5. HOW TO UPDATE
B24: Drivers | C24: Edit blue cells on Inputs or choose another driver in column E of ABC_Allocation; confirm Checks stay green.
B25: Year | C25: Change Inputs!C6 and refresh the volume and driver data for that year.

Sheet Dashboard
B1: Cost Accounting Dashboard
B2: Sampaguita Foods & Distribution Corporation (SFDC) | PHP in thousands (unless otherwise stated) | FY2025
B3: =HYPERLINK("#Cover!A1","◄ Back to Cover") -> ◄ Back to Cover
B5: Model integrity | D5: =Model_Status -> ✔ All 20 integrity checks passed
B7: NET SALES | E7: OPERATING PROFIT | H7: BREAK-EVEN NET SALES | K7: MARGIN OF SAFETY
B8: =CVP_BreakEven!G7 -> 972442 | E8: =Product_Costing!G18 -> 58733 | H8: =CVP_BreakEven!G19 -> 686912.65 | K8: =CVP_BreakEven!G23 -> 0.29362096
B9: ="Gross margin "&TEXT(Product_Costing!G11,"0.0%") -> Gross margin 25.7% | E9: ="Operating margin "&TEXT(Product_Costing!G19,"0.0%") -> Operating margin 6.0% | H9: =TEXT(CVP_BreakEven!G21,"0.0%")&" of actual net sales" -> 70.6% of actual net sales | K9: ="PHP "&TEXT(CVP_BreakEven!G22/1000,"#,##0.0")&" million above break-even" -> PHP 285.5 million above break-even
B11: CONTRIBUTION MARGIN RATIO | E11: OPERATING LEVERAGE | H11: BEST CATEGORY (ABC MARGIN) | K11: WEAKEST CATEGORY (ABC MARGIN)
B12: =CVP_BreakEven!G11 -> 0.20569864 | E12: =CVP_BreakEven!G24 -> 3.4057515 | H12: =Chart_Data!C42 -> Household & PC | K12: =Chart_Data!C43 -> Fresh & Frozen
B13: ="CM PHP "&TEXT(CVP_BreakEven!G10/1000,"#,##0.0")&" million" -> CM PHP 200.0 million | E13: ="1% sales change = "&TEXT(CVP_BreakEven!G24,"0.0")&"% profit change" -> 1% sales change = 3.4% profit change | H13: =TEXT(Chart_Data!D42,"0.0%")&" operating margin" -> 9.6% operating margin | K13: =TEXT(Chart_Data!D43,"0.0%")&" operating margin" -> -4.4% operating margin
B15: KEY INSIGHTS
B16: ="1. Net sales of PHP "&TEXT(CVP_BreakEven!G7/1000,"#,##0.0")&" million must reach PHP "&TEXT(CVP_BreakEven!G19/1000,"#,##0.0")&" million to break even, leaving a margin of safety of "&TEXT(CVP_BreakEven!G23,"0.0%")&"." -> 1. Net sales of PHP 972.4 million must reach PHP 686.9 million to break even, leaving a margin of safety of 29.4%.
B17: ="2. Thin contribution margin ("&TEXT(CVP_BreakEven!G11,"0.0%")&") and fixed costs of PHP "&TEXT(CVP_BreakEven!G14/1000,"#,##0.0")&" million give operating leverage of "&TEXT(CVP_BreakEven!G24,"0.00")&"x." -> 2. Thin contribution margin (20.6%) and fixed costs of PHP 141.3 million give operating leverage of 3.41x.
B18: ="3. ABC puts "&Chart_Data!C42&" first ("&TEXT(Chart_Data!D42,"0.0%")&" operating margin) and "&Chart_Data!C43&" last ("&TEXT(Chart_Data!D43,"0.0%")&")." -> 3. ABC puts Household & PC first (9.6% operating margin) and Fresh & Frozen last (-4.4%).
B19: ="4. Traditional costing misstates profit most for "&Chart_Data!C44&" by PHP "&TEXT(Chart_Data!D44,"#,##0")&"K ("&IF(Chart_Data!C45>0,"understated","overstated")&" by traditional costing)." -> 4. Traditional costing misstates profit most for Packaged Food by PHP 7,049K (understated by traditional costing).
B20: ="5. To earn PHP "&TEXT(Target_OP/1000,"#,##0.0")&" million operating profit, net sales must grow "&TEXT(CVP_BreakEven!F29,"0.0%")&" to PHP "&TEXT(CVP_BreakEven!G28/1000,"#,##0.0")&" million." -> 5. To earn PHP 75.0 million operating profit, net sales must grow 8.1% to PHP 1,051.5 million.

Sheet Product_Costing
B1: Product Costing by Category
B2: Sampaguita Foods & Distribution Corporation (SFDC) | PHP in thousands unless stated | activity-based vs traditional (sales-based) allocation
B3: =HYPERLINK("#Cover!A1","◄ Back to Cover") -> ◄ Back to Cover
B5: Line | C5: Packaged Food | D5: Beverages | E5: Household & Personal Care | F5: Fresh & Frozen | G5: Total
B6: A. VOLUME AND GROSS PROFIT
B7: Cases sold ('000) | C7: =Inputs!C11 -> 590 | D7: =Inputs!C12 -> 650 | E7: =Inputs!C13 -> 280 | F7: =Inputs!C14 -> 160 | G7: =SUM(C7:F7) -> 1680
B8: Net sales | C8: =SUMIFS(S_Sales,S_Year,Cost_Year,S_Cat,C$5) -> 382510 | D8: =SUMIFS(S_Sales,S_Year,Cost_Year,S_Cat,D$5) -> 292182 | E8: =SUMIFS(S_Sales,S_Year,Cost_Year,S_Cat,E$5) -> 170561 | F8: =SUMIFS(S_Sales,S_Year,Cost_Year,S_Cat,F$5) -> 127189 | G8: =SUM(C8:F8) -> 972442
B9: Cost of sales (merchandise cost) | C9: =SUMIFS(S_COGS,S_Year,Cost_Year,S_Cat,C$5) -> 286694 | D9: =SUMIFS(S_COGS,S_Year,Cost_Year,S_Cat,D$5) -> 213400 | E9: =SUMIFS(S_COGS,S_Year,Cost_Year,S_Cat,E$5) -> 119380 | F9: =SUMIFS(S_COGS,S_Year,Cost_Year,S_Cat,F$5) -> 103074 | G9: =SUM(C9:F9) -> 722548
B10: Gross profit | C10: =C8-C9 -> 95816 | D10: =D8-D9 -> 78782 | E10: =E8-E9 -> 51181 | F10: =F8-F9 -> 24115 | G10: =SUM(C10:F10) -> 249894
B11: Gross margin % | C11: =IFERROR(C10/C8,0) -> 0.2504928 | D11: =IFERROR(D10/D8,0) -> 0.26963331 | E11: =IFERROR(E10/E8,0) -> 0.30007446 | F11: =IFERROR(F10/F8,0) -> 0.18959973 | G11: =IFERROR(G10/G8,0) -> 0.25697574
B12: B. ACTIVITY-BASED OPERATING COSTS
B13: Variable selling costs (commissions, promotions, freight) | C13: =SUMIFS(ABC_Allocation!H$17:H$33,ABC_Allocation!$C$17:$C$33,"Selling & Distribution",ABC_Allocation!$D$17:$D$33,"Variable") -> 16510.903 | D13: =SUMIFS(ABC_Allocation!I$17:I$33,ABC_Allocation!$C$17:$C$33,"Selling & Distribution",ABC_Allocation!$D$17:$D$33,"Variable") -> 17421.3 | E13: =SUMIFS(ABC_Allocation!J$17:J$33,ABC_Allocation!$C$17:$C$33,"Selling & Distribution",ABC_Allocation!$D$17:$D$33,"Variable") -> 9264.1245 | F13: =SUMIFS(ABC_Allocation!K$17:K$33,ABC_Allocation!$C$17:$C$33,"Selling & Distribution",ABC_Allocation!$D$17:$D$33,"Variable") -> 5198.6727 | G13: =SUM(C13:F13) -> 48395
B14: Fixed selling & distribution (warehouse, logistics staff) | C14: =SUMIFS(ABC_Allocation!H$17:H$33,ABC_Allocation!$C$17:$C$33,"Selling & Distribution",ABC_Allocation!$D$17:$D$33,"Fixed") -> 19307.043 | D14: =SUMIFS(ABC_Allocation!I$17:I$33,ABC_Allocation!$C$17:$C$33,"Selling & Distribution",ABC_Allocation!$D$17:$D$33,"Fixed") -> 15050.695 | E14: =SUMIFS(ABC_Allocation!J$17:J$33,ABC_Allocation!$C$17:$C$33,"Selling & Distribution",ABC_Allocation!$D$17:$D$33,"Fixed") -> 10282.175 | F14: =SUMIFS(ABC_Allocation!K$17:K$33,ABC_Allocation!$C$17:$C$33,"Selling & Distribution",ABC_Allocation!$D$17:$D$33,"Fixed") -> 13042.086 | G14: =SUM(C14:F14) -> 57682
B15: General & administrative | C15: =SUMIFS(ABC_Allocation!H$17:H$33,ABC_Allocation!$C$17:$C$33,"General & Administrative") -> 25112.328 | D15: =SUMIFS(ABC_Allocation!I$17:I$33,ABC_Allocation!$C$17:$C$33,"General & Administrative") -> 19126.423 | E15: =SUMIFS(ABC_Allocation!J$17:J$33,ABC_Allocation!$C$17:$C$33,"General & Administrative") -> 11213.844 | F15: =SUMIFS(ABC_Allocation!K$17:K$33,ABC_Allocation!$C$17:$C$33,"General & Administrative") -> 8374.4053 | G15: =SUM(C15:F15) -> 63827
B16: Depreciation | C16: =SUMIFS(ABC_Allocation!H$17:H$33,ABC_Allocation!$C$17:$C$33,"Depreciation") -> 7214.0884 | D16: =SUMIFS(ABC_Allocation!I$17:I$33,ABC_Allocation!$C$17:$C$33,"Depreciation") -> 6852.8583 | E16: =SUMIFS(ABC_Allocation!J$17:J$33,ABC_Allocation!$C$17:$C$33,"Depreciation") -> 4031.7562 | F16: =SUMIFS(ABC_Allocation!K$17:K$33,ABC_Allocation!$C$17:$C$33,"Depreciation") -> 3158.2972 | G16: =SUM(C16:F16) -> 21257
B17: Total operating expenses (ABC) | C17: =SUM(C13:C16) -> 68144.363 | D17: =SUM(D13:D16) -> 58451.276 | E17: =SUM(E13:E16) -> 34791.9 | F17: =SUM(F13:F16) -> 29773.461 | G17: =SUM(C17:F17) -> 191161
B18: Operating profit (ABC) | C18: =C10-C17 -> 27671.637 | D18: =D10-D17 -> 20330.724 | E18: =E10-E17 -> 16389.1 | F18: =F10-F17 -> -5658.4613 | G18: =SUM(C18:F18) -> 58733
B19: Operating margin % (ABC) | C19: =IFERROR(C18/C8,0) -> 0.072342259 | D19: =IFERROR(D18/D8,0) -> 0.069582396 | E19: =IFERROR(E18/E8,0) -> 0.096089377 | F19: =IFERROR(F18/F8,0) -> -0.044488606 | G19: =IFERROR(G18/G8,0) -> 0.060397432
B20: C. TRADITIONAL ALLOCATION (ALL OPERATING COSTS SPREAD ON NET SALES)
B21: Operating expenses allocated on net sales | C21: =$G$17*C8/$G$8 -> 75193.167 | D21: =$G$17*D8/$G$8 -> 57436.642 | E21: =$G$17*E8/$G$8 -> 33528.592 | F21: =$G$17*F8/$G$8 -> 25002.598 | G21: =SUM(C21:F21) -> 191161
B22: Operating profit (traditional) | C22: =C10-C21 -> 20622.833 | D22: =D10-D21 -> 21345.358 | E22: =E10-E21 -> 17652.408 | F22: =F10-F21 -> -887.59803 | G22: =SUM(C22:F22) -> 58733
B23: Operating margin % (traditional) | C23: =IFERROR(C22/C8,0) -> 0.053914493 | D23: =IFERROR(D22/D8,0) -> 0.073055006 | E23: =IFERROR(E22/E8,0) -> 0.10349616 | F23: =IFERROR(F22/F8,0) -> -0.0069785754 | G23: =IFERROR(G22/G8,0) -> 0.060397432
B24: Costing distortion: ABC less traditional profit | C24: =C18-C22 -> 7048.8049 | D24: =D18-D22 -> -1014.6341 | E24: =E18-E22 -> -1263.3075 | F24: =F18-F22 -> -4770.8633 | G24: =SUM(C24:F24) -> 0
B25: Distortion as % of ABC operating profit | C25: =IFERROR(C24/C18,0) -> 0.25473031 | D25: =IFERROR(D24/D18,0) -> -0.049906445 | E25: =IFERROR(E24/E18,0) -> -0.077082174 | F25: =IFERROR(F24/F18,0) -> 0.84313792
B26: D. UNIT ECONOMICS (PHP PER CASE)
B27: Selling price per case | C27: =IFERROR(C8/C7,0) -> 648.32203 | D27: =IFERROR(D8/D7,0) -> 449.51077 | E27: =IFERROR(E8/E7,0) -> 609.14643 | F27: =IFERROR(F8/F7,0) -> 794.93125 | G27: =IFERROR(G8/G7,0) -> 578.83452
B28: Cost of sales per case | C28: =IFERROR(C9/C7,0) -> 485.92203 | D28: =IFERROR(D9/D7,0) -> 328.30769 | E28: =IFERROR(E9/E7,0) -> 426.35714 | F28: =IFERROR(F9/F7,0) -> 644.2125 | G28: =IFERROR(G9/G7,0) -> 430.0881
B29: Gross profit per case | C29: =C27-C28 -> 162.4 | D29: =D27-D28 -> 121.20308 | E29: =E27-E28 -> 182.78929 | F29: =F27-F28 -> 150.71875 | G29: =G27-G28 -> 148.74643
B30: Operating cost per case (ABC) | C30: =IFERROR(C17/C7,0) -> 115.49892 | D30: =IFERROR(D17/D7,0) -> 89.925041 | E30: =IFERROR(E17/E7,0) -> 124.25678 | F30: =IFERROR(F17/F7,0) -> 186.08413 | G30: =IFERROR(G17/G7,0) -> 113.78631
B31: Full cost per case (ABC) | C31: =C28+C30 -> 601.42095 | D31: =D28+D30 -> 418.23273 | E31: =E28+E30 -> 550.61393 | F31: =F28+F30 -> 830.29663 | G31: =G28+G30 -> 543.8744
B32: Operating profit per case (ABC) | C32: =C27-C31 -> 46.90108 | D32: =D27-D31 -> 31.278036 | E32: =E27-E31 -> 58.532501 | F32: =F27-F31 -> -35.365383 | G32: =G27-G31 -> 34.960119
B33: Operating profit per case (traditional) | C33: =IFERROR(C22/C7,0) -> 34.953954 | D33: =IFERROR(D22/D7,0) -> 32.839012 | E33: =IFERROR(E22/E7,0) -> 63.044313 | F33: =IFERROR(F22/F7,0) -> -5.5474877 | G33: =IFERROR(G22/G7,0) -> 34.960119
B34: Rank by ABC operating margin (1 = best) | C34: =RANK(C19,$C$19:$F$19) -> 2 | D34: =RANK(D19,$C$19:$F$19) -> 3 | E34: =RANK(E19,$C$19:$F$19) -> 1 | F34: =RANK(F19,$C$19:$F$19) -> 4
B36: Reading the table: traditional costing assumes every peso of sales consumes the same overhead. ABC traces overhead to what each category actually uses (cube, pallet space, order lines, promotion and credit exposure), so bulky, order-intensive and cold-chain categories carry more cost per peso of sales. A positive distortion means traditional costing under-states that category's profit; a negative one means it over-states it.

Sheet ABC_Allocation
B1: Activity-Based Cost Allocation
B2: Sampaguita Foods & Distribution Corporation (SFDC) | PHP in thousands | every operating cost pool is assigned to product categories through a cost driver
B3: =HYPERLINK("#Cover!A1","◄ Back to Cover") -> ◄ Back to Cover
B5: A. COST DRIVER QUANTITIES BY CATEGORY
B6: Driver | C6: Unit | E6: Packaged Food | F6: Beverages | G6: Household & PC | H6: Fresh & Frozen | I6: Total
B7: Net sales | C7: PHP '000 | E7: =Product_Costing!C8 -> 382510 | F7: =Product_Costing!D8 -> 292182 | G7: =Product_Costing!E8 -> 170561 | H7: =Product_Costing!F8 -> 127189 | I7: =SUM(E7:H7) -> 972442
B8: Promotion share | C8: % share | E8: =Inputs!E11 -> 0.38 | F8: =Inputs!E12 -> 0.32 | G8: =Inputs!E13 -> 0.18 | H8: =Inputs!E14 -> 0.12 | I8: =SUM(E8:H8) -> 1
B9: Delivery cube | C9: '000 m³ | E9: =Inputs!C11*Inputs!D11 -> 590 | F9: =Inputs!C12*Inputs!D12 -> 845 | G9: =Inputs!C13*Inputs!D13 -> 420 | H9: =Inputs!C14*Inputs!D14 -> 176 | I9: =SUM(E9:H9) -> 2031
B10: Pallet positions | C10: % share | E10: =Inputs!F11 -> 0.36 | F10: =Inputs!F12 -> 0.24 | G10: =Inputs!F13 -> 0.18 | H10: =Inputs!F14 -> 0.22 | I10: =SUM(E10:H10) -> 1
B11: Order lines | C11: '000 lines | E11: =Inputs!G11 -> 410 | F11: =Inputs!G12 -> 360 | G11: =Inputs!G13 -> 230 | H11: =Inputs!G14 -> 300 | I11: =SUM(E11:H11) -> 1300
B12: Credit sales | C12: PHP '000 | E12: =Product_Costing!C8*Inputs!H11 -> 306008 | F12: =Product_Costing!D8*Inputs!H12 -> 204527.4 | G12: =Product_Costing!E8*Inputs!H13 -> 144976.85 | H12: =Product_Costing!F8*Inputs!H14 -> 114470.1 | I12: =SUM(E12:H12) -> 769982.35
B15: B. COST POOLS AND ALLOCATION TO PRODUCT CATEGORIES
B16: Cost pool | C16: Function | D16: Behaviour | E16: Driver | F16: Pool cost | G16: Cost per driver unit | H16: Packaged Food | I16: Beverages | J16: Household & PC | K16: Fresh & Frozen | L16: Allocation check
B17: Sales commissions & incentives | C17: Selling & Distribution | D17: Variable | E17: Net sales | F17: =SUMIFS(E_Amt,E_Year,Cost_Year,E_Line,$B17) -> 15695 | G17: =IFERROR(F17/INDEX($I$7:$I$12,MATCH($E17,$B$7:$B$12,0)),0) -> 0.01613978 | H17: =$F17*INDEX(E$7:E$12,MATCH($E17,$B$7:$B$12,0))/INDEX($I$7:$I$12,MATCH($E17,$B$7:$B$12,0)) -> 6173.6273 | I17: =$F17*INDEX(F$7:F$12,MATCH($E17,$B$7:$B$12,0))/INDEX($I$7:$I$12,MATCH($E17,$B$7:$B$12,0)) -> 4715.7532 | J17: =$F17*INDEX(G$7:G$12,MATCH($E17,$B$7:$B$12,0))/INDEX($I$7:$I$12,MATCH($E17,$B$7:$B$12,0)) -> 2752.817 | K17: =$F17*INDEX(H$7:H$12,MATCH($E17,$B$7:$B$12,0))/INDEX($I$7:$I$12,MATCH($E17,$B$7:$B$12,0)) -> 2052.8025 | L17: =SUM(H17:K17)-F17 -> 0
B18: Advertising & promotions | C18: Selling & Distribution | D18: Variable | E18: Promotion share | F18: =SUMIFS(E_Amt,E_Year,Cost_Year,E_Line,$B18) -> 9363 | G18: =IFERROR(F18/INDEX($I$7:$I$12,MATCH($E18,$B$7:$B$12,0)),0) -> 9363 | H18: =$F18*INDEX(E$7:E$12,MATCH($E18,$B$7:$B$12,0))/INDEX($I$7:$I$12,MATCH($E18,$B$7:$B$12,0)) -> 3557.94 | I18: =$F18*INDEX(F$7:F$12,MATCH($E18,$B$7:$B$12,0))/INDEX($I$7:$I$12,MATCH($E18,$B$7:$B$12,0)) -> 2996.16 | J18: =$F18*INDEX(G$7:G$12,MATCH($E18,$B$7:$B$12,0))/INDEX($I$7:$I$12,MATCH($E18,$B$7:$B$12,0)) -> 1685.34 | K18: =$F18*INDEX(H$7:H$12,MATCH($E18,$B$7:$B$12,0))/INDEX($I$7:$I$12,MATCH($E18,$B$7:$B$12,0)) -> 1123.56 | L18: =SUM(H18:K18)-F18 -> 0
B19: Freight & delivery | C19: Selling & Distribution | D19: Variable | E19: Delivery cube | F19: =SUMIFS(E_Amt,E_Year,Cost_Year,E_Line,$B19) -> 23337 | G19: =IFERROR(F19/INDEX($I$7:$I$12,MATCH($E19,$B$7:$B$12,0)),0) -> 11.490399 | H19: =$F19*INDEX(E$7:E$12,MATCH($E19,$B$7:$B$12,0))/INDEX($I$7:$I$12,MATCH($E19,$B$7:$B$12,0)) -> 6779.3353 | I19: =$F19*INDEX(F$7:F$12,MATCH($E19,$B$7:$B$12,0))/INDEX($I$7:$I$12,MATCH($E19,$B$7:$B$12,0)) -> 9709.387 | J19: =$F19*INDEX(G$7:G$12,MATCH($E19,$B$7:$B$12,0))/INDEX($I$7:$I$12,MATCH($E19,$B$7:$B$12,0)) -> 4825.9675 | K19: =$F19*INDEX(H$7:H$12,MATCH($E19,$B$7:$B$12,0))/INDEX($I$7:$I$12,MATCH($E19,$B$7:$B$12,0)) -> 2022.3102 | L19: =SUM(H19:K19)-F19 -> 0
B20: Warehouse rent & utilities | C20: Selling & Distribution | D20: Fixed | E20: Pallet positions | F20: =SUMIFS(E_Amt,E_Year,Cost_Year,E_Line,$B20) -> 24992 | G20: =IFERROR(F20/INDEX($I$7:$I$12,MATCH($E20,$B$7:$B$12,0)),0) -> 24992 | H20: =$F20*INDEX(E$7:E$12,MATCH($E20,$B$7:$B$12,0))/INDEX($I$7:$I$12,MATCH($E20,$B$7:$B$12,0)) -> 8997.12 | I20: =$F20*INDEX(F$7:F$12,MATCH($E20,$B$7:$B$12,0))/INDEX($I$7:$I$12,MATCH($E20,$B$7:$B$12,0)) -> 5998.08 | J20: =$F20*INDEX(G$7:G$12,MATCH($E20,$B$7:$B$12,0))/INDEX($I$7:$I$12,MATCH($E20,$B$7:$B$12,0)) -> 4498.56 | K20: =$F20*INDEX(H$7:H$12,MATCH($E20,$B$7:$B$12,0))/INDEX($I$7:$I$12,MATCH($E20,$B$7:$B$12,0)) -> 5498.24 | L20: =SUM(H20:K20)-F20 -> 0
B21: Selling & logistics staff costs | C21: Selling & Distribution | D21: Fixed | E21: Order lines | F21: =SUMIFS(E_Amt,E_Year,Cost_Year,E_Line,$B21) -> 32690 | G21: =IFERROR(F21/INDEX($I$7:$I$12,MATCH($E21,$B$7:$B$12,0)),0) -> 25.146154 | H21: =$F21*INDEX(E$7:E$12,MATCH($E21,$B$7:$B$12,0))/INDEX($I$7:$I$12,MATCH($E21,$B$7:$B$12,0)) -> 10309.923 | I21: =$F21*INDEX(F$7:F$12,MATCH($E21,$B$7:$B$12,0))/INDEX($I$7:$I$12,MATCH($E21,$B$7:$B$12,0)) -> 9052.6154 | J21: =$F21*INDEX(G$7:G$12,MATCH($E21,$B$7:$B$12,0))/INDEX($I$7:$I$12,MATCH($E21,$B$7:$B$12,0)) -> 5783.6154 | K21: =$F21*INDEX(H$7:H$12,MATCH($E21,$B$7:$B$12,0))/INDEX($I$7:$I$12,MATCH($E21,$B$7:$B$12,0)) -> 7543.8462 | L21: =SUM(H21:K21)-F21 -> 0
B22: Salaries & wages (G&A) | C22: General & Administrative | D22: Fixed | E22: Net sales | F22: =SUMIFS(E_Amt,E_Year,Cost_Year,E_Line,$B22) -> 30213 | G22: =IFERROR(F22/INDEX($I$7:$I$12,MATCH($E22,$B$7:$B$12,0)),0) -> 0.031069205 | H22: =$F22*INDEX(E$7:E$12,MATCH($E22,$B$7:$B$12,0))/INDEX($I$7:$I$12,MATCH($E22,$B$7:$B$12,0)) -> 11884.282 | I22: =$F22*INDEX(F$7:F$12,MATCH($E22,$B$7:$B$12,0))/INDEX($I$7:$I$12,MATCH($E22,$B$7:$B$12,0)) -> 9077.8625 | J22: =$F22*INDEX(G$7:G$12,MATCH($E22,$B$7:$B$12,0))/INDEX($I$7:$I$12,MATCH($E22,$B$7:$B$12,0)) -> 5299.1947 | K22: =$F22*INDEX(H$7:H$12,MATCH($E22,$B$7:$B$12,0))/INDEX($I$7:$I$12,MATCH($E22,$B$7:$B$12,0)) -> 3951.6611 | L22: =SUM(H22:K22)-F22 -> 0
B23: Employee benefits & contributions | C23: General & Administrative | D23: Fixed | E23: Net sales | F23: =SUMIFS(E_Amt,E_Year,Cost_Year,E_Line,$B23) -> 8130 | G23: =IFERROR(F23/INDEX($I$7:$I$12,MATCH($E23,$B$7:$B$12,0)),0) -> 0.0083603958 | H23: =$F23*INDEX(E$7:E$12,MATCH($E23,$B$7:$B$12,0))/INDEX($I$7:$I$12,MATCH($E23,$B$7:$B$12,0)) -> 3197.935 | I23: =$F23*INDEX(F$7:F$12,MATCH($E23,$B$7:$B$12,0))/INDEX($I$7:$I$12,MATCH($E23,$B$7:$B$12,0)) -> 2442.7572 | J23: =$F23*INDEX(G$7:G$12,MATCH($E23,$B$7:$B$12,0))/INDEX($I$7:$I$12,MATCH($E23,$B$7:$B$12,0)) -> 1425.9575 | K23: =$F23*INDEX(H$7:H$12,MATCH($E23,$B$7:$B$12,0))/INDEX($I$7:$I$12,MATCH($E23,$B$7:$B$12,0)) -> 1063.3504 | L23: =SUM(H23:K23)-F23 -> 0
B24: Professional fees | C24: General & Administrative | D24: Fixed | E24: Net sales | F24: =SUMIFS(E_Amt,E_Year,Cost_Year,E_Line,$B24) -> 4500 | G24: =IFERROR(F24/INDEX($I$7:$I$12,MATCH($E24,$B$7:$B$12,0)),0) -> 0.0046275253 | H24: =$F24*INDEX(E$7:E$12,MATCH($E24,$B$7:$B$12,0))/INDEX($I$7:$I$12,MATCH($E24,$B$7:$B$12,0)) -> 1770.0747 | I24: =$F24*INDEX(F$7:F$12,MATCH($E24,$B$7:$B$12,0))/INDEX($I$7:$I$12,MATCH($E24,$B$7:$B$12,0)) -> 1352.0796 | J24: =$F24*INDEX(G$7:G$12,MATCH($E24,$B$7:$B$12,0))/INDEX($I$7:$I$12,MATCH($E24,$B$7:$B$12,0)) -> 789.27535 | K24: =$F24*INDEX(H$7:H$12,MATCH($E24,$B$7:$B$12,0))/INDEX($I$7:$I$12,MATCH($E24,$B$7:$B$12,0)) -> 588.57032 | L24: =SUM(H24:K24)-F24 -> 0
B25: Office rent & utilities | C25: General & Administrative | D25: Fixed | E25: Net sales | F25: =SUMIFS(E_Amt,E_Year,Cost_Year,E_Line,$B25) -> 6839 | G25: =IFERROR(F25/INDEX($I$7:$I$12,MATCH($E25,$B$7:$B$12,0)),0) -> 0.0070328102 | H25: =$F25*INDEX(E$7:E$12,MATCH($E25,$B$7:$B$12,0))/INDEX($I$7:$I$12,MATCH($E25,$B$7:$B$12,0)) -> 2690.1202 | I25: =$F25*INDEX(F$7:F$12,MATCH($E25,$B$7:$B$12,0))/INDEX($I$7:$I$12,MATCH($E25,$B$7:$B$12,0)) -> 2054.8605 | J25: =$F25*INDEX(G$7:G$12,MATCH($E25,$B$7:$B$12,0))/INDEX($I$7:$I$12,MATCH($E25,$B$7:$B$12,0)) -> 1199.5231 | K25: =$F25*INDEX(H$7:H$12,MATCH($E25,$B$7:$B$12,0))/INDEX($I$7:$I$12,MATCH($E25,$B$7:$B$12,0)) -> 894.49609 | L25: =SUM(H25:K25)-F25 -> 0
B26: Repairs & maintenance | C26: General & Administrative | D26: Fixed | E26: Net sales | F26: =SUMIFS(E_Amt,E_Year,Cost_Year,E_Line,$B26) -> 2729 | G26: =IFERROR(F26/INDEX($I$7:$I$12,MATCH($E26,$B$7:$B$12,0)),0) -> 0.002806337 | H26: =$F26*INDEX(E$7:E$12,MATCH($E26,$B$7:$B$12,0))/INDEX($I$7:$I$12,MATCH($E26,$B$7:$B$12,0)) -> 1073.452 | I26: =$F26*INDEX(F$7:F$12,MATCH($E26,$B$7:$B$12,0))/INDEX($I$7:$I$12,MATCH($E26,$B$7:$B$12,0)) -> 819.96117 | J26: =$F26*INDEX(G$7:G$12,MATCH($E26,$B$7:$B$12,0))/INDEX($I$7:$I$12,MATCH($E26,$B$7:$B$12,0)) -> 478.65165 | K26: =$F26*INDEX(H$7:H$12,MATCH($E26,$B$7:$B$12,0))/INDEX($I$7:$I$12,MATCH($E26,$B$7:$B$12,0)) -> 356.9352 | L26: =SUM(H26:K26)-F26 -> 0
B27: Taxes, licenses & insurance | C27: General & Administrative | D27: Fixed | E27: Net sales | F27: =SUMIFS(E_Amt,E_Year,Cost_Year,E_Line,$B27) -> 5484 | G27: =IFERROR(F27/INDEX($I$7:$I$12,MATCH($E27,$B$7:$B$12,0)),0) -> 0.0056394109 | H27: =$F27*INDEX(E$7:E$12,MATCH($E27,$B$7:$B$12,0))/INDEX($I$7:$I$12,MATCH($E27,$B$7:$B$12,0)) -> 2157.1311 | I27: =$F27*INDEX(F$7:F$12,MATCH($E27,$B$7:$B$12,0))/INDEX($I$7:$I$12,MATCH($E27,$B$7:$B$12,0)) -> 1647.7344 | J27: =$F27*INDEX(G$7:G$12,MATCH($E27,$B$7:$B$12,0))/INDEX($I$7:$I$12,MATCH($E27,$B$7:$B$12,0)) -> 961.86356 | K27: =$F27*INDEX(H$7:H$12,MATCH($E27,$B$7:$B$12,0))/INDEX($I$7:$I$12,MATCH($E27,$B$7:$B$12,0)) -> 717.27103 | L27: =SUM(H27:K27)-F27 -> 0
B28: Communication, IT & supplies | C28: General & Administrative | D28: Fixed | E28: Net sales | F28: =SUMIFS(E_Amt,E_Year,Cost_Year,E_Line,$B28) -> 4463 | G28: =IFERROR(F28/INDEX($I$7:$I$12,MATCH($E28,$B$7:$B$12,0)),0) -> 0.0045894768 | H28: =$F28*INDEX(E$7:E$12,MATCH($E28,$B$7:$B$12,0))/INDEX($I$7:$I$12,MATCH($E28,$B$7:$B$12,0)) -> 1755.5208 | I28: =$F28*INDEX(F$7:F$12,MATCH($E28,$B$7:$B$12,0))/INDEX($I$7:$I$12,MATCH($E28,$B$7:$B$12,0)) -> 1340.9625 | J28: =$F28*INDEX(G$7:G$12,MATCH($E28,$B$7:$B$12,0))/INDEX($I$7:$I$12,MATCH($E28,$B$7:$B$12,0)) -> 782.78575 | K28: =$F28*INDEX(H$7:H$12,MATCH($E28,$B$7:$B$12,0))/INDEX($I$7:$I$12,MATCH($E28,$B$7:$B$12,0)) -> 583.73096 | L28: =SUM(H28:K28)-F28 -> 0
B29: Bad debts & credit losses | C29: General & Administrative | D29: Variable | E29: Credit sales | F29: =SUMIFS(E_Amt,E_Year,Cost_Year,E_Line,$B29) -> 1469 | G29: =IFERROR(F29/INDEX($I$7:$I$12,MATCH($E29,$B$7:$B$12,0)),0) -> 0.0019078359 | H29: =$F29*INDEX(E$7:E$12,MATCH($E29,$B$7:$B$12,0))/INDEX($I$7:$I$12,MATCH($E29,$B$7:$B$12,0)) -> 583.81306 | I29: =$F29*INDEX(F$7:F$12,MATCH($E29,$B$7:$B$12,0))/INDEX($I$7:$I$12,MATCH($E29,$B$7:$B$12,0)) -> 390.20472 | J29: =$F29*INDEX(G$7:G$12,MATCH($E29,$B$7:$B$12,0))/INDEX($I$7:$I$12,MATCH($E29,$B$7:$B$12,0)) -> 276.59204 | K29: =$F29*INDEX(H$7:H$12,MATCH($E29,$B$7:$B$12,0))/INDEX($I$7:$I$12,MATCH($E29,$B$7:$B$12,0)) -> 218.39017 | L29: =SUM(H29:K29)-F29 -> 0
B30: Depreciation - Buildings & warehouse improvements | C30: Depreciation | D30: Fixed | E30: Pallet positions | F30: =FS_Data!$E$22 -> 3825 | G30: =IFERROR(F30/INDEX($I$7:$I$12,MATCH($E30,$B$7:$B$12,0)),0) -> 3825 | H30: =$F30*INDEX(E$7:E$12,MATCH($E30,$B$7:$B$12,0))/INDEX($I$7:$I$12,MATCH($E30,$B$7:$B$12,0)) -> 1377 | I30: =$F30*INDEX(F$7:F$12,MATCH($E30,$B$7:$B$12,0))/INDEX($I$7:$I$12,MATCH($E30,$B$7:$B$12,0)) -> 918 | J30: =$F30*INDEX(G$7:G$12,MATCH($E30,$B$7:$B$12,0))/INDEX($I$7:$I$12,MATCH($E30,$B$7:$B$12,0)) -> 688.5 | K30: =$F30*INDEX(H$7:H$12,MATCH($E30,$B$7:$B$12,0))/INDEX($I$7:$I$12,MATCH($E30,$B$7:$B$12,0)) -> 841.5 | L30: =SUM(H30:K30)-F30 -> 0
B31: Depreciation - Warehouse equipment & racking | C31: Depreciation | D31: Fixed | E31: Pallet positions | F31: =FS_Data!$E$23 -> 4583 | G31: =IFERROR(F31/INDEX($I$7:$I$12,MATCH($E31,$B$7:$B$12,0)),0) -> 4583 | H31: =$F31*INDEX(E$7:E$12,MATCH($E31,$B$7:$B$12,0))/INDEX($I$7:$I$12,MATCH($E31,$B$7:$B$12,0)) -> 1649.88 | I31: =$F31*INDEX(F$7:F$12,MATCH($E31,$B$7:$B$12,0))/INDEX($I$7:$I$12,MATCH($E31,$B$7:$B$12,0)) -> 1099.92 | J31: =$F31*INDEX(G$7:G$12,MATCH($E31,$B$7:$B$12,0))/INDEX($I$7:$I$12,MATCH($E31,$B$7:$B$12,0)) -> 824.94 | K31: =$F31*INDEX(H$7:H$12,MATCH($E31,$B$7:$B$12,0))/INDEX($I$7:$I$12,MATCH($E31,$B$7:$B$12,0)) -> 1008.26 | L31: =SUM(H31:K31)-F31 -> 0
B32: Depreciation - Delivery vehicles | C32: Depreciation | D32: Fixed | E32: Delivery cube | F32: =FS_Data!$E$24 -> 8429 | G32: =IFERROR(F32/INDEX($I$7:$I$12,MATCH($E32,$B$7:$B$12,0)),0) -> 4.1501723 | H32: =$F32*INDEX(E$7:E$12,MATCH($E32,$B$7:$B$12,0))/INDEX($I$7:$I$12,MATCH($E32,$B$7:$B$12,0)) -> 2448.6017 | I32: =$F32*INDEX(F$7:F$12,MATCH($E32,$B$7:$B$12,0))/INDEX($I$7:$I$12,MATCH($E32,$B$7:$B$12,0)) -> 3506.8956 | J32: =$F32*INDEX(G$7:G$12,MATCH($E32,$B$7:$B$12,0))/INDEX($I$7:$I$12,MATCH($E32,$B$7:$B$12,0)) -> 1743.0724 | K32: =$F32*INDEX(H$7:H$12,MATCH($E32,$B$7:$B$12,0))/INDEX($I$7:$I$12,MATCH($E32,$B$7:$B$12,0)) -> 730.43033 | L32: =SUM(H32:K32)-F32 -> 0
B33: Depreciation - Office furniture & IT equipment | C33: Depreciation | D33: Fixed | E33: Net sales | F33: =FS_Data!$E$25 -> 4420 | G33: =IFERROR(F33/INDEX($I$7:$I$12,MATCH($E33,$B$7:$B$12,0)),0) -> 0.0045452582 | H33: =$F33*INDEX(E$7:E$12,MATCH($E33,$B$7:$B$12,0))/INDEX($I$7:$I$12,MATCH($E33,$B$7:$B$12,0)) -> 1738.6067 | I33: =$F33*INDEX(F$7:F$12,MATCH($E33,$B$7:$B$12,0))/INDEX($I$7:$I$12,MATCH($E33,$B$7:$B$12,0)) -> 1328.0426 | J33: =$F33*INDEX(G$7:G$12,MATCH($E33,$B$7:$B$12,0))/INDEX($I$7:$I$12,MATCH($E33,$B$7:$B$12,0)) -> 775.24379 | K33: =$F33*INDEX(H$7:H$12,MATCH($E33,$B$7:$B$12,0))/INDEX($I$7:$I$12,MATCH($E33,$B$7:$B$12,0)) -> 578.10685 | L33: =SUM(H33:K33)-F33 -> 0
B34: Total operating costs | F34: =SUM(F17:F33) -> 191161 | H34: =SUM(H17:H33) -> 68144.363 | I34: =SUM(I17:I33) -> 58451.276 | J34: =SUM(J17:J33) -> 34791.9 | K34: =SUM(K17:K33) -> 29773.461 | L34: =SUM(L17:L33) -> 0
B36: Method: each pool is spread over the categories in proportion to the driver quantity chosen in column E (blue, change the driver name to re-assign). Variable/fixed behaviour follows the Project 1 chart-of-accounts mapping. Depreciation is split by asset class and follows the activity that uses the asset (warehouse assets by pallet positions, vehicles by delivery cube, office/IT by sales).

Sheet CVP_BreakEven
B1: Cost-Volume-Profit and Break-Even Analysis
B2: Sampaguita Foods & Distribution Corporation (SFDC) | PHP in thousands unless stated | contribution margin approach, reconciled to Project 1
B3: =HYPERLINK("#Cover!A1","◄ Back to Cover") -> ◄ Back to Cover
B5: Line | C5: Packaged Food | D5: Beverages | E5: Household & Personal Care | F5: Fresh & Frozen | G5: Total
B6: A. CONTRIBUTION MARGIN STATEMENT
B7: Net sales | C7: =Product_Costing!C8 -> 382510 | D7: =Product_Costing!D8 -> 292182 | E7: =Product_Costing!E8 -> 170561 | F7: =Product_Costing!F8 -> 127189 | G7: =SUM(C7:F7) -> 972442
B8: Variable cost of sales | C8: =Product_Costing!C9 -> 286694 | D8: =Product_Costing!D9 -> 213400 | E8: =Product_Costing!E9 -> 119380 | F8: =Product_Costing!F9 -> 103074 | G8: =SUM(C8:F8) -> 722548
B9: Variable operating expenses | C9: =SUMIFS(ABC_Allocation!H$17:H$33,ABC_Allocation!$D$17:$D$33,"Variable") -> 17094.716 | D9: =SUMIFS(ABC_Allocation!I$17:I$33,ABC_Allocation!$D$17:$D$33,"Variable") -> 17811.505 | E9: =SUMIFS(ABC_Allocation!J$17:J$33,ABC_Allocation!$D$17:$D$33,"Variable") -> 9540.7166 | F9: =SUMIFS(ABC_Allocation!K$17:K$33,ABC_Allocation!$D$17:$D$33,"Variable") -> 5417.0628 | G9: =SUM(C9:F9) -> 49864
B10: Contribution margin | C10: =C7-C8-C9 -> 78721.284 | D10: =D7-D8-D9 -> 60970.495 | E10: =E7-E8-E9 -> 41640.283 | F10: =F7-F8-F9 -> 18697.937 | G10: =SUM(C10:F10) -> 200030
B11: Contribution margin ratio | C11: =IFERROR(C10/C7,0) -> 0.2058019 | D11: =IFERROR(D10/D7,0) -> 0.208673 | E11: =IFERROR(E10/E7,0) -> 0.24413719 | F11: =IFERROR(F10/F7,0) -> 0.14700907 | G11: =IFERROR(G10/G7,0) -> 0.20569864
B12: Fixed operating expenses (excluding depreciation) | C12: =SUMIFS(ABC_Allocation!H$17:H$33,ABC_Allocation!$D$17:$D$33,"Fixed",ABC_Allocation!$C$17:$C$33,"<>Depreciation") -> 43835.558 | D12: =SUMIFS(ABC_Allocation!I$17:I$33,ABC_Allocation!$D$17:$D$33,"Fixed",ABC_Allocation!$C$17:$C$33,"<>Depreciation") -> 33786.913 | E12: =SUMIFS(ABC_Allocation!J$17:J$33,ABC_Allocation!$D$17:$D$33,"Fixed",ABC_Allocation!$C$17:$C$33,"<>Depreciation") -> 21219.427 | F12: =SUMIFS(ABC_Allocation!K$17:K$33,ABC_Allocation!$D$17:$D$33,"Fixed",ABC_Allocation!$C$17:$C$33,"<>Depreciation") -> 21198.101 | G12: =SUM(C12:F12) -> 120040
B13: Depreciation (fixed) | C13: =SUMIFS(ABC_Allocation!H$17:H$33,ABC_Allocation!$C$17:$C$33,"Depreciation") -> 7214.0884 | D13: =SUMIFS(ABC_Allocation!I$17:I$33,ABC_Allocation!$C$17:$C$33,"Depreciation") -> 6852.8583 | E13: =SUMIFS(ABC_Allocation!J$17:J$33,ABC_Allocation!$C$17:$C$33,"Depreciation") -> 4031.7562 | F13: =SUMIFS(ABC_Allocation!K$17:K$33,ABC_Allocation!$C$17:$C$33,"Depreciation") -> 3158.2972 | G13: =SUM(C13:F13) -> 21257
B14: Total fixed costs | C14: =C12+C13 -> 51049.647 | D14: =D12+D13 -> 40639.771 | E14: =E12+E13 -> 25251.183 | F14: =F12+F13 -> 24356.398 | G14: =SUM(C14:F14) -> 141297
B15: Operating profit | C15: =C10-C14 -> 27671.637 | D15: =D10-D14 -> 20330.724 | E15: =E10-E14 -> 16389.1 | F15: =F10-F14 -> -5658.4613 | G15: =SUM(C15:F15) -> 58733
B16: B. BREAK-EVEN ANALYSIS
B17: Stand-alone break-even net sales (category's own fixed costs) | C17: =IFERROR(C14/C11,0) -> 248052.36 | D17: =IFERROR(D14/D11,0) -> 194753.38 | E17: =IFERROR(E14/E11,0) -> 103430.3 | F17: =IFERROR(F14/F11,0) -> 165679.56 | G17: n/a | I17: Each category carries a share of fixed costs by activity. Categories with a stand-alone break-even above actual sales do not cover their own fixed costs.
B18: Break-even net sales at current sales mix | C18: =$G$19*C7/$G$7 -> 270197.05 | D18: =$G$19*D7/$G$7 -> 206391.24 | E18: =$G$19*E7/$G$7 -> 120480.72 | F18: =$G$19*F7/$G$7 -> 89843.644 | G18: =SUM(C18:F18) -> 686912.65
B19: Company break-even net sales (total fixed costs / blended CM ratio) | G19: =IFERROR(G14/G11,0) -> 686912.65
B20: Break-even cases ('000) at current mix | C20: =IFERROR(C18/Product_Costing!C27,0) -> 416.76364 | D20: =IFERROR(D18/Product_Costing!D27,0) -> 459.14638 | E20: =IFERROR(E18/Product_Costing!E27,0) -> 197.78613 | F20: =IFERROR(F18/Product_Costing!F27,0) -> 113.02065 | G20: =SUM(C20:F20) -> 1186.7168
B21: Break-even as % of actual net sales | C21: =IFERROR(C18/C7,0) -> 0.70637904 | D21: =IFERROR(D18/D7,0) -> 0.70637904 | E21: =IFERROR(E18/E7,0) -> 0.70637904 | F21: =IFERROR(F18/F7,0) -> 0.70637904 | G21: =IFERROR(G18/G7,0) -> 0.70637904
B22: Margin of safety (PHP '000) | C22: =C7-C18 -> 112312.95 | D22: =D7-D18 -> 85790.758 | E22: =E7-E18 -> 50080.284 | F22: =F7-F18 -> 37345.356 | G22: =G7-G18 -> 285529.35
B23: Margin of safety % | C23: =IFERROR(C22/C7,0) -> 0.29362096 | D23: =IFERROR(D22/D7,0) -> 0.29362096 | E23: =IFERROR(E22/E7,0) -> 0.29362096 | F23: =IFERROR(F22/F7,0) -> 0.29362096 | G23: =IFERROR(G22/G7,0) -> 0.29362096
B24: Degree of operating leverage (CM / operating profit) | C24: =IFERROR(C10/C15,0) -> 2.8448365 | D24: =IFERROR(D10/D15,0) -> 2.9989338 | E24: =IFERROR(E10/E15,0) -> 2.5407303 | F24: =IFERROR(F10/F15,0) -> -3.3044208 | G24: =IFERROR(G10/G15,0) -> 3.4057515
B26: C. TARGET PROFIT ANALYSIS
B27: Target operating profit (Inputs) | G27: =Target_OP -> 75000
B28: Required net sales = (fixed costs + target profit) / blended CM ratio | G28: =IFERROR((G14+G27)/G11,0) -> 1051523.7
B29: Increase over actual net sales | F29: =IFERROR(G28/G7-1,0) -> 0.081322802 | G29: =G28-G7 -> 79081.708
B30: Required cases ('000) at average price | G30: =IFERROR(G28/Product_Costing!G27,0) -> 1816.6223
B33: D. RECONCILIATION TO PROJECT 1 (EXPENSE ANALYSIS, SECTION C)
B34: Item | C34: This model | D34: Project 1 | E34: Difference
B35: Contribution margin | C35: =G10 -> 200030 | D35: =FS_Data!E14 -> 200030 | E35: =C35-D35 -> 0
B36: Variable operating expenses | C36: =G9 -> 49864 | D36: =FS_Data!E13 -> 49864 | E36: =C36-D36 -> 0
B37: Fixed operating expenses | C37: =G12 -> 120040 | D37: =FS_Data!E15 -> 120040 | E37: =C37-D37 -> 0
B38: Break-even net sales | C38: =G19 -> 686912.65 | D38: =FS_Data!E17 -> 686912.65 | E38: =C38-D38 -> 0
B39: Margin of safety % | C39: =G23 -> 0.29362096 | D39: =FS_Data!E18 -> 0.29362096 | E39: =C39-D39 -> 0
B40: Degree of operating leverage | C40: =G24 -> 3.4057515 | D40: =FS_Data!E19 -> 3.4057515 | E40: =C40-D40 -> 0

Sheet Cost_Behaviour
B1: Cost Behaviour: High-Low and Regression
B2: Sampaguita Foods & Distribution Corporation (SFDC) | PHP in thousands | tests the fixed/variable classification against 12 months of data
B3: =HYPERLINK("#Cover!A1","◄ Back to Cover") -> ◄ Back to Cover
B5: A. MONTHLY COST MATRIX (FROM THE LEDGERS)
B6: Expense line | C6: Project 1 behaviour | E6: Jan | F6: Feb | G6: Mar | H6: Apr | I6: May | J6: Jun | K6: Jul | L6: Aug | M6: Sep | N6: Oct | O6: Nov | P6: Dec | Q6: Slope (% of sales) | R6: R² | S6: Regression says
B7: Month number | E7: 1 | F7: 2 | G7: 3 | H7: 4 | I7: 5 | J7: 6 | K7: 7 | L7: 8 | M7: 9 | N7: 10 | O7: 11 | P7: 12
B8: Net sales | E8: =SUMIFS(S_Sales,S_Year,Cost_Year,S_Month,E$7) -> 74463 | F8: =SUMIFS(S_Sales,S_Year,Cost_Year,S_Month,F$7) -> 71689 | G8: =SUMIFS(S_Sales,S_Year,Cost_Year,S_Month,G$7) -> 77757 | H8: =SUMIFS(S_Sales,S_Year,Cost_Year,S_Month,H$7) -> 79023 | I8: =SUMIFS(S_Sales,S_Year,Cost_Year,S_Month,I$7) -> 81946 | J8: =SUMIFS(S_Sales,S_Year,Cost_Year,S_Month,J$7) -> 79418 | K8: =SUMIFS(S_Sales,S_Year,Cost_Year,S_Month,K$7) -> 81667 | L8: =SUMIFS(S_Sales,S_Year,Cost_Year,S_Month,L$7) -> 81105 | ... P8: =SUMIFS(S_Sales,S_Year,Cost_Year,S_Month,P$7) -> 93902
B9: Sales commissions & incentives | C9: Variable | E9: =SUMIFS(E_Amt,E_Year,Cost_Year,E_Month,E$7,E_Line,$B9) -> 1171 | F9: =SUMIFS(E_Amt,E_Year,Cost_Year,E_Month,F$7,E_Line,$B9) -> 1158 | G9: =SUMIFS(E_Amt,E_Year,Cost_Year,E_Month,G$7,E_Line,$B9) -> 1270 | H9: =SUMIFS(E_Amt,E_Year,Cost_Year,E_Month,H$7,E_Line,$B9) -> 1284 | I9: =SUMIFS(E_Amt,E_Year,Cost_Year,E_Month,I$7,E_Line,$B9) -> 1347 | J9: =SUMIFS(E_Amt,E_Year,Cost_Year,E_Month,J$7,E_Line,$B9) -> 1282 | K9: =SUMIFS(E_Amt,E_Year,Cost_Year,E_Month,K$7,E_Line,$B9) -> 1314 | L9: =SUMIFS(E_Amt,E_Year,Cost_Year,E_Month,L$7,E_Line,$B9) -> 1272 | ... P9: =SUMIFS(E_Amt,E_Year,Cost_Year,E_Month,P$7,E_Line,$B9) -> 1546 | Q9: =SLOPE(E9:P9,$E$8:$P$8) -> 0.017636726 | R9: =RSQ(E9:P9,$E$8:$P$8) -> 0.96210724 | S9: =IF(AND(R9>=0.5,Q9>=0.002),"Variable",IF(R9>=0.5,"Mixed","Fixed")) -> Variable | T9: =IF(S9=C9,"✔ agrees with Project 1",IF(S9="Mixed","◐ semi-variable","✖ review classification")) -> ✔ agrees with Project 1
B10: Advertising & promotions | C10: Variable | E10: =SUMIFS(E_Amt,E_Year,Cost_Year,E_Month,E$7,E_Line,$B10) -> 655 | F10: =SUMIFS(E_Amt,E_Year,Cost_Year,E_Month,F$7,E_Line,$B10) -> 662 | G10: =SUMIFS(E_Amt,E_Year,Cost_Year,E_Month,G$7,E_Line,$B10) -> 703 | H10: =SUMIFS(E_Amt,E_Year,Cost_Year,E_Month,H$7,E_Line,$B10) -> 717 | I10: =SUMIFS(E_Amt,E_Year,Cost_Year,E_Month,I$7,E_Line,$B10) -> 727 | J10: =SUMIFS(E_Amt,E_Year,Cost_Year,E_Month,J$7,E_Line,$B10) -> 728 | K10: =SUMIFS(E_Amt,E_Year,Cost_Year,E_Month,K$7,E_Line,$B10) -> 747 | L10: =SUMIFS(E_Amt,E_Year,Cost_Year,E_Month,L$7,E_Line,$B10) -> 740 | ... P10: =SUMIFS(E_Amt,E_Year,Cost_Year,E_Month,P$7,E_Line,$B10) -> 1027 | Q10: =SLOPE(E10:P10,$E$8:$P$8) -> 0.019793015 | R10: =RSQ(E10:P10,$E$8:$P$8) -> 0.7569427 | S10: =IF(AND(R10>=0.5,Q10>=0.002),"Variable",IF(R10>=0.5,"Mixed","Fixed")) -> Variable | T10: =IF(S10=C10,"✔ agrees with Project 1",IF(S10="Mixed","◐ semi-variable","✖ review classification")) -> ✔ agrees with Project 1
B11: Freight & delivery | C11: Variable | E11: =SUMIFS(E_Amt,E_Year,Cost_Year,E_Month,E$7,E_Line,$B11) -> 1837 | F11: =SUMIFS(E_Amt,E_Year,Cost_Year,E_Month,F$7,E_Line,$B11) -> 1670 | G11: =SUMIFS(E_Amt,E_Year,Cost_Year,E_Month,G$7,E_Line,$B11) -> 1865 | H11: =SUMIFS(E_Amt,E_Year,Cost_Year,E_Month,H$7,E_Line,$B11) -> 1941 | I11: =SUMIFS(E_Amt,E_Year,Cost_Year,E_Month,I$7,E_Line,$B11) -> 1936 | J11: =SUMIFS(E_Amt,E_Year,Cost_Year,E_Month,J$7,E_Line,$B11) -> 1929 | K11: =SUMIFS(E_Amt,E_Year,Cost_Year,E_Month,K$7,E_Line,$B11) -> 2014 | L11: =SUMIFS(E_Amt,E_Year,Cost_Year,E_Month,L$7,E_Line,$B11) -> 1914 | ... P11: =SUMIFS(E_Amt,E_Year,Cost_Year,E_Month,P$7,E_Line,$B11) -> 2228 | Q11: =SLOPE(E11:P11,$E$8:$P$8) -> 0.022415142 | R11: =RSQ(E11:P11,$E$8:$P$8) -> 0.91452463 | S11: =IF(AND(R11>=0.5,Q11>=0.002),"Variable",IF(R11>=0.5,"Mixed","Fixed")) -> Variable | T11: =IF(S11=C11,"✔ agrees with Project 1",IF(S11="Mixed","◐ semi-variable","✖ review classification")) -> ✔ agrees with Project 1
B12: Warehouse rent & utilities | C12: Fixed | E12: =SUMIFS(E_Amt,E_Year,Cost_Year,E_Month,E$7,E_Line,$B12) -> 2107 | F12: =SUMIFS(E_Amt,E_Year,Cost_Year,E_Month,F$7,E_Line,$B12) -> 2121 | G12: =SUMIFS(E_Amt,E_Year,Cost_Year,E_Month,G$7,E_Line,$B12) -> 2096 | H12: =SUMIFS(E_Amt,E_Year,Cost_Year,E_Month,H$7,E_Line,$B12) -> 2104 | I12: =SUMIFS(E_Amt,E_Year,Cost_Year,E_Month,I$7,E_Line,$B12) -> 2058 | J12: =SUMIFS(E_Amt,E_Year,Cost_Year,E_Month,J$7,E_Line,$B12) -> 2064 | K12: =SUMIFS(E_Amt,E_Year,Cost_Year,E_Month,K$7,E_Line,$B12) -> 2061 | L12: =SUMIFS(E_Amt,E_Year,Cost_Year,E_Month,L$7,E_Line,$B12) -> 2065 | ... P12: =SUMIFS(E_Amt,E_Year,Cost_Year,E_Month,P$7,E_Line,$B12) -> 2050 | Q12: =SLOPE(E12:P12,$E$8:$P$8) -> -0.0027988275 | R12: =RSQ(E12:P12,$E$8:$P$8) -> 0.3848826 | S12: =IF(AND(R12>=0.5,Q12>=0.002),"Variable",IF(R12>=0.5,"Mixed","Fixed")) -> Fixed | T12: =IF(S12=C12,"✔ agrees with Project 1",IF(S12="Mixed","◐ semi-variable","✖ review classification")) -> ✔ agrees with Project 1
B13: Selling & logistics staff costs | C13: Fixed | E13: =SUMIFS(E_Amt,E_Year,Cost_Year,E_Month,E$7,E_Line,$B13) -> 2691 | F13: =SUMIFS(E_Amt,E_Year,Cost_Year,E_Month,F$7,E_Line,$B13) -> 2705 | G13: =SUMIFS(E_Amt,E_Year,Cost_Year,E_Month,G$7,E_Line,$B13) -> 2758 | H13: =SUMIFS(E_Amt,E_Year,Cost_Year,E_Month,H$7,E_Line,$B13) -> 2730 | I13: =SUMIFS(E_Amt,E_Year,Cost_Year,E_Month,I$7,E_Line,$B13) -> 2705 | J13: =SUMIFS(E_Amt,E_Year,Cost_Year,E_Month,J$7,E_Line,$B13) -> 2716 | K13: =SUMIFS(E_Amt,E_Year,Cost_Year,E_Month,K$7,E_Line,$B13) -> 2717 | L13: =SUMIFS(E_Amt,E_Year,Cost_Year,E_Month,L$7,E_Line,$B13) -> 2727 | ... P13: =SUMIFS(E_Amt,E_Year,Cost_Year,E_Month,P$7,E_Line,$B13) -> 2685 | Q13: =SLOPE(E13:P13,$E$8:$P$8) -> -0.00030856397 | R13: =RSQ(E13:P13,$E$8:$P$8) -> 0.0038847213 | S13: =IF(AND(R13>=0.5,Q13>=0.002),"Variable",IF(R13>=0.5,"Mixed","Fixed")) -> Fixed | T13: =IF(S13=C13,"✔ agrees with Project 1",IF(S13="Mixed","◐ semi-variable","✖ review classification")) -> ✔ agrees with Project 1
B14: Salaries & wages (G&A) | C14: Fixed | E14: =SUMIFS(E_Amt,E_Year,Cost_Year,E_Month,E$7,E_Line,$B14) -> 2500 | F14: =SUMIFS(E_Amt,E_Year,Cost_Year,E_Month,F$7,E_Line,$B14) -> 2531 | G14: =SUMIFS(E_Amt,E_Year,Cost_Year,E_Month,G$7,E_Line,$B14) -> 2474 | H14: =SUMIFS(E_Amt,E_Year,Cost_Year,E_Month,H$7,E_Line,$B14) -> 2562 | I14: =SUMIFS(E_Amt,E_Year,Cost_Year,E_Month,I$7,E_Line,$B14) -> 2567 | J14: =SUMIFS(E_Amt,E_Year,Cost_Year,E_Month,J$7,E_Line,$B14) -> 2512 | K14: =SUMIFS(E_Amt,E_Year,Cost_Year,E_Month,K$7,E_Line,$B14) -> 2540 | L14: =SUMIFS(E_Amt,E_Year,Cost_Year,E_Month,L$7,E_Line,$B14) -> 2553 | ... P14: =SUMIFS(E_Amt,E_Year,Cost_Year,E_Month,P$7,E_Line,$B14) -> 2473 | Q14: =SLOPE(E14:P14,$E$8:$P$8) -> -0.001930008 | R14: =RSQ(E14:P14,$E$8:$P$8) -> 0.10634975 | S14: =IF(AND(R14>=0.5,Q14>=0.002),"Variable",IF(R14>=0.5,"Mixed","Fixed")) -> Fixed | T14: =IF(S14=C14,"✔ agrees with Project 1",IF(S14="Mixed","◐ semi-variable","✖ review classification")) -> ✔ agrees with Project 1
B15: Employee benefits & contributions | C15: Fixed | E15: =SUMIFS(E_Amt,E_Year,Cost_Year,E_Month,E$7,E_Line,$B15) -> 673 | F15: =SUMIFS(E_Amt,E_Year,Cost_Year,E_Month,F$7,E_Line,$B15) -> 674 | G15: =SUMIFS(E_Amt,E_Year,Cost_Year,E_Month,G$7,E_Line,$B15) -> 683 | H15: =SUMIFS(E_Amt,E_Year,Cost_Year,E_Month,H$7,E_Line,$B15) -> 667 | I15: =SUMIFS(E_Amt,E_Year,Cost_Year,E_Month,I$7,E_Line,$B15) -> 678 | J15: =SUMIFS(E_Amt,E_Year,Cost_Year,E_Month,J$7,E_Line,$B15) -> 677 | K15: =SUMIFS(E_Amt,E_Year,Cost_Year,E_Month,K$7,E_Line,$B15) -> 685 | L15: =SUMIFS(E_Amt,E_Year,Cost_Year,E_Month,L$7,E_Line,$B15) -> 666 | ... P15: =SUMIFS(E_Amt,E_Year,Cost_Year,E_Month,P$7,E_Line,$B15) -> 666 | Q15: =SLOPE(E15:P15,$E$8:$P$8) -> 3.5754487e-05 | R15: =RSQ(E15:P15,$E$8:$P$8) -> 0.00055796889 | S15: =IF(AND(R15>=0.5,Q15>=0.002),"Variable",IF(R15>=0.5,"Mixed","Fixed")) -> Fixed | T15: =IF(S15=C15,"✔ agrees with Project 1",IF(S15="Mixed","◐ semi-variable","✖ review classification")) -> ✔ agrees with Project 1
B16: Professional fees | C16: Fixed | E16: =SUMIFS(E_Amt,E_Year,Cost_Year,E_Month,E$7,E_Line,$B16) -> 335 | F16: =SUMIFS(E_Amt,E_Year,Cost_Year,E_Month,F$7,E_Line,$B16) -> 325 | G16: =SUMIFS(E_Amt,E_Year,Cost_Year,E_Month,G$7,E_Line,$B16) -> 867 | H16: =SUMIFS(E_Amt,E_Year,Cost_Year,E_Month,H$7,E_Line,$B16) -> 330 | I16: =SUMIFS(E_Amt,E_Year,Cost_Year,E_Month,I$7,E_Line,$B16) -> 331 | J16: =SUMIFS(E_Amt,E_Year,Cost_Year,E_Month,J$7,E_Line,$B16) -> 328 | K16: =SUMIFS(E_Amt,E_Year,Cost_Year,E_Month,K$7,E_Line,$B16) -> 333 | L16: =SUMIFS(E_Amt,E_Year,Cost_Year,E_Month,L$7,E_Line,$B16) -> 326 | ... P16: =SUMIFS(E_Amt,E_Year,Cost_Year,E_Month,P$7,E_Line,$B16) -> 334 | Q16: =SLOPE(E16:P16,$E$8:$P$8) -> -0.0048740225 | R16: =RSQ(E16:P16,$E$8:$P$8) -> 0.031044455 | S16: =IF(AND(R16>=0.5,Q16>=0.002),"Variable",IF(R16>=0.5,"Mixed","Fixed")) -> Fixed | T16: =IF(S16=C16,"✔ agrees with Project 1",IF(S16="Mixed","◐ semi-variable","✖ review classification")) -> ✔ agrees with Project 1
B17: Office rent & utilities | C17: Fixed | E17: =SUMIFS(E_Amt,E_Year,Cost_Year,E_Month,E$7,E_Line,$B17) -> 574 | F17: =SUMIFS(E_Amt,E_Year,Cost_Year,E_Month,F$7,E_Line,$B17) -> 580 | G17: =SUMIFS(E_Amt,E_Year,Cost_Year,E_Month,G$7,E_Line,$B17) -> 563 | H17: =SUMIFS(E_Amt,E_Year,Cost_Year,E_Month,H$7,E_Line,$B17) -> 569 | I17: =SUMIFS(E_Amt,E_Year,Cost_Year,E_Month,I$7,E_Line,$B17) -> 561 | J17: =SUMIFS(E_Amt,E_Year,Cost_Year,E_Month,J$7,E_Line,$B17) -> 568 | K17: =SUMIFS(E_Amt,E_Year,Cost_Year,E_Month,K$7,E_Line,$B17) -> 577 | L17: =SUMIFS(E_Amt,E_Year,Cost_Year,E_Month,L$7,E_Line,$B17) -> 580 | ... P17: =SUMIFS(E_Amt,E_Year,Cost_Year,E_Month,P$7,E_Line,$B17) -> 568 | Q17: =SLOPE(E17:P17,$E$8:$P$8) -> -0.00040837906 | R17: =RSQ(E17:P17,$E$8:$P$8) -> 0.11633763 | S17: =IF(AND(R17>=0.5,Q17>=0.002),"Variable",IF(R17>=0.5,"Mixed","Fixed")) -> Fixed | T17: =IF(S17=C17,"✔ agrees with Project 1",IF(S17="Mixed","◐ semi-variable","✖ review classification")) -> ✔ agrees with Project 1
B18: Repairs & maintenance | C18: Fixed | E18: =SUMIFS(E_Amt,E_Year,Cost_Year,E_Month,E$7,E_Line,$B18) -> 257 | F18: =SUMIFS(E_Amt,E_Year,Cost_Year,E_Month,F$7,E_Line,$B18) -> 243 | G18: =SUMIFS(E_Amt,E_Year,Cost_Year,E_Month,G$7,E_Line,$B18) -> 237 | H18: =SUMIFS(E_Amt,E_Year,Cost_Year,E_Month,H$7,E_Line,$B18) -> 232 | I18: =SUMIFS(E_Amt,E_Year,Cost_Year,E_Month,I$7,E_Line,$B18) -> 234 | J18: =SUMIFS(E_Amt,E_Year,Cost_Year,E_Month,J$7,E_Line,$B18) -> 219 | K18: =SUMIFS(E_Amt,E_Year,Cost_Year,E_Month,K$7,E_Line,$B18) -> 206 | L18: =SUMIFS(E_Amt,E_Year,Cost_Year,E_Month,L$7,E_Line,$B18) -> 222 | ... P18: =SUMIFS(E_Amt,E_Year,Cost_Year,E_Month,P$7,E_Line,$B18) -> 239 | Q18: =SLOPE(E18:P18,$E$8:$P$8) -> -0.0010448141 | R18: =RSQ(E18:P18,$E$8:$P$8) -> 0.13145841 | S18: =IF(AND(R18>=0.5,Q18>=0.002),"Variable",IF(R18>=0.5,"Mixed","Fixed")) -> Fixed | T18: =IF(S18=C18,"✔ agrees with Project 1",IF(S18="Mixed","◐ semi-variable","✖ review classification")) -> ✔ agrees with Project 1
B19: Taxes, licenses & insurance | C19: Fixed | E19: =SUMIFS(E_Amt,E_Year,Cost_Year,E_Month,E$7,E_Line,$B19) -> 456 | F19: =SUMIFS(E_Amt,E_Year,Cost_Year,E_Month,F$7,E_Line,$B19) -> 461 | G19: =SUMIFS(E_Amt,E_Year,Cost_Year,E_Month,G$7,E_Line,$B19) -> 460 | H19: =SUMIFS(E_Amt,E_Year,Cost_Year,E_Month,H$7,E_Line,$B19) -> 453 | I19: =SUMIFS(E_Amt,E_Year,Cost_Year,E_Month,I$7,E_Line,$B19) -> 457 | J19: =SUMIFS(E_Amt,E_Year,Cost_Year,E_Month,J$7,E_Line,$B19) -> 457 | K19: =SUMIFS(E_Amt,E_Year,Cost_Year,E_Month,K$7,E_Line,$B19) -> 454 | L19: =SUMIFS(E_Amt,E_Year,Cost_Year,E_Month,L$7,E_Line,$B19) -> 452 | ... P19: =SUMIFS(E_Amt,E_Year,Cost_Year,E_Month,P$7,E_Line,$B19) -> 462 | Q19: =SLOPE(E19:P19,$E$8:$P$8) -> 0.00014136694 | R19: =RSQ(E19:P19,$E$8:$P$8) -> 0.047257225 | S19: =IF(AND(R19>=0.5,Q19>=0.002),"Variable",IF(R19>=0.5,"Mixed","Fixed")) -> Fixed | T19: =IF(S19=C19,"✔ agrees with Project 1",IF(S19="Mixed","◐ semi-variable","✖ review classification")) -> ✔ agrees with Project 1
B20: Communication, IT & supplies | C20: Fixed | E20: =SUMIFS(E_Amt,E_Year,Cost_Year,E_Month,E$7,E_Line,$B20) -> 371 | F20: =SUMIFS(E_Amt,E_Year,Cost_Year,E_Month,F$7,E_Line,$B20) -> 374 | G20: =SUMIFS(E_Amt,E_Year,Cost_Year,E_Month,G$7,E_Line,$B20) -> 377 | H20: =SUMIFS(E_Amt,E_Year,Cost_Year,E_Month,H$7,E_Line,$B20) -> 378 | I20: =SUMIFS(E_Amt,E_Year,Cost_Year,E_Month,I$7,E_Line,$B20) -> 371 | J20: =SUMIFS(E_Amt,E_Year,Cost_Year,E_Month,J$7,E_Line,$B20) -> 368 | K20: =SUMIFS(E_Amt,E_Year,Cost_Year,E_Month,K$7,E_Line,$B20) -> 369 | L20: =SUMIFS(E_Amt,E_Year,Cost_Year,E_Month,L$7,E_Line,$B20) -> 366 | ... P20: =SUMIFS(E_Amt,E_Year,Cost_Year,E_Month,P$7,E_Line,$B20) -> 372 | Q20: =SLOPE(E20:P20,$E$8:$P$8) -> -0.00016617022 | R20: =RSQ(E20:P20,$E$8:$P$8) -> 0.047447765 | S20: =IF(AND(R20>=0.5,Q20>=0.002),"Variable",IF(R20>=0.5,"Mixed","Fixed")) -> Fixed | T20: =IF(S20=C20,"✔ agrees with Project 1",IF(S20="Mixed","◐ semi-variable","✖ review classification")) -> ✔ agrees with Project 1
B21: Bad debts & credit losses | C21: Variable | E21: =SUMIFS(E_Amt,E_Year,Cost_Year,E_Month,E$7,E_Line,$B21) -> 114 | F21: =SUMIFS(E_Amt,E_Year,Cost_Year,E_Month,F$7,E_Line,$B21) -> 105 | G21: =SUMIFS(E_Amt,E_Year,Cost_Year,E_Month,G$7,E_Line,$B21) -> 117 | H21: =SUMIFS(E_Amt,E_Year,Cost_Year,E_Month,H$7,E_Line,$B21) -> 121 | I21: =SUMIFS(E_Amt,E_Year,Cost_Year,E_Month,I$7,E_Line,$B21) -> 125 | J21: =SUMIFS(E_Amt,E_Year,Cost_Year,E_Month,J$7,E_Line,$B21) -> 119 | K21: =SUMIFS(E_Amt,E_Year,Cost_Year,E_Month,K$7,E_Line,$B21) -> 119 | L21: =SUMIFS(E_Amt,E_Year,Cost_Year,E_Month,L$7,E_Line,$B21) -> 124 | ... P21: =SUMIFS(E_Amt,E_Year,Cost_Year,E_Month,P$7,E_Line,$B21) -> 145 | Q21: =SLOPE(E21:P21,$E$8:$P$8) -> 0.0017127825 | R21: =RSQ(E21:P21,$E$8:$P$8) -> 0.95286329 | S21: =IF(AND(R21>=0.5,Q21>=0.002),"Variable",IF(R21>=0.5,"Mixed","Fixed")) -> Mixed | T21: =IF(S21=C21,"✔ agrees with Project 1",IF(S21="Mixed","◐ semi-variable","✖ review classification")) -> ◐ semi-variable
B22: Total ledger operating expenses | E22: =SUM(E9:E21) -> 13741 | F22: =SUM(F9:F21) -> 13609 | G22: =SUM(G9:G21) -> 14470 | H22: =SUM(H9:H21) -> 14088 | I22: =SUM(I9:I21) -> 14097 | J22: =SUM(J9:J21) -> 13967 | K22: =SUM(K9:K21) -> 14136 | L22: =SUM(L9:L21) -> 14007 | ... P22: =SUM(P9:P21) -> 14795 | Q22: =SLOPE(E22:P22,$E$8:$P$8) -> 0.050204002 | R22: =RSQ(E22:P22,$E$8:$P$8) -> 0.74521513
B24: B. HIGH-LOW METHOD ON TOTAL LEDGER OPERATING EXPENSES
B25: High month (highest net sales) | C25: =INDEX($E$7:$P$7,MATCH(MAX($E$8:$P$8),$E$8:$P$8,0)) -> 12
B26: Net sales - high | C26: =MAX($E$8:$P$8) -> 93902
B27: Total expenses - high | C27: =INDEX($E$22:$P$22,MATCH(MAX($E$8:$P$8),$E$8:$P$8,0)) -> 14795
B28: Low month (lowest net sales) | C28: =INDEX($E$7:$P$7,MATCH(MIN($E$8:$P$8),$E$8:$P$8,0)) -> 2
B29: Net sales - low | C29: =MIN($E$8:$P$8) -> 71689
B30: Total expenses - low | C30: =INDEX($E$22:$P$22,MATCH(MIN($E$8:$P$8),$E$8:$P$8,0)) -> 13609
B31: Variable cost rate (% of net sales) | C31: =IFERROR((C27-C30)/(C26-C29),0) -> 0.053392158
B32: Implied monthly fixed cost | C32: =C27-C31*C26 -> 9781.3696
B33: Regression: variable rate / intercept | C33: =Q22 -> 0.050204002 | D33: =INTERCEPT(E22:P22,$E$8:$P$8) -> 10090.293
B34: Project 1 classification: variable rate / monthly fixed | C34: =FS_Data!E13/P1_Sales -> 0.051277094 | D34: =FS_Data!E15/12 -> 10003.333
B36: Interpretation: the ledger-based high-low and regression estimates are statistical and noisy (12 points, seasonal promotions, inflation during the year). They support - rather than replace - the accounting classification used in the CVP analysis. A line marked 'review classification' behaves differently from its label and should be examined before relying on break-even figures.

Sheet Sensitivity
B1: What-If and Sensitivity Analysis
B2: Sampaguita Foods & Distribution Corporation (SFDC) | PHP in thousands | change the yellow cells to test scenarios
B3: =HYPERLINK("#Cover!A1","◄ Back to Cover") -> ◄ Back to Cover
B5: A. SCENARIO INPUTS
B6: Selling price change | C6: 0
B7: Volume change | C7: 0.05
B8: Cost of sales per unit change | C8: 0.01
B9: Variable operating expense per unit change | C9: 0
B10: Fixed cost change | C10: 0.03
B12: PHP '000 | C12: Base case | D12: Scenario | E12: Change | F12: Change %
B13: Net sales | C13: =CVP_BreakEven!G7 -> 972442 | D13: =CVP_BreakEven!G7*(1+C7)*(1+C6) -> 1021064.1 | E13: =D13-C13 -> 48622.1 | F13: =IFERROR(D13/C13-1,0) -> 0.05
B14: Variable cost of sales | C14: =CVP_BreakEven!G8 -> 722548 | D14: =CVP_BreakEven!G8*(1+C7)*(1+C8) -> 766262.15 | E14: =D14-C14 -> 43714.154 | F14: =IFERROR(D14/C14-1,0) -> 0.0605
B15: Variable operating expenses | C15: =CVP_BreakEven!G9 -> 49864 | D15: =CVP_BreakEven!G9*(1+C7)*(1+C9) -> 52357.2 | E15: =D15-C15 -> 2493.2 | F15: =IFERROR(D15/C15-1,0) -> 0.05
B16: Contribution margin | C16: =C13-C14-C15 -> 200030 | D16: =D13-D14-D15 -> 202444.75 | E16: =D16-C16 -> 2414.746 | F16: =IFERROR(D16/C16-1,0) -> 0.012071919
B17: Fixed costs (incl. depreciation) | C17: =CVP_BreakEven!G14 -> 141297 | D17: =CVP_BreakEven!G14*(1+C10) -> 145535.91 | E17: =D17-C17 -> 4238.91 | F17: =IFERROR(D17/C17-1,0) -> 0.03
B18: Operating profit | C18: =C16-C17 -> 58733 | D18: =D16-D17 -> 56908.836 | E18: =D18-C18 -> -1824.164 | F18: =IFERROR(D18/C18-1,0) -> -0.031058587
B19: Contribution margin ratio | C19: =IFERROR(C16/C13,0) -> 0.20569864 | D19: =IFERROR(D16/D13,0) -> 0.1982684 | E19: =D19-C19 -> -0.0074302426 | F19: =""
B20: Break-even net sales | C20: =IFERROR(C17/C19,0) -> 686912.65 | D20: =IFERROR(D17/D19,0) -> 734034.82 | E20: =D20-C20 -> 47122.172 | F20: =IFERROR(D20/C20-1,0) -> 0.068599948
B21: Margin of safety % | C21: =IFERROR(1-C20/C13,0) -> 0.29362096 | D21: =IFERROR(1-D20/D13,0) -> 0.28110799 | E21: =D21-C21 -> -0.012512965 | F21: =""
B22: Degree of operating leverage | C22: =IFERROR(C16/C18,0) -> 3.4057515 | D22: =IFERROR(D16/D18,0) -> 3.5573517 | E22: =D22-C22 -> 0.15160028 | F22: =""
B24: B. OPERATING PROFIT - VOLUME CHANGE (ROWS) x PRICE CHANGE (COLUMNS)
B25: Volume change \ Price change | C25: -0.02 | D25: -0.01 | E25: 0 | F25: 0.01 | G25: 0.02
B26: -0.1 | C26: =$C$13*(1+$B26)*(1+C$25)-($C$14+$C$15)*(1+$B26)-$C$17 -> 21226.044 | D26: =$C$13*(1+$B26)*(1+D$25)-($C$14+$C$15)*(1+$B26)-$C$17 -> 29978.022 | E26: =$C$13*(1+$B26)*(1+E$25)-($C$14+$C$15)*(1+$B26)-$C$17 -> 38730 | F26: =$C$13*(1+$B26)*(1+F$25)-($C$14+$C$15)*(1+$B26)-$C$17 -> 47481.978 | G26: =$C$13*(1+$B26)*(1+G$25)-($C$14+$C$15)*(1+$B26)-$C$17 -> 56233.956
B27: -0.05 | C27: =$C$13*(1+$B27)*(1+C$25)-($C$14+$C$15)*(1+$B27)-$C$17 -> 30255.102 | D27: =$C$13*(1+$B27)*(1+D$25)-($C$14+$C$15)*(1+$B27)-$C$17 -> 39493.301 | E27: =$C$13*(1+$B27)*(1+E$25)-($C$14+$C$15)*(1+$B27)-$C$17 -> 48731.5 | F27: =$C$13*(1+$B27)*(1+F$25)-($C$14+$C$15)*(1+$B27)-$C$17 -> 57969.699 | G27: =$C$13*(1+$B27)*(1+G$25)-($C$14+$C$15)*(1+$B27)-$C$17 -> 67207.898
B28: 0 | C28: =$C$13*(1+$B28)*(1+C$25)-($C$14+$C$15)*(1+$B28)-$C$17 -> 39284.16 | D28: =$C$13*(1+$B28)*(1+D$25)-($C$14+$C$15)*(1+$B28)-$C$17 -> 49008.58 | E28: =$C$13*(1+$B28)*(1+E$25)-($C$14+$C$15)*(1+$B28)-$C$17 -> 58733 | F28: =$C$13*(1+$B28)*(1+F$25)-($C$14+$C$15)*(1+$B28)-$C$17 -> 68457.42 | G28: =$C$13*(1+$B28)*(1+G$25)-($C$14+$C$15)*(1+$B28)-$C$17 -> 78181.84
B29: 0.05 | C29: =$C$13*(1+$B29)*(1+C$25)-($C$14+$C$15)*(1+$B29)-$C$17 -> 48313.218 | D29: =$C$13*(1+$B29)*(1+D$25)-($C$14+$C$15)*(1+$B29)-$C$17 -> 58523.859 | E29: =$C$13*(1+$B29)*(1+E$25)-($C$14+$C$15)*(1+$B29)-$C$17 -> 68734.5 | F29: =$C$13*(1+$B29)*(1+F$25)-($C$14+$C$15)*(1+$B29)-$C$17 -> 78945.141 | G29: =$C$13*(1+$B29)*(1+G$25)-($C$14+$C$15)*(1+$B29)-$C$17 -> 89155.782
B30: 0.1 | C30: =$C$13*(1+$B30)*(1+C$25)-($C$14+$C$15)*(1+$B30)-$C$17 -> 57342.276 | D30: =$C$13*(1+$B30)*(1+D$25)-($C$14+$C$15)*(1+$B30)-$C$17 -> 68039.138 | E30: =$C$13*(1+$B30)*(1+E$25)-($C$14+$C$15)*(1+$B30)-$C$17 -> 78736 | F30: =$C$13*(1+$B30)*(1+F$25)-($C$14+$C$15)*(1+$B30)-$C$17 -> 89432.862 | G30: =$C$13*(1+$B30)*(1+G$25)-($C$14+$C$15)*(1+$B30)-$C$17 -> 100129.72
B32: C. BREAK-EVEN NET SALES - FIXED COST CHANGE (ROWS) x VARIABLE COST CHANGE (COLUMNS)
B33: Fixed cost change \ Variable cost change | C33: -0.05 | D33: -0.025 | E33: 0 | F33: 0.025 | G33: 0.05
B34: -0.1 | C34: =IFERROR($C$17*(1+$B34)/(1-($C$14+$C$15)/$C$13*(1+C$33)),0) -> 518175.2 | D34: =IFERROR($C$17*(1+$B34)/(1-($C$14+$C$15)/$C$13*(1+D$33)),0) -> 563794.36 | E34: =IFERROR($C$17*(1+$B34)/(1-($C$14+$C$15)/$C$13*(1+E$33)),0) -> 618221.38 | F34: =IFERROR($C$17*(1+$B34)/(1-($C$14+$C$15)/$C$13*(1+F$33)),0) -> 684279.71 | G34: =IFERROR($C$17*(1+$B34)/(1-($C$14+$C$15)/$C$13*(1+G$33)),0) -> 766143.88
B35: -0.05 | C35: =IFERROR($C$17*(1+$B35)/(1-($C$14+$C$15)/$C$13*(1+C$33)),0) -> 546962.72 | D35: =IFERROR($C$17*(1+$B35)/(1-($C$14+$C$15)/$C$13*(1+D$33)),0) -> 595116.27 | E35: =IFERROR($C$17*(1+$B35)/(1-($C$14+$C$15)/$C$13*(1+E$33)),0) -> 652567.02 | F35: =IFERROR($C$17*(1+$B35)/(1-($C$14+$C$15)/$C$13*(1+F$33)),0) -> 722295.25 | G35: =IFERROR($C$17*(1+$B35)/(1-($C$14+$C$15)/$C$13*(1+G$33)),0) -> 808707.43
B36: 0 | C36: =IFERROR($C$17*(1+$B36)/(1-($C$14+$C$15)/$C$13*(1+C$33)),0) -> 575750.23 | D36: =IFERROR($C$17*(1+$B36)/(1-($C$14+$C$15)/$C$13*(1+D$33)),0) -> 626438.18 | E36: =IFERROR($C$17*(1+$B36)/(1-($C$14+$C$15)/$C$13*(1+E$33)),0) -> 686912.65 | F36: =IFERROR($C$17*(1+$B36)/(1-($C$14+$C$15)/$C$13*(1+F$33)),0) -> 760310.79 | G36: =IFERROR($C$17*(1+$B36)/(1-($C$14+$C$15)/$C$13*(1+G$33)),0) -> 851270.97
B37: 0.05 | C37: =IFERROR($C$17*(1+$B37)/(1-($C$14+$C$15)/$C$13*(1+C$33)),0) -> 604537.74 | D37: =IFERROR($C$17*(1+$B37)/(1-($C$14+$C$15)/$C$13*(1+D$33)),0) -> 657760.08 | E37: =IFERROR($C$17*(1+$B37)/(1-($C$14+$C$15)/$C$13*(1+E$33)),0) -> 721258.28 | F37: =IFERROR($C$17*(1+$B37)/(1-($C$14+$C$15)/$C$13*(1+F$33)),0) -> 798326.33 | G37: =IFERROR($C$17*(1+$B37)/(1-($C$14+$C$15)/$C$13*(1+G$33)),0) -> 893834.52
B38: 0.1 | C38: =IFERROR($C$17*(1+$B38)/(1-($C$14+$C$15)/$C$13*(1+C$33)),0) -> 633325.25 | D38: =IFERROR($C$17*(1+$B38)/(1-($C$14+$C$15)/$C$13*(1+D$33)),0) -> 689081.99 | E38: =IFERROR($C$17*(1+$B38)/(1-($C$14+$C$15)/$C$13*(1+E$33)),0) -> 755603.91 | F38: =IFERROR($C$17*(1+$B38)/(1-($C$14+$C$15)/$C$13*(1+F$33)),0) -> 836341.87 | G38: =IFERROR($C$17*(1+$B38)/(1-($C$14+$C$15)/$C$13*(1+G$33)),0) -> 936398.07
B40: Section B shades profits at or above the base case green. Section C reads: break-even net sales if fixed costs and the variable cost ratio change by the percentages shown. A 5% rise in variable costs lifts break-even sharply because the contribution margin ratio is thin (about 20%).

Sheet Inputs
B1: Inputs and Cost Driver Data
B2: Sampaguita Foods & Distribution Corporation (SFDC) | Blue = input, yellow fill = key assumption (fictional operating data)
B3: =HYPERLINK("#Cover!A1","◄ Back to Cover") -> ◄ Back to Cover
B5: 1. GENERAL PARAMETERS
B6: Costing year (ledger year) | C6: 2025 | I6: Cost-driver volumes below are FY2025 data; update them if you change the year.
B7: Target operating profit (PHP '000) | C7: 75000
B9: 2. VOLUME AND ACTIVITY DRIVERS BY PRODUCT CATEGORY (FY2025)
B10: Product category | C10: Cases sold ('000) | D10: Cube factor (m³ per case) | E10: Promotion share (%) | F10: Pallet positions share (%) | G10: Order lines processed ('000) | H10: Credit sales share (%) | I10: Basis
B11: Packaged Food | C11: 590 | D11: 1 | E11: 0.38 | F11: 0.36 | G11: 410 | H11: 0.8 | I11: Largest category; steady case sizes
B12: Beverages | C12: 650 | D12: 1.3 | E12: 0.32 | F12: 0.24 | G12: 360 | H12: 0.7 | I12: Heavy, bulky cases (cube 1.3) and high volume
B13: Household & Personal Care | C13: 280 | D13: 1.5 | E13: 0.18 | F13: 0.18 | G13: 230 | H13: 0.85 | I13: Bulky, low-density cartons (cube 1.5)
