Workbook

Sheet Cover
B2: PORTFOLIO PROJECT 03
B3: Excel Budgeting System
B4: Sampaguita Foods & Distribution Corporation (SFDC)
B5: Monthly budget vs actual, flex budget, reforecast and driver-based FY2026 budget built on the Project 1 ledgers
B7: Prepared by Bengie Hirnani | Version 1.0 | PHP in thousands (unless otherwise stated)
B10: Model status | C10: =Model_Status -> ✔ All 15 integrity checks passed
B11: Scope | C11: Approved FY2025 monthly budget compared with actuals rebuilt from the Project 1 ledgers; variance flags with dual thresholds; flexible budget and operating-profit bridge; rolling full-year reforecast; driver-based FY2026 budget benchmarked against the Project 1 trend forecast; interactive dashboard with month and YTD views.
B12: Data notice | C12: The company, budget and figures are fictional. Actuals reconcile to the Project 1 income statement (control totals on Checks). FY2026 drivers are management assumptions on the Assumptions sheet.
B14: NAVIGATION - click a button to jump to a sheet
B15: DASHBOARD
B16: =HYPERLINK("#Dashboard!A1","Dashboard") -> Dashboard | C16: Month / YTD selector, KPI cards, insights and 4 charts
B18: BUDGET VS ACTUAL
B19: =HYPERLINK("#Variance!A1","Variance") -> Variance | C19: Static budget vs actual with favourable/unfavourable flags
B20: =HYPERLINK("#Flex_Budget!A1","Flex Budget") -> Flex Budget | C20: Flexible budget and operating profit bridge
B21: =HYPERLINK("#Forecast!A1","Forecast") -> Forecast | C21: Rolling full-year reforecast by selected month
B23: BUDGETS
B24: =HYPERLINK("#Budget_FY2026!A1","Budget FY2026") -> Budget FY2026 | C24: Driver-based FY2026 budget by month, compared with the Project 1 trend
B25: =HYPERLINK("#Assumptions!A1","Assumptions") -> Assumptions | C25: FY2026 drivers, thresholds and parameters
B26: =HYPERLINK("#Budget_FY2025!A1","Budget FY2025") -> Budget FY2025 | C26: Approved FY2025 monthly budget (inputs)
B27: =HYPERLINK("#Actuals!A1","Actuals") -> Actuals | C27: FY2025 actuals rebuilt from the ledgers (SUMIFS)
B29: DATA AND CONTROLS
B30: =HYPERLINK("#FS_Data!A1","FS Data") -> FS Data | C30: Project 1 control totals
B31: =HYPERLINK("#Data_Sales!A1","Data Sales") -> Data Sales | C31: Monthly sales ledger (Project 1)
B32: =HYPERLINK("#Data_Expenses!A1","Data Expenses") -> Data Expenses | C32: Monthly expense ledger (Project 1)
B33: =HYPERLINK("#Chart_Data!A1","Chart Data") -> Chart Data | C33: Helper tables for charts
B34: =HYPERLINK("#Lists!A1","Lists") -> Lists | C34: Drop-down lists and selector helpers
B35: =HYPERLINK("#Checks!A1","Checks") -> Checks | C35: Model integrity checks
B36: =HYPERLINK("#Documentation!A1","Documentation") -> Documentation | C36: Purpose, method, conventions, how to update

Sheet Documentation
B1: Budgeting System Documentation
B2: Sampaguita Foods & Distribution Corporation (SFDC) | Documentation
B3: =HYPERLINK("#Cover!A1","◄ Back to Cover") -> ◄ Back to Cover
B5: 1. PURPOSE
B6: Objective | C6: Show a complete management budgeting cycle for a Philippine distributor: approved budget, monthly variance monitoring, flexible-budget diagnosis, reforecasting and next-year budget preparation.
B7: Link to Project 1 | C7: Actual sales, cost of sales and operating expenses are rebuilt from the same ledgers as Project 1 with SUMIFS; depreciation comes from the Project 1 PPE schedule. Operating profit of PHP 58.7 million for FY2025 reconciles exactly (see Checks).
B9: 2. HOW THE MODEL FLOWS
B10: Step 1 | C10: Budget_FY2025 holds the approved monthly budget (inputs). Actuals pulls the ledgers by year, month and category/line.
B11: Step 2 | C11: Variance compares budget and actual for the month or year-to-date selected on the Dashboard, applying the favourable/(unfavourable) sign convention and review flags.
B12: Step 3 | C12: Flex_Budget restates the budget at actual sales to split the operating-profit variance into sales activity and spending effects.
B13: Step 4 | C13: Forecast projects the full year from actuals to date plus run-rate-adjusted budget. Budget_FY2026 applies the Assumptions drivers to FY2025 actuals.
B15: 3. CONVENTIONS
B16: Colours | C16: Blue = input; black = formula on the same sheet; green = formula linking another sheet; yellow fill = key assumption or selector.
B17: Signs | C17: Variance columns are always 'favourable positive'. Costs are shown as positive amounts in the grids.
B18: Units | C18: PHP in thousands unless stated.
B20: 4. KEY ASSUMPTIONS AND LIMITS
B21: Budget basis | C21: FY2025 budget derived from FY2024 actuals with category growth and inflation assumptions (see note on Budget_FY2025). It is a fictional dataset created for demonstration.
B22: Depreciation | C22: Actual depreciation is the Project 1 annual charge spread evenly across months; budget depreciation is PHP 20.8 million spread evenly.
B23: Forecast | C23: Run-rate method is deliberately simple and does not model seasonality of the remaining months beyond the budget phasing.
B24: Not modelled | C24: Cash budget, balance sheet budget, capex budget and departmental (cost-centre) budgets.
B26: 5. HOW TO UPDATE
B27: New month | C27: Append ledger rows to Data_Sales / Data_Expenses and extend the S_ and E_ named ranges (Formulas > Name Manager).
B28: New budget | C28: Overwrite blue cells on Budget_FY2025 or change drivers on Assumptions; confirm the Checks banner stays green.

Sheet Dashboard
B1: Budget vs Actual Dashboard
B2: Sampaguita Foods & Distribution Corporation (SFDC) | PHP in thousands (unless otherwise stated)
B3: =HYPERLINK("#Cover!A1","◄ Back to Cover") -> ◄ Back to Cover
B5: Month | C5: Apr | E5: View | F5: Month | H5: Model integrity | J5: =Model_Status -> ✔ All 15 integrity checks passed
B7: NET SALES | E7: GROSS PROFIT | H7: OPERATING EXPENSES | K7: OPERATING PROFIT
B8: =Variance!D12 -> 79023 | E8: =Variance!D19 -> 20169 | H8: =Variance!D38 -> 15859.417 | K8: =Variance!D39 -> 4309.5833
B9: =IF(Variance!E12>=0,"▲ ","▼ ")&TEXT(ABS(Variance!F12),"0.0%")&IF(Variance!E12>=0," favourable"," unfavourable")&" vs budget" -> ▼ 5.7% unfavourable vs budget | E9: =IF(Variance!E19>=0,"▲ ","▼ ")&TEXT(ABS(Variance!F19),"0.0%")&IF(Variance!E19>=0," favourable"," unfavourable")&" vs budget" -> ▼ 5.3% unfavourable vs budget | H9: =IF(Variance!E38>=0,"▲ ","▼ ")&TEXT(ABS(Variance!F38),"0.0%")&IF(Variance!E38>=0," favourable"," unfavourable")&" vs budget" -> ▲ 0.2% favourable vs budget | K9: =IF(Variance!E39>=0,"▲ ","▼ ")&TEXT(ABS(Variance!F39),"0.0%")&IF(Variance!E39>=0," favourable"," unfavourable")&" vs budget" -> ▼ 20.6% unfavourable vs budget
B11: GROSS MARGIN | E11: OPERATING MARGIN | H11: EXPENSE LINES OVER BUDGET | K11: FULL-YEAR OPERATING PROFIT OUTLOOK
B12: =Variance!D20 -> 0.25522949 | E12: =Variance!D40 -> 0.05453581 | H12: =COUNTIF(Chart_Data!$C$20:$C$32,"<0") -> 4 | K12: =Forecast!P18 -> 52132.285
B13: =TEXT(Variance!E20*100,"+0.00;-0.00")&" pts vs budget ("&TEXT(Variance!C20,"0.0%")&")" -> +0.09 pts vs budget (25.4%) | E13: =TEXT(Variance!E40*100,"+0.00;-0.00")&" pts vs budget ("&TEXT(Variance!C40,"0.0%")&")" -> -1.02 pts vs budget (6.5%) | H13: ="of 13 lines; "&COUNTIFS(Variance!$G$22:$G$35,"▼*")&" breach the review threshold" -> of 13 lines; 1 breach the review threshold | K13: =IF(Forecast!R18>=0,"▲ ","▼ ")&TEXT(ABS(Forecast!R18),"#,##0")&" vs full-year budget" -> ▼ 3,421 vs full-year budget
B15: KEY INSIGHTS (update automatically with the selection)
B16: ="1. Net sales for "&Period_Label&" were PHP "&TEXT(Variance!D12/1000,"#,##0.0")&" million, "&TEXT(ABS(Variance!F12),"0.0%")&IF(Variance!E12>=0," above"," below")&" budget." -> 1. Net sales for Apr FY2025 were PHP 79.0 million, 5.7% below budget.
B17: ="2. Operating profit was PHP "&TEXT(Variance!D39/1000,"#,##0.0")&" million, "&TEXT(ABS(Variance!F39),"0.0%")&IF(Variance!E39>=0," above"," below")&" budget; gross margin "&TEXT(Variance!D20,"0.0%")&" vs "&TEXT(Variance!C20,"0.0%")&" budgeted." -> 2. Operating profit was PHP 4.3 million, 20.6% below budget; gross margin 25.5% vs 25.4% budgeted.
B18: ="3. Largest unfavourable expense line: "&Chart_Data!C34&IF(Chart_Data!C35<0," (PHP "&TEXT(-Chart_Data!C35,"#,##0")&"K over budget).",".")&" Largest favourable: "&Chart_Data!C36&IF(Chart_Data!C37>0," (PHP "&TEXT(Chart_Data!C37,"#,##0")&"K under budget).",".") -> 3. Largest unfavourable expense line: Warehouse rent & utilities (PHP 116K over budget). Largest favourable: Freight & delivery (PHP 73K under budget).
B19: ="4. Flex budget: sales activity added PHP "&TEXT(Flex_Budget!F23,"#,##0;(#,##0)")&"K to budgeted profit; spending and margin effects added PHP "&TEXT(Flex_Budget!G23,"#,##0;(#,##0)")&"K." -> 4. Flex budget: sales activity added PHP (968)K to budgeted profit; spending and margin effects added PHP (149)K.
B20: ="5. Reforecast full-year operating profit PHP "&TEXT(Forecast!P18/1000,"#,##0.0")&" million vs budget PHP "&TEXT(Forecast!Q18/1000,"#,##0.0")&" million. FY2026 budget operating profit: PHP "&TEXT(Budget_FY2026!P39/1000,"#,##0.0")&" million." -> 5. Reforecast full-year operating profit PHP 52.1 million vs budget PHP 55.6 million. FY2026 budget operating profit: PHP 67.4 million.

Sheet Variance
B1: Budget vs Actual Variance Analysis
B2: Sampaguita Foods & Distribution Corporation (SFDC) | PHP in thousands | positive variance = favourable to profit
B3: =HYPERLINK("#Cover!A1","◄ Back to Cover") -> ◄ Back to Cover
B4: ="Period: "&Period_Label -> Period: Apr FY2025
B5: Line | C5: Budget | D5: Actual | E5: Variance F / (U) | F5: Variance % | G5: Review flag
B7: NET SALES
B8: Packaged Food | C8: =(View_Mode="Month")*SUMPRODUCT((Budget_FY2025!$D$6:$O$6=Sel_M)*Budget_FY2025!$D8:$O8)+(View_Mode<>"Month")*SUMPRODUCT((Budget_FY2025!$D$6:$O$6<=Sel_M)*Budget_FY2025!$D8:$O8) -> 32709 | D8: =(View_Mode="Month")*SUMPRODUCT((Actuals!$D$6:$O$6=Sel_M)*Actuals!$D8:$O8)+(View_Mode<>"Month")*SUMPRODUCT((Actuals!$D$6:$O$6<=Sel_M)*Actuals!$D8:$O8) -> 30564 | E8: =D8-C8 -> -2145 | F8: =IFERROR(E8/C8,0) -> -0.065578281 | G8: =IF(AND(ABS(F8)>=Thr_Pct,ABS(E8)>=Thr_Abs),IF(E8>0,"▲ Favourable","▼ Unfavourable"),"● On budget") -> ▼ Unfavourable
B9: Beverages | C9: =(View_Mode="Month")*SUMPRODUCT((Budget_FY2025!$D$6:$O$6=Sel_M)*Budget_FY2025!$D9:$O9)+(View_Mode<>"Month")*SUMPRODUCT((Budget_FY2025!$D$6:$O$6<=Sel_M)*Budget_FY2025!$D9:$O9) -> 25802 | D9: =(View_Mode="Month")*SUMPRODUCT((Actuals!$D$6:$O$6=Sel_M)*Actuals!$D9:$O9)+(View_Mode<>"Month")*SUMPRODUCT((Actuals!$D$6:$O$6<=Sel_M)*Actuals!$D9:$O9) -> 24653 | E9: =D9-C9 -> -1149 | F9: =IFERROR(E9/C9,0) -> -0.044531432 | G9: =IF(AND(ABS(F9)>=Thr_Pct,ABS(E9)>=Thr_Abs),IF(E9>0,"▲ Favourable","▼ Unfavourable"),"● On budget") -> ● On budget
B10: Household & Personal Care | C10: =(View_Mode="Month")*SUMPRODUCT((Budget_FY2025!$D$6:$O$6=Sel_M)*Budget_FY2025!$D10:$O10)+(View_Mode<>"Month")*SUMPRODUCT((Budget_FY2025!$D$6:$O$6<=Sel_M)*Budget_FY2025!$D10:$O10) -> 14233 | D10: =(View_Mode="Month")*SUMPRODUCT((Actuals!$D$6:$O$6=Sel_M)*Actuals!$D10:$O10)+(View_Mode<>"Month")*SUMPRODUCT((Actuals!$D$6:$O$6<=Sel_M)*Actuals!$D10:$O10) -> 13386 | E10: =D10-C10 -> -847 | F10: =IFERROR(E10/C10,0) -> -0.05950959 | G10: =IF(AND(ABS(F10)>=Thr_Pct,ABS(E10)>=Thr_Abs),IF(E10>0,"▲ Favourable","▼ Unfavourable"),"● On budget") -> ▼ Unfavourable
B11: Fresh & Frozen | C11: =(View_Mode="Month")*SUMPRODUCT((Budget_FY2025!$D$6:$O$6=Sel_M)*Budget_FY2025!$D11:$O11)+(View_Mode<>"Month")*SUMPRODUCT((Budget_FY2025!$D$6:$O$6<=Sel_M)*Budget_FY2025!$D11:$O11) -> 11031 | D11: =(View_Mode="Month")*SUMPRODUCT((Actuals!$D$6:$O$6=Sel_M)*Actuals!$D11:$O11)+(View_Mode<>"Month")*SUMPRODUCT((Actuals!$D$6:$O$6<=Sel_M)*Actuals!$D11:$O11) -> 10420 | E11: =D11-C11 -> -611 | F11: =IFERROR(E11/C11,0) -> -0.055389357 | G11: =IF(AND(ABS(F11)>=Thr_Pct,ABS(E11)>=Thr_Abs),IF(E11>0,"▲ Favourable","▼ Unfavourable"),"● On budget") -> ▼ Unfavourable
B12: Total net sales | C12: =(View_Mode="Month")*SUMPRODUCT((Budget_FY2025!$D$6:$O$6=Sel_M)*Budget_FY2025!$D12:$O12)+(View_Mode<>"Month")*SUMPRODUCT((Budget_FY2025!$D$6:$O$6<=Sel_M)*Budget_FY2025!$D12:$O12) -> 83775 | D12: =(View_Mode="Month")*SUMPRODUCT((Actuals!$D$6:$O$6=Sel_M)*Actuals!$D12:$O12)+(View_Mode<>"Month")*SUMPRODUCT((Actuals!$D$6:$O$6<=Sel_M)*Actuals!$D12:$O12) -> 79023 | E12: =D12-C12 -> -4752 | F12: =IFERROR(E12/C12,0) -> -0.056723366 | G12: =IF(AND(ABS(F12)>=Thr_Pct,ABS(E12)>=Thr_Abs),IF(E12>0,"▲ Favourable","▼ Unfavourable"),"● On budget") -> ▼ Unfavourable
B13: COST OF SALES
B14: Packaged Food | C14: =(View_Mode="Month")*SUMPRODUCT((Budget_FY2025!$D$6:$O$6=Sel_M)*Budget_FY2025!$D14:$O14)+(View_Mode<>"Month")*SUMPRODUCT((Budget_FY2025!$D$6:$O$6<=Sel_M)*Budget_FY2025!$D14:$O14) -> 24593 | D14: =(View_Mode="Month")*SUMPRODUCT((Actuals!$D$6:$O$6=Sel_M)*Actuals!$D14:$O14)+(View_Mode<>"Month")*SUMPRODUCT((Actuals!$D$6:$O$6<=Sel_M)*Actuals!$D14:$O14) -> 23005 | E14: =C14-D14 -> 1588 | F14: =IFERROR(E14/C14,0) -> 0.064571219 | G14: =IF(AND(ABS(F14)>=Thr_Pct,ABS(E14)>=Thr_Abs),IF(E14>0,"▲ Favourable","▼ Unfavourable"),"● On budget") -> ▲ Favourable
B15: Beverages | C15: =(View_Mode="Month")*SUMPRODUCT((Budget_FY2025!$D$6:$O$6=Sel_M)*Budget_FY2025!$D15:$O15)+(View_Mode<>"Month")*SUMPRODUCT((Budget_FY2025!$D$6:$O$6<=Sel_M)*Budget_FY2025!$D15:$O15) -> 18919 | D15: =(View_Mode="Month")*SUMPRODUCT((Actuals!$D$6:$O$6=Sel_M)*Actuals!$D15:$O15)+(View_Mode<>"Month")*SUMPRODUCT((Actuals!$D$6:$O$6<=Sel_M)*Actuals!$D15:$O15) -> 18013 | E15: =C15-D15 -> 906 | F15: =IFERROR(E15/C15,0) -> 0.047888366 | G15: =IF(AND(ABS(F15)>=Thr_Pct,ABS(E15)>=Thr_Abs),IF(E15>0,"▲ Favourable","▼ Unfavourable"),"● On budget") -> ● On budget
B16: Household & Personal Care | C16: =(View_Mode="Month")*SUMPRODUCT((Budget_FY2025!$D$6:$O$6=Sel_M)*Budget_FY2025!$D16:$O16)+(View_Mode<>"Month")*SUMPRODUCT((Budget_FY2025!$D$6:$O$6<=Sel_M)*Budget_FY2025!$D16:$O16) -> 9996 | D16: =(View_Mode="Month")*SUMPRODUCT((Actuals!$D$6:$O$6=Sel_M)*Actuals!$D16:$O16)+(View_Mode<>"Month")*SUMPRODUCT((Actuals!$D$6:$O$6<=Sel_M)*Actuals!$D16:$O16) -> 9378 | E16: =C16-D16 -> 618 | F16: =IFERROR(E16/C16,0) -> 0.06182473 | G16: =IF(AND(ABS(F16)>=Thr_Pct,ABS(E16)>=Thr_Abs),IF(E16>0,"▲ Favourable","▼ Unfavourable"),"● On budget") -> ▲ Favourable
B17: Fresh & Frozen | C17: =(View_Mode="Month")*SUMPRODUCT((Budget_FY2025!$D$6:$O$6=Sel_M)*Budget_FY2025!$D17:$O17)+(View_Mode<>"Month")*SUMPRODUCT((Budget_FY2025!$D$6:$O$6<=Sel_M)*Budget_FY2025!$D17:$O17) -> 8958 | D17: =(View_Mode="Month")*SUMPRODUCT((Actuals!$D$6:$O$6=Sel_M)*Actuals!$D17:$O17)+(View_Mode<>"Month")*SUMPRODUCT((Actuals!$D$6:$O$6<=Sel_M)*Actuals!$D17:$O17) -> 8458 | E17: =C17-D17 -> 500 | F17: =IFERROR(E17/C17,0) -> 0.05581603 | G17: =IF(AND(ABS(F17)>=Thr_Pct,ABS(E17)>=Thr_Abs),IF(E17>0,"▲ Favourable","▼ Unfavourable"),"● On budget") -> ▲ Favourable
B18: Total cost of sales | C18: =(View_Mode="Month")*SUMPRODUCT((Budget_FY2025!$D$6:$O$6=Sel_M)*Budget_FY2025!$D18:$O18)+(View_Mode<>"Month")*SUMPRODUCT((Budget_FY2025!$D$6:$O$6<=Sel_M)*Budget_FY2025!$D18:$O18) -> 62466 | D18: =(View_Mode="Month")*SUMPRODUCT((Actuals!$D$6:$O$6=Sel_M)*Actuals!$D18:$O18)+(View_Mode<>"Month")*SUMPRODUCT((Actuals!$D$6:$O$6<=Sel_M)*Actuals!$D18:$O18) -> 58854 | E18: =C18-D18 -> 3612 | F18: =IFERROR(E18/C18,0) -> 0.057823456 | G18: =IF(AND(ABS(F18)>=Thr_Pct,ABS(E18)>=Thr_Abs),IF(E18>0,"▲ Favourable","▼ Unfavourable"),"● On budget") -> ▲ Favourable
B19: Gross profit | C19: =(View_Mode="Month")*SUMPRODUCT((Budget_FY2025!$D$6:$O$6=Sel_M)*Budget_FY2025!$D19:$O19)+(View_Mode<>"Month")*SUMPRODUCT((Budget_FY2025!$D$6:$O$6<=Sel_M)*Budget_FY2025!$D19:$O19) -> 21309 | D19: =(View_Mode="Month")*SUMPRODUCT((Actuals!$D$6:$O$6=Sel_M)*Actuals!$D19:$O19)+(View_Mode<>"Month")*SUMPRODUCT((Actuals!$D$6:$O$6<=Sel_M)*Actuals!$D19:$O19) -> 20169 | E19: =D19-C19 -> -1140 | F19: =IFERROR(E19/C19,0) -> -0.053498522 | G19: =IF(AND(ABS(F19)>=Thr_Pct,ABS(E19)>=Thr_Abs),IF(E19>0,"▲ Favourable","▼ Unfavourable"),"● On budget") -> ▼ Unfavourable
B20: Gross margin % | C20: =IFERROR(C19/C12,0) -> 0.25435989 | D20: =IFERROR(D19/D12,0) -> 0.25522949 | E20: =D20-C20 -> 0.00086959758 | F20: pts
B21: OPERATING EXPENSES
B22: Sales commissions & incentives | C22: =(View_Mode="Month")*SUMPRODUCT((Budget_FY2025!$D$6:$O$6=Sel_M)*Budget_FY2025!$D22:$O22)+(View_Mode<>"Month")*SUMPRODUCT((Budget_FY2025!$D$6:$O$6<=Sel_M)*Budget_FY2025!$D22:$O22) -> 1340 | D22: =(View_Mode="Month")*SUMPRODUCT((Actuals!$D$6:$O$6=Sel_M)*Actuals!$D22:$O22)+(View_Mode<>"Month")*SUMPRODUCT((Actuals!$D$6:$O$6<=Sel_M)*Actuals!$D22:$O22) -> 1284 | E22: =C22-D22 -> 56 | F22: =IFERROR(E22/C22,0) -> 0.041791045 | G22: =IF(AND(ABS(F22)>=Thr_Pct,ABS(E22)>=Thr_Abs),IF(E22>0,"▲ Favourable","▼ Unfavourable"),"● On budget") -> ● On budget
B23: Advertising & promotions | C23: =(View_Mode="Month")*SUMPRODUCT((Budget_FY2025!$D$6:$O$6=Sel_M)*Budget_FY2025!$D23:$O23)+(View_Mode<>"Month")*SUMPRODUCT((Budget_FY2025!$D$6:$O$6<=Sel_M)*Budget_FY2025!$D23:$O23) -> 774 | D23: =(View_Mode="Month")*SUMPRODUCT((Actuals!$D$6:$O$6=Sel_M)*Actuals!$D23:$O23)+(View_Mode<>"Month")*SUMPRODUCT((Actuals!$D$6:$O$6<=Sel_M)*Actuals!$D23:$O23) -> 717 | E23: =C23-D23 -> 57 | F23: =IFERROR(E23/C23,0) -> 0.073643411 | G23: =IF(AND(ABS(F23)>=Thr_Pct,ABS(E23)>=Thr_Abs),IF(E23>0,"▲ Favourable","▼ Unfavourable"),"● On budget") -> ● On budget
B24: Freight & delivery | C24: =(View_Mode="Month")*SUMPRODUCT((Budget_FY2025!$D$6:$O$6=Sel_M)*Budget_FY2025!$D24:$O24)+(View_Mode<>"Month")*SUMPRODUCT((Budget_FY2025!$D$6:$O$6<=Sel_M)*Budget_FY2025!$D24:$O24) -> 2014 | D24: =(View_Mode="Month")*SUMPRODUCT((Actuals!$D$6:$O$6=Sel_M)*Actuals!$D24:$O24)+(View_Mode<>"Month")*SUMPRODUCT((Actuals!$D$6:$O$6<=Sel_M)*Actuals!$D24:$O24) -> 1941 | E24: =C24-D24 -> 73 | F24: =IFERROR(E24/C24,0) -> 0.036246276 | G24: =IF(AND(ABS(F24)>=Thr_Pct,ABS(E24)>=Thr_Abs),IF(E24>0,"▲ Favourable","▼ Unfavourable"),"● On budget") -> ● On budget
B25: Warehouse rent & utilities | C25: =(View_Mode="Month")*SUMPRODUCT((Budget_FY2025!$D$6:$O$6=Sel_M)*Budget_FY2025!$D25:$O25)+(View_Mode<>"Month")*SUMPRODUCT((Budget_FY2025!$D$6:$O$6<=Sel_M)*Budget_FY2025!$D25:$O25) -> 1988 | D25: =(View_Mode="Month")*SUMPRODUCT((Actuals!$D$6:$O$6=Sel_M)*Actuals!$D25:$O25)+(View_Mode<>"Month")*SUMPRODUCT((Actuals!$D$6:$O$6<=Sel_M)*Actuals!$D25:$O25) -> 2104 | E25: =C25-D25 -> -116 | F25: =IFERROR(E25/C25,0) -> -0.058350101 | G25: =IF(AND(ABS(F25)>=Thr_Pct,ABS(E25)>=Thr_Abs),IF(E25>0,"▲ Favourable","▼ Unfavourable"),"● On budget") -> ▼ Unfavourable
B26: Selling & logistics staff costs | C26: =(View_Mode="Month")*SUMPRODUCT((Budget_FY2025!$D$6:$O$6=Sel_M)*Budget_FY2025!$D26:$O26)+(View_Mode<>"Month")*SUMPRODUCT((Budget_FY2025!$D$6:$O$6<=Sel_M)*Budget_FY2025!$D26:$O26) -> 2692 | D26: =(View_Mode="Month")*SUMPRODUCT((Actuals!$D$6:$O$6=Sel_M)*Actuals!$D26:$O26)+(View_Mode<>"Month")*SUMPRODUCT((Actuals!$D$6:$O$6<=Sel_M)*Actuals!$D26:$O26) -> 2730 | E26: =C26-D26 -> -38 | F26: =IFERROR(E26/C26,0) -> -0.014115899 | G26: =IF(AND(ABS(F26)>=Thr_Pct,ABS(E26)>=Thr_Abs),IF(E26>0,"▲ Favourable","▼ Unfavourable"),"● On budget") -> ● On budget
B27: Selling & distribution | C27: =(View_Mode="Month")*SUMPRODUCT((Budget_FY2025!$D$6:$O$6=Sel_M)*Budget_FY2025!$D27:$O27)+(View_Mode<>"Month")*SUMPRODUCT((Budget_FY2025!$D$6:$O$6<=Sel_M)*Budget_FY2025!$D27:$O27) -> 8808 | D27: =(View_Mode="Month")*SUMPRODUCT((Actuals!$D$6:$O$6=Sel_M)*Actuals!$D27:$O27)+(View_Mode<>"Month")*SUMPRODUCT((Actuals!$D$6:$O$6<=Sel_M)*Actuals!$D27:$O27) -> 8776 | E27: =C27-D27 -> 32 | F27: =IFERROR(E27/C27,0) -> 0.0036330609 | G27: =IF(AND(ABS(F27)>=Thr_Pct,ABS(E27)>=Thr_Abs),IF(E27>0,"▲ Favourable","▼ Unfavourable"),"● On budget") -> ● On budget
B28: Salaries & wages (G&A) | C28: =(View_Mode="Month")*SUMPRODUCT((Budget_FY2025!$D$6:$O$6=Sel_M)*Budget_FY2025!$D28:$O28)+(View_Mode<>"Month")*SUMPRODUCT((Budget_FY2025!$D$6:$O$6<=Sel_M)*Budget_FY2025!$D28:$O28) -> 2522 | D28: =(View_Mode="Month")*SUMPRODUCT((Actuals!$D$6:$O$6=Sel_M)*Actuals!$D28:$O28)+(View_Mode<>"Month")*SUMPRODUCT((Actuals!$D$6:$O$6<=Sel_M)*Actuals!$D28:$O28) -> 2562 | E28: =C28-D28 -> -40 | F28: =IFERROR(E28/C28,0) -> -0.015860428 | G28: =IF(AND(ABS(F28)>=Thr_Pct,ABS(E28)>=Thr_Abs),IF(E28>0,"▲ Favourable","▼ Unfavourable"),"● On budget") -> ● On budget
B29: Employee benefits & contributions | C29: =(View_Mode="Month")*SUMPRODUCT((Budget_FY2025!$D$6:$O$6=Sel_M)*Budget_FY2025!$D29:$O29)+(View_Mode<>"Month")*SUMPRODUCT((Budget_FY2025!$D$6:$O$6<=Sel_M)*Budget_FY2025!$D29:$O29) -> 691 | D29: =(View_Mode="Month")*SUMPRODUCT((Actuals!$D$6:$O$6=Sel_M)*Actuals!$D29:$O29)+(View_Mode<>"Month")*SUMPRODUCT((Actuals!$D$6:$O$6<=Sel_M)*Actuals!$D29:$O29) -> 667 | E29: =C29-D29 -> 24 | F29: =IFERROR(E29/C29,0) -> 0.034732272 | G29: =IF(AND(ABS(F29)>=Thr_Pct,ABS(E29)>=Thr_Abs),IF(E29>0,"▲ Favourable","▼ Unfavourable"),"● On budget") -> ● On budget
B30: Professional fees | C30: =(View_Mode="Month")*SUMPRODUCT((Budget_FY2025!$D$6:$O$6=Sel_M)*Budget_FY2025!$D30:$O30)+(View_Mode<>"Month")*SUMPRODUCT((Budget_FY2025!$D$6:$O$6<=Sel_M)*Budget_FY2025!$D30:$O30) -> 335 | D30: =(View_Mode="Month")*SUMPRODUCT((Actuals!$D$6:$O$6=Sel_M)*Actuals!$D30:$O30)+(View_Mode<>"Month")*SUMPRODUCT((Actuals!$D$6:$O$6<=Sel_M)*Actuals!$D30:$O30) -> 330 | E30: =C30-D30 -> 5 | F30: =IFERROR(E30/C30,0) -> 0.014925373 | G30: =IF(AND(ABS(F30)>=Thr_Pct,ABS(E30)>=Thr_Abs),IF(E30>0,"▲ Favourable","▼ Unfavourable"),"● On budget") -> ● On budget
B31: Office rent & utilities | C31: =(View_Mode="Month")*SUMPRODUCT((Budget_FY2025!$D$6:$O$6=Sel_M)*Budget_FY2025!$D31:$O31)+(View_Mode<>"Month")*SUMPRODUCT((Budget_FY2025!$D$6:$O$6<=Sel_M)*Budget_FY2025!$D31:$O31) -> 579 | D31: =(View_Mode="Month")*SUMPRODUCT((Actuals!$D$6:$O$6=Sel_M)*Actuals!$D31:$O31)+(View_Mode<>"Month")*SUMPRODUCT((Actuals!$D$6:$O$6<=Sel_M)*Actuals!$D31:$O31) -> 569 | E31: =C31-D31 -> 10 | F31: =IFERROR(E31/C31,0) -> 0.017271157 | G31: =IF(AND(ABS(F31)>=Thr_Pct,ABS(E31)>=Thr_Abs),IF(E31>0,"▲ Favourable","▼ Unfavourable"),"● On budget") -> ● On budget
B32: Repairs & maintenance | C32: =(View_Mode="Month")*SUMPRODUCT((Budget_FY2025!$D$6:$O$6=Sel_M)*Budget_FY2025!$D32:$O32)+(View_Mode<>"Month")*SUMPRODUCT((Budget_FY2025!$D$6:$O$6<=Sel_M)*Budget_FY2025!$D32:$O32) -> 224 | D32: =(View_Mode="Month")*SUMPRODUCT((Actuals!$D$6:$O$6=Sel_M)*Actuals!$D32:$O32)+(View_Mode<>"Month")*SUMPRODUCT((Actuals!$D$6:$O$6<=Sel_M)*Actuals!$D32:$O32) -> 232 | E32: =C32-D32 -> -8 | F32: =IFERROR(E32/C32,0) -> -0.035714286 | G32: =IF(AND(ABS(F32)>=Thr_Pct,ABS(E32)>=Thr_Abs),IF(E32>0,"▲ Favourable","▼ Unfavourable"),"● On budget") -> ● On budget
B33: Taxes, licenses & insurance | C33: =(View_Mode="Month")*SUMPRODUCT((Budget_FY2025!$D$6:$O$6=Sel_M)*Budget_FY2025!$D33:$O33)+(View_Mode<>"Month")*SUMPRODUCT((Budget_FY2025!$D$6:$O$6<=Sel_M)*Budget_FY2025!$D33:$O33) -> 473 | D33: =(View_Mode="Month")*SUMPRODUCT((Actuals!$D$6:$O$6=Sel_M)*Actuals!$D33:$O33)+(View_Mode<>"Month")*SUMPRODUCT((Actuals!$D$6:$O$6<=Sel_M)*Actuals!$D33:$O33) -> 453 | E33: =C33-D33 -> 20 | F33: =IFERROR(E33/C33,0) -> 0.042283298 | G33: =IF(AND(ABS(F33)>=Thr_Pct,ABS(E33)>=Thr_Abs),IF(E33>0,"▲ Favourable","▼ Unfavourable"),"● On budget") -> ● On budget
... B38: Total operating expenses | C38: =(View_Mode="Month")*SUMPRODUCT((Budget_FY2025!$D$6:$O$6=Sel_M)*Budget_FY2025!$D38:$O38)+(View_Mode<>"Month")*SUMPRODUCT((Budget_FY2025!$D$6:$O$6<=Sel_M)*Budget_FY2025!$D38:$O38) -> 15883.333 | D38: =(View_Mode="Month")*SUMPRODUCT((Actuals!$D$6:$O$6=Sel_M)*Actuals!$D38:$O38)+(View_Mode<>"Month")*SUMPRODUCT((Actuals!$D$6:$O$6<=Sel_M)*Actuals!$D38:$O38) -> 15859.417 | E38: =C38-D38 -> 23.916667 | F38: =IFERROR(E38/C38,0) -> 0.0015057712 | G38: =IF(AND(ABS(F38)>=Thr_Pct,ABS(E38)>=Thr_Abs),IF(E38>0,"▲ Favourable","▼ Unfavourable"),"● On budget") -> ● On budget
B39: Operating profit | C39: =(View_Mode="Month")*SUMPRODUCT((Budget_FY2025!$D$6:$O$6=Sel_M)*Budget_FY2025!$D39:$O39)+(View_Mode<>"Month")*SUMPRODUCT((Budget_FY2025!$D$6:$O$6<=Sel_M)*Budget_FY2025!$D39:$O39) -> 5425.6667 | D39: =(View_Mode="Month")*SUMPRODUCT((Actuals!$D$6:$O$6=Sel_M)*Actuals!$D39:$O39)+(View_Mode<>"Month")*SUMPRODUCT((Actuals!$D$6:$O$6<=Sel_M)*Actuals!$D39:$O39) -> 4309.5833 | E39: =D39-C39 -> -1116.0833 | F39: =IFERROR(E39/C39,0) -> -0.20570437 | G39: =IF(AND(ABS(F39)>=Thr_Pct,ABS(E39)>=Thr_Abs),IF(E39>0,"▲ Favourable","▼ Unfavourable"),"● On budget") -> ▼ Unfavourable
B40: Operating margin % | C40: =IFERROR(C39/C12,0) -> 0.064764747 | D40: =IFERROR(D39/D12,0) -> 0.05453581 | E40: =D40-C40 -> -0.010228937 | F40: pts
B42: Sign convention: revenue and profit lines - actual less budget; cost lines - budget less actual, so a positive number is always good for profit. Flag rules: |variance %| >= threshold AND |variance PHP| >= threshold (Assumptions).

Sheet Flex_Budget
B1: Flexible Budget Analysis
B2: Sampaguita Foods & Distribution Corporation (SFDC) | PHP in thousands | separates the effect of sales activity from cost spending
B3: =HYPERLINK("#Cover!A1","◄ Back to Cover") -> ◄ Back to Cover
B4: ="Period: "&Period_Label -> Period: Apr FY2025
B5: Line | C5: Static budget | D5: Flexed budget | E5: Actual | F5: Sales activity variance | G5: Spending variance
B6: Net sales | C6: =Variance!C12 -> 83775 | D6: =E6 -> 79023 | E6: =Variance!D12 -> 79023 | F6: =D6-C6 -> -4752 | G6: =E6-D6 -> 0
B7: Cost of sales | C7: =Variance!C18 -> 62466 | D7: =C7*IFERROR($E$6/$C$6,1) -> 58922.718 | E7: =Variance!D18 -> 58854 | F7: =C7-D7 -> 3543.2818 | G7: =D7-E7 -> 68.718209
B8: Sales commissions & incentives | C8: =Variance!C22 -> 1340 | D8: =C8*IFERROR($E$6/$C$6,1) -> 1263.9907 | E8: =Variance!D22 -> 1284 | F8: =C8-D8 -> 76.009311 | G8: =D8-E8 -> -20.009311
B9: Advertising & promotions | C9: =Variance!C23 -> 774 | D9: =C9*IFERROR($E$6/$C$6,1) -> 730.09611 | E9: =Variance!D23 -> 717 | F9: =C9-D9 -> 43.903885 | G9: =D9-E9 -> 13.096115
B10: Freight & delivery | C10: =Variance!C24 -> 2014 | D10: =C10*IFERROR($E$6/$C$6,1) -> 1899.7591 | E10: =Variance!D24 -> 1941 | F10: =C10-D10 -> 114.24086 | G10: =D10-E10 -> -41.240859
B11: Bad debts & credit losses | C11: =Variance!C35 -> 124 | D11: =C11*IFERROR($E$6/$C$6,1) -> 116.9663 | E11: =Variance!D35 -> 121 | F11: =C11-D11 -> 7.0336974 | G11: =D11-E11 -> -4.0336974
B12: Contribution margin | C12: =C6-SUM(C7:C11) -> 17057 | D12: =D6-SUM(D7:D11) -> 16089.47 | E12: =E6-SUM(E7:E11) -> 16106 | F12: =F6+SUM(F7:F11) -> -967.53046 | G12: =G6+SUM(G7:G11) -> 16.530457
B13: Warehouse rent & utilities | C13: =Variance!C25 -> 1988 | D13: =C13 -> 1988 | E13: =Variance!D25 -> 2104 | F13: =C13-D13 -> 0 | G13: =D13-E13 -> -116
B14: Selling & logistics staff costs | C14: =Variance!C26 -> 2692 | D14: =C14 -> 2692 | E14: =Variance!D26 -> 2730 | F14: =C14-D14 -> 0 | G14: =D14-E14 -> -38
B15: Salaries & wages (G&A) | C15: =Variance!C28 -> 2522 | D15: =C15 -> 2522 | E15: =Variance!D28 -> 2562 | F15: =C15-D15 -> 0 | G15: =D15-E15 -> -40
B16: Employee benefits & contributions | C16: =Variance!C29 -> 691 | D16: =C16 -> 691 | E16: =Variance!D29 -> 667 | F16: =C16-D16 -> 0 | G16: =D16-E16 -> 24
B17: Professional fees | C17: =Variance!C30 -> 335 | D17: =C17 -> 335 | E17: =Variance!D30 -> 330 | F17: =C17-D17 -> 0 | G17: =D17-E17 -> 5
B18: Office rent & utilities | C18: =Variance!C31 -> 579 | D18: =C18 -> 579 | E18: =Variance!D31 -> 569 | F18: =C18-D18 -> 0 | G18: =D18-E18 -> 10
B19: Repairs & maintenance | C19: =Variance!C32 -> 224 | D19: =C19 -> 224 | E19: =Variance!D32 -> 232 | F19: =C19-D19 -> 0 | G19: =D19-E19 -> -8
B20: Taxes, licenses & insurance | C20: =Variance!C33 -> 473 | D20: =C20 -> 473 | E20: =Variance!D33 -> 453 | F20: =C20-D20 -> 0 | G20: =D20-E20 -> 20
B21: Communication, IT & supplies | C21: =Variance!C34 -> 394 | D21: =C21 -> 394 | E21: =Variance!D34 -> 378 | F21: =C21-D21 -> 0 | G21: =D21-E21 -> 16
B22: Depreciation | C22: =Variance!C37 -> 1733.3333 | D22: =C22 -> 1733.3333 | E22: =Variance!D37 -> 1771.4167 | F22: =C22-D22 -> 0 | G22: =D22-E22 -> -38.083333
B23: Operating profit | C23: =C12-SUM(C13:C22) -> 5425.6667 | D23: =D12-SUM(D13:D22) -> 4458.1362 | E23: =E12-SUM(E13:E22) -> 4309.5833 | F23: =F12+SUM(F13:F22) -> -967.53046 | G23: =G12+SUM(G13:G22) -> -148.55288
B25: OPERATING PROFIT BRIDGE: STATIC BUDGET TO ACTUAL
B26: Static budget operating profit | C26: =C23 -> 5425.6667
B27: Sales activity effect (volume/price/mix at budget margins) | C27: =F23 -> -967.53046
B28: Cost of sales rate effect (margin vs budget ratio) | C28: =G7 -> 68.718209
B29: Variable operating expense spending | C29: =SUM(G8:G11) -> -52.187753
B30: Fixed expense and depreciation spending | C30: =SUM(G13:G22) -> -165.08333
B31: Actual operating profit | C31: =SUM(C26:C30) -> 4309.5833 | D31: =IF(ABS(C31-E23)<=0.5,"✔ agrees to actual","✖ does not agree") -> ✔ agrees to actual
B33: Flexed budget = static budget re-computed at actual net sales: cost of sales and variable expenses scale with sales (budget cost ratio x actual sales); fixed expenses and depreciation do not flex. Sales activity variance = flexed less static budget; spending variance = flexed budget less actual (cost lines) so positive is favourable.

Sheet Forecast
B1: Rolling Full-Year Reforecast
B2: Sampaguita Foods & Distribution Corporation (SFDC) | PHP in thousands | actual for closed months, run-rate adjusted budget for remaining months
B3: =HYPERLINK("#Cover!A1","◄ Back to Cover") -> ◄ Back to Cover
B4: ="Actuals through "&INDEX(Lists!$B$5:$B$16,Sel_M)&" FY"&Act_Year&"; remaining months = budget x YTD run-rate factor" -> Actuals through Apr FY2025; remaining months = budget x YTD run-rate factor
B5: Line | D5: Jan | E5: Feb | F5: Mar | G5: Apr | H5: May | I5: Jun | J5: Jul | K5: Aug | L5: Sep | M5: Oct | N5: Nov | O5: Dec | P5: Full year | Q5: Full-year budget | R5: Variance F / (U)
B6: Month number | D6: 1 | E6: 2 | F6: 3 | G6: 4 | H6: 5 | I6: 6 | J6: 7 | K6: 8 | L6: 9 | M6: 10 | N6: 11 | O6: 12
B8: Run-rate factors (YTD actual / YTD budget)
B9: Net sales factor | C9: =IFERROR(SUMPRODUCT((Actuals!$D$6:$O$6<=Sel_M)*Actuals!$D12:$O12)/SUMPRODUCT((Budget_FY2025!$D$6:$O$6<=Sel_M)*Budget_FY2025!$D12:$O12),1) -> 0.97933558
B10: Cost of sales ratio factor (YTD COGS% / budget COGS%) | C10: =IFERROR((SUMPRODUCT((Actuals!$D$6:$O$6<=Sel_M)*Actuals!$D18:$O18)/SUMPRODUCT((Actuals!$D$6:$O$6<=Sel_M)*Actuals!$D12:$O12))/(SUMPRODUCT((Budget_FY2025!$D$6:$O$6<=Sel_M)*Budget_FY2025!$D18:$O18)/SUMPRODUCT((Budget_FY2025!$D$6:$O$6<=Sel_M)*Budget_FY2025!$D12:$O12)),1) -> 0.99640608
B11: Operating expense factor (YTD actual / YTD budget) | C11: =IFERROR(SUMPRODUCT((Actuals!$D$6:$O$6<=Sel_M)*Actuals!$D38:$O38)/SUMPRODUCT((Budget_FY2025!$D$6:$O$6<=Sel_M)*Budget_FY2025!$D38:$O38),1) -> 1.0045982
B14: Net sales | D14: =IF(D$6<=Sel_M,Actuals!D12,Budget_FY2025!D12*$C$9) -> 74463 | E14: =IF(E$6<=Sel_M,Actuals!E12,Budget_FY2025!E12*$C$9) -> 71689 | F14: =IF(F$6<=Sel_M,Actuals!F12,Budget_FY2025!F12*$C$9) -> 77757 | G14: =IF(G$6<=Sel_M,Actuals!G12,Budget_FY2025!G12*$C$9) -> 79023 | H14: =IF(H$6<=Sel_M,Actuals!H12,Budget_FY2025!H12*$C$9) -> 81807.819 | I14: =IF(I$6<=Sel_M,Actuals!I12,Budget_FY2025!I12*$C$9) -> 79417.26 | J14: =IF(J$6<=Sel_M,Actuals!J12,Budget_FY2025!J12*$C$9) -> 78818.886 | K14: =IF(K$6<=Sel_M,Actuals!K12,Budget_FY2025!K12*$C$9) -> 78437.925 | ... O14: =IF(O$6<=Sel_M,Actuals!O12,Budget_FY2025!O12*$C$9) -> 85703.616 | P14: =SUM(D14:O14) -> 944999.1 | Q14: =Budget_FY2025!P12 -> 964939 | R14: =P14-Q14 -> -19939.901
B15: Cost of sales | D15: =IF(D$6<=Sel_M,Actuals!D18,D14*IFERROR(Budget_FY2025!D18/Budget_FY2025!D12,0)*$C$10) -> 55344 | E15: =IF(E$6<=Sel_M,Actuals!E18,E14*IFERROR(Budget_FY2025!E18/Budget_FY2025!E12,0)*$C$10) -> 53187 | F15: =IF(F$6<=Sel_M,Actuals!F18,F14*IFERROR(Budget_FY2025!F18/Budget_FY2025!F12,0)*$C$10) -> 57725 | G15: =IF(G$6<=Sel_M,Actuals!G18,G14*IFERROR(Budget_FY2025!G18/Budget_FY2025!G12,0)*$C$10) -> 58854 | H15: =IF(H$6<=Sel_M,Actuals!H18,H14*IFERROR(Budget_FY2025!H18/Budget_FY2025!H12,0)*$C$10) -> 60755.275 | I15: =IF(I$6<=Sel_M,Actuals!I18,I14*IFERROR(Budget_FY2025!I18/Budget_FY2025!I12,0)*$C$10) -> 58987.097 | J15: =IF(J$6<=Sel_M,Actuals!J18,J14*IFERROR(Budget_FY2025!J18/Budget_FY2025!J12,0)*$C$10) -> 58541.149 | K15: =IF(K$6<=Sel_M,Actuals!K18,K14*IFERROR(Budget_FY2025!K18/Budget_FY2025!K12,0)*$C$10) -> 58226.936 | ... O15: =IF(O$6<=Sel_M,Actuals!O18,O14*IFERROR(Budget_FY2025!O18/Budget_FY2025!O12,0)*$C$10) -> 63564.649 | P15: =SUM(D15:O15) -> 701824.38 | Q15: =Budget_FY2025!P18 -> 719218 | R15: =Q15-P15 -> 17393.622
B16: Gross profit | D16: =D14-D15 -> 19119 | E16: =E14-E15 -> 18502 | F16: =F14-F15 -> 20032 | G16: =G14-G15 -> 20169 | H16: =H14-H15 -> 21052.543 | I16: =I14-I15 -> 20430.164 | J16: =J14-J15 -> 20277.737 | K16: =K14-K15 -> 20210.989 | ... O16: =O14-O15 -> 22138.966 | P16: =SUM(D16:O16) -> 243174.72 | Q16: =Budget_FY2025!P19 -> 245721 | R16: =P16-Q16 -> -2546.2797
B17: Total operating expenses | D17: =IF(D$6<=Sel_M,Actuals!D38,Budget_FY2025!D38*$C$11) -> 15512.417 | E17: =IF(E$6<=Sel_M,Actuals!E38,Budget_FY2025!E38*$C$11) -> 15380.417 | F17: =IF(F$6<=Sel_M,Actuals!F38,Budget_FY2025!F38*$C$11) -> 16241.417 | G17: =IF(G$6<=Sel_M,Actuals!G38,Budget_FY2025!G38*$C$11) -> 15859.417 | H17: =IF(H$6<=Sel_M,Actuals!H38,Budget_FY2025!H38*$C$11) -> 15760.472 | I17: =IF(I$6<=Sel_M,Actuals!I38,Budget_FY2025!I38*$C$11) -> 15731.338 | J17: =IF(J$6<=Sel_M,Actuals!J38,Budget_FY2025!J38*$C$11) -> 15656.998 | K17: =IF(K$6<=Sel_M,Actuals!K38,Budget_FY2025!K38*$C$11) -> 15823.762 | ... O17: =IF(O$6<=Sel_M,Actuals!O38,Budget_FY2025!O38*$C$11) -> 16845.438 | P17: =SUM(D17:O17) -> 191042.44 | Q17: =Budget_FY2025!P38 -> 190168 | R17: =Q17-P17 -> -874.43556
B18: Operating profit | D18: =D16-D17 -> 3606.5833 | E18: =E16-E17 -> 3121.5833 | F18: =F16-F17 -> 3790.5833 | G18: =G16-G17 -> 4309.5833 | H18: =H16-H17 -> 5292.0715 | I18: =I16-I17 -> 4698.8251 | J18: =J16-J17 -> 4620.7392 | K18: =K16-K17 -> 4387.2271 | ... O18: =O16-O17 -> 5293.5283 | P18: =SUM(D18:O18) -> 52132.285 | Q18: =Budget_FY2025!P39 -> 55553 | R18: =P18-Q18 -> -3420.7152
B19: Operating margin % | D19: =IFERROR(D18/D14,0) -> 0.048434569 | E19: =IFERROR(E18/E14,0) -> 0.043543407 | F19: =IFERROR(F18/F14,0) -> 0.048749094 | G19: =IFERROR(G18/G14,0) -> 0.05453581 | H19: =IFERROR(H18/H14,0) -> 0.064689067 | I19: =IFERROR(I18/I14,0) -> 0.059166295 | J19: =IFERROR(J18/J14,0) -> 0.058624771 | K19: =IFERROR(K18/K14,0) -> 0.055932473 | ... P19: =IFERROR(P18/P14,0) -> 0.055166492 | Q19: =Budget_FY2025!P40 -> 0.057571515
B22: Method: months up to the selected month use actuals. Later months use the approved budget scaled by the YTD run-rate (sales factor), the YTD cost-of-sales ratio relative to budget, and the YTD operating-expense factor. Choose December on the Dashboard to see the full-year actual outcome.

Sheet Budget_FY2026
B1: Driver-Based Budget FY2026 - Monthly
B2: Sampaguita Foods & Distribution Corporation (SFDC) | PHP in thousands | formulas driven by the Assumptions sheet
B3: =HYPERLINK("#Cover!A1","◄ Back to Cover") -> ◄ Back to Cover
B5: Line | C5: Behaviour | D5: Jan | E5: Feb | F5: Mar | G5: Apr | H5: May | I5: Jun | J5: Jul | K5: Aug | L5: Sep | M5: Oct | N5: Nov | O5: Dec | P5: FY total | Q5: FY2025 actual | R5: Growth %
B6: Month number | D6: 1 | E6: 2 | F6: 3 | G6: 4 | H6: 5 | I6: 6 | J6: 7 | K6: 8 | L6: 9 | M6: 10 | N6: 11 | O6: 12
B7: NET SALES
B8: Packaged Food | D8: =Actuals!D8*(1+Assumptions!$C$12) -> 31256.685 | E8: =Actuals!E8*(1+Assumptions!$C$12) -> 30484.56 | F8: =Actuals!F8*(1+Assumptions!$C$12) -> 31685.88 | G8: =Actuals!G8*(1+Assumptions!$C$12) -> 32550.66 | H8: =Actuals!H8*(1+Assumptions!$C$12) -> 33677.43 | I8: =Actuals!I8*(1+Assumptions!$C$12) -> 32825.43 | J8: =Actuals!J8*(1+Assumptions!$C$12) -> 34595.46 | K8: =Actuals!K8*(1+Assumptions!$C$12) -> 34119.405 | ... O8: =Actuals!O8*(1+Assumptions!$C$12) -> 40063.17 | P8: =SUM(D8:O8) -> 407373.15 | Q8: =Actuals!P8 -> 382510 | R8: =IFERROR(P8/Q8-1,0) -> 0.065
B9: Beverages | D9: =Actuals!D9*(1+Assumptions!$C$13) -> 23774.64 | E9: =Actuals!E9*(1+Assumptions!$C$13) -> 22819.8 | F9: =Actuals!F9*(1+Assumptions!$C$13) -> 26678.58 | G9: =Actuals!G9*(1+Assumptions!$C$13) -> 26995.035 | H9: =Actuals!H9*(1+Assumptions!$C$13) -> 27884.175 | I9: =Actuals!I9*(1+Assumptions!$C$13) -> 26847.21 | J9: =Actuals!J9*(1+Assumptions!$C$13) -> 26234.01 | K9: =Actuals!K9*(1+Assumptions!$C$13) -> 26431.11 | ... O9: =Actuals!O9*(1+Assumptions!$C$13) -> 30552.69 | P9: =SUM(D9:O9) -> 319939.29 | Q9: =Actuals!P9 -> 292182 | R9: =IFERROR(P9/Q9-1,0) -> 0.095
B10: Household & Personal Care | D10: =Actuals!D10*(1+Assumptions!$C$14) -> 14108.6 | E10: =Actuals!E10*(1+Assumptions!$C$14) -> 13119.62 | F10: =Actuals!F10*(1+Assumptions!$C$14) -> 14171.14 | G10: =Actuals!G10*(1+Assumptions!$C$14) -> 14189.16 | H10: =Actuals!H10*(1+Assumptions!$C$14) -> 15214.18 | I10: =Actuals!I10*(1+Assumptions!$C$14) -> 14544.26 | J10: =Actuals!J10*(1+Assumptions!$C$14) -> 15340.32 | K10: =Actuals!K10*(1+Assumptions!$C$14) -> 15149.52 | ... O10: =Actuals!O10*(1+Assumptions!$C$14) -> 17752.88 | P10: =SUM(D10:O10) -> 180794.66 | Q10: =Actuals!P10 -> 170561 | R10: =IFERROR(P10/Q10-1,0) -> 0.06
B11: Fresh & Frozen | D11: =Actuals!D11*(1+Assumptions!$C$15) -> 11252.58 | E11: =Actuals!E11*(1+Assumptions!$C$15) -> 10980.52 | F11: =Actuals!F11*(1+Assumptions!$C$15) -> 11453.28 | G11: =Actuals!G11*(1+Assumptions!$C$15) -> 11618.3 | H11: =Actuals!H11*(1+Assumptions!$C$15) -> 11714.19 | I11: =Actuals!I11*(1+Assumptions!$C$15) -> 11548.055 | J11: =Actuals!J11*(1+Assumptions!$C$15) -> 11989.595 | K11: =Actuals!K11*(1+Assumptions!$C$15) -> 11861.37 | ... O11: =Actuals!O11*(1+Assumptions!$C$15) -> 12971.91 | P11: =SUM(D11:O11) -> 141815.73 | Q11: =Actuals!P11 -> 127189 | R11: =IFERROR(P11/Q11-1,0) -> 0.115
B12: Total net sales | D12: =SUM(D8:D11) -> 80392.505 | E12: =SUM(E8:E11) -> 77404.5 | F12: =SUM(F8:F11) -> 83988.88 | G12: =SUM(G8:G11) -> 85353.155 | H12: =SUM(H8:H11) -> 88489.975 | I12: =SUM(I8:I11) -> 85764.955 | J12: =SUM(J8:J11) -> 88159.385 | K12: =SUM(K8:K11) -> 87561.405 | ... P12: =SUM(P8:P11) -> 1049922.8 | Q12: =Actuals!P12 -> 972442 | R12: =IFERROR(P12/Q12-1,0) -> 0.079676562
B13: COST OF SALES
B14: Packaged Food | D14: =D8*(IFERROR(Actuals!D14/Actuals!D8,0)+Assumptions!$D$12) -> 23378.88 | E14: =E8*(IFERROR(Actuals!E14/Actuals!E8,0)+Assumptions!$D$12) -> 22789.935 | F14: =F8*(IFERROR(Actuals!F14/Actuals!F8,0)+Assumptions!$D$12) -> 23681.34 | G14: =G8*(IFERROR(Actuals!G14/Actuals!G8,0)+Assumptions!$D$12) -> 24500.325 | H14: =H8*(IFERROR(Actuals!H14/Actuals!H8,0)+Assumptions!$D$12) -> 25301.205 | I14: =I8*(IFERROR(Actuals!I14/Actuals!I8,0)+Assumptions!$D$12) -> 24614.28 | J14: =J8*(IFERROR(Actuals!J14/Actuals!J8,0)+Assumptions!$D$12) -> 25896.54 | K14: =K8*(IFERROR(Actuals!K14/Actuals!K8,0)+Assumptions!$D$12) -> 25551.48 | ... O14: =O8*(IFERROR(Actuals!O14/Actuals!O8,0)+Assumptions!$D$12) -> 30137.37 | P14: =SUM(D14:O14) -> 305329.11 | Q14: =Actuals!P14 -> 286694 | R14: =IFERROR(P14/Q14-1,0) -> 0.065
B15: Beverages | D15: =D9*(IFERROR(Actuals!D15/Actuals!D9,0)+Assumptions!$D$13) -> 17362.951 | E15: =E9*(IFERROR(Actuals!E15/Actuals!E9,0)+Assumptions!$D$13) -> 16567.7 | F15: =F9*(IFERROR(Actuals!F15/Actuals!F9,0)+Assumptions!$D$13) -> 19419.028 | G15: =G9*(IFERROR(Actuals!G15/Actuals!G9,0)+Assumptions!$D$13) -> 19670.245 | H15: =H9*(IFERROR(Actuals!H15/Actuals!H9,0)+Assumptions!$D$13) -> 20329.847 | I15: =I9*(IFERROR(Actuals!I15/Actuals!I9,0)+Assumptions!$D$13) -> 19597.176 | J15: =J9*(IFERROR(Actuals!J15/Actuals!J9,0)+Assumptions!$D$13) -> 19085.942 | K15: =K9*(IFERROR(Actuals!K15/Actuals!K9,0)+Assumptions!$D$13) -> 19300.168 | ... O15: =O9*(IFERROR(Actuals!O15/Actuals!O9,0)+Assumptions!$D$13) -> 22281.275 | P15: =SUM(D15:O15) -> 233033.12 | Q15: =Actuals!P15 -> 213400 | R15: =IFERROR(P15/Q15-1,0) -> 0.092001506
B16: Household & Personal Care | D16: =D10*(IFERROR(Actuals!D16/Actuals!D10,0)+Assumptions!$D$14) -> 9862.24 | E16: =E10*(IFERROR(Actuals!E16/Actuals!E10,0)+Assumptions!$D$14) -> 9167.94 | F16: =F10*(IFERROR(Actuals!F16/Actuals!F10,0)+Assumptions!$D$14) -> 9931.14 | G16: =G10*(IFERROR(Actuals!G16/Actuals!G10,0)+Assumptions!$D$14) -> 9940.68 | H16: =H10*(IFERROR(Actuals!H16/Actuals!H10,0)+Assumptions!$D$14) -> 10653 | I16: =I10*(IFERROR(Actuals!I16/Actuals!I10,0)+Assumptions!$D$14) -> 10181.3 | J16: =J10*(IFERROR(Actuals!J16/Actuals!J10,0)+Assumptions!$D$14) -> 10742.04 | K16: =K10*(IFERROR(Actuals!K16/Actuals!K10,0)+Assumptions!$D$14) -> 10579.86 | ... O16: =O10*(IFERROR(Actuals!O16/Actuals!O10,0)+Assumptions!$D$14) -> 12411.54 | P16: =SUM(D16:O16) -> 126542.8 | Q16: =Actuals!P16 -> 119380 | R16: =IFERROR(P16/Q16-1,0) -> 0.06
B17: Fresh & Frozen | D17: =D11*(IFERROR(Actuals!D17/Actuals!D11,0)+Assumptions!$D$15) -> 9095.8623 | E17: =E11*(IFERROR(Actuals!E17/Actuals!E11,0)+Assumptions!$D$15) -> 8850.2634 | F17: =F11*(IFERROR(Actuals!F17/Actuals!F11,0)+Assumptions!$D$15) -> 9261.3952 | G17: =G11*(IFERROR(Actuals!G17/Actuals!G11,0)+Assumptions!$D$15) -> 9395.8151 | H17: =H11*(IFERROR(Actuals!H17/Actuals!H11,0)+Assumptions!$D$15) -> 9443.4724 | I17: =I11*(IFERROR(Actuals!I17/Actuals!I11,0)+Assumptions!$D$15) -> 9324.6658 | J17: =J11*(IFERROR(Actuals!J17/Actuals!J11,0)+Assumptions!$D$15) -> 9665.6462 | K17: =K11*(IFERROR(Actuals!K17/Actuals!K11,0)+Assumptions!$D$15) -> 9537.8059 | ... O17: =O11*(IFERROR(Actuals!O17/Actuals!O11,0)+Assumptions!$D$15) -> 10511.214 | P17: =SUM(D17:O17) -> 114502.06 | Q17: =Actuals!P17 -> 103074 | R17: =IFERROR(P17/Q17-1,0) -> 0.11087241
B18: Total cost of sales | D18: =SUM(D14:D17) -> 59699.933 | E18: =SUM(E14:E17) -> 57375.839 | F18: =SUM(F14:F17) -> 62292.903 | G18: =SUM(G14:G17) -> 63507.065 | H18: =SUM(H14:H17) -> 65727.524 | I18: =SUM(I14:I17) -> 63717.421 | J18: =SUM(J14:J17) -> 65390.168 | K18: =SUM(K14:K17) -> 64969.314 | ... P18: =SUM(P14:P17) -> 779407.09 | Q18: =Actuals!P18 -> 722548 | R18: =IFERROR(P18/Q18-1,0) -> 0.07869248
B19: Gross profit | D19: =D12-D18 -> 20692.572 | E19: =E12-E18 -> 20028.661 | F19: =F12-F18 -> 21695.977 | G19: =G12-G18 -> 21846.09 | H19: =H12-H18 -> 22762.451 | I19: =I12-I18 -> 22047.534 | J19: =J12-J18 -> 22769.217 | K19: =K12-K18 -> 22592.091 | ... P19: =P12-P18 -> 270515.74 | Q19: =Actuals!P19 -> 249894 | R19: =IFERROR(P19/Q19-1,0) -> 0.082521952
B20: Gross margin % | D20: =IFERROR(D19/D12,0) -> 0.25739429 | E20: =IFERROR(E19/E12,0) -> 0.25875319 | F20: =IFERROR(F19/F12,0) -> 0.25831964 | G20: =IFERROR(G19/G12,0) -> 0.25594941 | H20: =IFERROR(H19/H12,0) -> 0.25723197 | I20: =IFERROR(I19/I12,0) -> 0.25706926 | J20: =IFERROR(J19/J12,0) -> 0.25827332 | K20: =IFERROR(K19/K12,0) -> 0.25801426 | ... P20: =IFERROR(P19/P12,0) -> 0.25765297 | Q20: =Actuals!P20 -> 0.25697574
B21: OPERATING EXPENSES
B22: Sales commissions & incentives | C22: Variable | D22: =IF(Assumptions!$C$19="Variable",D$12*IFERROR(Actuals!$P22/Actuals!$P$12,0)*(1+Assumptions!$D$19),Actuals!D22*(1+Assumptions!$D$19)) -> 1297.5173 | E22: =IF(Assumptions!$C$19="Variable",E$12*IFERROR(Actuals!$P22/Actuals!$P$12,0)*(1+Assumptions!$D$19),Actuals!E22*(1+Assumptions!$D$19)) -> 1249.2916 | F22: =IF(Assumptions!$C$19="Variable",F$12*IFERROR(Actuals!$P22/Actuals!$P$12,0)*(1+Assumptions!$D$19),Actuals!F22*(1+Assumptions!$D$19)) -> 1355.5621 | G22: =IF(Assumptions!$C$19="Variable",G$12*IFERROR(Actuals!$P22/Actuals!$P$12,0)*(1+Assumptions!$D$19),Actuals!G22*(1+Assumptions!$D$19)) -> 1377.5811 | H22: =IF(Assumptions!$C$19="Variable",H$12*IFERROR(Actuals!$P22/Actuals!$P$12,0)*(1+Assumptions!$D$19),Actuals!H22*(1+Assumptions!$D$19)) -> 1428.2087 | I22: =IF(Assumptions!$C$19="Variable",I$12*IFERROR(Actuals!$P22/Actuals!$P$12,0)*(1+Assumptions!$D$19),Actuals!I22*(1+Assumptions!$D$19)) -> 1384.2275 | J22: =IF(Assumptions!$C$19="Variable",J$12*IFERROR(Actuals!$P22/Actuals!$P$12,0)*(1+Assumptions!$D$19),Actuals!J22*(1+Assumptions!$D$19)) -> 1422.8731 | K22: =IF(Assumptions!$C$19="Variable",K$12*IFERROR(Actuals!$P22/Actuals!$P$12,0)*(1+Assumptions!$D$19),Actuals!K22*(1+Assumptions!$D$19)) -> 1413.2218 | ... O22: =IF(Assumptions!$C$19="Variable",O$12*IFERROR(Actuals!$P22/Actuals!$P$12,0)*(1+Assumptions!$D$19),Actuals!O22*(1+Assumptions!$D$19)) -> 1635.6158 | P22: =SUM(D22:O22) -> 16945.524 | Q22: =Actuals!P22 -> 15695 | R22: =IFERROR(P22/Q22-1,0) -> 0.079676562
B23: Advertising & promotions | C23: Variable | D23: =IF(Assumptions!$C$20="Variable",D$12*IFERROR(Actuals!$P23/Actuals!$P$12,0)*(1+Assumptions!$D$20),Actuals!D23*(1+Assumptions!$D$20)) -> 812.7485 | E23: =IF(Assumptions!$C$20="Variable",E$12*IFERROR(Actuals!$P23/Actuals!$P$12,0)*(1+Assumptions!$D$20),Actuals!E23*(1+Assumptions!$D$20)) -> 782.5405 | F23: =IF(Assumptions!$C$20="Variable",F$12*IFERROR(Actuals!$P23/Actuals!$P$12,0)*(1+Assumptions!$D$20),Actuals!F23*(1+Assumptions!$D$20)) -> 849.10697 | G23: =IF(Assumptions!$C$20="Variable",G$12*IFERROR(Actuals!$P23/Actuals!$P$12,0)*(1+Assumptions!$D$20),Actuals!G23*(1+Assumptions!$D$20)) -> 862.89945 | H23: =IF(Assumptions!$C$20="Variable",H$12*IFERROR(Actuals!$P23/Actuals!$P$12,0)*(1+Assumptions!$D$20),Actuals!H23*(1+Assumptions!$D$20)) -> 894.61193 | I23: =IF(Assumptions!$C$20="Variable",I$12*IFERROR(Actuals!$P23/Actuals!$P$12,0)*(1+Assumptions!$D$20),Actuals!I23*(1+Assumptions!$D$20)) -> 867.06265 | J23: =IF(Assumptions!$C$20="Variable",J$12*IFERROR(Actuals!$P23/Actuals!$P$12,0)*(1+Assumptions!$D$20),Actuals!J23*(1+Assumptions!$D$20)) -> 891.26975 | K23: =IF(Assumptions!$C$20="Variable",K$12*IFERROR(Actuals!$P23/Actuals!$P$12,0)*(1+Assumptions!$D$20),Actuals!K23*(1+Assumptions!$D$20)) -> 885.22432 | ... O23: =IF(Assumptions!$C$20="Variable",O$12*IFERROR(Actuals!$P23/Actuals!$P$12,0)*(1+Assumptions!$D$20),Actuals!O23*(1+Assumptions!$D$20)) -> 1024.5291 | P23: =SUM(D23:O23) -> 10614.462 | Q23: =Actuals!P23 -> 9363 | R23: =IFERROR(P23/Q23-1,0) -> 0.13366039
B24: Freight & delivery | C24: Variable | D24: =IF(Assumptions!$C$21="Variable",D$12*IFERROR(Actuals!$P24/Actuals!$P$12,0)*(1+Assumptions!$D$21),Actuals!D24*(1+Assumptions!$D$21)) -> 1909.9943 | E24: =IF(Assumptions!$C$21="Variable",E$12*IFERROR(Actuals!$P24/Actuals!$P$12,0)*(1+Assumptions!$D$21),Actuals!E24*(1+Assumptions!$D$21)) -> 1839.0042 | F24: =IF(Assumptions!$C$21="Variable",F$12*IFERROR(Actuals!$P24/Actuals!$P$12,0)*(1+Assumptions!$D$21),Actuals!F24*(1+Assumptions!$D$21)) -> 1995.4383 | G24: =IF(Assumptions!$C$21="Variable",G$12*IFERROR(Actuals!$P24/Actuals!$P$12,0)*(1+Assumptions!$D$21),Actuals!G24*(1+Assumptions!$D$21)) -> 2027.8512 | H24: =IF(Assumptions!$C$21="Variable",H$12*IFERROR(Actuals!$P24/Actuals!$P$12,0)*(1+Assumptions!$D$21),Actuals!H24*(1+Assumptions!$D$21)) -> 2102.3769 | I24: =IF(Assumptions!$C$21="Variable",I$12*IFERROR(Actuals!$P24/Actuals!$P$12,0)*(1+Assumptions!$D$21),Actuals!I24*(1+Assumptions!$D$21)) -> 2037.6349 | J24: =IF(Assumptions!$C$21="Variable",J$12*IFERROR(Actuals!$P24/Actuals!$P$12,0)*(1+Assumptions!$D$21),Actuals!J24*(1+Assumptions!$D$21)) -> 2094.5227 | K24: =IF(Assumptions!$C$21="Variable",K$12*IFERROR(Actuals!$P24/Actuals!$P$12,0)*(1+Assumptions!$D$21),Actuals!K24*(1+Assumptions!$D$21)) -> 2080.3156 | ... O24: =IF(Assumptions!$C$21="Variable",O$12*IFERROR(Actuals!$P24/Actuals!$P$12,0)*(1+Assumptions!$D$21),Actuals!O24*(1+Assumptions!$D$21)) -> 2407.6879 | P24: =SUM(D24:O24) -> 24944.448 | Q24: =Actuals!P24 -> 23337 | R24: =IFERROR(P24/Q24-1,0) -> 0.068879796
B25: Warehouse rent & utilities | C25: Fixed | D25: =IF(Assumptions!$C$22="Variable",D$12*IFERROR(Actuals!$P25/Actuals!$P$12,0)*(1+Assumptions!$D$22),Actuals!D25*(1+Assumptions!$D$22)) -> 2233.42 | E25: =IF(Assumptions!$C$22="Variable",E$12*IFERROR(Actuals!$P25/Actuals!$P$12,0)*(1+Assumptions!$D$22),Actuals!E25*(1+Assumptions!$D$22)) -> 2248.26 | F25: =IF(Assumptions!$C$22="Variable",F$12*IFERROR(Actuals!$P25/Actuals!$P$12,0)*(1+Assumptions!$D$22),Actuals!F25*(1+Assumptions!$D$22)) -> 2221.76 | G25: =IF(Assumptions!$C$22="Variable",G$12*IFERROR(Actuals!$P25/Actuals!$P$12,0)*(1+Assumptions!$D$22),Actuals!G25*(1+Assumptions!$D$22)) -> 2230.24 | H25: =IF(Assumptions!$C$22="Variable",H$12*IFERROR(Actuals!$P25/Actuals!$P$12,0)*(1+Assumptions!$D$22),Actuals!H25*(1+Assumptions!$D$22)) -> 2181.48 | I25: =IF(Assumptions!$C$22="Variable",I$12*IFERROR(Actuals!$P25/Actuals!$P$12,0)*(1+Assumptions!$D$22),Actuals!I25*(1+Assumptions!$D$22)) -> 2187.84 | J25: =IF(Assumptions!$C$22="Variable",J$12*IFERROR(Actuals!$P25/Actuals!$P$12,0)*(1+Assumptions!$D$22),Actuals!J25*(1+Assumptions!$D$22)) -> 2184.66 | K25: =IF(Assumptions!$C$22="Variable",K$12*IFERROR(Actuals!$P25/Actuals!$P$12,0)*(1+Assumptions!$D$22),Actuals!K25*(1+Assumptions!$D$22)) -> 2188.9 | ... O25: =IF(Assumptions!$C$22="Variable",O$12*IFERROR(Actuals!$P25/Actuals!$P$12,0)*(1+Assumptions!$D$22),Actuals!O25*(1+Assumptions!$D$22)) -> 2173 | P25: =SUM(D25:O25) -> 26491.52 | Q25: =Actuals!P25 -> 24992 | R25: =IFERROR(P25/Q25-1,0) -> 0.06
B26: Selling & logistics staff costs | C26: Fixed | D26: =IF(Assumptions!$C$23="Variable",D$12*IFERROR(Actuals!$P26/Actuals!$P$12,0)*(1+Assumptions!$D$23),Actuals!D26*(1+Assumptions!$D$23)) -> 2839.005 | E26: =IF(Assumptions!$C$23="Variable",E$12*IFERROR(Actuals!$P26/Actuals!$P$12,0)*(1+Assumptions!$D$23),Actuals!E26*(1+Assumptions!$D$23)) -> 2853.775 | F26: =IF(Assumptions!$C$23="Variable",F$12*IFERROR(Actuals!$P26/Actuals!$P$12,0)*(1+Assumptions!$D$23),Actuals!F26*(1+Assumptions!$D$23)) -> 2909.69 | G26: =IF(Assumptions!$C$23="Variable",G$12*IFERROR(Actuals!$P26/Actuals!$P$12,0)*(1+Assumptions!$D$23),Actuals!G26*(1+Assumptions!$D$23)) -> 2880.15 | H26: =IF(Assumptions!$C$23="Variable",H$12*IFERROR(Actuals!$P26/Actuals!$P$12,0)*(1+Assumptions!$D$23),Actuals!H26*(1+Assumptions!$D$23)) -> 2853.775 | I26: =IF(Assumptions!$C$23="Variable",I$12*IFERROR(Actuals!$P26/Actuals!$P$12,0)*(1+Assumptions!$D$23),Actuals!I26*(1+Assumptions!$D$23)) -> 2865.38 | J26: =IF(Assumptions!$C$23="Variable",J$12*IFERROR(Actuals!$P26/Actuals!$P$12,0)*(1+Assumptions!$D$23),Actuals!J26*(1+Assumptions!$D$23)) -> 2866.435 | K26: =IF(Assumptions!$C$23="Variable",K$12*IFERROR(Actuals!$P26/Actuals!$P$12,0)*(1+Assumptions!$D$23),Actuals!K26*(1+Assumptions!$D$23)) -> 2876.985 | ... O26: =IF(Assumptions!$C$23="Variable",O$12*IFERROR(Actuals!$P26/Actuals!$P$12,0)*(1+Assumptions!$D$23),Actuals!O26*(1+Assumptions!$D$23)) -> 2832.675 | P26: =SUM(D26:O26) -> 34487.95 | Q26: =Actuals!P26 -> 32690 | R26: =IFERROR(P26/Q26-1,0) -> 0.055
B27: Selling & distribution | D27: =SUM(D22:D26) -> 9092.6852 | E27: =SUM(E22:E26) -> 8972.8713 | F27: =SUM(F22:F26) -> 9331.5573 | G27: =SUM(G22:G26) -> 9378.7218 | H27: =SUM(H22:H26) -> 9460.4526 | I27: =SUM(I22:I26) -> 9342.1451 | J27: =SUM(J22:J26) -> 9459.7605 | K27: =SUM(K22:K26) -> 9444.6468 | ... P27: =SUM(P22:P26) -> 113483.9 | Q27: =Actuals!P27 -> 106077 | R27: =IFERROR(P27/Q27-1,0) -> 0.069825727
B28: Salaries & wages (G&A) | C28: Fixed | D28: =IF(Assumptions!$C$24="Variable",D$12*IFERROR(Actuals!$P28/Actuals!$P$12,0)*(1+Assumptions!$D$24),Actuals!D28*(1+Assumptions!$D$24)) -> 2625 | E28: =IF(Assumptions!$C$24="Variable",E$12*IFERROR(Actuals!$P28/Actuals!$P$12,0)*(1+Assumptions!$D$24),Actuals!E28*(1+Assumptions!$D$24)) -> 2657.55 | F28: =IF(Assumptions!$C$24="Variable",F$12*IFERROR(Actuals!$P28/Actuals!$P$12,0)*(1+Assumptions!$D$24),Actuals!F28*(1+Assumptions!$D$24)) -> 2597.7 | G28: =IF(Assumptions!$C$24="Variable",G$12*IFERROR(Actuals!$P28/Actuals!$P$12,0)*(1+Assumptions!$D$24),Actuals!G28*(1+Assumptions!$D$24)) -> 2690.1 | H28: =IF(Assumptions!$C$24="Variable",H$12*IFERROR(Actuals!$P28/Actuals!$P$12,0)*(1+Assumptions!$D$24),Actuals!H28*(1+Assumptions!$D$24)) -> 2695.35 | I28: =IF(Assumptions!$C$24="Variable",I$12*IFERROR(Actuals!$P28/Actuals!$P$12,0)*(1+Assumptions!$D$24),Actuals!I28*(1+Assumptions!$D$24)) -> 2637.6 | J28: =IF(Assumptions!$C$24="Variable",J$12*IFERROR(Actuals!$P28/Actuals!$P$12,0)*(1+Assumptions!$D$24),Actuals!J28*(1+Assumptions!$D$24)) -> 2667 | K28: =IF(Assumptions!$C$24="Variable",K$12*IFERROR(Actuals!$P28/Actuals!$P$12,0)*(1+Assumptions!$D$24),Actuals!K28*(1+Assumptions!$D$24)) -> 2680.65 | ... O28: =IF(Assumptions!$C$24="Variable",O$12*IFERROR(Actuals!$P28/Actuals!$P$12,0)*(1+Assumptions!$D$24),Actuals!O28*(1+Assumptions!$D$24)) -> 2596.65 | P28: =SUM(D28:O28) -> 31723.65 | Q28: =Actuals!P28 -> 30213 | R28: =IFERROR(P28/Q28-1,0) -> 0.05
B29: Employee benefits & contributions | C29: Fixed | D29: =IF(Assumptions!$C$25="Variable",D$12*IFERROR(Actuals!$P29/Actuals!$P$12,0)*(1+Assumptions!$D$25),Actuals!D29*(1+Assumptions!$D$25)) -> 706.65 | E29: =IF(Assumptions!$C$25="Variable",E$12*IFERROR(Actuals!$P29/Actuals!$P$12,0)*(1+Assumptions!$D$25),Actuals!E29*(1+Assumptions!$D$25)) -> 707.7 | F29: =IF(Assumptions!$C$25="Variable",F$12*IFERROR(Actuals!$P29/Actuals!$P$12,0)*(1+Assumptions!$D$25),Actuals!F29*(1+Assumptions!$D$25)) -> 717.15 | G29: =IF(Assumptions!$C$25="Variable",G$12*IFERROR(Actuals!$P29/Actuals!$P$12,0)*(1+Assumptions!$D$25),Actuals!G29*(1+Assumptions!$D$25)) -> 700.35 | H29: =IF(Assumptions!$C$25="Variable",H$12*IFERROR(Actuals!$P29/Actuals!$P$12,0)*(1+Assumptions!$D$25),Actuals!H29*(1+Assumptions!$D$25)) -> 711.9 | I29: =IF(Assumptions!$C$25="Variable",I$12*IFERROR(Actuals!$P29/Actuals!$P$12,0)*(1+Assumptions!$D$25),Actuals!I29*(1+Assumptions!$D$25)) -> 710.85 | J29: =IF(Assumptions!$C$25="Variable",J$12*IFERROR(Actuals!$P29/Actuals!$P$12,0)*(1+Assumptions!$D$25),Actuals!J29*(1+Assumptions!$D$25)) -> 719.25 | K29: =IF(Assumptions!$C$25="Variable",K$12*IFERROR(Actuals!$P29/Actuals!$P$12,0)*(1+Assumptions!$D$25),Actuals!K29*(1+Assumptions!$D$25)) -> 699.3 | ... O29: =IF(Assumptions!$C$25="Variable",O$12*IFERROR(Actuals!$P29/Actuals!$P$12,0)*(1+Assumptions!$D$25),Actuals!O29*(1+Assumptions!$D$25)) -> 699.3 | P29: =SUM(D29:O29) -> 8536.5 | Q29: =Actuals!P29 -> 8130 | R29: =IFERROR(P29/Q29-1,0) -> 0.05
B30: Professional fees | C30: Fixed | D30: =IF(Assumptions!$C$26="Variable",D$12*IFERROR(Actuals!$P30/Actuals!$P$12,0)*(1+Assumptions!$D$26),Actuals!D30*(1+Assumptions!$D$26)) -> 348.4 | E30: =IF(Assumptions!$C$26="Variable",E$12*IFERROR(Actuals!$P30/Actuals!$P$12,0)*(1+Assumptions!$D$26),Actuals!E30*(1+Assumptions!$D$26)) -> 338 | F30: =IF(Assumptions!$C$26="Variable",F$12*IFERROR(Actuals!$P30/Actuals!$P$12,0)*(1+Assumptions!$D$26),Actuals!F30*(1+Assumptions!$D$26)) -> 901.68 | G30: =IF(Assumptions!$C$26="Variable",G$12*IFERROR(Actuals!$P30/Actuals!$P$12,0)*(1+Assumptions!$D$26),Actuals!G30*(1+Assumptions!$D$26)) -> 343.2 | H30: =IF(Assumptions!$C$26="Variable",H$12*IFERROR(Actuals!$P30/Actuals!$P$12,0)*(1+Assumptions!$D$26),Actuals!H30*(1+Assumptions!$D$26)) -> 344.24 | I30: =IF(Assumptions!$C$26="Variable",I$12*IFERROR(Actuals!$P30/Actuals!$P$12,0)*(1+Assumptions!$D$26),Actuals!I30*(1+Assumptions!$D$26)) -> 341.12 | J30: =IF(Assumptions!$C$26="Variable",J$12*IFERROR(Actuals!$P30/Actuals!$P$12,0)*(1+Assumptions!$D$26),Actuals!J30*(1+Assumptions!$D$26)) -> 346.32 | K30: =IF(Assumptions!$C$26="Variable",K$12*IFERROR(Actuals!$P30/Actuals!$P$12,0)*(1+Assumptions!$D$26),Actuals!K30*(1+Assumptions!$D$26)) -> 339.04 | ... O30: =IF(Assumptions!$C$26="Variable",O$12*IFERROR(Actuals!$P30/Actuals!$P$12,0)*(1+Assumptions!$D$26),Actuals!O30*(1+Assumptions!$D$26)) -> 347.36 | P30: =SUM(D30:O30) -> 4680 | Q30: =Actuals!P30 -> 4500 | R30: =IFERROR(P30/Q30-1,0) -> 0.04
B31: Office rent & utilities | C31: Fixed | D31: =IF(Assumptions!$C$27="Variable",D$12*IFERROR(Actuals!$P31/Actuals!$P$12,0)*(1+Assumptions!$D$27),Actuals!D31*(1+Assumptions!$D$27)) -> 596.96 | E31: =IF(Assumptions!$C$27="Variable",E$12*IFERROR(Actuals!$P31/Actuals!$P$12,0)*(1+Assumptions!$D$27),Actuals!E31*(1+Assumptions!$D$27)) -> 603.2 | F31: =IF(Assumptions!$C$27="Variable",F$12*IFERROR(Actuals!$P31/Actuals!$P$12,0)*(1+Assumptions!$D$27),Actuals!F31*(1+Assumptions!$D$27)) -> 585.52 | G31: =IF(Assumptions!$C$27="Variable",G$12*IFERROR(Actuals!$P31/Actuals!$P$12,0)*(1+Assumptions!$D$27),Actuals!G31*(1+Assumptions!$D$27)) -> 591.76 | H31: =IF(Assumptions!$C$27="Variable",H$12*IFERROR(Actuals!$P31/Actuals!$P$12,0)*(1+Assumptions!$D$27),Actuals!H31*(1+Assumptions!$D$27)) -> 583.44 | I31: =IF(Assumptions!$C$27="Variable",I$12*IFERROR(Actuals!$P31/Actuals!$P$12,0)*(1+Assumptions!$D$27),Actuals!I31*(1+Assumptions!$D$27)) -> 590.72 | J31: =IF(Assumptions!$C$27="Variable",J$12*IFERROR(Actuals!$P31/Actuals!$P$12,0)*(1+Assumptions!$D$27),Actuals!J31*(1+Assumptions!$D$27)) -> 600.08 | K31: =IF(Assumptions!$C$27="Variable",K$12*IFERROR(Actuals!$P31/Actuals!$P$12,0)*(1+Assumptions!$D$27),Actuals!K31*(1+Assumptions!$D$27)) -> 603.2 | ... O31: =IF(Assumptions!$C$27="Variable",O$12*IFERROR(Actuals!$P31/Actuals!$P$12,0)*(1+Assumptions!$D$27),Actuals!O31*(1+Assumptions!$D$27)) -> 590.72 | P31: =SUM(D31:O31) -> 7112.56 | Q31: =Actuals!P31 -> 6839 | R31: =IFERROR(P31/Q31-1,0) -> 0.04
B32: Repairs & maintenance | C32: Fixed | D32: =IF(Assumptions!$C$28="Variable",D$12*IFERROR(Actuals!$P32/Actuals!$P$12,0)*(1+Assumptions!$D$28),Actuals!D32*(1+Assumptions!$D$28)) -> 264.71 | E32: =IF(Assumptions!$C$28="Variable",E$12*IFERROR(Actuals!$P32/Actuals!$P$12,0)*(1+Assumptions!$D$28),Actuals!E32*(1+Assumptions!$D$28)) -> 250.29 | F32: =IF(Assumptions!$C$28="Variable",F$12*IFERROR(Actuals!$P32/Actuals!$P$12,0)*(1+Assumptions!$D$28),Actuals!F32*(1+Assumptions!$D$28)) -> 244.11 | G32: =IF(Assumptions!$C$28="Variable",G$12*IFERROR(Actuals!$P32/Actuals!$P$12,0)*(1+Assumptions!$D$28),Actuals!G32*(1+Assumptions!$D$28)) -> 238.96 | H32: =IF(Assumptions!$C$28="Variable",H$12*IFERROR(Actuals!$P32/Actuals!$P$12,0)*(1+Assumptions!$D$28),Actuals!H32*(1+Assumptions!$D$28)) -> 241.02 | I32: =IF(Assumptions!$C$28="Variable",I$12*IFERROR(Actuals!$P32/Actuals!$P$12,0)*(1+Assumptions!$D$28),Actuals!I32*(1+Assumptions!$D$28)) -> 225.57 | J32: =IF(Assumptions!$C$28="Variable",J$12*IFERROR(Actuals!$P32/Actuals!$P$12,0)*(1+Assumptions!$D$28),Actuals!J32*(1+Assumptions!$D$28)) -> 212.18 | K32: =IF(Assumptions!$C$28="Variable",K$12*IFERROR(Actuals!$P32/Actuals!$P$12,0)*(1+Assumptions!$D$28),Actuals!K32*(1+Assumptions!$D$28)) -> 228.66 | ... O32: =IF(Assumptions!$C$28="Variable",O$12*IFERROR(Actuals!$P32/Actuals!$P$12,0)*(1+Assumptions!$D$28),Actuals!O32*(1+Assumptions!$D$28)) -> 246.17 | P32: =SUM(D32:O32) -> 2810.87 | Q32: =Actuals!P32 -> 2729 | R32: =IFERROR(P32/Q32-1,0) -> 0.03
B33: Taxes, licenses & insurance | C33: Fixed | D33: =IF(Assumptions!$C$29="Variable",D$12*IFERROR(Actuals!$P33/Actuals!$P$12,0)*(1+Assumptions!$D$29),Actuals!D33*(1+Assumptions!$D$29)) -> 469.68 | E33: =IF(Assumptions!$C$29="Variable",E$12*IFERROR(Actuals!$P33/Actuals!$P$12,0)*(1+Assumptions!$D$29),Actuals!E33*(1+Assumptions!$D$29)) -> 474.83 | F33: =IF(Assumptions!$C$29="Variable",F$12*IFERROR(Actuals!$P33/Actuals!$P$12,0)*(1+Assumptions!$D$29),Actuals!F33*(1+Assumptions!$D$29)) -> 473.8 | G33: =IF(Assumptions!$C$29="Variable",G$12*IFERROR(Actuals!$P33/Actuals!$P$12,0)*(1+Assumptions!$D$29),Actuals!G33*(1+Assumptions!$D$29)) -> 466.59 | H33: =IF(Assumptions!$C$29="Variable",H$12*IFERROR(Actuals!$P33/Actuals!$P$12,0)*(1+Assumptions!$D$29),Actuals!H33*(1+Assumptions!$D$29)) -> 470.71 | I33: =IF(Assumptions!$C$29="Variable",I$12*IFERROR(Actuals!$P33/Actuals!$P$12,0)*(1+Assumptions!$D$29),Actuals!I33*(1+Assumptions!$D$29)) -> 470.71 | J33: =IF(Assumptions!$C$29="Variable",J$12*IFERROR(Actuals!$P33/Actuals!$P$12,0)*(1+Assumptions!$D$29),Actuals!J33*(1+Assumptions!$D$29)) -> 467.62 | K33: =IF(Assumptions!$C$29="Variable",K$12*IFERROR(Actuals!$P33/Actuals!$P$12,0)*(1+Assumptions!$D$29),Actuals!K33*(1+Assumptions!$D$29)) -> 465.56 | ... O33: =IF(Assumptions!$C$29="Variable",O$12*IFERROR(Actuals!$P33/Actuals!$P$12,0)*(1+Assumptions!$D$29),Actuals!O33*(1+Assumptions!$D$29)) -> 475.86 | P33: =SUM(D33:O33) -> 5648.52 | Q33: =Actuals!P33 -> 5484 | R33: =IFERROR(P33/Q33-1,0) -> 0.03
