Workbook

Sheet Cover
B2: PORTFOLIO PROJECT 01
B3: Financial Statement Analysis
B4: =Inputs!$C$6 -> Sampaguita Foods & Distribution Corporation (SFDC)
B5: ="Integrated three-statement model and analytical review | FY"&Inputs!D$22&" - FY"&Inputs!F$22 -> Integrated three-statement model and analytical review | FY2023 - FY2025
B7: ="Prepared by "&Inputs!$C$12&" | Version 1.0 | "&Inputs!$C$11 -> Prepared by Bengie Hirnani | Version 1.0 | PHP in thousands (unless otherwise stated)
B10: Model status | C10: =Model_Status -> ✔ All 23 integrity checks passed
B11: Scope | C11: Income statement, balance sheet, cash flow, changes in equity, notes, supporting schedules, horizontal, vertical, trend and common-size analysis, revenue and expense analysis, ratio analysis and an executive dashboard - all formula-driven from one inputs sheet and two transaction ledgers.
B12: Data notice | C12: The company, its figures and the ledgers are entirely fictional and were created for portfolio demonstration. Philippine tax rates are inputs - verify against current BIR rules before reuse.
B14: NAVIGATION - click a button to jump to a sheet
B15: FINANCIAL REPORTS
B16: =HYPERLINK("#Dashboard!A1","Dashboard") -> Dashboard | C16: Executive KPI dashboard with year selector and charts
B17: =HYPERLINK("#Income_Statement!A1","Income Statement") -> Income Statement | C17: Statement of comprehensive income (by function)
B18: =HYPERLINK("#Balance_Sheet!A1","Balance Sheet") -> Balance Sheet | C18: Statement of financial position
B19: =HYPERLINK("#Cash_Flow!A1","Cash Flow") -> Cash Flow | C19: Statement of cash flows (indirect method)
B20: =HYPERLINK("#Equity_Changes!A1","Equity Changes") -> Equity Changes | C20: Statement of changes in equity
B21: =HYPERLINK("#Notes_to_FS!A1","Notes to FS") -> Notes to FS | C21: Notes to the financial statements
B23: ANALYSIS
B24: =HYPERLINK("#Horizontal!A1","Horizontal") -> Horizontal | C24: Horizontal analysis: peso and % change, flags
B25: =HYPERLINK("#Vertical!A1","Vertical") -> Vertical | C25: Vertical analysis: % of net sales / total assets
B26: =HYPERLINK("#Common_Size!A1","Common Size") -> Common Size | C26: Common-size statements with year comparison
B27: =HYPERLINK("#Trend!A1","Trend") -> Trend | C27: Trend indices, CAGR and FY2026-27 projections
B28: =HYPERLINK("#Revenue_Analysis!A1","Revenue Analysis") -> Revenue Analysis | C28: Revenue by month, category, region, quarter (filters)
B29: =HYPERLINK("#Expense_Analysis!A1","Expense Analysis") -> Expense Analysis | C29: Expense analysis, cost behaviour and break-even
B30: =HYPERLINK("#Ratio_Analysis!A1","Ratio Analysis") -> Ratio Analysis | C30: Profitability, liquidity, solvency, efficiency, DuPont
B32: MODEL ENGINE AND CONTROLS
B33: =HYPERLINK("#Inputs!A1","Inputs") -> Inputs | C33: All assumptions and opening balances (blue cells)
B34: =HYPERLINK("#Schedules!A1","Schedules") -> Schedules | C34: PPE, working capital, borrowings and tax schedules
B35: =HYPERLINK("#Data_Sales!A1","Data Sales") -> Data Sales | C35: Monthly sales ledger by category and region
B36: =HYPERLINK("#Data_Expenses!A1","Data Expenses") -> Data Expenses | C36: Monthly operating expense ledger
B37: =HYPERLINK("#Chart_Data!A1","Chart Data") -> Chart Data | C37: Helper tables feeding dashboard charts
B38: =HYPERLINK("#Lists!A1","Lists") -> Lists | C38: Drop-down lists and named labels
B39: =HYPERLINK("#Checks!A1","Checks") -> Checks | C39: Model integrity checks
B40: =HYPERLINK("#Documentation!A1","Documentation") -> Documentation | C40: Purpose, structure, colour legend, assumptions, methodology

Sheet Documentation
B1: Model Documentation
B2: =Inputs!$C$6&" | "&Inputs!$C$11 -> Sampaguita Foods & Distribution Corporation (SFDC) | PHP in thousands (unless otherwise stated)
B3: =HYPERLINK("#Cover!A1","◄ Back to Cover") -> ◄ Back to Cover
B5: 1. PURPOSE AND BUSINESS CONTEXT
B6: Objective | C6: Demonstrate a professional, fully integrated financial statement analysis for a fictional Philippine distribution company: three linked statements, notes, schedules and a complete analytical review (horizontal, vertical, trend, common-size, revenue, expense, profitability, liquidity, solvency and efficiency).
B7: Company | C7: =Inputs!$C$6&" - "&Inputs!$C$9&". Head office: "&Inputs!$C$8&"." -> Sampaguita Foods & Distribution Corporation (SFDC) - Wholesale distribution of packaged food, beverages, household products and fresh & frozen goods. Head office: Taguig City, Metro Manila, Philippines (warehouses: Laguna, Cebu, Davao).
B8: Reporting basis | C8: Philippine Financial Reporting Standards (PFRS), expenses presented by function, financial year ending 31 December, amounts in PHP thousands.
B9: Shared company model | C9: Projects 2-6 of the portfolio (ratio dashboard, budgeting, cost accounting, internal control, tax computation) are built on this same fictional company so figures reconcile across deliverables.
B11: 2. HOW THE MODEL FLOWS
B12: Step 1 - Inputs | C12: Assumptions, opening balances (FY2022), working-capital drivers, PPE additions and disposals, loan movements, tax rates and the expense chart-of-accounts mapping are entered on Inputs (blue cells).
B13: Step 2 - Ledgers | C13: Data_Sales (monthly net sales and cost of sales by category and region) and Data_Expenses (monthly operating expenses by line) feed the income statement through SUMIFS and the analysis sheets through SUMIFS/SUMPRODUCT.
B14: Step 3 - Schedules | C14: Schedules computes PPE roll-forwards and depreciation, working-capital balances from DSO/DIO/DPO drivers, borrowings and finance costs, and the income tax computation (RCIT vs MCIT, final tax).
B15: Step 4 - Statements | C15: Income statement, balance sheet, cash flow (indirect method) and changes in equity are linked. Closing cash is derived from the cash flow statement, so the balance sheet balances by construction - the Checks sheet proves it.
B16: Step 5 - Analysis | C16: Horizontal, vertical, common-size, trend, revenue, expense and ratio sheets read the statements; the dashboard reads Chart_Data. Changing any input updates all of them.
B18: 3. SHEET INDEX
B19: Cover | C19: Title page, model status and navigation
B20: Documentation | C20: Purpose, structure, colour legend, assumptions, methodology
B21: Dashboard | C21: Executive KPI dashboard with year selector and charts
B22: Income Statement | C22: Statement of comprehensive income (by function)
B23: Balance Sheet | C23: Statement of financial position
B24: Cash Flow | C24: Statement of cash flows (indirect method)
B25: Equity Changes | C25: Statement of changes in equity
B26: Notes to FS | C26: Notes to the financial statements
B27: Schedules | C27: PPE, working capital, borrowings and tax schedules
B28: Horizontal | C28: Horizontal analysis: peso and % change, flags
B29: Vertical | C29: Vertical analysis: % of net sales / total assets
B30: Common Size | C30: Common-size statements with year comparison
... B40: Checks | C40: Model integrity checks
B42: 4. COLOUR AND FORMAT CONVENTIONS
B43: Blue text | C43: Hard-coded input or ledger data. Change these cells only.
B44: Black text | C44: Formula calculated on the same sheet.
B45: Green text | C45: Formula that links directly to another sheet.
B46: Yellow fill | C46: Key assumption or selector (drop-down) that drives results.
B47: Number formats | C47: Negative values appear in parentheses; zero appears as a dash; percentages to one decimal; multiples as 0.00x. Expenses are shown as negatives in the statements (positive in analysis tables).
B49: 5. KEY ASSUMPTIONS AND SIMPLIFICATIONS
B50: Tax | C50: Current income tax = higher of RCIT (25% of taxable income) and MCIT (2% of gross income); 20% final tax on bank interest. Rates are inputs. Deferred tax is not modelled.
B51: Working capital | C51: Receivables, inventories, payables, prepayments and accruals are driven by DSO, DIO, DPO and % of operating expenses so that sales changes flow through to cash.
B52: Depreciation | C52: Straight-line by asset class with half-year convention on additions and disposals, capped so net book value never goes negative. Land is not depreciated.
B53: Interest | C53: Finance costs use average balances. Interest income uses prior year-end cash, which avoids a circular reference.
B54: Dividends | C54: Declared and paid in the same year at a payout ratio of net profit.
...

Sheet Dashboard
B1: Executive Dashboard
B2: =Inputs!$C$6&" | "&Inputs!$C$11 -> Sampaguita Foods & Distribution Corporation (SFDC) | PHP in thousands (unless otherwise stated)
B3: =HYPERLINK("#Cover!A1","◄ Back to Cover") -> ◄ Back to Cover
B5: Fiscal year | C5: 2025 | E5: Model integrity | F5: =Model_Status -> ✔ All 23 integrity checks passed
B7: NET SALES | E7: GROSS PROFIT | H7: EBITDA | K7: NET PROFIT
B8: =Chart_Data!F48 -> 972442 | E8: =Chart_Data!F49 -> 249894 | H8: =Chart_Data!F50 -> 82040 | K8: =Chart_Data!F51 -> 37406
B9: =IF(Chart_Data!H48="n/a","First year in model",IF(Chart_Data!H48>=0,"▲ ","▼ ")&TEXT(ABS(Chart_Data!H48),"0.0%")&" vs FY"&(Dash_Year-1)) -> ▲ 8.4% vs FY2024 | E9: =IF(Chart_Data!H49="n/a","First year in model",IF(Chart_Data!H49>=0,"▲ ","▼ ")&TEXT(ABS(Chart_Data!H49),"0.0%")&" vs FY"&(Dash_Year-1)) -> ▲ 9.3% vs FY2024 | H9: =IF(Chart_Data!H50="n/a","First year in model",IF(Chart_Data!H50>=0,"▲ ","▼ ")&TEXT(ABS(Chart_Data!H50),"0.0%")&" vs FY"&(Dash_Year-1)) -> ▲ 19.0% vs FY2024 | K9: =IF(Chart_Data!H51="n/a","First year in model",IF(Chart_Data!H51>=0,"▲ ","▼ ")&TEXT(ABS(Chart_Data!H51),"0.0%")&" vs FY"&(Dash_Year-1)) -> ▲ 28.9% vs FY2024
B11: TOTAL ASSETS | E11: TOTAL EQUITY | H11: NET DEBT | K11: FREE CASH FLOW
B12: =Chart_Data!F52 -> 478465 | E12: =Chart_Data!F53 -> 244502 | H12: =Chart_Data!F54 -> 51252 | K12: =Chart_Data!F55 -> 30860
B13: =IF(Chart_Data!H52="n/a","First year in model",IF(Chart_Data!H52>=0,"▲ ","▼ ")&TEXT(ABS(Chart_Data!H52),"0.0%")&" vs FY"&(Dash_Year-1)) -> ▲ 3.6% vs FY2024 | E13: =IF(Chart_Data!H53="n/a","First year in model",IF(Chart_Data!H53>=0,"▲ ","▼ ")&TEXT(ABS(Chart_Data!H53),"0.0%")&" vs FY"&(Dash_Year-1)) -> ▲ 12.0% vs FY2024 | H13: =IF(Chart_Data!H54="n/a","First year in model",IF(Chart_Data!H54>=0,"▲ ","▼ ")&TEXT(ABS(Chart_Data!H54),"0.0%")&" vs FY"&(Dash_Year-1)) -> ▼ 28.4% vs FY2024 | K13: =IF(Chart_Data!H55="n/a","First year in model",IF(Chart_Data!H55>=0,"▲ ","▼ ")&TEXT(ABS(Chart_Data!H55),"0.0%")&" vs FY"&(Dash_Year-1)) -> ▲ 131.2% vs FY2024
B80: KEY INSIGHTS (update automatically with the selected year)
B81: ="1. Net sales of PHP "&TEXT(Chart_Data!F48/1000,"#,##0.0")&" million "&IF(Chart_Data!H48="n/a","are the first year of the model period.",IF(Chart_Data!H48>=0,"grew ","fell ")&TEXT(ABS(Chart_Data!H48),"0.0%")&" year-on-year.") -> 1. Net sales of PHP 972.4 million grew 8.4% year-on-year.
B82: ="2. Margins: gross "&TEXT(INDEX(Ratio_Analysis!$D$7:$F$7,MATCH(Dash_Year,Ratio_Analysis!$D$5:$F$5,0)),"0.0%")&", EBITDA "&TEXT(INDEX(Ratio_Analysis!$D$8:$F$8,MATCH(Dash_Year,Ratio_Analysis!$D$5:$F$5,0)),"0.0%")&", net "&TEXT(INDEX(Ratio_Analysis!$D$10:$F$10,MATCH(Dash_Year,Ratio_Analysis!$D$5:$F$5,0)),"0.0%")&"; return on equity "&TEXT(INDEX(Ratio_Analysis!$D$12:$F$12,MATCH(Dash_Year,Ratio_Analysis!$D$5:$F$5,0)),"0.0%")&"." -> 2. Margins: gross 25.7%, EBITDA 8.4%, net 3.8%; return on equity 16.2%.
B83: ="3. Liquidity and leverage: current ratio "&TEXT(INDEX(Ratio_Analysis!$D$16:$F$16,MATCH(Dash_Year,Ratio_Analysis!$D$5:$F$5,0)),"0.00")&"x, borrowings-to-equity "&TEXT(INDEX(Ratio_Analysis!$D$24:$F$24,MATCH(Dash_Year,Ratio_Analysis!$D$5:$F$5,0)),"0.00")&"x, interest cover "&TEXT(INDEX(Ratio_Analysis!$D$28:$F$28,MATCH(Dash_Year,Ratio_Analysis!$D$5:$F$5,0)),"0.0")&"x, net debt "&TEXT(INDEX(Ratio_Analysis!$D$30:$F$30,MATCH(Dash_Year,Ratio_Analysis!$D$5:$F$5,0)),"0.0")&"x EBITDA." -> 3. Liquidity and leverage: current ratio 1.76x, borrowings-to-equity 0.54x, interest cover 5.2x, net debt 0.6x EBITDA.
B84: ="4. Cash: operating cash flow converts "&TEXT(INDEX(Ratio_Analysis!$D$47:$F$47,MATCH(Dash_Year,Ratio_Analysis!$D$5:$F$5,0)),"0%")&" of net profit; free cash flow is PHP "&TEXT(Chart_Data!F55/1000,"#,##0.0")&" million." -> 4. Cash: operating cash flow converts 154% of net profit; free cash flow is PHP 30.9 million.
B85: ="5. Largest category: "&INDEX(Chart_Data!B19:B22,MATCH(MAX(Chart_Data!C19:C22),Chart_Data!C19:C22,0))&" at "&TEXT(MAX(Chart_Data!C19:C22)/SUM(Chart_Data!C19:C22),"0%")&" of net sales." -> 5. Largest category: Packaged Food at 39% of net sales.

Sheet Income_Statement
B1: Statement of Comprehensive Income
B2: =Inputs!$C$6&" | "&Inputs!$C$11 -> Sampaguita Foods & Distribution Corporation (SFDC) | PHP in thousands (unless otherwise stated)
B3: =HYPERLINK("#Cover!A1","◄ Back to Cover") -> ◄ Back to Cover
B4: For the years ended 31 December
B5: PHP '000 | D5: =Inputs!D$22 -> 2023 | E5: =Inputs!E$22 -> 2024 | F5: =Inputs!F$22 -> 2025 | G5: Note
B6: CONTINUING OPERATIONS
B7: Net sales | D7: =SUMIFS(Sales_Net,Sales_Year,D$5) -> 821118 | E7: =SUMIFS(Sales_Net,Sales_Year,E$5) -> 897238 | F7: =SUMIFS(Sales_Net,Sales_Year,F$5) -> 972442 | G7: Note 9
B8: Cost of sales | D8: =-SUMIFS(Sales_COGS,Sales_Year,D$5) -> -613977 | E8: =-SUMIFS(Sales_COGS,Sales_Year,E$5) -> -668558 | F8: =-SUMIFS(Sales_COGS,Sales_Year,F$5) -> -722548 | G8: Note 10
B9: Gross profit | D9: =SUM(D7:D8) -> 207141 | E9: =SUM(E7:E8) -> 228680 | F9: =SUM(F7:F8) -> 249894
B10: Selling and distribution expenses | D10: =-SUMIFS(Exp_Amt,Exp_Year,D$5,Exp_Func,Func_SD) -> -93216 | E10: =-SUMIFS(Exp_Amt,Exp_Year,E$5,Exp_Func,Func_SD) -> -99930 | F10: =-SUMIFS(Exp_Amt,Exp_Year,F$5,Exp_Func,Func_SD) -> -106077 | G10: Note 10
B11: General and administrative expenses | D11: =-SUMIFS(Exp_Amt,Exp_Year,D$5,Exp_Func,Func_GA) -> -58315 | E11: =-SUMIFS(Exp_Amt,Exp_Year,E$5,Exp_Func,Func_GA) -> -61197 | F11: =-SUMIFS(Exp_Amt,Exp_Year,F$5,Exp_Func,Func_GA) -> -63827 | G11: Note 10
B12: Depreciation | D12: =-Schedules!D62 -> -17389 | E12: =-Schedules!E62 -> -19250 | F12: =-Schedules!F62 -> -21257 | G12: Note 6
B13: Operating profit | D13: =SUM(D9:D12) -> 38221 | E13: =SUM(E9:E12) -> 48303 | F13: =SUM(F9:F12) -> 58733
B14: Gain / (loss) on disposal of property and equipment | D14: =Schedules!D67 -> 400 | E14: =Schedules!E67 -> -150 | F14: =Schedules!F67 -> 350
B15: Other income | D15: =Inputs!D27 -> 1350 | E15: =Inputs!E27 -> 1520 | F15: =Inputs!F27 -> 1700
B16: Interest income | D16: =Schedules!D91 -> 775 | E16: =Schedules!E91 -> 873 | F16: =Schedules!F91 -> 1207
B17: Finance costs | D17: =-Schedules!D90 -> -10421 | E17: =-Schedules!E90 -> -11475 | F17: =-Schedules!F90 -> -11696 | G17: Note 7
B18: Profit before income tax | D18: =SUM(D13:D17) -> 30325 | E18: =SUM(E13:E17) -> 39071 | F18: =SUM(F13:F17) -> 50294
B19: Income tax expense | D19: =-Schedules!D103 -> -7843 | E19: =-Schedules!E103 -> -10062 | F19: =-Schedules!F103 -> -12888 | G19: Note 11
B20: Net profit for the year | D20: =SUM(D18:D19) -> 22482 | E20: =SUM(E18:E19) -> 29009 | F20: =SUM(F18:F19) -> 37406
B22: MEMORANDUM ITEMS
B23: EBIT (operating profit + gains and other income) | D23: =SUM(D13:D15) -> 39971 | E23: =SUM(E13:E15) -> 49673 | F23: =SUM(F13:F15) -> 60783
B24: EBITDA | D24: =D23-D12 -> 57360 | E24: =E23-E12 -> 68923 | F24: =F23-F12 -> 82040
B25: Total operating expenses (selling, G&A and depreciation) | D25: =-SUM(D10:D12) -> 168920 | E25: =-SUM(E10:E12) -> 180377 | F25: =-SUM(F10:F12) -> 191161

Sheet Balance_Sheet
B1: Statement of Financial Position
B2: =Inputs!$C$6&" | "&Inputs!$C$11 -> Sampaguita Foods & Distribution Corporation (SFDC) | PHP in thousands (unless otherwise stated)
B3: =HYPERLINK("#Cover!A1","◄ Back to Cover") -> ◄ Back to Cover
B4: As at 31 December
B5: PHP '000 | C5: =Inputs!C$22 -> 2022 | D5: =Inputs!D$22 -> 2023 | E5: =Inputs!E$22 -> 2024 | F5: =Inputs!F$22 -> 2025 | G5: Note
B6: ASSETS
B7: Current assets
B8: Cash and cash equivalents | C8: =Inputs!C38 -> 62000 | D8: =Cash_Flow!D40 -> 58216 | E8: =Cash_Flow!E40 -> 80460 | F8: =Cash_Flow!F40 -> 81748 | G8: Note 3
B9: Trade and other receivables | C9: =Schedules!C73 -> 71000 | D9: =Schedules!D73 -> 80987 | E9: =Schedules!E73 -> 88495 | F9: =Schedules!F73 -> 93248 | G9: Note 4
B10: Inventories | C10: =Schedules!C74 -> 74500 | D10: =Schedules!D74 -> 75696 | E10: =Schedules!E74 -> 80593 | F10: =Schedules!F74 -> 85122 | G10: Note 5
B11: Prepayments and other current assets | C11: =Schedules!C75 -> 11200 | D11: =Schedules!D75 -> 11365 | E11: =Schedules!E75 -> 12085 | F11: =Schedules!F75 -> 12743
B12: Total current assets | C12: =SUM(C8:C11) -> 218700 | D12: =SUM(D8:D11) -> 226264 | E12: =SUM(E8:E11) -> 261633 | F12: =SUM(F8:F11) -> 272861
B13: Non-current assets
B14: Property, plant and equipment, net | C14: =Schedules!C60 -> 174700 | D14: =Schedules!D60 -> 178711 | E14: =Schedules!E60 -> 189761 | F14: =Schedules!F60 -> 194504 | G14: Note 6
B15: Other non-current assets | C15: =Inputs!C50 -> 9800 | D15: =Inputs!D50 -> 10200 | E15: =Inputs!E50 -> 10500 | F15: =Inputs!F50 -> 11100
B16: Total non-current assets | C16: =SUM(C14:C15) -> 184500 | D16: =SUM(D14:D15) -> 188911 | E16: =SUM(E14:E15) -> 200261 | F16: =SUM(F14:F15) -> 205604
B17: TOTAL ASSETS | C17: =C12+C16 -> 403200 | D17: =D12+D16 -> 415175 | E17: =E12+E16 -> 461894 | F17: =F12+F16 -> 478465
B19: LIABILITIES AND EQUITY
B20: Current liabilities
B21: Trade and other payables | C21: =Schedules!C76 -> 62300 | D21: =Schedules!D76 -> 67285 | E21: =Schedules!E76 -> 75098 | F21: =Schedules!F76 -> 83143
B22: Accrued expenses | C22: =Schedules!C77 -> 13400 | D22: =Schedules!D77 -> 13638 | E22: =Schedules!E77 -> 14501 | F22: =Schedules!F77 -> 15291
B23: Income tax payable | C23: =Schedules!C105 -> 2800 | D23: =Schedules!D105 -> 1691 | E23: =Schedules!E105 -> 1977 | F23: =Schedules!F105 -> 2529 | G23: Note 11
B24: Short-term loans | C24: =Schedules!C80 -> 45000 | D24: =Schedules!D80 -> 48000 | E24: =Schedules!E80 -> 42000 | F24: =Schedules!F80 -> 38000 | G24: Note 7
B25: Current portion of long-term loans | C25: =Schedules!C85 -> 12000 | D25: =Schedules!D85 -> 13000 | E25: =Schedules!E85 -> 15000 | F25: =Schedules!F85 -> 16500 | G25: Note 7
B26: Total current liabilities | C26: =SUM(C21:C25) -> 135500 | D26: =SUM(D21:D25) -> 143614 | E26: =SUM(E21:E25) -> 148576 | F26: =SUM(F21:F25) -> 155463
B27: Non-current liabilities
B28: Long-term loans, net of current portion | C28: =Schedules!C86 -> 88000 | D28: =Schedules!D86 -> 75000 | E28: =Schedules!E86 -> 95000 | F28: =Schedules!F86 -> 78500 | G28: Note 7
B29: Total liabilities | C29: =C26+C28 -> 223500 | D29: =D26+D28 -> 218614 | E29: =E26+E28 -> 243576 | F29: =F26+F28 -> 233963
B30: Equity
B31: Share capital | C31: =Inputs!C46 -> 120000 | D31: =Equity_Changes!C11 -> 120000 | E31: =Equity_Changes!C19 -> 120000 | F31: =Equity_Changes!C27 -> 120000 | G31: Note 8
B32: Additional paid-in capital | C32: =Inputs!C47 -> 18000 | D32: =Equity_Changes!D11 -> 18000 | E32: =Equity_Changes!D19 -> 18000 | F32: =Equity_Changes!D27 -> 18000 | G32: Note 8
B33: Retained earnings | C33: =Inputs!C48 -> 41700 | D33: =Equity_Changes!E11 -> 58561 | E33: =Equity_Changes!E19 -> 80318 | F33: =Equity_Changes!E27 -> 106502 | G33: Note 8
B34: Total equity | C34: =SUM(C31:C33) -> 179700 | D34: =SUM(D31:D33) -> 196561 | E34: =SUM(E31:E33) -> 218318 | F34: =SUM(F31:F33) -> 244502
B35: TOTAL LIABILITIES AND EQUITY | C35: =C29+C34 -> 403200 | D35: =D29+D34 -> 415175 | E35: =E29+E34 -> 461894 | F35: =F29+F34 -> 478465
B37: Balance check (assets less liabilities and equity) | C37: =ROUND(C17-C35,0) -> 0 | D37: =ROUND(D17-D35,0) -> 0 | E37: =ROUND(E17-E35,0) -> 0 | F37: =ROUND(F17-F35,0) -> 0

Sheet Cash_Flow
B1: Statement of Cash Flows (Indirect Method)
B2: =Inputs!$C$6&" | "&Inputs!$C$11 -> Sampaguita Foods & Distribution Corporation (SFDC) | PHP in thousands (unless otherwise stated)
B3: =HYPERLINK("#Cover!A1","◄ Back to Cover") -> ◄ Back to Cover
B4: For the years ended 31 December
B5: PHP '000 | D5: =Inputs!D$22 -> 2023 | E5: =Inputs!E$22 -> 2024 | F5: =Inputs!F$22 -> 2025
B6: CASH FLOWS FROM OPERATING ACTIVITIES
B7: Profit before income tax | D7: =Income_Statement!D18 -> 30325 | E7: =Income_Statement!E18 -> 39071 | F7: =Income_Statement!F18 -> 50294
B8: Adjustments: depreciation | D8: =-Income_Statement!D12 -> 17389 | E8: =-Income_Statement!E12 -> 19250 | F8: =-Income_Statement!F12 -> 21257
B9: Adjustments: (gain) / loss on disposal | D9: =-Income_Statement!D14 -> -400 | E9: =-Income_Statement!E14 -> 150 | F9: =-Income_Statement!F14 -> -350
B10: Adjustments: interest income | D10: =-Income_Statement!D16 -> -775 | E10: =-Income_Statement!E16 -> -873 | F10: =-Income_Statement!F16 -> -1207
B11: Adjustments: finance costs | D11: =-Income_Statement!D17 -> 10421 | E11: =-Income_Statement!E17 -> 11475 | F11: =-Income_Statement!F17 -> 11696
B12: Operating profit before working capital changes | D12: =SUM(D7:D11) -> 56960 | E12: =SUM(E7:E11) -> 69073 | F12: =SUM(F7:F11) -> 81690
B13: (Increase) / decrease in trade and other receivables | D13: =Balance_Sheet!C9-Balance_Sheet!D9 -> -9987 | E13: =Balance_Sheet!D9-Balance_Sheet!E9 -> -7508 | F13: =Balance_Sheet!E9-Balance_Sheet!F9 -> -4753
B14: (Increase) / decrease in inventories | D14: =Balance_Sheet!C10-Balance_Sheet!D10 -> -1196 | E14: =Balance_Sheet!D10-Balance_Sheet!E10 -> -4897 | F14: =Balance_Sheet!E10-Balance_Sheet!F10 -> -4529
B15: (Increase) / decrease in prepayments | D15: =Balance_Sheet!C11-Balance_Sheet!D11 -> -165 | E15: =Balance_Sheet!D11-Balance_Sheet!E11 -> -720 | F15: =Balance_Sheet!E11-Balance_Sheet!F11 -> -658
B16: Increase / (decrease) in trade and other payables | D16: =Balance_Sheet!D21-Balance_Sheet!C21 -> 4985 | E16: =Balance_Sheet!E21-Balance_Sheet!D21 -> 7813 | F16: =Balance_Sheet!F21-Balance_Sheet!E21 -> 8045
B17: Increase / (decrease) in accrued expenses | D17: =Balance_Sheet!D22-Balance_Sheet!C22 -> 238 | E17: =Balance_Sheet!E22-Balance_Sheet!D22 -> 863 | F17: =Balance_Sheet!F22-Balance_Sheet!E22 -> 790
B18: Cash generated from operations | D18: =D12+SUM(D13:D17) -> 50835 | E18: =E12+SUM(E13:E17) -> 64624 | F18: =F12+SUM(F13:F17) -> 80585
B19: Interest received | D19: =Schedules!D91 -> 775 | E19: =Schedules!E91 -> 873 | F19: =Schedules!F91 -> 1207
B20: Interest paid | D20: =-Schedules!D90 -> -10421 | E20: =-Schedules!E90 -> -11475 | F20: =-Schedules!F90 -> -11696
B21: Income taxes paid | D21: =-Schedules!D106 -> -8952 | E21: =-Schedules!E106 -> -9776 | F21: =-Schedules!F106 -> -12336
B22: Net cash from operating activities | D22: =SUM(D18:D21) -> 32237 | E22: =SUM(E18:E21) -> 44246 | F22: =SUM(F18:F21) -> 57760
B24: CASH FLOWS FROM INVESTING ACTIVITIES
B25: Purchase of property, plant and equipment | D25: =-Schedules!D61 -> -22100 | E25: =-Schedules!E61 -> -30900 | F25: =-Schedules!F61 -> -26900
B26: Proceeds from disposal of property and equipment | D26: =Schedules!D66 -> 1100 | E26: =Schedules!E66 -> 450 | F26: =Schedules!F66 -> 1250
B27: (Increase) / decrease in other non-current assets | D27: =Balance_Sheet!C15-Balance_Sheet!D15 -> -400 | E27: =Balance_Sheet!D15-Balance_Sheet!E15 -> -300 | F27: =Balance_Sheet!E15-Balance_Sheet!F15 -> -600
B28: Net cash used in investing activities | D28: =SUM(D25:D27) -> -21400 | E28: =SUM(E25:E27) -> -30750 | F28: =SUM(F25:F27) -> -26250
B30: CASH FLOWS FROM FINANCING ACTIVITIES
B31: Proceeds from long-term loans | D31: =Schedules!D82 -> 0 | E31: =Schedules!E82 -> 35000 | F31: =Schedules!F82 -> 0
B32: Repayment of long-term loans | D32: =Schedules!D83 -> -12000 | E32: =Schedules!E83 -> -13000 | F32: =Schedules!F83 -> -15000
B33: Net proceeds from / (repayment of) short-term loans | D33: =Balance_Sheet!D24-Balance_Sheet!C24 -> 3000 | E33: =Balance_Sheet!E24-Balance_Sheet!D24 -> -6000 | F33: =Balance_Sheet!F24-Balance_Sheet!E24 -> -4000
B34: Proceeds from issuance of shares | D34: =Inputs!D55+Inputs!D56 -> 0 | E34: =Inputs!E55+Inputs!E56 -> 0 | F34: =Inputs!F55+Inputs!F56 -> 0
B35: Dividends paid | D35: =Equity_Changes!E9 -> -5621 | E35: =Equity_Changes!E17 -> -7252 | F35: =Equity_Changes!E25 -> -11222
B36: Net cash from / (used in) financing activities | D36: =SUM(D31:D35) -> -14621 | E36: =SUM(E31:E35) -> 8748 | F36: =SUM(F31:F35) -> -30222
B38: Net increase / (decrease) in cash and cash equivalents | D38: =D22+D28+D36 -> -3784 | E38: =E22+E28+E36 -> 22244 | F38: =F22+F28+F36 -> 1288
B39: Cash and cash equivalents at beginning of year | D39: =Balance_Sheet!C8 -> 62000 | E39: =Balance_Sheet!D8 -> 58216 | F39: =Balance_Sheet!E8 -> 80460
B40: Cash and cash equivalents at end of year | D40: =D39+D38 -> 58216 | E40: =E39+E38 -> 80460 | F40: =F39+F38 -> 81748
B42: MEMORANDUM
B43: Free cash flow (operating cash flow less capital expenditure) | D43: =D22+D25 -> 10137 | E43: =E22+E25 -> 13346 | F43: =F22+F25 -> 30860

Sheet Equity_Changes
B1: Statement of Changes in Equity
B2: =Inputs!$C$6&" | "&Inputs!$C$11 -> Sampaguita Foods & Distribution Corporation (SFDC) | PHP in thousands (unless otherwise stated)
B3: =HYPERLINK("#Cover!A1","◄ Back to Cover") -> ◄ Back to Cover
B5: PHP '000 | C5: Share capital | D5: Additional paid-in capital | E5: Retained earnings | F5: Total equity
B6: ="Year ended 31 December "&Inputs!D$22 -> Year ended 31 December 2023
B7: Balance at 1 January | C7: =Inputs!C46 -> 120000 | D7: =Inputs!C47 -> 18000 | E7: =Inputs!C48 -> 41700 | F7: =SUM(C7:E7) -> 179700
B8: Net profit for the year | E8: =Income_Statement!D20 -> 22482 | F8: =SUM(C8:E8) -> 22482
B9: Cash dividends declared and paid | E9: =-MAX(0,ROUND(Inputs!D30*E8,0)) -> -5621 | F9: =SUM(C9:E9) -> -5621
B10: Issuance of shares | C10: =Inputs!D55 -> 0 | D10: =Inputs!D56 -> 0 | F10: =SUM(C10:E10) -> 0
B11: Balance at 31 December | C11: =SUM(C7:C10) -> 120000 | D11: =SUM(D7:D10) -> 18000 | E11: =SUM(E7:E10) -> 58561 | F11: =SUM(C11:E11) -> 196561
B14: ="Year ended 31 December "&Inputs!E$22 -> Year ended 31 December 2024
B15: Balance at 1 January | C15: =C11 -> 120000 | D15: =D11 -> 18000 | E15: =E11 -> 58561 | F15: =SUM(C15:E15) -> 196561
B16: Net profit for the year | E16: =Income_Statement!E20 -> 29009 | F16: =SUM(C16:E16) -> 29009
B17: Cash dividends declared and paid | E17: =-MAX(0,ROUND(Inputs!E30*E16,0)) -> -7252 | F17: =SUM(C17:E17) -> -7252
B18: Issuance of shares | C18: =Inputs!E55 -> 0 | D18: =Inputs!E56 -> 0 | F18: =SUM(C18:E18) -> 0
B19: Balance at 31 December | C19: =SUM(C15:C18) -> 120000 | D19: =SUM(D15:D18) -> 18000 | E19: =SUM(E15:E18) -> 80318 | F19: =SUM(C19:E19) -> 218318
B22: ="Year ended 31 December "&Inputs!F$22 -> Year ended 31 December 2025
B23: Balance at 1 January | C23: =C19 -> 120000 | D23: =D19 -> 18000 | E23: =E19 -> 80318 | F23: =SUM(C23:E23) -> 218318
B24: Net profit for the year | E24: =Income_Statement!F20 -> 37406 | F24: =SUM(C24:E24) -> 37406
B25: Cash dividends declared and paid | E25: =-MAX(0,ROUND(Inputs!F30*E24,0)) -> -11222 | F25: =SUM(C25:E25) -> -11222
B26: Issuance of shares | C26: =Inputs!F55 -> 0 | D26: =Inputs!F56 -> 0 | F26: =SUM(C26:E26) -> 0
B27: Balance at 31 December | C27: =SUM(C23:C26) -> 120000 | D27: =SUM(D23:D26) -> 18000 | E27: =SUM(E23:E26) -> 106502 | F27: =SUM(C27:E27) -> 244502

Sheet Notes_to_FS
B1: Notes to the Financial Statements
B2: =Inputs!$C$6&" | "&Inputs!$C$11 -> Sampaguita Foods & Distribution Corporation (SFDC) | PHP in thousands (unless otherwise stated)
B3: =HYPERLINK("#Cover!A1","◄ Back to Cover") -> ◄ Back to Cover
B5: NOTE 1 - CORPORATE INFORMATION
B6: =Inputs!$C$6&" (the Company) is a domestic corporation registered in the Philippines with its head office in "&Inputs!$C$8&". The Company is engaged in the "&LOWER(Inputs!$C$9)&". The financial statements are presented in Philippine peso, the Company's functional currency, rounded to the nearest thousand unless otherwise stated. All names and figures are fictional and prepared for portfolio demonstration." -> Sampaguita Foods & Distribution Corporation (SFDC) (the Company) is a domestic corporation registered in the Philippines with its head office in Taguig City, Metro Manila, Philippines (warehouses: Laguna, Cebu, Davao). The Company is engaged in the wholesale distribution of packaged food, beverages, household products and fresh & frozen goods. The financial statements are presented in Philippine peso, the Company's functional currency, rounded to the nearest thousand unless otherwise stated. All names and figures are fictional and prepared for portfolio demonstration.
B8: NOTE 2 - BASIS OF PREPARATION AND SIGNIFICANT ACCOUNTING POLICIES
B9: Statement of compliance. The financial statements are prepared in accordance with Philippine Financial Reporting Standards (PFRS) under the historical cost convention, using the accrual basis, with expenses presented by function.
B10: Revenue (PFRS 15). Revenue from the wholesale distribution of goods is recognised at a point in time when control transfers to the customer on delivery, net of trade discounts, returns and value-added tax.
B11: Inventories (PAS 2). Merchandise inventories are stated at the lower of cost (weighted average) and net realisable value.
B12: Property, plant and equipment (PAS 16). Stated at cost less accumulated depreciation. Depreciation is computed on a straight-line basis over the estimated useful lives of the assets (see Inputs); land is not depreciated. Gains and losses on disposal are recognised in profit or loss.
B13: Income taxes (PAS 12). Current income tax is the higher of the regular corporate income tax (RCIT) on taxable income and the minimum corporate income tax (MCIT) on gross income. Interest income from bank deposits is subject to final tax. Deferred tax is not modelled because temporary differences are assumed to be immaterial.
B14: Financial instruments (PFRS 9). Receivables and payables are measured at amortised cost; credit losses are recognised through the bad debts expense line.
B15: Model scope. Leases (PFRS 16), employee benefits (PAS 19) and deferred taxes are outside the scope of this illustrative model.
B17: NOTE 3 - CASH AND CASH EQUIVALENTS
B18: PHP '000 | D18: =Inputs!D$22 -> 2023 | E18: =Inputs!E$22 -> 2024 | F18: =Inputs!F$22 -> 2025
B19: Cash on hand | D19: =ROUND(Balance_Sheet!D8*Inputs!D58,0) -> 873 | E19: =ROUND(Balance_Sheet!E8*Inputs!E58,0) -> 1207 | F19: =ROUND(Balance_Sheet!F8*Inputs!F58,0) -> 1226
B20: Short-term placements (maturity of three months or less) | D20: =ROUND(Balance_Sheet!D8*Inputs!D59,0) -> 6986 | E20: =ROUND(Balance_Sheet!E8*Inputs!E59,0) -> 9655 | F20: =ROUND(Balance_Sheet!F8*Inputs!F59,0) -> 9810
B21: Cash in banks | D21: =Balance_Sheet!D8-D19-D20 -> 50357 | E21: =Balance_Sheet!E8-E19-E20 -> 69598 | F21: =Balance_Sheet!F8-F19-F20 -> 70712
B22: Total cash and cash equivalents | D22: =SUM(D19:D21) -> 58216 | E22: =SUM(E19:E21) -> 80460 | F22: =SUM(F19:F21) -> 81748
B24: NOTE 4 - TRADE AND OTHER RECEIVABLES (AGEING)
B25: PHP '000 | D25: =Inputs!D$22 -> 2023 | E25: =Inputs!E$22 -> 2024 | F25: =Inputs!F$22 -> 2025
B26: 31-60 days | D26: =ROUND(Balance_Sheet!D9*Inputs!D60,0) -> 14578 | E26: =ROUND(Balance_Sheet!E9*Inputs!E60,0) -> 15044 | F26: =ROUND(Balance_Sheet!F9*Inputs!F60,0) -> 14920
B27: 61-90 days | D27: =ROUND(Balance_Sheet!D9*Inputs!D61,0) -> 5669 | E27: =ROUND(Balance_Sheet!E9*Inputs!E61,0) -> 5752 | F27: =ROUND(Balance_Sheet!F9*Inputs!F61,0) -> 5595
B28: Over 90 days | D28: =ROUND(Balance_Sheet!D9*Inputs!D62,0) -> 2835 | E28: =ROUND(Balance_Sheet!E9*Inputs!E62,0) -> 2655 | F28: =ROUND(Balance_Sheet!F9*Inputs!F62,0) -> 2331
B29: Current (0-30 days) | D29: =Balance_Sheet!D9-D26-D27-D28 -> 57905 | E29: =Balance_Sheet!E9-E26-E27-E28 -> 65044 | F29: =Balance_Sheet!F9-F26-F27-F28 -> 70402
B30: Total trade and other receivables | D30: =D29+D26+D27+D28 -> 80987 | E30: =E29+E26+E27+E28 -> 88495 | F30: =F29+F26+F27+F28 -> 93248
B31: Over 90 days as % of total receivables | D31: =IFERROR(D28/D30,0) -> 0.035005618 | E31: =IFERROR(E28/E30,0) -> 0.030001695 | F31: =IFERROR(F28/F30,0) -> 0.024997855
B32: Days sales outstanding | D32: =IFERROR(Balance_Sheet!D9/Income_Statement!D7*Days_Year,0) -> 36.000009 | E32: =IFERROR(Balance_Sheet!E9/Income_Statement!E7*Days_Year,0) -> 36.000119 | F32: =IFERROR(Balance_Sheet!F9/Income_Statement!F7*Days_Year,0) -> 35.000051
B34: NOTE 5 - INVENTORIES (BY PRODUCT CATEGORY)
B35: PHP '000 | D35: =Inputs!D$22 -> 2023 | E35: =Inputs!E$22 -> 2024 | F35: =Inputs!F$22 -> 2025
B36: Packaged Food | D36: =ROUND(Balance_Sheet!D10*SUMIFS(Sales_COGS,Sales_Year,Inputs!D$22,Sales_Cat,"Packaged Food")/SUMIFS(Sales_COGS,Sales_Year,Inputs!D$22),0) -> 30854 | E36: =ROUND(Balance_Sheet!E10*SUMIFS(Sales_COGS,Sales_Year,Inputs!E$22,Sales_Cat,"Packaged Food")/SUMIFS(Sales_COGS,Sales_Year,Inputs!E$22),0) -> 32463 | F36: =ROUND(Balance_Sheet!F10*SUMIFS(Sales_COGS,Sales_Year,Inputs!F$22,Sales_Cat,"Packaged Food")/SUMIFS(Sales_COGS,Sales_Year,Inputs!F$22),0) -> 33775
B37: Beverages | D37: =ROUND(Balance_Sheet!D10*SUMIFS(Sales_COGS,Sales_Year,Inputs!D$22,Sales_Cat,"Beverages")/SUMIFS(Sales_COGS,Sales_Year,Inputs!D$22),0) -> 21726 | E37: =ROUND(Balance_Sheet!E10*SUMIFS(Sales_COGS,Sales_Year,Inputs!E$22,Sales_Cat,"Beverages")/SUMIFS(Sales_COGS,Sales_Year,Inputs!E$22),0) -> 23390 | F37: =ROUND(Balance_Sheet!F10*SUMIFS(Sales_COGS,Sales_Year,Inputs!F$22,Sales_Cat,"Beverages")/SUMIFS(Sales_COGS,Sales_Year,Inputs!F$22),0) -> 25140
B38: Household & Personal Care | D38: =ROUND(Balance_Sheet!D10*SUMIFS(Sales_COGS,Sales_Year,Inputs!D$22,Sales_Cat,"Household & Personal Care")/SUMIFS(Sales_COGS,Sales_Year,Inputs!D$22),0) -> 13000 | E38: =ROUND(Balance_Sheet!E10*SUMIFS(Sales_COGS,Sales_Year,Inputs!E$22,Sales_Cat,"Household & Personal Care")/SUMIFS(Sales_COGS,Sales_Year,Inputs!E$22),0) -> 13600 | F38: =ROUND(Balance_Sheet!F10*SUMIFS(Sales_COGS,Sales_Year,Inputs!F$22,Sales_Cat,"Household & Personal Care")/SUMIFS(Sales_COGS,Sales_Year,Inputs!F$22),0) -> 14064
B39: Fresh & Frozen | D39: =Balance_Sheet!D10-SUM(D36:D38) -> 10116 | E39: =Balance_Sheet!E10-SUM(E36:E38) -> 11140 | F39: =Balance_Sheet!F10-SUM(F36:F38) -> 12143 | G39: Remainder so the note ties to the balance sheet
B40: Total inventories (allocated on cost-of-sales mix) | D40: =SUM(D36:D39) -> 75696 | E40: =SUM(E36:E39) -> 80593 | F40: =SUM(F36:F39) -> 85122
B41: Days inventory on hand | D41: =IFERROR(Balance_Sheet!D10/-Income_Statement!D8*Days_Year,0) -> 45.000122 | E41: =IFERROR(Balance_Sheet!E10/-Income_Statement!E8*Days_Year,0) -> 43.99984 | F41: =IFERROR(Balance_Sheet!F10/-Income_Statement!F8*Days_Year,0) -> 42.999953
B43: NOTE 6 - PROPERTY, PLANT AND EQUIPMENT
B44: PHP '000 | D44: =Inputs!D$22 -> 2023 | E44: =Inputs!E$22 -> 2024 | F44: =Inputs!F$22 -> 2025
B45: Land (net book value) | D45: =Schedules!D16 -> 60000 | E45: =Schedules!E16 -> 60000 | F45: =Schedules!F16 -> 60000
B46: Buildings & warehouse improvements (net book value) | D46: =Schedules!D26 -> 71225 | E46: =Schedules!E26 -> 78692 | F46: =Schedules!F26 -> 81367
...

Sheet Schedules
B1: Supporting Schedules
B2: =Inputs!$C$6&" | "&Inputs!$C$11 -> Sampaguita Foods & Distribution Corporation (SFDC) | PHP in thousands (unless otherwise stated)
B3: =HYPERLINK("#Cover!A1","◄ Back to Cover") -> ◄ Back to Cover
B5: PHP '000 | C5: =Inputs!C$22 -> 2022 | D5: =Inputs!D$22 -> 2023 | E5: =Inputs!E$22 -> 2024 | F5: =Inputs!F$22 -> 2025
B6: A. PROPERTY, PLANT AND EQUIPMENT ROLL-FORWARD (by asset class)
B7: Land
B8: Cost - opening | D8: =C11 -> 60000 | E8: =D11 -> 60000 | F8: =E11 -> 60000
B9: Additions | D9: =Inputs!D74 -> 0 | E9: =Inputs!E74 -> 0 | F9: =Inputs!F74 -> 0
B10: Disposals | D10: =-Inputs!D80 -> 0 | E10: =-Inputs!E80 -> 0 | F10: =-Inputs!F80 -> 0
B11: Cost - closing | C11: =Inputs!$D$66 -> 60000 | D11: =SUM(D8:D10) -> 60000 | E11: =SUM(E8:E10) -> 60000 | F11: =SUM(F8:F10) -> 60000
B12: Accumulated depreciation - opening | D12: =C15 -> 0 | E12: =D15 -> 0 | F12: =E15 -> 0
B13: Depreciation for the year | D13: =IF(Inputs!$C$66=0,0,MAX(0,MIN(ROUND((D8+0.5*D9+0.5*D10)/Inputs!$C$66,0),D11-(D12+D14)))) -> 0 | E13: =IF(Inputs!$C$66=0,0,MAX(0,MIN(ROUND((E8+0.5*E9+0.5*E10)/Inputs!$C$66,0),E11-(E12+E14)))) -> 0 | F13: =IF(Inputs!$C$66=0,0,MAX(0,MIN(ROUND((F8+0.5*F9+0.5*F10)/Inputs!$C$66,0),F11-(F12+F14)))) -> 0
B14: Disposals | D14: =-Inputs!D86 -> 0 | E14: =-Inputs!E86 -> 0 | F14: =-Inputs!F86 -> 0
B15: Accumulated depreciation - closing | C15: =Inputs!$E$66 -> 0 | D15: =SUM(D12:D14) -> 0 | E15: =SUM(E12:E14) -> 0 | F15: =SUM(F12:F14) -> 0
B16: Net book value | C16: =C11-C15 -> 60000 | D16: =D11-D15 -> 60000 | E16: =E11-E15 -> 60000 | F16: =F11-F15 -> 60000
B17: Buildings & warehouse improvements
B18: Cost - opening | D18: =C21 -> 96000 | E18: =D21 -> 100500 | F18: =E21 -> 111500
B19: Additions | D19: =Inputs!D75 -> 4500 | E19: =Inputs!E75 -> 11000 | F19: =Inputs!F75 -> 6500
B20: Disposals | D20: =-Inputs!D81 -> 0 | E20: =-Inputs!E81 -> 0 | F20: =-Inputs!F81 -> 0
B21: Cost - closing | C21: =Inputs!$D$67 -> 96000 | D21: =SUM(D18:D20) -> 100500 | E21: =SUM(E18:E20) -> 111500 | F21: =SUM(F18:F20) -> 118000
B22: Accumulated depreciation - opening | D22: =C25 -> 26000 | E22: =D25 -> 29275 | F22: =E25 -> 32808
B23: Depreciation for the year | D23: =IF(Inputs!$C$67=0,0,MAX(0,MIN(ROUND((D18+0.5*D19+0.5*D20)/Inputs!$C$67,0),D21-(D22+D24)))) -> 3275 | E23: =IF(Inputs!$C$67=0,0,MAX(0,MIN(ROUND((E18+0.5*E19+0.5*E20)/Inputs!$C$67,0),E21-(E22+E24)))) -> 3533 | F23: =IF(Inputs!$C$67=0,0,MAX(0,MIN(ROUND((F18+0.5*F19+0.5*F20)/Inputs!$C$67,0),F21-(F22+F24)))) -> 3825
B24: Disposals | D24: =-Inputs!D87 -> 0 | E24: =-Inputs!E87 -> 0 | F24: =-Inputs!F87 -> 0
B25: Accumulated depreciation - closing | C25: =Inputs!$E$67 -> 26000 | D25: =SUM(D22:D24) -> 29275 | E25: =SUM(E22:E24) -> 32808 | F25: =SUM(F22:F24) -> 36633
B26: Net book value | C26: =C21-C25 -> 70000 | D26: =D21-D25 -> 71225 | E26: =E21-E25 -> 78692 | F26: =F21-F25 -> 81367
B27: Warehouse equipment & racking
B28: Cost - opening | D28: =C31 -> 38000 | E28: =D31 -> 43200 | F28: =E31 -> 51600
B29: Additions | D29: =Inputs!D76 -> 5200 | E29: =Inputs!E76 -> 8400 | F29: =Inputs!F76 -> 6800
B30: Disposals | D30: =-Inputs!D82 -> 0 | E30: =-Inputs!E82 -> 0 | F30: =-Inputs!F82 -> 0
B31: Cost - closing | C31: =Inputs!$D$68 -> 38000 | D31: =SUM(D28:D30) -> 43200 | E31: =SUM(E28:E30) -> 51600 | F31: =SUM(F28:F30) -> 58400
B32: Accumulated depreciation - opening | D32: =C35 -> 18500 | E32: =D35 -> 21883 | F32: =E35 -> 25833
B33: Depreciation for the year | D33: =IF(Inputs!$C$68=0,0,MAX(0,MIN(ROUND((D28+0.5*D29+0.5*D30)/Inputs!$C$68,0),D31-(D32+D34)))) -> 3383 | E33: =IF(Inputs!$C$68=0,0,MAX(0,MIN(ROUND((E28+0.5*E29+0.5*E30)/Inputs!$C$68,0),E31-(E32+E34)))) -> 3950 | F33: =IF(Inputs!$C$68=0,0,MAX(0,MIN(ROUND((F28+0.5*F29+0.5*F30)/Inputs!$C$68,0),F31-(F32+F34)))) -> 4583
B34: Disposals | D34: =-Inputs!D88 -> 0 | E34: =-Inputs!E88 -> 0 | F34: =-Inputs!F88 -> 0
B35: Accumulated depreciation - closing | C35: =Inputs!$E$68 -> 18500 | D35: =SUM(D32:D34) -> 21883 | E35: =SUM(E32:E34) -> 25833 | F35: =SUM(F32:F34) -> 30416
B36: Net book value | C36: =C31-C35 -> 19500 | D36: =D31-D35 -> 21317 | E36: =E31-E35 -> 25767 | F36: =F31-F35 -> 27984
B37: Delivery vehicles
B38: Cost - opening | D38: =C41 -> 52000 | E38: =D41 -> 55400 | F38: =E41 -> 57400
B39: Additions | D39: =Inputs!D77 -> 9800 | E39: =Inputs!E77 -> 7600 | F39: =Inputs!F77 -> 10400
B40: Disposals | D40: =-Inputs!D83 -> -6400 | E40: =-Inputs!E83 -> -5600 | F40: =-Inputs!F83 -> -7200
B41: Cost - closing | C41: =Inputs!$D$69 -> 52000 | D41: =SUM(D38:D40) -> 55400 | E41: =SUM(E38:E40) -> 57400 | F41: =SUM(F38:F40) -> 60600
...

Sheet Horizontal
B1: Horizontal Analysis
B2: =Inputs!$C$6&" | "&Inputs!$C$11 -> Sampaguita Foods & Distribution Corporation (SFDC) | PHP in thousands (unless otherwise stated)
B3: =HYPERLINK("#Cover!A1","◄ Back to Cover") -> ◄ Back to Cover
B4: Peso and percentage change year-on-year. Expenses are shown as negatives, so a negative change signals higher cost. Flags trigger above the review threshold set on Inputs.
B5: PHP '000 | C5: =Inputs!D$22 -> 2023 | D5: =Inputs!E$22 -> 2024 | E5: =Inputs!F$22 -> 2025 | F5: Change FY24 vs FY23 | G5: % change | H5: Change FY25 vs FY24 | I5: % change | J5: Flag FY24 | K5: Flag FY25
B6: INCOME STATEMENT
B7: Net sales | C7: =Income_Statement!D7 -> 821118 | D7: =Income_Statement!E7 -> 897238 | E7: =Income_Statement!F7 -> 972442 | F7: =D7-C7 -> 76120 | G7: =IFERROR(F7/ABS(C7),0) -> 0.092702876 | H7: =E7-D7 -> 75204 | I7: =IFERROR(H7/ABS(D7),0) -> 0.083817226 | J7: =IF(ABS(G7)>Var_Threshold,IF(G7>0,"▲ ","▼ ")&TEXT(ABS(G7),"0.0%"),"–") -> – | K7: =IF(ABS(I7)>Var_Threshold,IF(I7>0,"▲ ","▼ ")&TEXT(ABS(I7),"0.0%"),"–") -> –
B8: Cost of sales | C8: =Income_Statement!D8 -> -613977 | D8: =Income_Statement!E8 -> -668558 | E8: =Income_Statement!F8 -> -722548 | F8: =D8-C8 -> -54581 | G8: =IFERROR(F8/ABS(C8),0) -> -0.088897467 | H8: =E8-D8 -> -53990 | I8: =IFERROR(H8/ABS(D8),0) -> -0.080755896 | J8: =IF(ABS(G8)>Var_Threshold,IF(G8>0,"▲ ","▼ ")&TEXT(ABS(G8),"0.0%"),"–") -> – | K8: =IF(ABS(I8)>Var_Threshold,IF(I8>0,"▲ ","▼ ")&TEXT(ABS(I8),"0.0%"),"–") -> –
B9: Gross profit | C9: =Income_Statement!D9 -> 207141 | D9: =Income_Statement!E9 -> 228680 | E9: =Income_Statement!F9 -> 249894 | F9: =D9-C9 -> 21539 | G9: =IFERROR(F9/ABS(C9),0) -> 0.10398231 | H9: =E9-D9 -> 21214 | I9: =IFERROR(H9/ABS(D9),0) -> 0.092767186 | J9: =IF(ABS(G9)>Var_Threshold,IF(G9>0,"▲ ","▼ ")&TEXT(ABS(G9),"0.0%"),"–") -> ▲ 10.4% | K9: =IF(ABS(I9)>Var_Threshold,IF(I9>0,"▲ ","▼ ")&TEXT(ABS(I9),"0.0%"),"–") -> –
B10: Selling and distribution expenses | C10: =Income_Statement!D10 -> -93216 | D10: =Income_Statement!E10 -> -99930 | E10: =Income_Statement!F10 -> -106077 | F10: =D10-C10 -> -6714 | G10: =IFERROR(F10/ABS(C10),0) -> -0.072026262 | H10: =E10-D10 -> -6147 | I10: =IFERROR(H10/ABS(D10),0) -> -0.061513059 | J10: =IF(ABS(G10)>Var_Threshold,IF(G10>0,"▲ ","▼ ")&TEXT(ABS(G10),"0.0%"),"–") -> – | K10: =IF(ABS(I10)>Var_Threshold,IF(I10>0,"▲ ","▼ ")&TEXT(ABS(I10),"0.0%"),"–") -> –
B11: General and administrative expenses | C11: =Income_Statement!D11 -> -58315 | D11: =Income_Statement!E11 -> -61197 | E11: =Income_Statement!F11 -> -63827 | F11: =D11-C11 -> -2882 | G11: =IFERROR(F11/ABS(C11),0) -> -0.049421247 | H11: =E11-D11 -> -2630 | I11: =IFERROR(H11/ABS(D11),0) -> -0.042975963 | J11: =IF(ABS(G11)>Var_Threshold,IF(G11>0,"▲ ","▼ ")&TEXT(ABS(G11),"0.0%"),"–") -> – | K11: =IF(ABS(I11)>Var_Threshold,IF(I11>0,"▲ ","▼ ")&TEXT(ABS(I11),"0.0%"),"–") -> –
B12: Depreciation | C12: =Income_Statement!D12 -> -17389 | D12: =Income_Statement!E12 -> -19250 | E12: =Income_Statement!F12 -> -21257 | F12: =D12-C12 -> -1861 | G12: =IFERROR(F12/ABS(C12),0) -> -0.10702168 | H12: =E12-D12 -> -2007 | I12: =IFERROR(H12/ABS(D12),0) -> -0.10425974 | J12: =IF(ABS(G12)>Var_Threshold,IF(G12>0,"▲ ","▼ ")&TEXT(ABS(G12),"0.0%"),"–") -> ▼ 10.7% | K12: =IF(ABS(I12)>Var_Threshold,IF(I12>0,"▲ ","▼ ")&TEXT(ABS(I12),"0.0%"),"–") -> ▼ 10.4%
B13: Operating profit | C13: =Income_Statement!D13 -> 38221 | D13: =Income_Statement!E13 -> 48303 | E13: =Income_Statement!F13 -> 58733 | F13: =D13-C13 -> 10082 | G13: =IFERROR(F13/ABS(C13),0) -> 0.26378169 | H13: =E13-D13 -> 10430 | I13: =IFERROR(H13/ABS(D13),0) -> 0.21592862 | J13: =IF(ABS(G13)>Var_Threshold,IF(G13>0,"▲ ","▼ ")&TEXT(ABS(G13),"0.0%"),"–") -> ▲ 26.4% | K13: =IF(ABS(I13)>Var_Threshold,IF(I13>0,"▲ ","▼ ")&TEXT(ABS(I13),"0.0%"),"–") -> ▲ 21.6%
B14: Gain / (loss) on disposal of property and equipment | C14: =Income_Statement!D14 -> 400 | D14: =Income_Statement!E14 -> -150 | E14: =Income_Statement!F14 -> 350 | F14: =D14-C14 -> -550 | G14: =IFERROR(F14/ABS(C14),0) -> -1.375 | H14: =E14-D14 -> 500 | I14: =IFERROR(H14/ABS(D14),0) -> 3.3333333 | J14: =IF(ABS(G14)>Var_Threshold,IF(G14>0,"▲ ","▼ ")&TEXT(ABS(G14),"0.0%"),"–") -> ▼ 137.5% | K14: =IF(ABS(I14)>Var_Threshold,IF(I14>0,"▲ ","▼ ")&TEXT(ABS(I14),"0.0%"),"–") -> ▲ 333.3%
B15: Other income | C15: =Income_Statement!D15 -> 1350 | D15: =Income_Statement!E15 -> 1520 | E15: =Income_Statement!F15 -> 1700 | F15: =D15-C15 -> 170 | G15: =IFERROR(F15/ABS(C15),0) -> 0.12592593 | H15: =E15-D15 -> 180 | I15: =IFERROR(H15/ABS(D15),0) -> 0.11842105 | J15: =IF(ABS(G15)>Var_Threshold,IF(G15>0,"▲ ","▼ ")&TEXT(ABS(G15),"0.0%"),"–") -> ▲ 12.6% | K15: =IF(ABS(I15)>Var_Threshold,IF(I15>0,"▲ ","▼ ")&TEXT(ABS(I15),"0.0%"),"–") -> ▲ 11.8%
B16: Interest income | C16: =Income_Statement!D16 -> 775 | D16: =Income_Statement!E16 -> 873 | E16: =Income_Statement!F16 -> 1207 | F16: =D16-C16 -> 98 | G16: =IFERROR(F16/ABS(C16),0) -> 0.12645161 | H16: =E16-D16 -> 334 | I16: =IFERROR(H16/ABS(D16),0) -> 0.38258877 | J16: =IF(ABS(G16)>Var_Threshold,IF(G16>0,"▲ ","▼ ")&TEXT(ABS(G16),"0.0%"),"–") -> ▲ 12.6% | K16: =IF(ABS(I16)>Var_Threshold,IF(I16>0,"▲ ","▼ ")&TEXT(ABS(I16),"0.0%"),"–") -> ▲ 38.3%
B17: Finance costs | C17: =Income_Statement!D17 -> -10421 | D17: =Income_Statement!E17 -> -11475 | E17: =Income_Statement!F17 -> -11696 | F17: =D17-C17 -> -1054 | G17: =IFERROR(F17/ABS(C17),0) -> -0.10114192 | H17: =E17-D17 -> -221 | I17: =IFERROR(H17/ABS(D17),0) -> -0.019259259 | J17: =IF(ABS(G17)>Var_Threshold,IF(G17>0,"▲ ","▼ ")&TEXT(ABS(G17),"0.0%"),"–") -> ▼ 10.1% | K17: =IF(ABS(I17)>Var_Threshold,IF(I17>0,"▲ ","▼ ")&TEXT(ABS(I17),"0.0%"),"–") -> –
B18: Profit before income tax | C18: =Income_Statement!D18 -> 30325 | D18: =Income_Statement!E18 -> 39071 | E18: =Income_Statement!F18 -> 50294 | F18: =D18-C18 -> 8746 | G18: =IFERROR(F18/ABS(C18),0) -> 0.2884089 | H18: =E18-D18 -> 11223 | I18: =IFERROR(H18/ABS(D18),0) -> 0.2872463 | J18: =IF(ABS(G18)>Var_Threshold,IF(G18>0,"▲ ","▼ ")&TEXT(ABS(G18),"0.0%"),"–") -> ▲ 28.8% | K18: =IF(ABS(I18)>Var_Threshold,IF(I18>0,"▲ ","▼ ")&TEXT(ABS(I18),"0.0%"),"–") -> ▲ 28.7%
... B20: Net profit for the year | C20: =Income_Statement!D20 -> 22482 | D20: =Income_Statement!E20 -> 29009 | E20: =Income_Statement!F20 -> 37406 | F20: =D20-C20 -> 6527 | G20: =IFERROR(F20/ABS(C20),0) -> 0.29032115 | H20: =E20-D20 -> 8397 | I20: =IFERROR(H20/ABS(D20),0) -> 0.28946189 | J20: =IF(ABS(G20)>Var_Threshold,IF(G20>0,"▲ ","▼ ")&TEXT(ABS(G20),"0.0%"),"–") -> ▲ 29.0% | K20: =IF(ABS(I20)>Var_Threshold,IF(I20>0,"▲ ","▼ ")&TEXT(ABS(I20),"0.0%"),"–") -> ▲ 28.9%
B21: EBIT (operating profit + gains and other income) | C21: =Income_Statement!D23 -> 39971 | D21: =Income_Statement!E23 -> 49673 | E21: =Income_Statement!F23 -> 60783 | F21: =D21-C21 -> 9702 | G21: =IFERROR(F21/ABS(C21),0) -> 0.24272598 | H21: =E21-D21 -> 11110 | I21: =IFERROR(H21/ABS(D21),0) -> 0.22366275 | J21: =IF(ABS(G21)>Var_Threshold,IF(G21>0,"▲ ","▼ ")&TEXT(ABS(G21),"0.0%"),"–") -> ▲ 24.3% | K21: =IF(ABS(I21)>Var_Threshold,IF(I21>0,"▲ ","▼ ")&TEXT(ABS(I21),"0.0%"),"–") -> ▲ 22.4%
B22: EBITDA | C22: =Income_Statement!D24 -> 57360 | D22: =Income_Statement!E24 -> 68923 | E22: =Income_Statement!F24 -> 82040 | F22: =D22-C22 -> 11563 | G22: =IFERROR(F22/ABS(C22),0) -> 0.20158647 | H22: =E22-D22 -> 13117 | I22: =IFERROR(H22/ABS(D22),0) -> 0.19031383 | J22: =IF(ABS(G22)>Var_Threshold,IF(G22>0,"▲ ","▼ ")&TEXT(ABS(G22),"0.0%"),"–") -> ▲ 20.2% | K22: =IF(ABS(I22)>Var_Threshold,IF(I22>0,"▲ ","▼ ")&TEXT(ABS(I22),"0.0%"),"–") -> ▲ 19.0%
B23: Total operating expenses (selling, G&A and depreciation) | C23: =Income_Statement!D25 -> 168920 | D23: =Income_Statement!E25 -> 180377 | E23: =Income_Statement!F25 -> 191161 | F23: =D23-C23 -> 11457 | G23: =IFERROR(F23/ABS(C23),0) -> 0.067825006 | H23: =E23-D23 -> 10784 | I23: =IFERROR(H23/ABS(D23),0) -> 0.059785893 | J23: =IF(ABS(G23)>Var_Threshold,IF(G23>0,"▲ ","▼ ")&TEXT(ABS(G23),"0.0%"),"–") -> – | K23: =IF(ABS(I23)>Var_Threshold,IF(I23>0,"▲ ","▼ ")&TEXT(ABS(I23),"0.0%"),"–") -> –
B24: STATEMENT OF FINANCIAL POSITION
B25: Cash and cash equivalents | C25: =Balance_Sheet!D8 -> 58216 | D25: =Balance_Sheet!E8 -> 80460 | E25: =Balance_Sheet!F8 -> 81748 | F25: =D25-C25 -> 22244 | G25: =IFERROR(F25/ABS(C25),0) -> 0.38209427 | H25: =E25-D25 -> 1288 | I25: =IFERROR(H25/ABS(D25),0) -> 0.016007954 | J25: =IF(ABS(G25)>Var_Threshold,IF(G25>0,"▲ ","▼ ")&TEXT(ABS(G25),"0.0%"),"–") -> ▲ 38.2% | K25: =IF(ABS(I25)>Var_Threshold,IF(I25>0,"▲ ","▼ ")&TEXT(ABS(I25),"0.0%"),"–") -> –
B26: Trade and other receivables | C26: =Balance_Sheet!D9 -> 80987 | D26: =Balance_Sheet!E9 -> 88495 | E26: =Balance_Sheet!F9 -> 93248 | F26: =D26-C26 -> 7508 | G26: =IFERROR(F26/ABS(C26),0) -> 0.092706237 | H26: =E26-D26 -> 4753 | I26: =IFERROR(H26/ABS(D26),0) -> 0.053709249 | J26: =IF(ABS(G26)>Var_Threshold,IF(G26>0,"▲ ","▼ ")&TEXT(ABS(G26),"0.0%"),"–") -> – | K26: =IF(ABS(I26)>Var_Threshold,IF(I26>0,"▲ ","▼ ")&TEXT(ABS(I26),"0.0%"),"–") -> –
B27: Inventories | C27: =Balance_Sheet!D10 -> 75696 | D27: =Balance_Sheet!E10 -> 80593 | E27: =Balance_Sheet!F10 -> 85122 | F27: =D27-C27 -> 4897 | G27: =IFERROR(F27/ABS(C27),0) -> 0.064692982 | H27: =E27-D27 -> 4529 | I27: =IFERROR(H27/ABS(D27),0) -> 0.056195948 | J27: =IF(ABS(G27)>Var_Threshold,IF(G27>0,"▲ ","▼ ")&TEXT(ABS(G27),"0.0%"),"–") -> – | K27: =IF(ABS(I27)>Var_Threshold,IF(I27>0,"▲ ","▼ ")&TEXT(ABS(I27),"0.0%"),"–") -> –
B28: Prepayments and other current assets | C28: =Balance_Sheet!D11 -> 11365 | D28: =Balance_Sheet!E11 -> 12085 | E28: =Balance_Sheet!F11 -> 12743 | F28: =D28-C28 -> 720 | G28: =IFERROR(F28/ABS(C28),0) -> 0.063352398 | H28: =E28-D28 -> 658 | I28: =IFERROR(H28/ABS(D28),0) -> 0.054447662 | J28: =IF(ABS(G28)>Var_Threshold,IF(G28>0,"▲ ","▼ ")&TEXT(ABS(G28),"0.0%"),"–") -> – | K28: =IF(ABS(I28)>Var_Threshold,IF(I28>0,"▲ ","▼ ")&TEXT(ABS(I28),"0.0%"),"–") -> –
B29: Total current assets | C29: =Balance_Sheet!D12 -> 226264 | D29: =Balance_Sheet!E12 -> 261633 | E29: =Balance_Sheet!F12 -> 272861 | F29: =D29-C29 -> 35369 | G29: =IFERROR(F29/ABS(C29),0) -> 0.1563174 | H29: =E29-D29 -> 11228 | I29: =IFERROR(H29/ABS(D29),0) -> 0.042915076 | J29: =IF(ABS(G29)>Var_Threshold,IF(G29>0,"▲ ","▼ ")&TEXT(ABS(G29),"0.0%"),"–") -> ▲ 15.6% | K29: =IF(ABS(I29)>Var_Threshold,IF(I29>0,"▲ ","▼ ")&TEXT(ABS(I29),"0.0%"),"–") -> –
B30: Property, plant and equipment, net | C30: =Balance_Sheet!D14 -> 178711 | D30: =Balance_Sheet!E14 -> 189761 | E30: =Balance_Sheet!F14 -> 194504 | F30: =D30-C30 -> 11050 | G30: =IFERROR(F30/ABS(C30),0) -> 0.061831672 | H30: =E30-D30 -> 4743 | I30: =IFERROR(H30/ABS(D30),0) -> 0.024994598 | J30: =IF(ABS(G30)>Var_Threshold,IF(G30>0,"▲ ","▼ ")&TEXT(ABS(G30),"0.0%"),"–") -> – | K30: =IF(ABS(I30)>Var_Threshold,IF(I30>0,"▲ ","▼ ")&TEXT(ABS(I30),"0.0%"),"–") -> –
B31: Other non-current assets | C31: =Balance_Sheet!D15 -> 10200 | D31: =Balance_Sheet!E15 -> 10500 | E31: =Balance_Sheet!F15 -> 11100 | F31: =D31-C31 -> 300 | G31: =IFERROR(F31/ABS(C31),0) -> 0.029411765 | H31: =E31-D31 -> 600 | I31: =IFERROR(H31/ABS(D31),0) -> 0.057142857 | J31: =IF(ABS(G31)>Var_Threshold,IF(G31>0,"▲ ","▼ ")&TEXT(ABS(G31),"0.0%"),"–") -> – | K31: =IF(ABS(I31)>Var_Threshold,IF(I31>0,"▲ ","▼ ")&TEXT(ABS(I31),"0.0%"),"–") -> –
B32: Total non-current assets | C32: =Balance_Sheet!D16 -> 188911 | D32: =Balance_Sheet!E16 -> 200261 | E32: =Balance_Sheet!F16 -> 205604 | F32: =D32-C32 -> 11350 | G32: =IFERROR(F32/ABS(C32),0) -> 0.060081202 | H32: =E32-D32 -> 5343 | I32: =IFERROR(H32/ABS(D32),0) -> 0.026680182 | J32: =IF(ABS(G32)>Var_Threshold,IF(G32>0,"▲ ","▼ ")&TEXT(ABS(G32),"0.0%"),"–") -> – | K32: =IF(ABS(I32)>Var_Threshold,IF(I32>0,"▲ ","▼ ")&TEXT(ABS(I32),"0.0%"),"–") -> –
B33: TOTAL ASSETS | C33: =Balance_Sheet!D17 -> 415175 | D33: =Balance_Sheet!E17 -> 461894 | E33: =Balance_Sheet!F17 -> 478465 | F33: =D33-C33 -> 46719 | G33: =IFERROR(F33/ABS(C33),0) -> 0.11252845 | H33: =E33-D33 -> 16571 | I33: =IFERROR(H33/ABS(D33),0) -> 0.035876197 | J33: =IF(ABS(G33)>Var_Threshold,IF(G33>0,"▲ ","▼ ")&TEXT(ABS(G33),"0.0%"),"–") -> ▲ 11.3% | K33: =IF(ABS(I33)>Var_Threshold,IF(I33>0,"▲ ","▼ ")&TEXT(ABS(I33),"0.0%"),"–") -> –
B34: Trade and other payables | C34: =Balance_Sheet!D21 -> 67285 | D34: =Balance_Sheet!E21 -> 75098 | E34: =Balance_Sheet!F21 -> 83143 | F34: =D34-C34 -> 7813 | G34: =IFERROR(F34/ABS(C34),0) -> 0.11611801 | H34: =E34-D34 -> 8045 | I34: =IFERROR(H34/ABS(D34),0) -> 0.10712669 | J34: =IF(ABS(G34)>Var_Threshold,IF(G34>0,"▲ ","▼ ")&TEXT(ABS(G34),"0.0%"),"–") -> ▲ 11.6% | K34: =IF(ABS(I34)>Var_Threshold,IF(I34>0,"▲ ","▼ ")&TEXT(ABS(I34),"0.0%"),"–") -> ▲ 10.7%
B35: Accrued expenses | C35: =Balance_Sheet!D22 -> 13638 | D35: =Balance_Sheet!E22 -> 14501 | E35: =Balance_Sheet!F22 -> 15291 | F35: =D35-C35 -> 863 | G35: =IFERROR(F35/ABS(C35),0) -> 0.063279073 | H35: =E35-D35 -> 790 | I35: =IFERROR(H35/ABS(D35),0) -> 0.054479001 | J35: =IF(ABS(G35)>Var_Threshold,IF(G35>0,"▲ ","▼ ")&TEXT(ABS(G35),"0.0%"),"–") -> – | K35: =IF(ABS(I35)>Var_Threshold,IF(I35>0,"▲ ","▼ ")&TEXT(ABS(I35),"0.0%"),"–") -> –
B36: Income tax payable | C36: =Balance_Sheet!D23 -> 1691 | D36: =Balance_Sheet!E23 -> 1977 | E36: =Balance_Sheet!F23 -> 2529 | F36: =D36-C36 -> 286 | G36: =IFERROR(F36/ABS(C36),0) -> 0.16913069 | H36: =E36-D36 -> 552 | I36: =IFERROR(H36/ABS(D36),0) -> 0.27921093 | J36: =IF(ABS(G36)>Var_Threshold,IF(G36>0,"▲ ","▼ ")&TEXT(ABS(G36),"0.0%"),"–") -> ▲ 16.9% | K36: =IF(ABS(I36)>Var_Threshold,IF(I36>0,"▲ ","▼ ")&TEXT(ABS(I36),"0.0%"),"–") -> ▲ 27.9%
B37: Short-term loans | C37: =Balance_Sheet!D24 -> 48000 | D37: =Balance_Sheet!E24 -> 42000 | E37: =Balance_Sheet!F24 -> 38000 | F37: =D37-C37 -> -6000 | G37: =IFERROR(F37/ABS(C37),0) -> -0.125 | H37: =E37-D37 -> -4000 | I37: =IFERROR(H37/ABS(D37),0) -> -0.095238095 | J37: =IF(ABS(G37)>Var_Threshold,IF(G37>0,"▲ ","▼ ")&TEXT(ABS(G37),"0.0%"),"–") -> ▼ 12.5% | K37: =IF(ABS(I37)>Var_Threshold,IF(I37>0,"▲ ","▼ ")&TEXT(ABS(I37),"0.0%"),"–") -> –
B38: Current portion of long-term loans | C38: =Balance_Sheet!D25 -> 13000 | D38: =Balance_Sheet!E25 -> 15000 | E38: =Balance_Sheet!F25 -> 16500 | F38: =D38-C38 -> 2000 | G38: =IFERROR(F38/ABS(C38),0) -> 0.15384615 | H38: =E38-D38 -> 1500 | I38: =IFERROR(H38/ABS(D38),0) -> 0.1 | J38: =IF(ABS(G38)>Var_Threshold,IF(G38>0,"▲ ","▼ ")&TEXT(ABS(G38),"0.0%"),"–") -> ▲ 15.4% | K38: =IF(ABS(I38)>Var_Threshold,IF(I38>0,"▲ ","▼ ")&TEXT(ABS(I38),"0.0%"),"–") -> –
B39: Total current liabilities | C39: =Balance_Sheet!D26 -> 143614 | D39: =Balance_Sheet!E26 -> 148576 | E39: =Balance_Sheet!F26 -> 155463 | F39: =D39-C39 -> 4962 | G39: =IFERROR(F39/ABS(C39),0) -> 0.034550949 | H39: =E39-D39 -> 6887 | I39: =IFERROR(H39/ABS(D39),0) -> 0.046353381 | J39: =IF(ABS(G39)>Var_Threshold,IF(G39>0,"▲ ","▼ ")&TEXT(ABS(G39),"0.0%"),"–") -> – | K39: =IF(ABS(I39)>Var_Threshold,IF(I39>0,"▲ ","▼ ")&TEXT(ABS(I39),"0.0%"),"–") -> –
B40: Long-term loans, net of current portion | C40: =Balance_Sheet!D28 -> 75000 | D40: =Balance_Sheet!E28 -> 95000 | E40: =Balance_Sheet!F28 -> 78500 | F40: =D40-C40 -> 20000 | G40: =IFERROR(F40/ABS(C40),0) -> 0.26666667 | H40: =E40-D40 -> -16500 | I40: =IFERROR(H40/ABS(D40),0) -> -0.17368421 | J40: =IF(ABS(G40)>Var_Threshold,IF(G40>0,"▲ ","▼ ")&TEXT(ABS(G40),"0.0%"),"–") -> ▲ 26.7% | K40: =IF(ABS(I40)>Var_Threshold,IF(I40>0,"▲ ","▼ ")&TEXT(ABS(I40),"0.0%"),"–") -> ▼ 17.4%
B41: Total liabilities | C41: =Balance_Sheet!D29 -> 218614 | D41: =Balance_Sheet!E29 -> 243576 | E41: =Balance_Sheet!F29 -> 233963 | F41: =D41-C41 -> 24962 | G41: =IFERROR(F41/ABS(C41),0) -> 0.11418299 | H41: =E41-D41 -> -9613 | I41: =IFERROR(H41/ABS(D41),0) -> -0.039466121 | J41: =IF(ABS(G41)>Var_Threshold,IF(G41>0,"▲ ","▼ ")&TEXT(ABS(G41),"0.0%"),"–") -> ▲ 11.4% | K41: =IF(ABS(I41)>Var_Threshold,IF(I41>0,"▲ ","▼ ")&TEXT(ABS(I41),"0.0%"),"–") -> –
...

Sheet Vertical
B1: Vertical Analysis
B2: =Inputs!$C$6&" | "&Inputs!$C$11 -> Sampaguita Foods & Distribution Corporation (SFDC) | PHP in thousands (unless otherwise stated)
B3: =HYPERLINK("#Cover!A1","◄ Back to Cover") -> ◄ Back to Cover
B4: Income statement lines as % of net sales; balance sheet lines as % of total assets.
B5: PHP '000 | C5: =Inputs!D$22 -> 2023 | D5: =Inputs!E$22 -> 2024 | E5: =Inputs!F$22 -> 2025 | F5: ="% FY"&Inputs!D$22 -> % FY2023 | G5: ="% FY"&Inputs!E$22 -> % FY2024 | H5: ="% FY"&Inputs!F$22 -> % FY2025 | I5: Change in % pts (FY25 vs FY23)
B6: INCOME STATEMENT
B7: Net sales | C7: =Income_Statement!D7 -> 821118 | D7: =Income_Statement!E7 -> 897238 | E7: =Income_Statement!F7 -> 972442 | F7: =IFERROR(C7/C$7,0) -> 1 | G7: =IFERROR(D7/D$7,0) -> 1 | H7: =IFERROR(E7/E$7,0) -> 1 | I7: =H7-F7 -> 0
B8: Cost of sales | C8: =Income_Statement!D8 -> -613977 | D8: =Income_Statement!E8 -> -668558 | E8: =Income_Statement!F8 -> -722548 | F8: =IFERROR(C8/C$7,0) -> -0.74773297 | G8: =IFERROR(D8/D$7,0) -> -0.74512894 | H8: =IFERROR(E8/E$7,0) -> -0.74302426 | I8: =H8-F8 -> 0.0047087063
B9: Gross profit | C9: =Income_Statement!D9 -> 207141 | D9: =Income_Statement!E9 -> 228680 | E9: =Income_Statement!F9 -> 249894 | F9: =IFERROR(C9/C$7,0) -> 0.25226703 | G9: =IFERROR(D9/D$7,0) -> 0.25487106 | H9: =IFERROR(E9/E$7,0) -> 0.25697574 | I9: =H9-F9 -> 0.0047087063
B10: Selling and distribution expenses | C10: =Income_Statement!D10 -> -93216 | D10: =Income_Statement!E10 -> -99930 | E10: =Income_Statement!F10 -> -106077 | F10: =IFERROR(C10/C$7,0) -> -0.11352327 | G10: =IFERROR(D10/D$7,0) -> -0.11137513 | H10: =IFERROR(E10/E$7,0) -> -0.10908311 | I10: =H10-F10 -> 0.0044401571
B11: General and administrative expenses | C11: =Income_Statement!D11 -> -58315 | D11: =Income_Statement!E11 -> -61197 | E11: =Income_Statement!F11 -> -63827 | F11: =IFERROR(C11/C$7,0) -> -0.071019025 | G11: =IFERROR(D11/D$7,0) -> -0.068205983 | H11: =IFERROR(E11/E$7,0) -> -0.065635791 | I11: =H11-F11 -> 0.0053832341
B12: Depreciation | C12: =Income_Statement!D12 -> -17389 | D12: =Income_Statement!E12 -> -19250 | E12: =Income_Statement!F12 -> -21257 | F12: =IFERROR(C12/C$7,0) -> -0.021177224 | G12: =IFERROR(D12/D$7,0) -> -0.021454731 | H12: =IFERROR(E12/E$7,0) -> -0.021859401 | I12: =H12-F12 -> -0.00068217716
B13: Operating profit | C13: =Income_Statement!D13 -> 38221 | D13: =Income_Statement!E13 -> 48303 | E13: =Income_Statement!F13 -> 58733 | F13: =IFERROR(C13/C$7,0) -> 0.046547512 | G13: =IFERROR(D13/D$7,0) -> 0.053835214 | H13: =IFERROR(E13/E$7,0) -> 0.060397432 | I13: =H13-F13 -> 0.01384992
B14: Gain / (loss) on disposal of property and equipment | C14: =Income_Statement!D14 -> 400 | D14: =Income_Statement!E14 -> -150 | E14: =Income_Statement!F14 -> 350 | F14: =IFERROR(C14/C$7,0) -> 0.0004871407 | G14: =IFERROR(D14/D$7,0) -> -0.00016717972 | H14: =IFERROR(E14/E$7,0) -> 0.00035991864 | I14: =H14-F14 -> -0.00012722207
B15: Other income | C15: =Income_Statement!D15 -> 1350 | D15: =Income_Statement!E15 -> 1520 | E15: =Income_Statement!F15 -> 1700 | F15: =IFERROR(C15/C$7,0) -> 0.0016440999 | G15: =IFERROR(D15/D$7,0) -> 0.0016940879 | H15: =IFERROR(E15/E$7,0) -> 0.0017481762 | I15: =H15-F15 -> 0.00010407637
B16: Interest income | C16: =Income_Statement!D16 -> 775 | D16: =Income_Statement!E16 -> 873 | E16: =Income_Statement!F16 -> 1207 | F16: =IFERROR(C16/C$7,0) -> 0.00094383511 | G16: =IFERROR(D16/D$7,0) -> 0.00097298599 | H16: =IFERROR(E16/E$7,0) -> 0.0012412051 | I16: =H16-F16 -> 0.00029737002
B17: Finance costs | C17: =Income_Statement!D17 -> -10421 | D17: =Income_Statement!E17 -> -11475 | E17: =Income_Statement!F17 -> -11696 | F17: =IFERROR(C17/C$7,0) -> -0.012691233 | G17: =IFERROR(D17/D$7,0) -> -0.012789249 | H17: =IFERROR(E17/E$7,0) -> -0.012027453 | I17: =H17-F17 -> 0.00066378064
B18: Profit before income tax | C18: =Income_Statement!D18 -> 30325 | D18: =Income_Statement!E18 -> 39071 | E18: =Income_Statement!F18 -> 50294 | F18: =IFERROR(C18/C$7,0) -> 0.036931355 | G18: =IFERROR(D18/D$7,0) -> 0.04354586 | H18: =IFERROR(E18/E$7,0) -> 0.05171928 | I18: =H18-F18 -> 0.014787925
... B20: Net profit for the year | C20: =Income_Statement!D20 -> 22482 | D20: =Income_Statement!E20 -> 29009 | E20: =Income_Statement!F20 -> 37406 | F20: =IFERROR(C20/C$7,0) -> 0.027379743 | G20: =IFERROR(D20/D$7,0) -> 0.032331444 | H20: =IFERROR(E20/E$7,0) -> 0.038466047 | I20: =H20-F20 -> 0.011086304
B21: EBIT (operating profit + gains and other income) | C21: =Income_Statement!D23 -> 39971 | D21: =Income_Statement!E23 -> 49673 | E21: =Income_Statement!F23 -> 60783 | F21: =IFERROR(C21/C$7,0) -> 0.048678753 | G21: =IFERROR(D21/D$7,0) -> 0.055362122 | H21: =IFERROR(E21/E$7,0) -> 0.062505527 | I21: =H21-F21 -> 0.013826775
