Workbook

Sheet Cover
B2: PORTFOLIO PROJECT 05
B3: Internal Control Evaluation
B4: Sampaguita Foods & Distribution Corporation (SFDC)
B5: Order-to-cash (sales cycle): risk and control matrix, testing, deficiency evaluation and remediation tracking
B7: Prepared by Bengie Hirnani | Version 1.0 | PHP in thousands
B10: Model status | C10: =Model_Status -> ✔ All 13 integrity checks passed
B11: Scope | C11: Nine process steps, 16 risks, 24 controls, formula-driven sampling and test conclusions, deficiency classification against materiality, a residual-risk heat map and a remediation tracker. Accompanied by the Word report with flowchart.
B12: Data notice | C12: The company, test results and findings are fictional and were created to demonstrate an internal control evaluation. Materiality ties to the Project 1 financial statements.
B14: NAVIGATION - click a button to jump to a sheet
B15: DASHBOARD
B16: =HYPERLINK("#Dashboard!A1","Dashboard") -> Dashboard | C16: Control-environment dashboard: ratings, deficiencies, residual risk, remediation
B18: RISK AND CONTROL MATRIX
B19: =HYPERLINK("#Process_Steps!A1","Process Steps") -> Process Steps | C19: Order-to-cash process steps with control counts and step ratings
B20: =HYPERLINK("#Risks!A1","Risks") -> Risks | C20: Risk register: inherent and residual scoring
B21: =HYPERLINK("#Controls!A1","Controls") -> Controls | C21: 24 controls with design assessment, sampling, test results and ratings
B22: =HYPERLINK("#Findings!A1","Findings") -> Findings | C22: Deficiency evaluation, recommendations, owners, due dates and tracking
B23: =HYPERLINK("#Heatmap!A1","Heatmap") -> Heatmap | C23: Likelihood x impact heat map and top residual risks
B25: SETUP AND CONTROLS
B26: =HYPERLINK("#Sampling_Guide!A1","Sampling Guide") -> Sampling Guide | C26: Sample-size table by control frequency and risk level
B27: =HYPERLINK("#Inputs!A1","Inputs") -> Inputs | C27: Dates, materiality, thresholds, remediation days, holidays
B28: =HYPERLINK("#Chart_Data!A1","Chart Data") -> Chart Data | C28: Helper tables for dashboard charts
B29: =HYPERLINK("#Lists!A1","Lists") -> Lists | C29: Drop-down lists
B30: =HYPERLINK("#Checks!A1","Checks") -> Checks | C30: Model integrity checks
B31: =HYPERLINK("#Documentation!A1","Documentation") -> Documentation | C31: Scope, method, rating rules, how to use

Sheet Documentation
B1: Model Documentation
B2: Sampaguita Foods & Distribution Corporation (SFDC) | PHP in thousands | Order-to-cash (sales cycle)
B3: =HYPERLINK("#Cover!A1","◄ Back to Cover") -> ◄ Back to Cover
B5: 1. PURPOSE AND SCOPE
B6: Objective | C6: Evaluate the design and operating effectiveness of internal controls over SFDC's order-to-cash cycle for the period 1 January to 30 September 2026, using the COSO 2013 Internal Control - Integrated Framework as the reference model.
B7: Scope | C7: Nine process steps from customer onboarding to receivables monitoring, 16 risks and 24 controls (12 key-control tested manually, 5 automated). Results, populations and exceptions are fictional.
B8: Companion report | C8: The Word report (Internal Control Evaluation Report) contains the process narrative, the flowchart with control ratings, findings, recommendations and the management action plan.
B10: 2. METHOD
B11: Risk scoring | C11: Likelihood x impact on a 5 x 5 scale gives the inherent score. Residual score = inherent score x (1 - average risk reduction of the controls mapped to the risk). Reduction depends on the overall control rating (Inputs).
B12: Sampling | C12: Sample size comes from the Sampling_Guide by frequency and risk level (elevated when the inherent score is at least the threshold). Automated controls are tested once; controls with a missing design are not tested.
B13: Conclusions | C13: Operating result: Effective (no exceptions); Effective with exceptions (sample over 5 and deviation rate within tolerable rate); otherwise Ineffective. Overall rating combines design and operation.
B14: Deficiency evaluation | C14: Findings are rated by likelihood and magnitude against materiality (0.5% of FY2025 net sales). A compensating control lowers the class by one level. Remediation deadlines use WORKDAY with a holiday list.
B16: 3. CONVENTIONS
B17: Colours | C17: Blue = input; black = formula; green = cross-sheet link; yellow = key assumption.
B18: Ratings | C18: Green/Effective, light green/Effective with exceptions, amber/Needs improvement, red/Ineffective.
B19: Controls | C19: Drop-downs, whole-number validation, conditional formatting, 13 integrity checks and a model-status banner.
B21: 4. HOW TO USE
B22: Re-perform testing | C22: Update population and exceptions on Controls; sample sizes and ratings update automatically.
B23: Track remediation | C23: Update Status and the as-of date; days to due and flags recalculate.
B24: Limitations | C24: The workbook supports the evaluation but does not replace auditor judgement; thresholds and tolerable rates are policy inputs.

Sheet Dashboard
B1: Internal Control Dashboard: Order-to-Cash
B2: Sampaguita Foods & Distribution Corporation (SFDC) | PHP in thousands | Order-to-cash (sales cycle)
B3: =HYPERLINK("#Cover!A1","◄ Back to Cover") -> ◄ Back to Cover
B5: =IF(COUNTIF(Fnd_Class,"Material weakness")>0,"✖ NOT EFFECTIVE - "&COUNTIF(Fnd_Class,"Material weakness")&" material weakness(es), "&COUNTIF(Fnd_Class,"Significant deficiency")&" significant deficiency(ies) and "&COUNTIF(Fnd_Class,"Control deficiency")&" control deficiency(ies) at "&TEXT(Test_End,"d mmmm yyyy"),IF(COUNTIF(Fnd_Class,"Significant deficiency")>0,"● NEEDS IMPROVEMENT - "&COUNTIF(Fnd_Class,"Significant deficiency")&" significant deficiency(ies) at "&TEXT(Test_End,"d mmmm yyyy"),"✔ EFFECTIVE at "&TEXT(Test_End,"d mmmm yyyy"))) -> ✖ NOT EFFECTIVE - 1 material weakness(es), 3 significant deficiency(ies) and 4 control deficiency(ies) at 30 September 2026
B7: CONTROLS TESTED | E7: OPERATING EFFECTIVELY | H7: MATERIAL WEAKNESSES | K7: SIGNIFICANT DEFICIENCIES
B8: =COUNTA(Ctl_ID) -> 24 | E8: =(COUNTIF(Ctl_Rating,"Effective")+COUNTIF(Ctl_Rating,"Effective with exceptions"))/COUNTA(Ctl_ID) -> 0.625 | H8: =COUNTIF(Fnd_Class,"Material weakness") -> 1 | K8: =COUNTIF(Fnd_Class,"Significant deficiency") -> 3
B9: =COUNTIF(Ctl_Key,"Y")&" key controls | "&COUNTIF(Controls!$H$6:$H$29,"Automated")&" automated" -> 16 key controls | 4 automated | E9: =COUNTIF(Ctl_Rating,"Ineffective")&" ineffective, "&COUNTIF(Ctl_Rating,"Needs improvement")&" need improvement" -> 8 ineffective, 1 need improvement | H9: =IF(H8>0,"✖ Immediate attention","✔ None identified") -> ✖ Immediate attention | K9: =COUNTIF(Fnd_Class,"Control deficiency")&" further control deficiencies" -> 4 further control deficiencies
B11: HIGHEST RESIDUAL RISK | E11: RESIDUAL RISK: HIGH | H11: ACTIONS CLOSED | K11: OVERDUE ACTIONS
B12: =INDEX(Risk_ID,MATCH(MAX(Risk_Key),Risk_Key,0)) -> R08 | E12: =COUNTIF(Risks!$O$6:$O$21,"High") -> 1 | H12: =COUNTIF(Fnd_Status,"Closed")/COUNTA(Fnd_ID) -> 0.125 | K12: =SUMPRODUCT(--(LEFT(Fnd_Flag,1)="✖")) -> 0
B13: ="Residual score "&TEXT(MAX(Risk_Res),"0.0")&" of 25" -> Residual score 18.0 of 25 | E13: ="from "&COUNTIF(Risks!$K$6:$K$21,"High")&" high inherent risks" -> from 4 high inherent risks | H13: =COUNTIF(Fnd_Status,"In progress")&" in progress, "&COUNTIF(Fnd_Status,"Open")&" open" -> 3 in progress, 4 open | K13: =IF(SUMPRODUCT(--(LEFT(Fnd_Flag,1)="✖"))>0,"✖ Escalate to audit committee","✔ None overdue as at "&TEXT(As_Of,"d mmm yyyy")) -> ✔ None overdue as at 6 Oct 2026
H51: PROCESS STEP RATINGS
H52: =Process_Steps!B6&" "&Process_Steps!C6 -> P1 Customer onboarding and credit approval | L52: =Process_Steps!L6 -> Green | M52: =Process_Steps!K6 -> 1
H53: =Process_Steps!B7&" "&Process_Steps!C7 -> P2 Master data and pricing maintenance | L53: =Process_Steps!L7 -> Amber | M53: =Process_Steps!K7 -> 0.75
H54: =Process_Steps!B8&" "&Process_Steps!C8 -> P3 Sales order entry | L54: =Process_Steps!L8 -> Green | M54: =Process_Steps!K8 -> 1
H55: =Process_Steps!B9&" "&Process_Steps!C9 -> P4 Credit check and order release | L55: =Process_Steps!L9 -> Red | M55: =Process_Steps!K9 -> 0.33333333
H56: =Process_Steps!B10&" "&Process_Steps!C10 -> P5 Picking, packing and dispatch | L56: =Process_Steps!L10 -> Green | M56: =Process_Steps!K10 -> 1
H57: =Process_Steps!B11&" "&Process_Steps!C11 -> P6 Delivery and proof of delivery | L57: =Process_Steps!L11 -> Red | M57: =Process_Steps!K11 -> 0
H58: =Process_Steps!B12&" "&Process_Steps!C12 -> P7 Invoicing and VAT | L58: =Process_Steps!L12 -> Red | M58: =Process_Steps!K12 -> 0.75
H59: =Process_Steps!B13&" "&Process_Steps!C13 -> P8 Collection and cash application | L59: =Process_Steps!L13 -> Red | M59: =Process_Steps!K13 -> 0
H60: =Process_Steps!B14&" "&Process_Steps!C14 -> P9 Credit notes, returns and receivables monitoring | L60: =Process_Steps!L14 -> Red | M60: =Process_Steps!K14 -> 0.6
B68: KEY INSIGHTS (update automatically)
B69: ="1. "&COUNTIF(Ctl_Rating,"Effective")+COUNTIF(Ctl_Rating,"Effective with exceptions")&" of "&COUNTA(Ctl_ID)&" controls operate effectively; all "&COUNTIF(Controls!$H$6:$H$29,"Automated")&" automated controls passed, while "&COUNTIFS(Controls!$H$6:$H$29,"Manual",Ctl_Rating,"Ineffective")&" manual controls failed testing." -> 1. 15 of 24 controls operate effectively; all 4 automated controls passed, while 8 manual controls failed testing.
B70: ="2. Highest residual risk is "&INDEX(Risk_ID,MATCH(MAX(Risk_Key),Risk_Key,0))&" ("&INDEX(Risk_Name,MATCH(MAX(Risk_Key),Risk_Key,0))&") with a residual score of "&TEXT(MAX(Risk_Res),"0.0")&"." -> 2. Highest residual risk is R08 (Revenue is recognised without evidence that goods were delivered) with a residual score of 18.0.
B71: ="3. Materiality is PHP "&TEXT(Materiality/1000,"0.0")&" million; the largest single exposure identified is PHP "&TEXT(MAX(Fnd_Mag)/1000,"0.0")&" million." -> 3. Materiality is PHP 4.9 million; the largest single exposure identified is PHP 5.2 million.
B72: ="4. "&COUNTIF(Fnd_Status,"Closed")&" of "&COUNTA(Fnd_ID)&" findings are closed; the next remediation deadline is "&TEXT(SUMPRODUCT(MIN(Fnd_Due+(Fnd_Status="Closed")*100000)),"d mmm yyyy")&"." -> 4. 1 of 8 findings are closed; the next remediation deadline is 30 Oct 2026.

Sheet Process_Steps
B1: Order-to-Cash Process Steps
B2: Sampaguita Foods & Distribution Corporation (SFDC) | PHP in thousands | Order-to-cash (sales cycle)
B3: =HYPERLINK("#Cover!A1","◄ Back to Cover") -> ◄ Back to Cover
B5: ID | C5: Process step | D5: Description | E5: Risks | F5: Controls | G5: Key controls | H5: Effective | I5: Needs improvement | J5: Ineffective | K5: % effective | L5: Step rating | M5: Peak residual risk
B6: P1 | C6: Customer onboarding and credit approval | D6: New customers apply with KYC documents; credit limits are assessed and approved before account set-up. | E6: =COUNTIF(Risk_Step,B6) -> 1 | F6: =COUNTIF(Ctl_Step,B6) -> 1 | G6: =COUNTIFS(Ctl_Step,B6,Ctl_Key,"Y") -> 1 | H6: =COUNTIFS(Ctl_Step,B6,Ctl_Rating,"Effective")+COUNTIFS(Ctl_Step,B6,Ctl_Rating,"Effective with exceptions") -> 1 | I6: =COUNTIFS(Ctl_Step,B6,Ctl_Rating,"Needs improvement") -> 0 | J6: =COUNTIFS(Ctl_Step,B6,Ctl_Rating,"Ineffective") -> 0 | K6: =IFERROR(H6/F6,0) -> 1 | L6: =IF(F6=0,"n/a",IF(COUNTIFS(Ctl_Step,B6,Ctl_Rating,"Ineffective",Ctl_Key,"Y")>0,"Red",IF(I6+J6>0,"Amber","Green"))) -> Green | M6: =SUMPRODUCT(MAX((Risk_Step=B6)*Risk_Res)) -> 7.8
B7: P2 | C7: Master data and pricing maintenance | D7: Customer master data, price lists and discount matrices are maintained in the order system. | E7: =COUNTIF(Risk_Step,B7) -> 2 | F7: =COUNTIF(Ctl_Step,B7) -> 4 | G7: =COUNTIFS(Ctl_Step,B7,Ctl_Key,"Y") -> 2 | H7: =COUNTIFS(Ctl_Step,B7,Ctl_Rating,"Effective")+COUNTIFS(Ctl_Step,B7,Ctl_Rating,"Effective with exceptions") -> 3 | I7: =COUNTIFS(Ctl_Step,B7,Ctl_Rating,"Needs improvement") -> 0 | J7: =COUNTIFS(Ctl_Step,B7,Ctl_Rating,"Ineffective") -> 1 | K7: =IFERROR(H7/F7,0) -> 0.75 | L7: =IF(F7=0,"n/a",IF(COUNTIFS(Ctl_Step,B7,Ctl_Rating,"Ineffective",Ctl_Key,"Y")>0,"Red",IF(I7+J7>0,"Amber","Green"))) -> Amber | M7: =SUMPRODUCT(MAX((Risk_Step=B7)*Risk_Res)) -> 5.6
B8: P3 | C8: Sales order entry | D8: Customer purchase orders are keyed into the system and priced automatically. | E8: =COUNTIF(Risk_Step,B8) -> 1 | F8: =COUNTIF(Ctl_Step,B8) -> 1 | G8: =COUNTIFS(Ctl_Step,B8,Ctl_Key,"Y") -> 0 | H8: =COUNTIFS(Ctl_Step,B8,Ctl_Rating,"Effective")+COUNTIFS(Ctl_Step,B8,Ctl_Rating,"Effective with exceptions") -> 1 | I8: =COUNTIFS(Ctl_Step,B8,Ctl_Rating,"Needs improvement") -> 0 | J8: =COUNTIFS(Ctl_Step,B8,Ctl_Rating,"Ineffective") -> 0 | K8: =IFERROR(H8/F8,0) -> 1 | L8: =IF(F8=0,"n/a",IF(COUNTIFS(Ctl_Step,B8,Ctl_Rating,"Ineffective",Ctl_Key,"Y")>0,"Red",IF(I8+J8>0,"Amber","Green"))) -> Green | M8: =SUMPRODUCT(MAX((Risk_Step=B8)*Risk_Res)) -> 5.85
B9: P4 | C9: Credit check and order release | D9: Orders are checked against credit limits and overdue balances before release to the warehouse. | E9: =COUNTIF(Risk_Step,B9) -> 1 | F9: =COUNTIF(Ctl_Step,B9) -> 3 | G9: =COUNTIFS(Ctl_Step,B9,Ctl_Key,"Y") -> 3 | H9: =COUNTIFS(Ctl_Step,B9,Ctl_Rating,"Effective")+COUNTIFS(Ctl_Step,B9,Ctl_Rating,"Effective with exceptions") -> 1 | I9: =COUNTIFS(Ctl_Step,B9,Ctl_Rating,"Needs improvement") -> 0 | J9: =COUNTIFS(Ctl_Step,B9,Ctl_Rating,"Ineffective") -> 2 | K9: =IFERROR(H9/F9,0) -> 0.33333333 | L9: =IF(F9=0,"n/a",IF(COUNTIFS(Ctl_Step,B9,Ctl_Rating,"Ineffective",Ctl_Key,"Y")>0,"Red",IF(I9+J9>0,"Amber","Green"))) -> Red | M9: =SUMPRODUCT(MAX((Risk_Step=B9)*Risk_Res)) -> 12.266667
B10: P5 | C10: Picking, packing and dispatch | D10: Warehouse picks against released orders; vehicles leave against an approved dispatch plan. | E10: =COUNTIF(Risk_Step,B10) -> 2 | F10: =COUNTIF(Ctl_Step,B10) -> 3 | G10: =COUNTIFS(Ctl_Step,B10,Ctl_Key,"Y") -> 2 | H10: =COUNTIFS(Ctl_Step,B10,Ctl_Rating,"Effective")+COUNTIFS(Ctl_Step,B10,Ctl_Rating,"Effective with exceptions") -> 3 | I10: =COUNTIFS(Ctl_Step,B10,Ctl_Rating,"Needs improvement") -> 0 | J10: =COUNTIFS(Ctl_Step,B10,Ctl_Rating,"Ineffective") -> 0 | K10: =IFERROR(H10/F10,0) -> 1 | L10: =IF(F10=0,"n/a",IF(COUNTIFS(Ctl_Step,B10,Ctl_Rating,"Ineffective",Ctl_Key,"Y")>0,"Red",IF(I10+J10>0,"Amber","Green"))) -> Green | M10: =SUMPRODUCT(MAX((Risk_Step=B10)*Risk_Res)) -> 6.5
B11: P6 | C11: Delivery and proof of delivery | D11: Drivers obtain signed delivery receipts, which support billing. | E11: =COUNTIF(Risk_Step,B11) -> 1 | F11: =COUNTIF(Ctl_Step,B11) -> 1 | G11: =COUNTIFS(Ctl_Step,B11,Ctl_Key,"Y") -> 1 | H11: =COUNTIFS(Ctl_Step,B11,Ctl_Rating,"Effective")+COUNTIFS(Ctl_Step,B11,Ctl_Rating,"Effective with exceptions") -> 0 | I11: =COUNTIFS(Ctl_Step,B11,Ctl_Rating,"Needs improvement") -> 0 | J11: =COUNTIFS(Ctl_Step,B11,Ctl_Rating,"Ineffective") -> 1 | K11: =IFERROR(H11/F11,0) -> 0 | L11: =IF(F11=0,"n/a",IF(COUNTIFS(Ctl_Step,B11,Ctl_Rating,"Ineffective",Ctl_Key,"Y")>0,"Red",IF(I11+J11>0,"Amber","Green"))) -> Red | M11: =SUMPRODUCT(MAX((Risk_Step=B11)*Risk_Res)) -> 18
B12: P7 | C12: Invoicing and VAT | D12: VAT invoices are generated from matched order and delivery data; invoice series are controlled. | E12: =COUNTIF(Risk_Step,B12) -> 3 | F12: =COUNTIF(Ctl_Step,B12) -> 4 | G12: =COUNTIFS(Ctl_Step,B12,Ctl_Key,"Y") -> 2 | H12: =COUNTIFS(Ctl_Step,B12,Ctl_Rating,"Effective")+COUNTIFS(Ctl_Step,B12,Ctl_Rating,"Effective with exceptions") -> 3 | I12: =COUNTIFS(Ctl_Step,B12,Ctl_Rating,"Needs improvement") -> 0 | J12: =COUNTIFS(Ctl_Step,B12,Ctl_Rating,"Ineffective") -> 1 | K12: =IFERROR(H12/F12,0) -> 0.75 | L12: =IF(F12=0,"n/a",IF(COUNTIFS(Ctl_Step,B12,Ctl_Rating,"Ineffective",Ctl_Key,"Y")>0,"Red",IF(I12+J12>0,"Amber","Green"))) -> Red | M12: =SUMPRODUCT(MAX((Risk_Step=B12)*Risk_Res)) -> 10.8
B13: P8 | C13: Collection and cash application | D13: Customer payments are collected, deposited and applied to open invoices. | E13: =COUNTIF(Risk_Step,B13) -> 1 | F13: =COUNTIF(Ctl_Step,B13) -> 2 | G13: =COUNTIFS(Ctl_Step,B13,Ctl_Key,"Y") -> 2 | H13: =COUNTIFS(Ctl_Step,B13,Ctl_Rating,"Effective")+COUNTIFS(Ctl_Step,B13,Ctl_Rating,"Effective with exceptions") -> 0 | I13: =COUNTIFS(Ctl_Step,B13,Ctl_Rating,"Needs improvement") -> 1 | J13: =COUNTIFS(Ctl_Step,B13,Ctl_Rating,"Ineffective") -> 1 | K13: =IFERROR(H13/F13,0) -> 0 | L13: =IF(F13=0,"n/a",IF(COUNTIFS(Ctl_Step,B13,Ctl_Rating,"Ineffective",Ctl_Key,"Y")>0,"Red",IF(I13+J13>0,"Amber","Green"))) -> Red | M13: =SUMPRODUCT(MAX((Risk_Step=B13)*Risk_Res)) -> 12.75
B14: P9 | C14: Credit notes, returns and receivables monitoring | D14: Returns and credit notes are approved; aging, allowance, reconciliation and cut-off are reviewed each period. | E14: =COUNTIF(Risk_Step,B14) -> 4 | F14: =COUNTIF(Ctl_Step,B14) -> 5 | G14: =COUNTIFS(Ctl_Step,B14,Ctl_Key,"Y") -> 3 | H14: =COUNTIFS(Ctl_Step,B14,Ctl_Rating,"Effective")+COUNTIFS(Ctl_Step,B14,Ctl_Rating,"Effective with exceptions") -> 3 | I14: =COUNTIFS(Ctl_Step,B14,Ctl_Rating,"Needs improvement") -> 0 | J14: =COUNTIFS(Ctl_Step,B14,Ctl_Rating,"Ineffective") -> 2 | K14: =IFERROR(H14/F14,0) -> 0.6 | L14: =IF(F14=0,"n/a",IF(COUNTIFS(Ctl_Step,B14,Ctl_Rating,"Ineffective",Ctl_Key,"Y")>0,"Red",IF(I14+J14>0,"Amber","Green"))) -> Red | M14: =SUMPRODUCT(MAX((Risk_Step=B14)*Risk_Res)) -> 14.4
C15: Total | E15: =SUM(E6:E14) -> 16 | F15: =SUM(F6:F14) -> 24 | G15: =SUM(G6:G14) -> 16 | H15: =SUM(H6:H14) -> 15 | I15: =SUM(I6:I14) -> 1 | J15: =SUM(J6:J14) -> 8 | K15: =IFERROR(H15/F15,0) -> 0.625
B17: Step rating: Red = at least one key control is Ineffective; Amber = other control weaknesses; Green = all controls effective.

Sheet Risks
B1: Risk Register
B2: Sampaguita Foods & Distribution Corporation (SFDC) | PHP in thousands | Order-to-cash (sales cycle)
B3: =HYPERLINK("#Cover!A1","◄ Back to Cover") -> ◄ Back to Cover
B5: ID | C5: Step | D5: Process step | E5: Risk | F5: Assertion | G5: COSO component | H5: Likelihood (1-5) | I5: Impact (1-5) | J5: Inherent score | K5: Inherent rating | L5: Controls | M5: Avg control reduction | N5: Residual score | O5: Residual rating | Q5: Sort key
B6: R01 | C6: P1 | D6: =VLOOKUP(C6,Process_Steps!$B$6:$C$14,2,FALSE()) -> Customer onboarding and credit approval | E6: Fictitious or high-risk customers are onboarded without adequate vetting | F6: Occurrence | G6: Risk assessment | H6: 3 | I6: 4 | J6: =H6*I6 -> 12 | K6: =IF(J6>=High_Score,"High",IF(J6>=Med_Score,"Medium","Low")) -> Medium | L6: =COUNTIF(Ctl_Risk,B6) -> 1 | M6: =IFERROR(AVERAGEIFS(Ctl_Factor,Ctl_Risk,B6),0) -> 0.35 | N6: =J6*(1-M6) -> 7.8 | O6: =IF(N6>=High_Score,"High",IF(N6>=Med_Score,"Medium","Low")) -> Low | Q6: =N6+ROW()/1000000 -> 7.800006
B7: R02 | C7: P2 | D7: =VLOOKUP(C7,Process_Steps!$B$6:$C$14,2,FALSE()) -> Master data and pricing maintenance | E7: Unauthorised or erroneous changes to customer master data and credit limits | F7: Accuracy | G7: Control activities | H7: 2 | I7: 4 | J7: =H7*I7 -> 8 | K7: =IF(J7>=High_Score,"High",IF(J7>=Med_Score,"Medium","Low")) -> Medium | L7: =COUNTIF(Ctl_Risk,B7) -> 2 | M7: =IFERROR(AVERAGEIFS(Ctl_Factor,Ctl_Risk,B7),0) -> 0.3 | N7: =J7*(1-M7) -> 5.6 | O7: =IF(N7>=High_Score,"High",IF(N7>=Med_Score,"Medium","Low")) -> Low | Q7: =N7+ROW()/1000000 -> 5.600007
B8: R03 | C8: P2 | D8: =VLOOKUP(C8,Process_Steps!$B$6:$C$14,2,FALSE()) -> Master data and pricing maintenance | E8: Incorrect prices or unapproved discounts are applied to orders | F8: Accuracy | G8: Control activities | H8: 3 | I8: 3 | J8: =H8*I8 -> 9 | K8: =IF(J8>=High_Score,"High",IF(J8>=Med_Score,"Medium","Low")) -> Medium | L8: =COUNTIF(Ctl_Risk,B8) -> 2 | M8: =IFERROR(AVERAGEIFS(Ctl_Factor,Ctl_Risk,B8),0) -> 0.5 | N8: =J8*(1-M8) -> 4.5 | O8: =IF(N8>=High_Score,"High",IF(N8>=Med_Score,"Medium","Low")) -> Low | Q8: =N8+ROW()/1000000 -> 4.500008
B9: R04 | C9: P4 | D9: =VLOOKUP(C9,Process_Steps!$B$6:$C$14,2,FALSE()) -> Credit check and order release | E9: Orders are released beyond approved credit limits or to overdue accounts | F9: Valuation | G9: Control activities | H9: 4 | I9: 4 | J9: =H9*I9 -> 16 | K9: =IF(J9>=High_Score,"High",IF(J9>=Med_Score,"Medium","Low")) -> High | L9: =COUNTIF(Ctl_Risk,B9) -> 3 | M9: =IFERROR(AVERAGEIFS(Ctl_Factor,Ctl_Risk,B9),0) -> 0.23333333 | N9: =J9*(1-M9) -> 12.266667 | O9: =IF(N9>=High_Score,"High",IF(N9>=Med_Score,"Medium","Low")) -> Medium | Q9: =N9+ROW()/1000000 -> 12.266676
B10: R05 | C10: P3 | D10: =VLOOKUP(C10,Process_Steps!$B$6:$C$14,2,FALSE()) -> Sales order entry | E10: Sales orders are recorded differently from the customer purchase order | F10: Accuracy | G10: Control activities | H10: 3 | I10: 3 | J10: =H10*I10 -> 9 | K10: =IF(J10>=High_Score,"High",IF(J10>=Med_Score,"Medium","Low")) -> Medium | L10: =COUNTIF(Ctl_Risk,B10) -> 1 | M10: =IFERROR(AVERAGEIFS(Ctl_Factor,Ctl_Risk,B10),0) -> 0.35 | N10: =J10*(1-M10) -> 5.85 | O10: =IF(N10>=High_Score,"High",IF(N10>=Med_Score,"Medium","Low")) -> Low | Q10: =N10+ROW()/1000000 -> 5.85001
B11: R06 | C11: P5 | D11: =VLOOKUP(C11,Process_Steps!$B$6:$C$14,2,FALSE()) -> Picking, packing and dispatch | E11: Goods leave the warehouse without a valid, approved order | F11: Existence | G11: Control activities | H11: 2 | I11: 5 | J11: =H11*I11 -> 10 | K11: =IF(J11>=High_Score,"High",IF(J11>=Med_Score,"Medium","Low")) -> Medium | L11: =COUNTIF(Ctl_Risk,B11) -> 1 | M11: =IFERROR(AVERAGEIFS(Ctl_Factor,Ctl_Risk,B11),0) -> 0.35 | N11: =J11*(1-M11) -> 6.5 | O11: =IF(N11>=High_Score,"High",IF(N11>=Med_Score,"Medium","Low")) -> Low | Q11: =N11+ROW()/1000000 -> 6.500011
B12: R07 | C12: P5 | D12: =VLOOKUP(C12,Process_Steps!$B$6:$C$14,2,FALSE()) -> Picking, packing and dispatch | E12: Wrong quantities are picked or inventory is lost before dispatch | F12: Existence | G12: Control activities | H12: 3 | I12: 4 | J12: =H12*I12 -> 12 | K12: =IF(J12>=High_Score,"High",IF(J12>=Med_Score,"Medium","Low")) -> Medium | L12: =COUNTIF(Ctl_Risk,B12) -> 2 | M12: =IFERROR(AVERAGEIFS(Ctl_Factor,Ctl_Risk,B12),0) -> 0.5 | N12: =J12*(1-M12) -> 6 | O12: =IF(N12>=High_Score,"High",IF(N12>=Med_Score,"Medium","Low")) -> Low | Q12: =N12+ROW()/1000000 -> 6.000012
B13: R08 | C13: P6 | D13: =VLOOKUP(C13,Process_Steps!$B$6:$C$14,2,FALSE()) -> Delivery and proof of delivery | E13: Revenue is recognised without evidence that goods were delivered | F13: Occurrence | G13: Control activities | H13: 4 | I13: 5 | J13: =H13*I13 -> 20 | K13: =IF(J13>=High_Score,"High",IF(J13>=Med_Score,"Medium","Low")) -> High | L13: =COUNTIF(Ctl_Risk,B13) -> 1 | M13: =IFERROR(AVERAGEIFS(Ctl_Factor,Ctl_Risk,B13),0) -> 0.1 | N13: =J13*(1-M13) -> 18 | O13: =IF(N13>=High_Score,"High",IF(N13>=Med_Score,"Medium","Low")) -> High | Q13: =N13+ROW()/1000000 -> 18.000013
B14: R09 | C14: P7 | D14: =VLOOKUP(C14,Process_Steps!$B$6:$C$14,2,FALSE()) -> Invoicing and VAT | E14: Goods delivered are never invoiced (unbilled revenue) | F14: Completeness | G14: Monitoring activities | H14: 4 | I14: 3 | J14: =H14*I14 -> 12 | K14: =IF(J14>=High_Score,"High",IF(J14>=Med_Score,"Medium","Low")) -> Medium | L14: =COUNTIF(Ctl_Risk,B14) -> 1 | M14: =IFERROR(AVERAGEIFS(Ctl_Factor,Ctl_Risk,B14),0) -> 0.1 | N14: =J14*(1-M14) -> 10.8 | O14: =IF(N14>=High_Score,"High",IF(N14>=Med_Score,"Medium","Low")) -> Medium | Q14: =N14+ROW()/1000000 -> 10.800014
B15: R10 | C15: P7 | D15: =VLOOKUP(C15,Process_Steps!$B$6:$C$14,2,FALSE()) -> Invoicing and VAT | E15: Invoices contain wrong price, quantity or VAT | F15: Accuracy | G15: Control activities | H15: 3 | I15: 4 | J15: =H15*I15 -> 12 | K15: =IF(J15>=High_Score,"High",IF(J15>=Med_Score,"Medium","Low")) -> Medium | L15: =COUNTIF(Ctl_Risk,B15) -> 2 | M15: =IFERROR(AVERAGEIFS(Ctl_Factor,Ctl_Risk,B15),0) -> 0.5 | N15: =J15*(1-M15) -> 6 | O15: =IF(N15>=High_Score,"High",IF(N15>=Med_Score,"Medium","Low")) -> Low | Q15: =N15+ROW()/1000000 -> 6.000015
B16: R11 | C16: P7 | D16: =VLOOKUP(C16,Process_Steps!$B$6:$C$14,2,FALSE()) -> Invoicing and VAT | E16: Invoice series is not controlled, creating BIR compliance exposure | F16: Completeness | G16: Control activities | H16: 2 | I16: 4 | J16: =H16*I16 -> 8 | K16: =IF(J16>=High_Score,"High",IF(J16>=Med_Score,"Medium","Low")) -> Medium | L16: =COUNTIF(Ctl_Risk,B16) -> 1 | M16: =IFERROR(AVERAGEIFS(Ctl_Factor,Ctl_Risk,B16),0) -> 0.5 | N16: =J16*(1-M16) -> 4 | O16: =IF(N16>=High_Score,"High",IF(N16>=Med_Score,"Medium","Low")) -> Low | Q16: =N16+ROW()/1000000 -> 4.000016
B17: R12 | C17: P8 | D17: =VLOOKUP(C17,Process_Steps!$B$6:$C$14,2,FALSE()) -> Collection and cash application | E17: Collections are misappropriated or misapplied (including lapping) | F17: Existence | G17: Control environment | H17: 3 | I17: 5 | J17: =H17*I17 -> 15 | K17: =IF(J17>=High_Score,"High",IF(J17>=Med_Score,"Medium","Low")) -> High | L17: =COUNTIF(Ctl_Risk,B17) -> 2 | M17: =IFERROR(AVERAGEIFS(Ctl_Factor,Ctl_Risk,B17),0) -> 0.15 | N17: =J17*(1-M17) -> 12.75 | O17: =IF(N17>=High_Score,"High",IF(N17>=Med_Score,"Medium","Low")) -> Medium | Q17: =N17+ROW()/1000000 -> 12.750017
... B21: R16 | C21: P9 | D21: =VLOOKUP(C21,Process_Steps!$B$6:$C$14,2,FALSE()) -> Credit notes, returns and receivables monitoring | E21: Customer disputes and balance differences are not resolved | F21: Rights and obligations | G21: Information and communication | H21: 3 | I21: 3 | J21: =H21*I21 -> 9 | K21: =IF(J21>=High_Score,"High",IF(J21>=Med_Score,"Medium","Low")) -> Medium | L21: =COUNTIF(Ctl_Risk,B21) -> 1 | M21: =IFERROR(AVERAGEIFS(Ctl_Factor,Ctl_Risk,B21),0) -> 0.5 | N21: =J21*(1-M21) -> 4.5 | O21: =IF(N21>=High_Score,"High",IF(N21>=Med_Score,"Medium","Low")) -> Low | Q21: =N21+ROW()/1000000 -> 4.500021

Sheet Controls
B1: Controls and Test Results
B2: Sampaguita Foods & Distribution Corporation (SFDC) | PHP in thousands | Order-to-cash (sales cycle) | Testing period 1 Jan - 30 Sep 2026 (fictional results)
B3: =HYPERLINK("#Cover!A1","◄ Back to Cover") -> ◄ Back to Cover
B5: ID | C5: Risk | D5: Step | E5: Control description | F5: Owner | G5: Type | H5: Nature | I5: Frequency | J5: Key | K5: Design assessment | L5: Population | M5: Risk level | N5: Sample | O5: Excep-tions | P5: Deviation rate | Q5: Tolerable rate | R5: Operating result | S5: Overall rating | T5: Risk reduction | U5: Test notes
B6: C01 | C6: R01 | D6: =VLOOKUP(C6,Risks!$B$6:$C$21,2,FALSE()) -> P1 | E6: Credit application with KYC documents (TIN, business permit, bank reference) reviewed by the credit officer before account set-up | F6: Credit Officer | G6: Preventive | H6: Manual | I6: Per occurrence | J6: Y | K6: Effective | L6: 38 | M6: =IF(VLOOKUP(C6,Risks!$B$6:$J$21,9,FALSE())>=Elev_Score,"Elevated","Standard") -> Standard | N6: =IF(K6="Missing",0,IF(H6="Automated",1,MIN(L6,VLOOKUP(I6,Sampling_Table,IF(M6="Elevated",3,2),FALSE())))) -> 15 | O6: 1 | P6: =IFERROR(O6/N6,0) -> 0.066666667 | Q6: =IF(M6="Elevated",Tol_Elev,Tol_Std) -> 0.1 | R6: =IF(K6="Missing","Not operating",IF(O6=0,"Effective",IF(AND(N6>5,P6<=Q6),"Effective with exceptions","Ineffective"))) -> Effective with exceptions | S6: =IF(OR(K6="Missing",R6="Ineffective",R6="Not operating"),"Ineffective",IF(K6="Needs improvement","Needs improvement",R6)) -> Effective with exceptions | T6: =VLOOKUP(S6,Factor_Table,2,FALSE()) -> 0.35 | U6: One file missing the bank reference; obtained later.
B7: C02 | C7: R04 | D7: =VLOOKUP(C7,Risks!$B$6:$C$21,2,FALSE()) -> P4 | E7: Credit limits above PHP 500,000 are approved by the Finance Manager before activation | F7: Finance Manager | G7: Preventive | H7: Manual | I7: Weekly | J7: Y | K7: Effective | L7: 39 | M7: =IF(VLOOKUP(C7,Risks!$B$6:$J$21,9,FALSE())>=Elev_Score,"Elevated","Standard") -> Elevated | N7: =IF(K7="Missing",0,IF(H7="Automated",1,MIN(L7,VLOOKUP(I7,Sampling_Table,IF(M7="Elevated",3,2),FALSE())))) -> 12 | O7: 2 | P7: =IFERROR(O7/N7,0) -> 0.16666667 | Q7: =IF(M7="Elevated",Tol_Elev,Tol_Std) -> 0.05 | R7: =IF(K7="Missing","Not operating",IF(O7=0,"Effective",IF(AND(N7>5,P7<=Q7),"Effective with exceptions","Ineffective"))) -> Ineffective | S7: =IF(OR(K7="Missing",R7="Ineffective",R7="Not operating"),"Ineffective",IF(K7="Needs improvement","Needs improvement",R7)) -> Ineffective | T7: =VLOOKUP(S7,Factor_Table,2,FALSE()) -> 0.1 | U7: Two approvals not evidenced on the credit file.
B8: C03 | C8: R02 | D8: =VLOOKUP(C8,Risks!$B$6:$C$21,2,FALSE()) -> P2 | E8: Finance reviews the customer master-data change log monthly against approved requests | F8: Accounting Supervisor | G8: Detective | H8: Manual | I8: Monthly | J8: N | K8: Effective | L8: 9 | M8: =IF(VLOOKUP(C8,Risks!$B$6:$J$21,9,FALSE())>=Elev_Score,"Elevated","Standard") -> Standard | N8: =IF(K8="Missing",0,IF(H8="Automated",1,MIN(L8,VLOOKUP(I8,Sampling_Table,IF(M8="Elevated",3,2),FALSE())))) -> 2 | O8: 1 | P8: =IFERROR(O8/N8,0) -> 0.5 | Q8: =IF(M8="Elevated",Tol_Elev,Tol_Std) -> 0.1 | R8: =IF(K8="Missing","Not operating",IF(O8=0,"Effective",IF(AND(N8>5,P8<=Q8),"Effective with exceptions","Ineffective"))) -> Ineffective | S8: =IF(OR(K8="Missing",R8="Ineffective",R8="Not operating"),"Ineffective",IF(K8="Needs improvement","Needs improvement",R8)) -> Ineffective | T8: =VLOOKUP(S8,Factor_Table,2,FALSE()) -> 0.1 | U8: Review for April was not performed.
B9: C04 | C9: R02 | D9: =VLOOKUP(C9,Risks!$B$6:$C$21,2,FALSE()) -> P2 | E9: System restricts edits to credit limits and payment terms to the Credit department profile | F9: IT Manager | G9: Preventive | H9: Automated | I9: Multiple per day | J9: Y | K9: Effective | L9: 2400 | M9: =IF(VLOOKUP(C9,Risks!$B$6:$J$21,9,FALSE())>=Elev_Score,"Elevated","Standard") -> Standard | N9: =IF(K9="Missing",0,IF(H9="Automated",1,MIN(L9,VLOOKUP(I9,Sampling_Table,IF(M9="Elevated",3,2),FALSE())))) -> 1 | O9: 0 | P9: =IFERROR(O9/N9,0) -> 0 | Q9: =IF(M9="Elevated",Tol_Elev,Tol_Std) -> 0.1 | R9: =IF(K9="Missing","Not operating",IF(O9=0,"Effective",IF(AND(N9>5,P9<=Q9),"Effective with exceptions","Ineffective"))) -> Effective | S9: =IF(OR(K9="Missing",R9="Ineffective",R9="Not operating"),"Ineffective",IF(K9="Needs improvement","Needs improvement",R9)) -> Effective | T9: =VLOOKUP(S9,Factor_Table,2,FALSE()) -> 0.5 | U9: Access list agreed to the approved matrix; ITGCs effective.
B10: C05 | C10: R03 | D10: =VLOOKUP(C10,Risks!$B$6:$C$21,2,FALSE()) -> P2 | E10: Price-list changes are approved by the Sales Director before upload | F10: Sales Director | G10: Preventive | H10: Manual | I10: Monthly | J10: N | K10: Effective | L10: 9 | M10: =IF(VLOOKUP(C10,Risks!$B$6:$J$21,9,FALSE())>=Elev_Score,"Elevated","Standard") -> Standard | N10: =IF(K10="Missing",0,IF(H10="Automated",1,MIN(L10,VLOOKUP(I10,Sampling_Table,IF(M10="Elevated",3,2),FALSE())))) -> 2 | O10: 0 | P10: =IFERROR(O10/N10,0) -> 0 | Q10: =IF(M10="Elevated",Tol_Elev,Tol_Std) -> 0.1 | R10: =IF(K10="Missing","Not operating",IF(O10=0,"Effective",IF(AND(N10>5,P10<=Q10),"Effective with exceptions","Ineffective"))) -> Effective | S10: =IF(OR(K10="Missing",R10="Ineffective",R10="Not operating"),"Ineffective",IF(K10="Needs improvement","Needs improvement",R10)) -> Effective | T10: =VLOOKUP(S10,Factor_Table,2,FALSE()) -> 0.5
B11: C06 | C11: R03 | D11: =VLOOKUP(C11,Risks!$B$6:$C$21,2,FALSE()) -> P2 | E11: Discounts above 5% require system approval workflow | F11: IT Manager | G11: Preventive | H11: Automated | I11: Multiple per day | J11: Y | K11: Effective | L11: 2400 | M11: =IF(VLOOKUP(C11,Risks!$B$6:$J$21,9,FALSE())>=Elev_Score,"Elevated","Standard") -> Standard | N11: =IF(K11="Missing",0,IF(H11="Automated",1,MIN(L11,VLOOKUP(I11,Sampling_Table,IF(M11="Elevated",3,2),FALSE())))) -> 1 | O11: 0 | P11: =IFERROR(O11/N11,0) -> 0 | Q11: =IF(M11="Elevated",Tol_Elev,Tol_Std) -> 0.1 | R11: =IF(K11="Missing","Not operating",IF(O11=0,"Effective",IF(AND(N11>5,P11<=Q11),"Effective with exceptions","Ineffective"))) -> Effective | S11: =IF(OR(K11="Missing",R11="Ineffective",R11="Not operating"),"Ineffective",IF(K11="Needs improvement","Needs improvement",R11)) -> Effective | T11: =VLOOKUP(S11,Factor_Table,2,FALSE()) -> 0.5 | U11: Workflow configuration re-performed.
B12: C07 | C12: R04 | D12: =VLOOKUP(C12,Risks!$B$6:$C$21,2,FALSE()) -> P4 | E12: System blocks orders that exceed the credit limit or include overdue invoices; override by Credit Manager only | F12: Credit Manager | G12: Preventive | H12: Automated | I12: Multiple per day | J12: Y | K12: Effective | L12: 2400 | M12: =IF(VLOOKUP(C12,Risks!$B$6:$J$21,9,FALSE())>=Elev_Score,"Elevated","Standard") -> Elevated | N12: =IF(K12="Missing",0,IF(H12="Automated",1,MIN(L12,VLOOKUP(I12,Sampling_Table,IF(M12="Elevated",3,2),FALSE())))) -> 1 | O12: 0 | P12: =IFERROR(O12/N12,0) -> 0 | Q12: =IF(M12="Elevated",Tol_Elev,Tol_Std) -> 0.05 | R12: =IF(K12="Missing","Not operating",IF(O12=0,"Effective",IF(AND(N12>5,P12<=Q12),"Effective with exceptions","Ineffective"))) -> Effective | S12: =IF(OR(K12="Missing",R12="Ineffective",R12="Not operating"),"Ineffective",IF(K12="Needs improvement","Needs improvement",R12)) -> Effective | T12: =VLOOKUP(S12,Factor_Table,2,FALSE()) -> 0.5 | U12: Block logic re-performed with test orders.
B13: C08 | C13: R04 | D13: =VLOOKUP(C13,Risks!$B$6:$C$21,2,FALSE()) -> P4 | E13: Credit Manager reviews the weekly list of overridden orders with the Finance Manager | F13: Credit Manager | G13: Detective | H13: Manual | I13: Weekly | J13: Y | K13: Effective | L13: 39 | M13: =IF(VLOOKUP(C13,Risks!$B$6:$J$21,9,FALSE())>=Elev_Score,"Elevated","Standard") -> Elevated | N13: =IF(K13="Missing",0,IF(H13="Automated",1,MIN(L13,VLOOKUP(I13,Sampling_Table,IF(M13="Elevated",3,2),FALSE())))) -> 12 | O13: 3 | P13: =IFERROR(O13/N13,0) -> 0.25 | Q13: =IF(M13="Elevated",Tol_Elev,Tol_Std) -> 0.05 | R13: =IF(K13="Missing","Not operating",IF(O13=0,"Effective",IF(AND(N13>5,P13<=Q13),"Effective with exceptions","Ineffective"))) -> Ineffective | S13: =IF(OR(K13="Missing",R13="Ineffective",R13="Not operating"),"Ineffective",IF(K13="Needs improvement","Needs improvement",R13)) -> Ineffective | T13: =VLOOKUP(S13,Factor_Table,2,FALSE()) -> 0.1 | U13: Three weekly reviews not evidenced.
B14: C09 | C14: R05 | D14: =VLOOKUP(C14,Risks!$B$6:$C$21,2,FALSE()) -> P3 | E14: Orders above PHP 100,000 are verified to the customer PO by a second clerk | F14: Sales Supervisor | G14: Preventive | H14: Manual | I14: Daily | J14: N | K14: Effective | L14: 190 | M14: =IF(VLOOKUP(C14,Risks!$B$6:$J$21,9,FALSE())>=Elev_Score,"Elevated","Standard") -> Standard | N14: =IF(K14="Missing",0,IF(H14="Automated",1,MIN(L14,VLOOKUP(I14,Sampling_Table,IF(M14="Elevated",3,2),FALSE())))) -> 20 | O14: 2 | P14: =IFERROR(O14/N14,0) -> 0.1 | Q14: =IF(M14="Elevated",Tol_Elev,Tol_Std) -> 0.1 | R14: =IF(K14="Missing","Not operating",IF(O14=0,"Effective",IF(AND(N14>5,P14<=Q14),"Effective with exceptions","Ineffective"))) -> Effective with exceptions | S14: =IF(OR(K14="Missing",R14="Ineffective",R14="Not operating"),"Ineffective",IF(K14="Needs improvement","Needs improvement",R14)) -> Effective with exceptions | T14: =VLOOKUP(S14,Factor_Table,2,FALSE()) -> 0.35 | U14: Two orders keyed with transposed quantities.
B15: C10 | C15: R06 | D15: =VLOOKUP(C15,Risks!$B$6:$C$21,2,FALSE()) -> P5 | E15: Gate pass is matched to the approved dispatch plan before a vehicle leaves | F15: Warehouse Manager | G15: Preventive | H15: Manual | I15: Multiple per day | J15: Y | K15: Effective | L15: 2400 | M15: =IF(VLOOKUP(C15,Risks!$B$6:$J$21,9,FALSE())>=Elev_Score,"Elevated","Standard") -> Standard | N15: =IF(K15="Missing",0,IF(H15="Automated",1,MIN(L15,VLOOKUP(I15,Sampling_Table,IF(M15="Elevated",3,2),FALSE())))) -> 25 | O15: 1 | P15: =IFERROR(O15/N15,0) -> 0.04 | Q15: =IF(M15="Elevated",Tol_Elev,Tol_Std) -> 0.1 | R15: =IF(K15="Missing","Not operating",IF(O15=0,"Effective",IF(AND(N15>5,P15<=Q15),"Effective with exceptions","Ineffective"))) -> Effective with exceptions | S15: =IF(OR(K15="Missing",R15="Ineffective",R15="Not operating"),"Ineffective",IF(K15="Needs improvement","Needs improvement",R15)) -> Effective with exceptions | T15: =VLOOKUP(S15,Factor_Table,2,FALSE()) -> 0.35 | U15: One dispatch without a signed gate pass.
B16: C11 | C16: R07 | D16: =VLOOKUP(C16,Risks!$B$6:$C$21,2,FALSE()) -> P5 | E16: Pick lists are verified by barcode scan against the released order | F16: Warehouse Manager | G16: Preventive | H16: IT-dependent manual | I16: Multiple per day | J16: N | K16: Effective | L16: 2400 | M16: =IF(VLOOKUP(C16,Risks!$B$6:$J$21,9,FALSE())>=Elev_Score,"Elevated","Standard") -> Standard | N16: =IF(K16="Missing",0,IF(H16="Automated",1,MIN(L16,VLOOKUP(I16,Sampling_Table,IF(M16="Elevated",3,2),FALSE())))) -> 25 | O16: 0 | P16: =IFERROR(O16/N16,0) -> 0 | Q16: =IF(M16="Elevated",Tol_Elev,Tol_Std) -> 0.1 | R16: =IF(K16="Missing","Not operating",IF(O16=0,"Effective",IF(AND(N16>5,P16<=Q16),"Effective with exceptions","Ineffective"))) -> Effective | S16: =IF(OR(K16="Missing",R16="Ineffective",R16="Not operating"),"Ineffective",IF(K16="Needs improvement","Needs improvement",R16)) -> Effective | T16: =VLOOKUP(S16,Factor_Table,2,FALSE()) -> 0.5
B17: C12 | C17: R07 | D17: =VLOOKUP(C17,Risks!$B$6:$C$21,2,FALSE()) -> P5 | E17: Monthly cycle count with variance investigation above 0.5% of value | F17: Inventory Controller | G17: Detective | H17: Manual | I17: Monthly | J17: Y | K17: Effective | L17: 9 | M17: =IF(VLOOKUP(C17,Risks!$B$6:$J$21,9,FALSE())>=Elev_Score,"Elevated","Standard") -> Standard | N17: =IF(K17="Missing",0,IF(H17="Automated",1,MIN(L17,VLOOKUP(I17,Sampling_Table,IF(M17="Elevated",3,2),FALSE())))) -> 2 | O17: 0 | P17: =IFERROR(O17/N17,0) -> 0 | Q17: =IF(M17="Elevated",Tol_Elev,Tol_Std) -> 0.1 | R17: =IF(K17="Missing","Not operating",IF(O17=0,"Effective",IF(AND(N17>5,P17<=Q17),"Effective with exceptions","Ineffective"))) -> Effective | S17: =IF(OR(K17="Missing",R17="Ineffective",R17="Not operating"),"Ineffective",IF(K17="Needs improvement","Needs improvement",R17)) -> Effective | T17: =VLOOKUP(S17,Factor_Table,2,FALSE()) -> 0.5
B18: C13 | C18: R08 | D18: =VLOOKUP(C18,Risks!$B$6:$C$21,2,FALSE()) -> P6 | E18: Signed delivery receipts are matched to invoices before billing is released | F18: Billing Supervisor | G18: Preventive | H18: Manual | I18: Daily | J18: Y | K18: Effective | L18: 190 | M18: =IF(VLOOKUP(C18,Risks!$B$6:$J$21,9,FALSE())>=Elev_Score,"Elevated","Standard") -> Elevated | N18: =IF(K18="Missing",0,IF(H18="Automated",1,MIN(L18,VLOOKUP(I18,Sampling_Table,IF(M18="Elevated",3,2),FALSE())))) -> 30 | O18: 4 | P18: =IFERROR(O18/N18,0) -> 0.13333333 | Q18: =IF(M18="Elevated",Tol_Elev,Tol_Std) -> 0.05 | R18: =IF(K18="Missing","Not operating",IF(O18=0,"Effective",IF(AND(N18>5,P18<=Q18),"Effective with exceptions","Ineffective"))) -> Ineffective | S18: =IF(OR(K18="Missing",R18="Ineffective",R18="Not operating"),"Ineffective",IF(K18="Needs improvement","Needs improvement",R18)) -> Ineffective | T18: =VLOOKUP(S18,Factor_Table,2,FALSE()) -> 0.1 | U18: Four invoices released without a signed delivery receipt.
B19: C14 | C19: R09 | D19: =VLOOKUP(C19,Risks!$B$6:$C$21,2,FALSE()) -> P7 | E19: Daily reconciliation of delivery receipts to invoices and review of the unbilled report | F19: Billing Supervisor | G19: Detective | H19: Manual | I19: Daily | J19: Y | K19: Missing | L19: 190 | M19: =IF(VLOOKUP(C19,Risks!$B$6:$J$21,9,FALSE())>=Elev_Score,"Elevated","Standard") -> Standard | N19: =IF(K19="Missing",0,IF(H19="Automated",1,MIN(L19,VLOOKUP(I19,Sampling_Table,IF(M19="Elevated",3,2),FALSE())))) -> 0 | O19: 0 | P19: =IFERROR(O19/N19,0) -> 0 | Q19: =IF(M19="Elevated",Tol_Elev,Tol_Std) -> 0.1 | R19: =IF(K19="Missing","Not operating",IF(O19=0,"Effective",IF(AND(N19>5,P19<=Q19),"Effective with exceptions","Ineffective"))) -> Not operating | S19: =IF(OR(K19="Missing",R19="Ineffective",R19="Not operating"),"Ineffective",IF(K19="Needs improvement","Needs improvement",R19)) -> Ineffective | T19: =VLOOKUP(S19,Factor_Table,2,FALSE()) -> 0.1 | U19: No formal reconciliation is performed or documented.
B20: C15 | C20: R10 | D20: =VLOOKUP(C20,Risks!$B$6:$C$21,2,FALSE()) -> P7 | E20: System generates invoices from matched order and delivery data (three-way match) | F20: IT Manager | G20: Preventive | H20: Automated | I20: Multiple per day | J20: Y | K20: Effective | L20: 2400 | M20: =IF(VLOOKUP(C20,Risks!$B$6:$J$21,9,FALSE())>=Elev_Score,"Elevated","Standard") -> Standard | N20: =IF(K20="Missing",0,IF(H20="Automated",1,MIN(L20,VLOOKUP(I20,Sampling_Table,IF(M20="Elevated",3,2),FALSE())))) -> 1 | O20: 0 | P20: =IFERROR(O20/N20,0) -> 0 | Q20: =IF(M20="Elevated",Tol_Elev,Tol_Std) -> 0.1 | R20: =IF(K20="Missing","Not operating",IF(O20=0,"Effective",IF(AND(N20>5,P20<=Q20),"Effective with exceptions","Ineffective"))) -> Effective | S20: =IF(OR(K20="Missing",R20="Ineffective",R20="Not operating"),"Ineffective",IF(K20="Needs improvement","Needs improvement",R20)) -> Effective | T20: =VLOOKUP(S20,Factor_Table,2,FALSE()) -> 0.5 | U20: Match logic re-performed.
B21: C16 | C21: R10 | D21: =VLOOKUP(C21,Risks!$B$6:$C$21,2,FALSE()) -> P7 | E21: Monthly review of output VAT computation against the sales ledger | F21: Tax Accountant | G21: Detective | H21: Manual | I21: Monthly | J21: N | K21: Effective | L21: 9 | M21: =IF(VLOOKUP(C21,Risks!$B$6:$J$21,9,FALSE())>=Elev_Score,"Elevated","Standard") -> Standard | N21: =IF(K21="Missing",0,IF(H21="Automated",1,MIN(L21,VLOOKUP(I21,Sampling_Table,IF(M21="Elevated",3,2),FALSE())))) -> 2 | O21: 0 | P21: =IFERROR(O21/N21,0) -> 0 | Q21: =IF(M21="Elevated",Tol_Elev,Tol_Std) -> 0.1 | R21: =IF(K21="Missing","Not operating",IF(O21=0,"Effective",IF(AND(N21>5,P21<=Q21),"Effective with exceptions","Ineffective"))) -> Effective | S21: =IF(OR(K21="Missing",R21="Ineffective",R21="Not operating"),"Ineffective",IF(K21="Needs improvement","Needs improvement",R21)) -> Effective | T21: =VLOOKUP(S21,Factor_Table,2,FALSE()) -> 0.5
B22: C17 | C22: R11 | D22: =VLOOKUP(C22,Risks!$B$6:$C$21,2,FALSE()) -> P7 | E22: Weekly sequence check of invoice series and review of voided invoices | F22: Accounting Supervisor | G22: Detective | H22: Manual | I22: Weekly | J22: N | K22: Effective | L22: 39 | M22: =IF(VLOOKUP(C22,Risks!$B$6:$J$21,9,FALSE())>=Elev_Score,"Elevated","Standard") -> Standard | N22: =IF(K22="Missing",0,IF(H22="Automated",1,MIN(L22,VLOOKUP(I22,Sampling_Table,IF(M22="Elevated",3,2),FALSE())))) -> 8 | O22: 0 | P22: =IFERROR(O22/N22,0) -> 0 | Q22: =IF(M22="Elevated",Tol_Elev,Tol_Std) -> 0.1 | R22: =IF(K22="Missing","Not operating",IF(O22=0,"Effective",IF(AND(N22>5,P22<=Q22),"Effective with exceptions","Ineffective"))) -> Effective | S22: =IF(OR(K22="Missing",R22="Ineffective",R22="Not operating"),"Ineffective",IF(K22="Needs improvement","Needs improvement",R22)) -> Effective | T22: =VLOOKUP(S22,Factor_Table,2,FALSE()) -> 0.5
B23: C18 | C23: R12 | D23: =VLOOKUP(C23,Risks!$B$6:$C$21,2,FALSE()) -> P8 | E23: Collections are deposited intact daily; deposit slips reconciled to cash receipts by an independent staff member | F23: Treasury Officer | G23: Detective | H23: Manual | I23: Daily | J23: Y | K23: Effective | L23: 190 | M23: =IF(VLOOKUP(C23,Risks!$B$6:$J$21,9,FALSE())>=Elev_Score,"Elevated","Standard") -> Elevated | N23: =IF(K23="Missing",0,IF(H23="Automated",1,MIN(L23,VLOOKUP(I23,Sampling_Table,IF(M23="Elevated",3,2),FALSE())))) -> 30 | O23: 3 | P23: =IFERROR(O23/N23,0) -> 0.1 | Q23: =IF(M23="Elevated",Tol_Elev,Tol_Std) -> 0.05 | R23: =IF(K23="Missing","Not operating",IF(O23=0,"Effective",IF(AND(N23>5,P23<=Q23),"Effective with exceptions","Ineffective"))) -> Ineffective | S23: =IF(OR(K23="Missing",R23="Ineffective",R23="Not operating"),"Ineffective",IF(K23="Needs improvement","Needs improvement",R23)) -> Ineffective | T23: =VLOOKUP(S23,Factor_Table,2,FALSE()) -> 0.1 | U23: Three deposits delayed by one to three days.
B24: C19 | C24: R12 | D24: =VLOOKUP(C24,Risks!$B$6:$C$21,2,FALSE()) -> P8 | E24: Cash application is performed by staff independent of collection and billing | F24: Accounting Supervisor | G24: Preventive | H24: IT-dependent manual | I24: Daily | J24: Y | K24: Needs improvement | L24: 190 | M24: =IF(VLOOKUP(C24,Risks!$B$6:$J$21,9,FALSE())>=Elev_Score,"Elevated","Standard") -> Elevated | N24: =IF(K24="Missing",0,IF(H24="Automated",1,MIN(L24,VLOOKUP(I24,Sampling_Table,IF(M24="Elevated",3,2),FALSE())))) -> 30 | O24: 0 | P24: =IFERROR(O24/N24,0) -> 0 | Q24: =IF(M24="Elevated",Tol_Elev,Tol_Std) -> 0.05 | R24: =IF(K24="Missing","Not operating",IF(O24=0,"Effective",IF(AND(N24>5,P24<=Q24),"Effective with exceptions","Ineffective"))) -> Effective | S24: =IF(OR(K24="Missing",R24="Ineffective",R24="Not operating"),"Ineffective",IF(K24="Needs improvement","Needs improvement",R24)) -> Needs improvement | T24: =VLOOKUP(S24,Factor_Table,2,FALSE()) -> 0.2 | U24: Design gap: one user profile can post receipts and adjust customer balances.
B25: C20 | C25: R13 | D25: =VLOOKUP(C25,Risks!$B$6:$C$21,2,FALSE()) -> P9 | E25: Credit notes require supervisor approval and a return authorisation matched to the warehouse receipt | F25: Sales Supervisor | G25: Preventive | H25: Manual | I25: Weekly | J25: Y | K25: Effective | L25: 39 | M25: =IF(VLOOKUP(C25,Risks!$B$6:$J$21,9,FALSE())>=Elev_Score,"Elevated","Standard") -> Standard | N25: =IF(K25="Missing",0,IF(H25="Automated",1,MIN(L25,VLOOKUP(I25,Sampling_Table,IF(M25="Elevated",3,2),FALSE())))) -> 8 | O25: 2 | P25: =IFERROR(O25/N25,0) -> 0.25 | Q25: =IF(M25="Elevated",Tol_Elev,Tol_Std) -> 0.1 | R25: =IF(K25="Missing","Not operating",IF(O25=0,"Effective",IF(AND(N25>5,P25<=Q25),"Effective with exceptions","Ineffective"))) -> Ineffective | S25: =IF(OR(K25="Missing",R25="Ineffective",R25="Not operating"),"Ineffective",IF(K25="Needs improvement","Needs improvement",R25)) -> Ineffective | T25: =VLOOKUP(S25,Factor_Table,2,FALSE()) -> 0.1 | U25: Two credit notes approved after issue.
B26: C21 | C26: R14 | D26: =VLOOKUP(C26,Risks!$B$6:$C$21,2,FALSE()) -> P9 | E26: Monthly receivables aging reviewed by the Finance Manager with a documented allowance assessment | F26: Finance Manager | G26: Detective | H26: Manual | I26: Monthly | J26: Y | K26: Effective | L26: 9 | M26: =IF(VLOOKUP(C26,Risks!$B$6:$J$21,9,FALSE())>=Elev_Score,"Elevated","Standard") -> Elevated | N26: =IF(K26="Missing",0,IF(H26="Automated",1,MIN(L26,VLOOKUP(I26,Sampling_Table,IF(M26="Elevated",3,2),FALSE())))) -> 3 | O26: 1 | P26: =IFERROR(O26/N26,0) -> 0.33333333 | Q26: =IF(M26="Elevated",Tol_Elev,Tol_Std) -> 0.05 | R26: =IF(K26="Missing","Not operating",IF(O26=0,"Effective",IF(AND(N26>5,P26<=Q26),"Effective with exceptions","Ineffective"))) -> Ineffective | S26: =IF(OR(K26="Missing",R26="Ineffective",R26="Not operating"),"Ineffective",IF(K26="Needs improvement","Needs improvement",R26)) -> Ineffective | T26: =VLOOKUP(S26,Factor_Table,2,FALSE()) -> 0.1 | U26: One month lacked the documented allowance assessment.
B27: C22 | C27: R15 | D27: =VLOOKUP(C27,Risks!$B$6:$C$21,2,FALSE()) -> P9 | E27: Monthly AR sub-ledger to general-ledger reconciliation reviewed and signed | F27: Accounting Supervisor | G27: Detective | H27: Manual | I27: Monthly | J27: Y | K27: Effective | L27: 9 | M27: =IF(VLOOKUP(C27,Risks!$B$6:$J$21,9,FALSE())>=Elev_Score,"Elevated","Standard") -> Standard | N27: =IF(K27="Missing",0,IF(H27="Automated",1,MIN(L27,VLOOKUP(I27,Sampling_Table,IF(M27="Elevated",3,2),FALSE())))) -> 2 | O27: 0 | P27: =IFERROR(O27/N27,0) -> 0 | Q27: =IF(M27="Elevated",Tol_Elev,Tol_Std) -> 0.1 | R27: =IF(K27="Missing","Not operating",IF(O27=0,"Effective",IF(AND(N27>5,P27<=Q27),"Effective with exceptions","Ineffective"))) -> Effective | S27: =IF(OR(K27="Missing",R27="Ineffective",R27="Not operating"),"Ineffective",IF(K27="Needs improvement","Needs improvement",R27)) -> Effective | T27: =VLOOKUP(S27,Factor_Table,2,FALSE()) -> 0.5
B28: C23 | C28: R15 | D28: =VLOOKUP(C28,Risks!$B$6:$C$21,2,FALSE()) -> P9 | E28: Year-end cut-off test of the last five days of shipments | F28: Finance Manager | G28: Detective | H28: Manual | I28: Annual | J28: N | K28: Effective | L28: 1 | M28: =IF(VLOOKUP(C28,Risks!$B$6:$J$21,9,FALSE())>=Elev_Score,"Elevated","Standard") -> Standard | N28: =IF(K28="Missing",0,IF(H28="Automated",1,MIN(L28,VLOOKUP(I28,Sampling_Table,IF(M28="Elevated",3,2),FALSE())))) -> 1 | O28: 0 | P28: =IFERROR(O28/N28,0) -> 0 | Q28: =IF(M28="Elevated",Tol_Elev,Tol_Std) -> 0.1 | R28: =IF(K28="Missing","Not operating",IF(O28=0,"Effective",IF(AND(N28>5,P28<=Q28),"Effective with exceptions","Ineffective"))) -> Effective | S28: =IF(OR(K28="Missing",R28="Ineffective",R28="Not operating"),"Ineffective",IF(K28="Needs improvement","Needs improvement",R28)) -> Effective | T28: =VLOOKUP(S28,Factor_Table,2,FALSE()) -> 0.5
B29: C24 | C29: R16 | D29: =VLOOKUP(C29,Risks!$B$6:$C$21,2,FALSE()) -> P9 | E29: Quarterly statements of account circularised to the top 20 customers | F29: Credit Officer | G29: Detective | H29: Manual | I29: Quarterly | J29: N | K29: Effective | L29: 3 | M29: =IF(VLOOKUP(C29,Risks!$B$6:$J$21,9,FALSE())>=Elev_Score,"Elevated","Standard") -> Standard | N29: =IF(K29="Missing",0,IF(H29="Automated",1,MIN(L29,VLOOKUP(I29,Sampling_Table,IF(M29="Elevated",3,2),FALSE())))) -> 2 | O29: 0 | P29: =IFERROR(O29/N29,0) -> 0 | Q29: =IF(M29="Elevated",Tol_Elev,Tol_Std) -> 0.1 | R29: =IF(K29="Missing","Not operating",IF(O29=0,"Effective",IF(AND(N29>5,P29<=Q29),"Effective with exceptions","Ineffective"))) -> Effective | S29: =IF(OR(K29="Missing",R29="Ineffective",R29="Not operating"),"Ineffective",IF(K29="Needs improvement","Needs improvement",R29)) -> Effective | T29: =VLOOKUP(S29,Factor_Table,2,FALSE()) -> 0.5
E31: Blue cells are inputs (design assessment, population, exceptions found). Sample sizes, results and ratings are formulas driven by the Sampling_Guide and Inputs sheets.

Sheet Findings
B1: Findings, Deficiency Evaluation and Remediation Tracking
B2: Sampaguita Foods & Distribution Corporation (SFDC) | PHP in thousands | Order-to-cash (sales cycle) | Classification follows the rules on Inputs (materiality and likelihood)
B3: =HYPERLINK("#Cover!A1","◄ Back to Cover") -> ◄ Back to Cover
B5: ID | C5: Step | D5: Controls | E5: Finding | F5: Condition (what we found) | G5: Root cause | H5: Likelihood | I5: Magnitude (PHP '000) | J5: Compensating control? | K5: Base classification | L5: Final classification | M5: Priority | N5: Recommendation | O5: Owner | P5: Working days | Q5: Due date | R5: Status | S5: Days to due | T5: Tracking | U5: Management response
B6: F01 | C6: P4 | D6: C02, C08 | E6: Credit-limit approvals and override monitoring are not consistently evidenced | F6: Two of 12 weekly approvals tested show limits above PHP 500,000 activated without Finance Manager sign-off, and three of 12 weekly reviews of credit-limit overrides were not performed or not evidenced. At 30 September 2026, 12 customers exceeded their limits by an aggregate PHP 3.8 million. | G6: Approval relies on e-mail and verbal clearance; the override report is not scheduled and has no named backup reviewer. | H6: Reasonably possible | I6: 3800 | J6: No | K6: =IF(H6="Remote","Control deficiency",IF(I6>=Materiality,"Material weakness",IF(OR(I6>=SD_Factor*Materiality,AND(H6="Probable",I6>=Trivial_Factor*Materiality)),"Significant deficiency","Control deficiency"))) -> Significant deficiency | L6: =IF(J6="Yes",IF(K6="Material weakness","Significant deficiency",IF(K6="Significant deficiency","Control deficiency",K6)),K6) -> Significant deficiency | M6: =IF(L6="Material weakness","High",IF(L6="Significant deficiency","Medium","Low")) -> Medium | N6: Require approval within the credit system (no activation without an approval record), schedule the override report every Monday with a named backup reviewer, and escalate repeat overrides to the Finance Manager. | O6: Finance Manager | P6: =IF(L6="Material weakness",WD_MW,IF(L6="Significant deficiency",WD_SD,WD_CD)) -> 40 | Q6: =WORKDAY(Report_Date,P6,Holidays) -> 46353 | R6: In progress | S6: =IF(R6="Closed","",NETWORKDAYS(As_Of,Q6,Holidays)-1) -> 38 | T6: =IF(R6="Closed","✔ Closed",IF(S6<0,"✖ Overdue",IF(S6<=Soon_WD,"● Due soon","▲ On track"))) -> ▲ On track | U6: Accepted. System-enforced approval will be configured with IT; the override report will be scheduled from 12 October 2026.
B7: F02 | C7: P6 | D7: C13 | E7: Invoices are released without a signed delivery receipt | F7: Four of 30 invoices tested were issued without a signed delivery receipt on file (two receipts were signed after the invoice date). Extrapolating the 13% deviation rate to the population indicates potential revenue overstatement of about PHP 5.2 million. | G7: Billing releases invoices from the dispatch record when drivers return receipts late; no hold is applied in the system. | H7: Probable | I7: 5200 | J7: No | K7: =IF(H7="Remote","Control deficiency",IF(I7>=Materiality,"Material weakness",IF(OR(I7>=SD_Factor*Materiality,AND(H7="Probable",I7>=Trivial_Factor*Materiality)),"Significant deficiency","Control deficiency"))) -> Material weakness | L7: =IF(J7="Yes",IF(K7="Material weakness","Significant deficiency",IF(K7="Significant deficiency","Control deficiency",K7)),K7) -> Material weakness | M7: =IF(L7="Material weakness","High",IF(L7="Significant deficiency","Medium","Low")) -> High | N7: Block invoice release in the billing system until a scanned signed delivery receipt is attached; report outstanding receipts daily to the Warehouse Manager; add receipt return time to driver performance measures. | O7: Billing Supervisor | P7: =IF(L7="Material weakness",WD_MW,IF(L7="Significant deficiency",WD_SD,WD_CD)) -> 20 | Q7: =WORKDAY(Report_Date,P7,Holidays) -> 46325 | R7: In progress | S7: =IF(R7="Closed","",NETWORKDAYS(As_Of,Q7,Holidays)-1) -> 18 | T7: =IF(R7="Closed","✔ Closed",IF(S7<0,"✖ Overdue",IF(S7<=Soon_WD,"● Due soon","▲ On track"))) -> ▲ On track | U7: Accepted. Billing hold will be configured by 30 October 2026 and daily outstanding-receipt reporting starts immediately.
B8: F03 | C8: P7 | D8: C14 | E8: No reconciliation of deliveries to invoices (unbilled revenue) | F8: No daily or periodic reconciliation of delivery receipts to invoices is performed or documented. Re-performance for September found seven delivery receipts, totalling PHP 0.9 million, still unbilled after 30 days. | G8: The control was dropped when the billing team was reorganised and was never formalised in the procedures. | H8: Reasonably possible | I8: 950 | J8: No | K8: =IF(H8="Remote","Control deficiency",IF(I8>=Materiality,"Material weakness",IF(OR(I8>=SD_Factor*Materiality,AND(H8="Probable",I8>=Trivial_Factor*Materiality)),"Significant deficiency","Control deficiency"))) -> Control deficiency | L8: =IF(J8="Yes",IF(K8="Material weakness","Significant deficiency",IF(K8="Significant deficiency","Control deficiency",K8)),K8) -> Control deficiency | M8: =IF(L8="Material weakness","High",IF(L8="Significant deficiency","Medium","Low")) -> Low | N8: Re-establish the daily reconciliation with a standard template, require supervisor sign-off, and produce an aged unbilled report for the month-end close. | O8: Billing Supervisor | P8: =IF(L8="Material weakness",WD_MW,IF(L8="Significant deficiency",WD_SD,WD_CD)) -> 60 | Q8: =WORKDAY(Report_Date,P8,Holidays) -> 46392 | R8: Open | S8: =IF(R8="Closed","",NETWORKDAYS(As_Of,Q8,Holidays)-1) -> 58 | T8: =IF(R8="Closed","✔ Closed",IF(S8<0,"✖ Overdue",IF(S8<=Soon_WD,"● Due soon","▲ On track"))) -> ▲ On track | U8: Accepted. Template and sign-off to be implemented in October 2026.
B9: F04 | C9: P8 | D9: C18 | E9: Collections are not always deposited intact and daily | F9: Three of 30 daily deposits tested were made one to three days late, with cash held in the office safe overnight and over a weekend. | G9: Armored-courier pick-ups are scheduled only three times a week, and branch cut-off times are not enforced. | H9: Probable | I9: 800 | J9: No | K9: =IF(H9="Remote","Control deficiency",IF(I9>=Materiality,"Material weakness",IF(OR(I9>=SD_Factor*Materiality,AND(H9="Probable",I9>=Trivial_Factor*Materiality)),"Significant deficiency","Control deficiency"))) -> Significant deficiency | L9: =IF(J9="Yes",IF(K9="Material weakness","Significant deficiency",IF(K9="Significant deficiency","Control deficiency",K9)),K9) -> Significant deficiency | M9: =IF(L9="Material weakness","High",IF(L9="Significant deficiency","Medium","Low")) -> Medium | N9: Move to daily deposits or courier pick-ups, enforce a deposit cut-off, and have the independent reviewer investigate any deposit older than one banking day. | O9: Treasury Officer | P9: =IF(L9="Material weakness",WD_MW,IF(L9="Significant deficiency",WD_SD,WD_CD)) -> 40 | Q9: =WORKDAY(Report_Date,P9,Holidays) -> 46353 | R9: In progress | S9: =IF(R9="Closed","",NETWORKDAYS(As_Of,Q9,Holidays)-1) -> 38 | T9: =IF(R9="Closed","✔ Closed",IF(S9<0,"✖ Overdue",IF(S9<=Soon_WD,"● Due soon","▲ On track"))) -> ▲ On track | U9: Accepted. Courier contract is being renegotiated for daily pick-up.
B10: F05 | C10: P8 | D10: C19 | E10: Cash application lacks segregation of duties | F10: One accounting user profile can both post customer receipts and adjust customer balances (write-offs and credit entries). No exceptions were found in the sample, but the access design allows concealment of misappropriation. | G10: User roles were set up during the system roll-out and have not been recertified. | H10: Reasonably possible | I10: 2100 | J10: No | K10: =IF(H10="Remote","Control deficiency",IF(I10>=Materiality,"Material weakness",IF(OR(I10>=SD_Factor*Materiality,AND(H10="Probable",I10>=Trivial_Factor*Materiality)),"Significant deficiency","Control deficiency"))) -> Significant deficiency | L10: =IF(J10="Yes",IF(K10="Material weakness","Significant deficiency",IF(K10="Significant deficiency","Control deficiency",K10)),K10) -> Significant deficiency | M10: =IF(L10="Material weakness","High",IF(L10="Significant deficiency","Medium","Low")) -> Medium | N10: Remove balance-adjustment rights from the cash-application profile, perform a quarterly user-access recertification, and add a detective report of all manual balance adjustments for the Finance Manager. | O10: IT Manager | P10: =IF(L10="Material weakness",WD_MW,IF(L10="Significant deficiency",WD_SD,WD_CD)) -> 40 | Q10: =WORKDAY(Report_Date,P10,Holidays) -> 46353 | R10: Open | S10: =IF(R10="Closed","",NETWORKDAYS(As_Of,Q10,Holidays)-1) -> 38 | T10: =IF(R10="Closed","✔ Closed",IF(S10<0,"✖ Overdue",IF(S10<=Soon_WD,"● Due soon","▲ On track"))) -> ▲ On track | U10: Accepted. Profile changes planned for the next system maintenance window.
B11: F06 | C11: P9 | D11: C20 | E11: Credit notes are sometimes approved after issue | F11: Two of 8 credit notes tested were approved after being issued, and the return authorisation was not attached to one of them. | G11: Urgent customer requests are processed first and approved retrospectively. | H11: Reasonably possible | I11: 640 | J11: No | K11: =IF(H11="Remote","Control deficiency",IF(I11>=Materiality,"Material weakness",IF(OR(I11>=SD_Factor*Materiality,AND(H11="Probable",I11>=Trivial_Factor*Materiality)),"Significant deficiency","Control deficiency"))) -> Control deficiency | L11: =IF(J11="Yes",IF(K11="Material weakness","Significant deficiency",IF(K11="Significant deficiency","Control deficiency",K11)),K11) -> Control deficiency | M11: =IF(L11="Material weakness","High",IF(L11="Significant deficiency","Medium","Low")) -> Low | N11: Lock credit-note posting until the approval status is recorded in the system and require the return authorisation reference as a mandatory field. | O11: Sales Supervisor | P11: =IF(L11="Material weakness",WD_MW,IF(L11="Significant deficiency",WD_SD,WD_CD)) -> 60 | Q11: =WORKDAY(Report_Date,P11,Holidays) -> 46392 | R11: Open | S11: =IF(R11="Closed","",NETWORKDAYS(As_Of,Q11,Holidays)-1) -> 58 | T11: =IF(R11="Closed","✔ Closed",IF(S11<0,"✖ Overdue",IF(S11<=Soon_WD,"● Due soon","▲ On track"))) -> ▲ On track | U11: Accepted. Mandatory fields to be configured in the next system update.
