Workbook

Sheet Cover
B2: PORTFOLIO PROJECT 02
B3: Ratio Analysis Dashboard
B4: Sampaguita Foods & Distribution Corporation (SFDC)
B5: Benchmark scoring, DuPont, covenant and credit-risk analysis built on the Project 1 financial statements
B7: Prepared by Bengie Hirnani | Version 1.0 | PHP in thousands
B10: Model status | C10: =Model_Status -> ✔ All 20 integrity checks passed
B11: Scope | C11: 35 ratios, a weighted 0-100 benchmark scorecard with selectable benchmark sets, five-step DuPont with attribution, Altman Z''-score, bank covenant headroom, what-if sensitivity and an interactive dashboard with 8 charts.
B12: Data notice | C12: The company and its figures are fictional and tie to the Project 1 workbook (control totals on Checks). Benchmarks are illustrative - replace with peer or lender data.
B14: NAVIGATION - click a button to jump to a sheet
B15: DASHBOARD
B16: =HYPERLINK("#Dashboard!A1","Dashboard") -> Dashboard | C16: Executive ratio dashboard with year selector, health score and 8 charts
B18: ANALYSIS
B19: =HYPERLINK("#Ratios!A1","Ratios") -> Ratios | C19: 35 ratios across profitability, liquidity, solvency, efficiency and cash flow
B20: =HYPERLINK("#Scorecard!A1","Scorecard") -> Scorecard | C20: Weighted benchmark scoring (0-100), category scores and letter grade
B21: =HYPERLINK("#DuPont!A1","DuPont") -> DuPont | C21: Five-step DuPont analysis with driver attribution of ROE change
B22: =HYPERLINK("#Credit_Risk!A1","Credit Risk") -> Credit Risk | C22: Altman Z''-score and bank covenant compliance with headroom
B23: =HYPERLINK("#Sensitivity!A1","Sensitivity") -> Sensitivity | C23: What-if analysis: sales, margin, opex, DSO, DIO and interest rate shocks
B25: DATA AND CONTROLS
B26: =HYPERLINK("#FS_Data!A1","FS Data") -> FS Data | C26: Condensed financial statements from Project 1 (inputs)
B27: =HYPERLINK("#Benchmarks!A1","Benchmarks") -> Benchmarks | C27: Three benchmark sets, weights and direction
B28: =HYPERLINK("#Chart_Data!A1","Chart Data") -> Chart Data | C28: Helper tables for dashboard charts
B29: =HYPERLINK("#Lists!A1","Lists") -> Lists | C29: Drop-down lists and grade table
B30: =HYPERLINK("#Checks!A1","Checks") -> Checks | C30: Model integrity checks
B31: =HYPERLINK("#Documentation!A1","Documentation") -> Documentation | C31: Purpose, method, conventions, how to update

Sheet Documentation
B1: Model Documentation
B2: Sampaguita Foods & Distribution Corporation (SFDC) | PHP in thousands
B3: =HYPERLINK("#Cover!A1","◄ Back to Cover") -> ◄ Back to Cover
B5: 1. PURPOSE
B6: Objective | C6: Turn the Project 1 financial statements into a decision-ready ratio dashboard: what the ratios say, how they compare with a benchmark, why return on equity moved, how close the company is to bank covenants, and what happens under stress.
B7: Source data | C7: FS_Data holds condensed statements copied from the Project 1 workbook (blue cells). Subtotals are recalculated here and reconciled to Project 1 control totals on Checks.
B9: 2. HOW IT WORKS
B10: Ratios | C10: 35 ratios in five families, each with its definition. Averages use opening and closing balances.
B11: Scorecard | C11: Each of 17 key ratios is scored 0-100 (100 when the benchmark is met, scaled proportionally otherwise), weighted, rolled up to four category scores and an overall score with a letter grade. Choose the benchmark set on the Scorecard sheet.
B12: DuPont | C12: ROE is split into tax burden, interest burden, EBIT margin, asset turnover and equity multiplier. The change between any two years is attributed to each driver with an exact log-decomposition.
B13: Credit risk | C13: Altman Z''-score (emerging-market model) and four illustrative bank covenants with headroom and early-warning colouring.
B14: Sensitivity | C14: Shock net sales, gross margin, operating expenses, DSO, DIO and interest rates to see pro-forma ratios and covenant tests.
B16: 3. CONVENTIONS
B17: Colours | C17: Blue = input; black = formula; green = link to another sheet; yellow fill = selector or key assumption.
B18: Signs | C18: Expenses are negative in FS_Data (as in Project 1) and positive inside ratio formulas where noted.
B19: Controls | C19: Drop-downs for year, benchmark set and DuPont years; data validation on weights and direction; IFERROR on every ratio; model-status banner from the Checks sheet.
B21: 4. HOW TO UPDATE
B22: New data | C22: Overwrite the blue cells on FS_Data with new statements (or a different company) and keep the Checks banner green.
B23: Benchmarks | C23: Edit the Benchmarks sheet - weights, direction and the three reference sets.
B24: Google Sheets | C24: The workbook uses standard functions only (no macros), so it opens in Google Sheets; re-apply the chart styling if needed.

Sheet Dashboard
B1: Ratio Analysis Dashboard
B2: Sampaguita Foods & Distribution Corporation (SFDC) | PHP in thousands
B3: =HYPERLINK("#Cover!A1","◄ Back to Cover") -> ◄ Back to Cover
B5: Fiscal year | C5: 2025 | E5: Benchmark set | F5: =Bench_Set -> Top quartile | H5: Model integrity | I5: =Model_Status -> ✔ All 20 integrity checks passed
B7: FINANCIAL HEALTH SCORE | E7: RETURN ON EQUITY | H7: NET PROFIT MARGIN | K7: CURRENT RATIO
B8: =INDEX(Scorecard!$J$33:$L$33,MATCH(Dash_Year,Scorecard!$J$9:$L$9,0)) -> 84.330902 | E8: =INDEX(Ratios!$D$12:$F$12,MATCH(Dash_Year,Ratios!$D$5:$F$5,0)) -> 0.16164384 | H8: =INDEX(Ratios!$D$10:$F$10,MATCH(Dash_Year,Ratios!$D$5:$F$5,0)) -> 0.038466047 | K8: =INDEX(Ratios!$D$15:$F$15,MATCH(Dash_Year,Ratios!$D$5:$F$5,0)) -> 1.7551507
B9: ="Grade "&INDEX(Scorecard!$J$34:$L$34,MATCH(Dash_Year,Scorecard!$J$9:$L$9,0))&" - "&INDEX(Scorecard!$J$35:$L$35,MATCH(Dash_Year,Scorecard!$J$9:$L$9,0)) -> Grade B - Good | E9: =IF(IF(Scorecard!$F$14="Higher",INDEX(Ratios!$D$12:$F$12,MATCH(Dash_Year,Ratios!$D$5:$F$5,0))>=Scorecard!$E$14,INDEX(Ratios!$D$12:$F$12,MATCH(Dash_Year,Ratios!$D$5:$F$5,0))<=Scorecard!$E$14),"✔ Meets benchmark (",IF(IF(Scorecard!$F$14="Higher",INDEX(Ratios!$D$12:$F$12,MATCH(Dash_Year,Ratios!$D$5:$F$5,0))>=0.8*Scorecard!$E$14,INDEX(Ratios!$D$12:$F$12,MATCH(Dash_Year,Ratios!$D$5:$F$5,0))<=1.25*Scorecard!$E$14),"● Within 20% of benchmark (","✖ Misses benchmark ("))&TEXT(Scorecard!$E$14,"0.0%")&")" -> ● Within 20% of benchmark (20.0%) | H9: =IF(IF(Scorecard!$F$12="Higher",INDEX(Ratios!$D$10:$F$10,MATCH(Dash_Year,Ratios!$D$5:$F$5,0))>=Scorecard!$E$12,INDEX(Ratios!$D$10:$F$10,MATCH(Dash_Year,Ratios!$D$5:$F$5,0))<=Scorecard!$E$12),"✔ Meets benchmark (",IF(IF(Scorecard!$F$12="Higher",INDEX(Ratios!$D$10:$F$10,MATCH(Dash_Year,Ratios!$D$5:$F$5,0))>=0.8*Scorecard!$E$12,INDEX(Ratios!$D$10:$F$10,MATCH(Dash_Year,Ratios!$D$5:$F$5,0))<=1.25*Scorecard!$E$12),"● Within 20% of benchmark (","✖ Misses benchmark ("))&TEXT(Scorecard!$E$12,"0.0%")&")" -> ✖ Misses benchmark (5.0%) | K9: =IF(IF(Scorecard!$F$15="Higher",INDEX(Ratios!$D$15:$F$15,MATCH(Dash_Year,Ratios!$D$5:$F$5,0))>=Scorecard!$E$15,INDEX(Ratios!$D$15:$F$15,MATCH(Dash_Year,Ratios!$D$5:$F$5,0))<=Scorecard!$E$15),"✔ Meets benchmark (",IF(IF(Scorecard!$F$15="Higher",INDEX(Ratios!$D$15:$F$15,MATCH(Dash_Year,Ratios!$D$5:$F$5,0))>=0.8*Scorecard!$E$15,INDEX(Ratios!$D$15:$F$15,MATCH(Dash_Year,Ratios!$D$5:$F$5,0))<=1.25*Scorecard!$E$15),"● Within 20% of benchmark (","✖ Misses benchmark ("))&TEXT(Scorecard!$E$15,"0.00")&")" -> ● Within 20% of benchmark (2.00)
B11: BORROWINGS-TO-EQUITY | E11: INTEREST COVER | H11: CASH CONVERSION CYCLE (DAYS) | K11: ALTMAN Z''-SCORE
B12: =INDEX(Ratios!$D$21:$F$21,MATCH(Dash_Year,Ratios!$D$5:$F$5,0)) -> 0.54396283 | E12: =INDEX(Ratios!$D$25:$F$25,MATCH(Dash_Year,Ratios!$D$5:$F$5,0)) -> 5.1969049 | H12: =INDEX(Ratios!$D$36:$F$36,MATCH(Dash_Year,Ratios!$D$5:$F$5,0)) -> 35.995818 | K12: =INDEX(Credit_Risk!$D$11:$F$11,MATCH(Dash_Year,Credit_Risk!$D$5:$F$5,0)) -> 7.5362232
B13: =IF(IF(Scorecard!$F$19="Higher",INDEX(Ratios!$D$21:$F$21,MATCH(Dash_Year,Ratios!$D$5:$F$5,0))>=Scorecard!$E$19,INDEX(Ratios!$D$21:$F$21,MATCH(Dash_Year,Ratios!$D$5:$F$5,0))<=Scorecard!$E$19),"✔ Meets benchmark (",IF(IF(Scorecard!$F$19="Higher",INDEX(Ratios!$D$21:$F$21,MATCH(Dash_Year,Ratios!$D$5:$F$5,0))>=0.8*Scorecard!$E$19,INDEX(Ratios!$D$21:$F$21,MATCH(Dash_Year,Ratios!$D$5:$F$5,0))<=1.25*Scorecard!$E$19),"● Within 20% of benchmark (","✖ Misses benchmark ("))&TEXT(Scorecard!$E$19,"0.00")&")" -> ● Within 20% of benchmark (0.50) | E13: =IF(IF(Scorecard!$F$21="Higher",INDEX(Ratios!$D$25:$F$25,MATCH(Dash_Year,Ratios!$D$5:$F$5,0))>=Scorecard!$E$21,INDEX(Ratios!$D$25:$F$25,MATCH(Dash_Year,Ratios!$D$5:$F$5,0))<=Scorecard!$E$21),"✔ Meets benchmark (",IF(IF(Scorecard!$F$21="Higher",INDEX(Ratios!$D$25:$F$25,MATCH(Dash_Year,Ratios!$D$5:$F$5,0))>=0.8*Scorecard!$E$21,INDEX(Ratios!$D$25:$F$25,MATCH(Dash_Year,Ratios!$D$5:$F$5,0))<=1.25*Scorecard!$E$21),"● Within 20% of benchmark (","✖ Misses benchmark ("))&TEXT(Scorecard!$E$21,"0.0")&")" -> ✖ Misses benchmark (7.0) | H13: =IF(IF(Scorecard!$F$25="Higher",INDEX(Ratios!$D$36:$F$36,MATCH(Dash_Year,Ratios!$D$5:$F$5,0))>=Scorecard!$E$25,INDEX(Ratios!$D$36:$F$36,MATCH(Dash_Year,Ratios!$D$5:$F$5,0))<=Scorecard!$E$25),"✔ Meets benchmark (",IF(IF(Scorecard!$F$25="Higher",INDEX(Ratios!$D$36:$F$36,MATCH(Dash_Year,Ratios!$D$5:$F$5,0))>=0.8*Scorecard!$E$25,INDEX(Ratios!$D$36:$F$36,MATCH(Dash_Year,Ratios!$D$5:$F$5,0))<=1.25*Scorecard!$E$25),"● Within 20% of benchmark (","✖ Misses benchmark ("))&TEXT(Scorecard!$E$25,"0")&")" -> ✖ Misses benchmark (25) | K13: ="Zone: "&INDEX(Credit_Risk!$D$12:$F$12,MATCH(Dash_Year,Credit_Risk!$D$5:$F$5,0)) -> Zone: Safe
B80: KEY INSIGHTS (update automatically with the selected year)
B81: ="1. Financial health score is "&TEXT(INDEX(Scorecard!$J$33:$L$33,MATCH(Dash_Year,Scorecard!$J$9:$L$9,0)),"0.0")&" out of 100 against the "&Bench_Set&" benchmark set (grade "&INDEX(Scorecard!$J$34:$L$34,MATCH(Dash_Year,Scorecard!$J$9:$L$9,0))&")." -> 1. Financial health score is 84.3 out of 100 against the Top quartile benchmark set (grade B).
B82: ="2. Profitability: gross margin "&TEXT(INDEX(Ratios!$D$7:$F$7,MATCH(Dash_Year,Ratios!$D$5:$F$5,0)),"0.0%")&", net margin "&TEXT(INDEX(Ratios!$D$10:$F$10,MATCH(Dash_Year,Ratios!$D$5:$F$5,0)),"0.0%")&" and ROE "&TEXT(INDEX(Ratios!$D$12:$F$12,MATCH(Dash_Year,Ratios!$D$5:$F$5,0)),"0.0%")&"." -> 2. Profitability: gross margin 25.7%, net margin 3.8% and ROE 16.2%.
B83: ="3. Liquidity: current ratio "&TEXT(INDEX(Ratios!$D$15:$F$15,MATCH(Dash_Year,Ratios!$D$5:$F$5,0)),"0.00")&"x and quick ratio "&TEXT(INDEX(Ratios!$D$16:$F$16,MATCH(Dash_Year,Ratios!$D$5:$F$5,0)),"0.00")&"x; cash conversion cycle "&TEXT(INDEX(Ratios!$D$36:$F$36,MATCH(Dash_Year,Ratios!$D$5:$F$5,0)),"0")&" days." -> 3. Liquidity: current ratio 1.76x and quick ratio 1.13x; cash conversion cycle 36 days.
B84: ="4. Leverage: borrowings-to-equity "&TEXT(INDEX(Ratios!$D$21:$F$21,MATCH(Dash_Year,Ratios!$D$5:$F$5,0)),"0.00")&"x, interest cover "&TEXT(INDEX(Ratios!$D$25:$F$25,MATCH(Dash_Year,Ratios!$D$5:$F$5,0)),"0.0")&"x, net debt "&TEXT(INDEX(Ratios!$D$27:$F$27,MATCH(Dash_Year,Ratios!$D$5:$F$5,0)),"0.0")&"x EBITDA." -> 4. Leverage: borrowings-to-equity 0.54x, interest cover 5.2x, net debt 0.6x EBITDA.
B85: ="5. Credit risk: Altman Z''-score of "&TEXT(INDEX(Credit_Risk!$D$11:$F$11,MATCH(Dash_Year,Credit_Risk!$D$5:$F$5,0)),"0.00")&" places the company in the "&INDEX(Credit_Risk!$D$12:$F$12,MATCH(Dash_Year,Credit_Risk!$D$5:$F$5,0))&" zone." -> 5. Credit risk: Altman Z''-score of 7.54 places the company in the Safe zone.

Sheet Ratios
B1: Ratio Analysis
B2: Sampaguita Foods & Distribution Corporation (SFDC) | PHP in thousands | Averages use opening and closing balances
B3: =HYPERLINK("#Cover!A1","◄ Back to Cover") -> ◄ Back to Cover
B5: Ratio | C5: Category | D5: =FS_Data!D$5 -> 2023 | E5: =FS_Data!E$5 -> 2024 | F5: =FS_Data!F$5 -> 2025 | G5: Change FY25 vs FY24 | H5: Definition
B6: PROFITABILITY
B7: Gross profit margin | C7: Profitability | D7: =IFERROR(FS_Data!D9/FS_Data!D7,0) -> 0.25226703 | E7: =IFERROR(FS_Data!E9/FS_Data!E7,0) -> 0.25487106 | F7: =IFERROR(FS_Data!F9/FS_Data!F7,0) -> 0.25697574 | G7: =F7-E7 -> 0.0021046775 | H7: Gross profit / net sales
B8: EBITDA margin | C8: Profitability | D8: =IFERROR(FS_Data!D17/FS_Data!D7,0) -> 0.069855977 | E8: =IFERROR(FS_Data!E17/FS_Data!E7,0) -> 0.076816853 | F8: =IFERROR(FS_Data!F17/FS_Data!F7,0) -> 0.084364929 | G8: =F8-E8 -> 0.0075480752 | H8: EBITDA / net sales
B9: Operating profit margin | C9: Profitability | D9: =IFERROR(FS_Data!D13/FS_Data!D7,0) -> 0.046547512 | E9: =IFERROR(FS_Data!E13/FS_Data!E7,0) -> 0.053835214 | F9: =IFERROR(FS_Data!F13/FS_Data!F7,0) -> 0.060397432 | G9: =F9-E9 -> 0.0065622182 | H9: Operating profit / net sales
B10: Net profit margin | C10: Profitability | D10: =IFERROR(FS_Data!D22/FS_Data!D7,0) -> 0.027379743 | E10: =IFERROR(FS_Data!E22/FS_Data!E7,0) -> 0.032331444 | F10: =IFERROR(FS_Data!F22/FS_Data!F7,0) -> 0.038466047 | G10: =F10-E10 -> 0.0061346035 | H10: Net profit / net sales
B11: Return on assets (average) | C11: Profitability | D11: =IFERROR(FS_Data!D22/AVERAGE(FS_Data!C32,FS_Data!D32),0) -> 0.054943027 | E11: =IFERROR(FS_Data!E22/AVERAGE(FS_Data!D32,FS_Data!E32),0) -> 0.06614987 | F11: =IFERROR(FS_Data!F22/AVERAGE(FS_Data!E32,FS_Data!F32),0) -> 0.07955685 | G11: =F11-E11 -> 0.01340698 | H11: Net profit / average total assets
B12: Return on equity (average) | C12: Profitability | D12: =IFERROR(FS_Data!D22/AVERAGE(FS_Data!C44,FS_Data!D44),0) -> 0.11950215 | E12: =IFERROR(FS_Data!E22/AVERAGE(FS_Data!D44,FS_Data!E44),0) -> 0.13984318 | F12: =IFERROR(FS_Data!F22/AVERAGE(FS_Data!E44,FS_Data!F44),0) -> 0.16164384 | G12: =F12-E12 -> 0.021800652 | H12: Net profit / average equity
B13: Return on capital employed | C13: Profitability | D13: =IFERROR(FS_Data!D16/(FS_Data!D32-FS_Data!D38),0) -> 0.14718977 | E13: =IFERROR(FS_Data!E16/(FS_Data!E32-FS_Data!E38),0) -> 0.15853861 | F13: =IFERROR(FS_Data!F16/(FS_Data!F32-FS_Data!F38),0) -> 0.1881815 | G13: =F13-E13 -> 0.029642888 | H13: EBIT / (total assets - current liabilities)
B14: LIQUIDITY
B15: Current ratio | C15: Liquidity | D15: =IFERROR(FS_Data!D29/FS_Data!D38,0) -> 1.575501 | E15: =IFERROR(FS_Data!E29/FS_Data!E38,0) -> 1.7609372 | F15: =IFERROR(FS_Data!F29/FS_Data!F38,0) -> 1.7551507 | G15: =F15-E15 -> -0.0057864202 | H15: Current assets / current liabilities
B16: Quick ratio | C16: Liquidity | D16: =IFERROR((FS_Data!D25+FS_Data!D26)/FS_Data!D38,0) -> 0.96928572 | E16: =IFERROR((FS_Data!E25+FS_Data!E26)/FS_Data!E38,0) -> 1.1371621 | F16: =IFERROR((FS_Data!F25+FS_Data!F26)/FS_Data!F38,0) -> 1.125644 | G16: =F16-E16 -> -0.011518082 | H16: (Cash + receivables) / current liabilities
B17: Cash ratio | C17: Liquidity | D17: =IFERROR(FS_Data!D25/FS_Data!D38,0) -> 0.40536438 | E17: =IFERROR(FS_Data!E25/FS_Data!E38,0) -> 0.54154103 | F17: =IFERROR(FS_Data!F25/FS_Data!F38,0) -> 0.52583573 | G17: =F17-E17 -> -0.0157053 | H17: Cash / current liabilities
B18: Working capital (PHP '000) | C18: Liquidity | D18: =FS_Data!D29-FS_Data!D38 -> 82650 | E18: =FS_Data!E29-FS_Data!E38 -> 113057 | F18: =FS_Data!F29-FS_Data!F38 -> 117398 | G18: =F18-E18 -> 4341 | H18: Current assets - current liabilities
B19: Operating cash flow ratio | C19: Liquidity | D19: =IFERROR(FS_Data!D49/FS_Data!D38,0) -> 0.22446976 | E19: =IFERROR(FS_Data!E49/FS_Data!E38,0) -> 0.29780045 | F19: =IFERROR(FS_Data!F49/FS_Data!F38,0) -> 0.37153535 | G19: =F19-E19 -> 0.073734897 | H19: Operating cash flow / current liabilities
B20: SOLVENCY AND COVERAGE
B21: Borrowings-to-equity | C21: Solvency | D21: =IFERROR(FS_Data!D46/FS_Data!D44,0) -> 0.69189717 | E21: =IFERROR(FS_Data!E46/FS_Data!E44,0) -> 0.6962321 | F21: =IFERROR(FS_Data!F46/FS_Data!F44,0) -> 0.54396283 | G21: =F21-E21 -> -0.15226927 | H21: Total borrowings / total equity
B22: Total liabilities-to-equity | C22: Solvency | D22: =IFERROR(FS_Data!D40/FS_Data!D44,0) -> 1.1121942 | E22: =IFERROR(FS_Data!E40/FS_Data!E44,0) -> 1.1156936 | F22: =IFERROR(FS_Data!F40/FS_Data!F44,0) -> 0.95689606 | G22: =F22-E22 -> -0.15879756 | H22: Total liabilities / total equity
B23: Debt ratio | C23: Solvency | D23: =IFERROR(FS_Data!D40/FS_Data!D32,0) -> 0.52655868 | E23: =IFERROR(FS_Data!E40/FS_Data!E32,0) -> 0.52734177 | F23: =IFERROR(FS_Data!F40/FS_Data!F32,0) -> 0.48898666 | G23: =F23-E23 -> -0.038355116 | H23: Total liabilities / total assets
B24: Equity ratio | C24: Solvency | D24: =IFERROR(FS_Data!D44/FS_Data!D32,0) -> 0.47344132 | E24: =IFERROR(FS_Data!E44/FS_Data!E32,0) -> 0.47265823 | F24: =IFERROR(FS_Data!F44/FS_Data!F32,0) -> 0.51101334 | G24: =F24-E24 -> 0.038355116 | H24: Total equity / total assets
B25: Interest cover | C25: Solvency | D25: =IFERROR(FS_Data!D16/-FS_Data!D19,0) -> 3.8356204 | E25: =IFERROR(FS_Data!E16/-FS_Data!E19,0) -> 4.3288017 | F25: =IFERROR(FS_Data!F16/-FS_Data!F19,0) -> 5.1969049 | G25: =F25-E25 -> 0.86810318 | H25: EBIT / finance costs
B26: EBITDA interest cover | C26: Solvency | D26: =IFERROR(FS_Data!D17/-FS_Data!D19,0) -> 5.5042702 | E26: =IFERROR(FS_Data!E17/-FS_Data!E19,0) -> 6.0063617 | F26: =IFERROR(FS_Data!F17/-FS_Data!F19,0) -> 7.0143639 | G26: =F26-E26 -> 1.0080022 | H26: EBITDA / finance costs
B27: Net debt / EBITDA | C27: Solvency | D27: =IFERROR((FS_Data!D46-FS_Data!D25)/FS_Data!D17,0) -> 1.3560669 | E27: =IFERROR((FS_Data!E46-FS_Data!E25)/FS_Data!E17,0) -> 1.0379699 | F27: =IFERROR((FS_Data!F46-FS_Data!F25)/FS_Data!F17,0) -> 0.62471965 | G27: =F27-E27 -> -0.41325026 | H27: (Borrowings - cash) / EBITDA
B28: Debt service cover ratio | C28: Solvency | D28: =IFERROR(FS_Data!D17/(-FS_Data!D19-FS_Data!D52),0) -> 2.5583159 | E28: =IFERROR(FS_Data!E17/(-FS_Data!E19-FS_Data!E52),0) -> 2.8160572 | F28: =IFERROR(FS_Data!F17/(-FS_Data!F19-FS_Data!F52),0) -> 3.0731196 | G28: =F28-E28 -> 0.25706237 | H28: EBITDA / (finance costs + principal repaid)
B29: EFFICIENCY
B30: Receivables turnover | C30: Efficiency | D30: =IFERROR(FS_Data!D7/AVERAGE(FS_Data!C26,FS_Data!D26),0) -> 10.805108 | E30: =IFERROR(FS_Data!E7/AVERAGE(FS_Data!D26,FS_Data!E26),0) -> 10.588003 | F30: =IFERROR(FS_Data!F7/AVERAGE(FS_Data!E26,FS_Data!F26),0) -> 10.701287 | G30: =F30-E30 -> 0.11328354 | H30: Net sales / average receivables
B31: Days sales outstanding | C31: Efficiency | D31: =IFERROR(365/D30,0) -> 33.780318 | E31: =IFERROR(365/E30,0) -> 34.472977 | F31: =IFERROR(365/F30,0) -> 34.108047 | G31: =F31-E31 -> -0.36493001 | H31: 365 / receivables turnover
B32: Inventory turnover | C32: Efficiency | D32: =IFERROR(-FS_Data!D8/AVERAGE(FS_Data!C27,FS_Data!D27),0) -> 8.1756771 | E32: =IFERROR(-FS_Data!E8/AVERAGE(FS_Data!D27,FS_Data!E27),0) -> 8.555407 | F32: =IFERROR(-FS_Data!F8/AVERAGE(FS_Data!E27,FS_Data!F27),0) -> 8.7203693 | G32: =F32-E32 -> 0.16496234 | H32: Cost of sales / average inventories
B33: Days inventory outstanding | C33: Efficiency | D33: =IFERROR(365/D32,0) -> 44.64462 | E33: =IFERROR(365/E32,0) -> 42.663079 | F33: =IFERROR(365/F32,0) -> 41.856025 | G33: =F33-E33 -> -0.80705311 | H33: 365 / inventory turnover
B34: Payables turnover | C34: Efficiency | D34: =IFERROR(-FS_Data!D8/AVERAGE(FS_Data!C33,FS_Data!D33),0) -> 9.4760505 | E34: =IFERROR(-FS_Data!E8/AVERAGE(FS_Data!D33,FS_Data!E33),0) -> 9.3909807 | F34: =IFERROR(-FS_Data!F8/AVERAGE(FS_Data!E33,FS_Data!F33),0) -> 9.1322476 | G34: =F34-E34 -> -0.25873302 | H34: Cost of sales / average payables
B35: Days payables outstanding | C35: Efficiency | D35: =IFERROR(365/D34,0) -> 38.518157 | E35: =IFERROR(365/E34,0) -> 38.86708 | F35: =IFERROR(365/F34,0) -> 39.968255 | G35: =F35-E35 -> 1.1011744 | H35: 365 / payables turnover
B36: Cash conversion cycle (days) | C36: Efficiency | D36: =D31+D33-D35 -> 39.906782 | E36: =E31+E33-E35 -> 38.268975 | F36: =F31+F33-F35 -> 35.995818 | G36: =F36-E36 -> -2.2731575 | H36: DSO + DIO - DPO
B37: Total asset turnover | C37: Efficiency | D37: =IFERROR(FS_Data!D7/AVERAGE(FS_Data!C32,FS_Data!D32),0) -> 2.0067035 | E37: =IFERROR(FS_Data!E7/AVERAGE(FS_Data!D32,FS_Data!E32),0) -> 2.0459918 | F37: =IFERROR(FS_Data!F7/AVERAGE(FS_Data!E32,FS_Data!F32),0) -> 2.0682356 | G37: =F37-E37 -> 0.022243821 | H37: Net sales / average total assets
B38: Fixed asset turnover | C38: Efficiency | D38: =IFERROR(FS_Data!D7/AVERAGE(FS_Data!C30,FS_Data!D30),0) -> 4.6468163 | E38: =IFERROR(FS_Data!E7/AVERAGE(FS_Data!D30,FS_Data!E30),0) -> 4.8700471 | F38: =IFERROR(FS_Data!F7/AVERAGE(FS_Data!E30,FS_Data!F30),0) -> 5.0613093 | G38: =F38-E38 -> 0.19126214 | H38: Net sales / average net PPE
B39: CASH FLOW QUALITY
B40: Free cash flow (PHP '000) | C40: Cash | D40: =FS_Data!D54 -> 10137 | E40: =FS_Data!E54 -> 13346 | F40: =FS_Data!F54 -> 30860 | G40: =F40-E40 -> 17514 | H40: Operating cash flow - capital expenditure
B41: Free cash flow margin | C41: Cash | D41: =IFERROR(FS_Data!D54/FS_Data!D7,0) -> 0.012345363 | E41: =IFERROR(FS_Data!E54/FS_Data!E7,0) -> 0.014874537 | F41: =IFERROR(FS_Data!F54/FS_Data!F7,0) -> 0.03173454 | G41: =F41-E41 -> 0.016860003 | H41: Free cash flow / net sales
...

Sheet Scorecard
B1: Benchmark Scorecard
B2: Sampaguita Foods & Distribution Corporation (SFDC) | PHP in thousands | Score = 100 when the benchmark is met, scaled down proportionally otherwise
B3: =HYPERLINK("#Cover!A1","◄ Back to Cover") -> ◄ Back to Cover
B5: Benchmark set | C5: Top quartile
B6: Set index (helper) | C6: =MATCH(Bench_Set,Benchmarks!$F$5:$H$5,0) -> 2
G8: Ratio value | J8: Score (0-100)
B9: Ratio | C9: Category | D9: Weight | E9: Benchmark | F9: Better if | G9: =FS_Data!D$5 -> 2023 | H9: =FS_Data!E$5 -> 2024 | I9: =FS_Data!F$5 -> 2025 | J9: =FS_Data!D$5 -> 2023 | K9: =FS_Data!E$5 -> 2024 | L9: =FS_Data!F$5 -> 2025
B10: =Benchmarks!B6 -> Gross profit margin | C10: =Benchmarks!C6 -> Profitability | D10: =Benchmarks!E6 -> 6 | E10: =INDEX(Benchmarks!F6:H6,Set_Idx) -> 0.3 | F10: =Benchmarks!D6 -> Higher | G10: =Ratios!D7 -> 0.25226703 | H10: =Ratios!E7 -> 0.25487106 | I10: =Ratios!F7 -> 0.25697574 | J10: =IFERROR(IF($F10="Higher",MIN(100,MAX(0,100*G10/$E10)),IF(G10<=0,100,MIN(100,MAX(0,100*$E10/G10)))),0) -> 84.08901 | K10: =IFERROR(IF($F10="Higher",MIN(100,MAX(0,100*H10/$E10)),IF(H10<=0,100,MIN(100,MAX(0,100*$E10/H10)))),0) -> 84.95702 | L10: =IFERROR(IF($F10="Higher",MIN(100,MAX(0,100*I10/$E10)),IF(I10<=0,100,MIN(100,MAX(0,100*$E10/I10)))),0) -> 85.658579
B11: =Benchmarks!B7 -> Operating profit margin | C11: =Benchmarks!C7 -> Profitability | D11: =Benchmarks!E7 -> 6 | E11: =INDEX(Benchmarks!F7:H7,Set_Idx) -> 0.075 | F11: =Benchmarks!D7 -> Higher | G11: =Ratios!D9 -> 0.046547512 | H11: =Ratios!E9 -> 0.053835214 | I11: =Ratios!F9 -> 0.060397432 | J11: =IFERROR(IF($F11="Higher",MIN(100,MAX(0,100*G11/$E11)),IF(G11<=0,100,MIN(100,MAX(0,100*$E11/G11)))),0) -> 62.063349 | K11: =IFERROR(IF($F11="Higher",MIN(100,MAX(0,100*H11/$E11)),IF(H11<=0,100,MIN(100,MAX(0,100*$E11/H11)))),0) -> 71.780286 | L11: =IFERROR(IF($F11="Higher",MIN(100,MAX(0,100*I11/$E11)),IF(I11<=0,100,MIN(100,MAX(0,100*$E11/I11)))),0) -> 80.52991
B12: =Benchmarks!B8 -> Net profit margin | C12: =Benchmarks!C8 -> Profitability | D12: =Benchmarks!E8 -> 6 | E12: =INDEX(Benchmarks!F8:H8,Set_Idx) -> 0.05 | F12: =Benchmarks!D8 -> Higher | G12: =Ratios!D10 -> 0.027379743 | H12: =Ratios!E10 -> 0.032331444 | I12: =Ratios!F10 -> 0.038466047 | J12: =IFERROR(IF($F12="Higher",MIN(100,MAX(0,100*G12/$E12)),IF(G12<=0,100,MIN(100,MAX(0,100*$E12/G12)))),0) -> 54.759486 | K12: =IFERROR(IF($F12="Higher",MIN(100,MAX(0,100*H12/$E12)),IF(H12<=0,100,MIN(100,MAX(0,100*$E12/H12)))),0) -> 64.662888 | L12: =IFERROR(IF($F12="Higher",MIN(100,MAX(0,100*I12/$E12)),IF(I12<=0,100,MIN(100,MAX(0,100*$E12/I12)))),0) -> 76.932095
B13: =Benchmarks!B9 -> Return on assets (average) | C13: =Benchmarks!C9 -> Profitability | D13: =Benchmarks!E9 -> 6 | E13: =INDEX(Benchmarks!F9:H9,Set_Idx) -> 0.1 | F13: =Benchmarks!D9 -> Higher | G13: =Ratios!D11 -> 0.054943027 | H13: =Ratios!E11 -> 0.06614987 | I13: =Ratios!F11 -> 0.07955685 | J13: =IFERROR(IF($F13="Higher",MIN(100,MAX(0,100*G13/$E13)),IF(G13<=0,100,MIN(100,MAX(0,100*$E13/G13)))),0) -> 54.943027 | K13: =IFERROR(IF($F13="Higher",MIN(100,MAX(0,100*H13/$E13)),IF(H13<=0,100,MIN(100,MAX(0,100*$E13/H13)))),0) -> 66.14987 | L13: =IFERROR(IF($F13="Higher",MIN(100,MAX(0,100*I13/$E13)),IF(I13<=0,100,MIN(100,MAX(0,100*$E13/I13)))),0) -> 79.55685
B14: =Benchmarks!B10 -> Return on equity (average) | C14: =Benchmarks!C10 -> Profitability | D14: =Benchmarks!E10 -> 6 | E14: =INDEX(Benchmarks!F10:H10,Set_Idx) -> 0.2 | F14: =Benchmarks!D10 -> Higher | G14: =Ratios!D12 -> 0.11950215 | H14: =Ratios!E12 -> 0.13984318 | I14: =Ratios!F12 -> 0.16164384 | J14: =IFERROR(IF($F14="Higher",MIN(100,MAX(0,100*G14/$E14)),IF(G14<=0,100,MIN(100,MAX(0,100*$E14/G14)))),0) -> 59.751077 | K14: =IFERROR(IF($F14="Higher",MIN(100,MAX(0,100*H14/$E14)),IF(H14<=0,100,MIN(100,MAX(0,100*$E14/H14)))),0) -> 69.921592 | L14: =IFERROR(IF($F14="Higher",MIN(100,MAX(0,100*I14/$E14)),IF(I14<=0,100,MIN(100,MAX(0,100*$E14/I14)))),0) -> 80.821918
B15: =Benchmarks!B11 -> Current ratio | C15: =Benchmarks!C11 -> Liquidity | D15: =Benchmarks!E11 -> 8 | E15: =INDEX(Benchmarks!F11:H11,Set_Idx) -> 2 | F15: =Benchmarks!D11 -> Higher | G15: =Ratios!D15 -> 1.575501 | H15: =Ratios!E15 -> 1.7609372 | I15: =Ratios!F15 -> 1.7551507 | J15: =IFERROR(IF($F15="Higher",MIN(100,MAX(0,100*G15/$E15)),IF(G15<=0,100,MIN(100,MAX(0,100*$E15/G15)))),0) -> 78.77505 | K15: =IFERROR(IF($F15="Higher",MIN(100,MAX(0,100*H15/$E15)),IF(H15<=0,100,MIN(100,MAX(0,100*$E15/H15)))),0) -> 88.046858 | L15: =IFERROR(IF($F15="Higher",MIN(100,MAX(0,100*I15/$E15)),IF(I15<=0,100,MIN(100,MAX(0,100*$E15/I15)))),0) -> 87.757537
B16: =Benchmarks!B12 -> Quick ratio | C16: =Benchmarks!C12 -> Liquidity | D16: =Benchmarks!E12 -> 7 | E16: =INDEX(Benchmarks!F12:H12,Set_Idx) -> 1.2 | F16: =Benchmarks!D12 -> Higher | G16: =Ratios!D16 -> 0.96928572 | H16: =Ratios!E16 -> 1.1371621 | I16: =Ratios!F16 -> 1.125644 | J16: =IFERROR(IF($F16="Higher",MIN(100,MAX(0,100*G16/$E16)),IF(G16<=0,100,MIN(100,MAX(0,100*$E16/G16)))),0) -> 80.77381 | K16: =IFERROR(IF($F16="Higher",MIN(100,MAX(0,100*H16/$E16)),IF(H16<=0,100,MIN(100,MAX(0,100*$E16/H16)))),0) -> 94.76351 | L16: =IFERROR(IF($F16="Higher",MIN(100,MAX(0,100*I16/$E16)),IF(I16<=0,100,MIN(100,MAX(0,100*$E16/I16)))),0) -> 93.80367
B17: =Benchmarks!B13 -> Operating cash flow ratio | C17: =Benchmarks!C13 -> Liquidity | D17: =Benchmarks!E13 -> 5 | E17: =INDEX(Benchmarks!F13:H13,Set_Idx) -> 0.5 | F17: =Benchmarks!D13 -> Higher | G17: =Ratios!D19 -> 0.22446976 | H17: =Ratios!E19 -> 0.29780045 | I17: =Ratios!F19 -> 0.37153535 | J17: =IFERROR(IF($F17="Higher",MIN(100,MAX(0,100*G17/$E17)),IF(G17<=0,100,MIN(100,MAX(0,100*$E17/G17)))),0) -> 44.893952 | K17: =IFERROR(IF($F17="Higher",MIN(100,MAX(0,100*H17/$E17)),IF(H17<=0,100,MIN(100,MAX(0,100*$E17/H17)))),0) -> 59.56009 | L17: =IFERROR(IF($F17="Higher",MIN(100,MAX(0,100*I17/$E17)),IF(I17<=0,100,MIN(100,MAX(0,100*$E17/I17)))),0) -> 74.30707
B18: =Benchmarks!B14 -> Cash ratio | C18: =Benchmarks!C14 -> Liquidity | D18: =Benchmarks!E14 -> 5 | E18: =INDEX(Benchmarks!F14:H14,Set_Idx) -> 0.5 | F18: =Benchmarks!D14 -> Higher | G18: =Ratios!D17 -> 0.40536438 | H18: =Ratios!E17 -> 0.54154103 | I18: =Ratios!F17 -> 0.52583573 | J18: =IFERROR(IF($F18="Higher",MIN(100,MAX(0,100*G18/$E18)),IF(G18<=0,100,MIN(100,MAX(0,100*$E18/G18)))),0) -> 81.072876 | K18: =IFERROR(IF($F18="Higher",MIN(100,MAX(0,100*H18/$E18)),IF(H18<=0,100,MIN(100,MAX(0,100*$E18/H18)))),0) -> 100 | L18: =IFERROR(IF($F18="Higher",MIN(100,MAX(0,100*I18/$E18)),IF(I18<=0,100,MIN(100,MAX(0,100*$E18/I18)))),0) -> 100
B19: =Benchmarks!B15 -> Borrowings-to-equity | C19: =Benchmarks!C15 -> Solvency | D19: =Benchmarks!E15 -> 7 | E19: =INDEX(Benchmarks!F15:H15,Set_Idx) -> 0.5 | F19: =Benchmarks!D15 -> Lower | G19: =Ratios!D21 -> 0.69189717 | H19: =Ratios!E21 -> 0.6962321 | I19: =Ratios!F21 -> 0.54396283 | J19: =IFERROR(IF($F19="Higher",MIN(100,MAX(0,100*G19/$E19)),IF(G19<=0,100,MIN(100,MAX(0,100*$E19/G19)))),0) -> 72.265074 | K19: =IFERROR(IF($F19="Higher",MIN(100,MAX(0,100*H19/$E19)),IF(H19<=0,100,MIN(100,MAX(0,100*$E19/H19)))),0) -> 71.815132 | L19: =IFERROR(IF($F19="Higher",MIN(100,MAX(0,100*I19/$E19)),IF(I19<=0,100,MIN(100,MAX(0,100*$E19/I19)))),0) -> 91.918045
B20: =Benchmarks!B16 -> Debt ratio | C20: =Benchmarks!C16 -> Solvency | D20: =Benchmarks!E16 -> 4 | E20: =INDEX(Benchmarks!F16:H16,Set_Idx) -> 0.45 | F20: =Benchmarks!D16 -> Lower | G20: =Ratios!D23 -> 0.52655868 | H20: =Ratios!E23 -> 0.52734177 | I20: =Ratios!F23 -> 0.48898666 | J20: =IFERROR(IF($F20="Higher",MIN(100,MAX(0,100*G20/$E20)),IF(G20<=0,100,MIN(100,MAX(0,100*$E20/G20)))),0) -> 85.460561 | K20: =IFERROR(IF($F20="Higher",MIN(100,MAX(0,100*H20/$E20)),IF(H20<=0,100,MIN(100,MAX(0,100*$E20/H20)))),0) -> 85.333654 | L20: =IFERROR(IF($F20="Higher",MIN(100,MAX(0,100*I20/$E20)),IF(I20<=0,100,MIN(100,MAX(0,100*$E20/I20)))),0) -> 92.027051
B21: =Benchmarks!B17 -> Interest cover | C21: =Benchmarks!C17 -> Solvency | D21: =Benchmarks!E17 -> 7 | E21: =INDEX(Benchmarks!F17:H17,Set_Idx) -> 7 | F21: =Benchmarks!D17 -> Higher | G21: =Ratios!D25 -> 3.8356204 | H21: =Ratios!E25 -> 4.3288017 | I21: =Ratios!F25 -> 5.1969049 | J21: =IFERROR(IF($F21="Higher",MIN(100,MAX(0,100*G21/$E21)),IF(G21<=0,100,MIN(100,MAX(0,100*$E21/G21)))),0) -> 54.794577 | K21: =IFERROR(IF($F21="Higher",MIN(100,MAX(0,100*H21/$E21)),IF(H21<=0,100,MIN(100,MAX(0,100*$E21/H21)))),0) -> 61.840025 | L21: =IFERROR(IF($F21="Higher",MIN(100,MAX(0,100*I21/$E21)),IF(I21<=0,100,MIN(100,MAX(0,100*$E21/I21)))),0) -> 74.241499
B22: =Benchmarks!B18 -> Debt service cover ratio | C22: =Benchmarks!C18 -> Solvency | D22: =Benchmarks!E18 -> 7 | E22: =INDEX(Benchmarks!F18:H18,Set_Idx) -> 3.5 | F22: =Benchmarks!D18 -> Higher | G22: =Ratios!D28 -> 2.5583159 | H22: =Ratios!E28 -> 2.8160572 | I22: =Ratios!F28 -> 3.0731196 | J22: =IFERROR(IF($F22="Higher",MIN(100,MAX(0,100*G22/$E22)),IF(G22<=0,100,MIN(100,MAX(0,100*$E22/G22)))),0) -> 73.094739 | K22: =IFERROR(IF($F22="Higher",MIN(100,MAX(0,100*H22/$E22)),IF(H22<=0,100,MIN(100,MAX(0,100*$E22/H22)))),0) -> 80.458777 | L22: =IFERROR(IF($F22="Higher",MIN(100,MAX(0,100*I22/$E22)),IF(I22<=0,100,MIN(100,MAX(0,100*$E22/I22)))),0) -> 87.803416
B23: =Benchmarks!B19 -> Days sales outstanding | C23: =Benchmarks!C19 -> Efficiency | D23: =Benchmarks!E19 -> 5 | E23: =INDEX(Benchmarks!F19:H19,Set_Idx) -> 30 | F23: =Benchmarks!D19 -> Lower | G23: =Ratios!D31 -> 33.780318 | H23: =Ratios!E31 -> 34.472977 | I23: =Ratios!F31 -> 34.108047 | J23: =IFERROR(IF($F23="Higher",MIN(100,MAX(0,100*G23/$E23)),IF(G23<=0,100,MIN(100,MAX(0,100*$E23/G23)))),0) -> 88.80911 | K23: =IFERROR(IF($F23="Higher",MIN(100,MAX(0,100*H23/$E23)),IF(H23<=0,100,MIN(100,MAX(0,100*$E23/H23)))),0) -> 87.024686 | L23: =IFERROR(IF($F23="Higher",MIN(100,MAX(0,100*I23/$E23)),IF(I23<=0,100,MIN(100,MAX(0,100*$E23/I23)))),0) -> 87.955783
B24: =Benchmarks!B20 -> Days inventory outstanding | C24: =Benchmarks!C20 -> Efficiency | D24: =Benchmarks!E20 -> 5 | E24: =INDEX(Benchmarks!F20:H20,Set_Idx) -> 35 | F24: =Benchmarks!D20 -> Lower | G24: =Ratios!D33 -> 44.64462 | H24: =Ratios!E33 -> 42.663079 | I24: =Ratios!F33 -> 41.856025 | J24: =IFERROR(IF($F24="Higher",MIN(100,MAX(0,100*G24/$E24)),IF(G24<=0,100,MIN(100,MAX(0,100*$E24/G24)))),0) -> 78.396904 | K24: =IFERROR(IF($F24="Higher",MIN(100,MAX(0,100*H24/$E24)),IF(H24<=0,100,MIN(100,MAX(0,100*$E24/H24)))),0) -> 82.038149 | L24: =IFERROR(IF($F24="Higher",MIN(100,MAX(0,100*I24/$E24)),IF(I24<=0,100,MIN(100,MAX(0,100*$E24/I24)))),0) -> 83.61998
B25: =Benchmarks!B21 -> Cash conversion cycle (days) | C25: =Benchmarks!C21 -> Efficiency | D25: =Benchmarks!E21 -> 5 | E25: =INDEX(Benchmarks!F21:H21,Set_Idx) -> 25 | F25: =Benchmarks!D21 -> Lower | G25: =Ratios!D36 -> 39.906782 | H25: =Ratios!E36 -> 38.268975 | I25: =Ratios!F36 -> 35.995818 | J25: =IFERROR(IF($F25="Higher",MIN(100,MAX(0,100*G25/$E25)),IF(G25<=0,100,MIN(100,MAX(0,100*$E25/G25)))),0) -> 62.645994 | K25: =IFERROR(IF($F25="Higher",MIN(100,MAX(0,100*H25/$E25)),IF(H25<=0,100,MIN(100,MAX(0,100*$E25/H25)))),0) -> 65.327069 | L25: =IFERROR(IF($F25="Higher",MIN(100,MAX(0,100*I25/$E25)),IF(I25<=0,100,MIN(100,MAX(0,100*$E25/I25)))),0) -> 69.452513
B26: =Benchmarks!B22 -> Total asset turnover | C26: =Benchmarks!C22 -> Efficiency | D26: =Benchmarks!E22 -> 5 | E26: =INDEX(Benchmarks!F22:H22,Set_Idx) -> 2.4 | F26: =Benchmarks!D22 -> Higher | G26: =Ratios!D37 -> 2.0067035 | H26: =Ratios!E37 -> 2.0459918 | I26: =Ratios!F37 -> 2.0682356 | J26: =IFERROR(IF($F26="Higher",MIN(100,MAX(0,100*G26/$E26)),IF(G26<=0,100,MIN(100,MAX(0,100*$E26/G26)))),0) -> 83.612647 | K26: =IFERROR(IF($F26="Higher",MIN(100,MAX(0,100*H26/$E26)),IF(H26<=0,100,MIN(100,MAX(0,100*$E26/H26)))),0) -> 85.249659 | L26: =IFERROR(IF($F26="Higher",MIN(100,MAX(0,100*I26/$E26)),IF(I26<=0,100,MIN(100,MAX(0,100*$E26/I26)))),0) -> 86.176485
B28: CATEGORY SCORES AND OVERALL RATING
B29: Profitability | D29: =SUMIFS($D$10:$D$26,$C$10:$C$26,B29) -> 30 | J29: =IFERROR(SUMPRODUCT(($C$10:$C$26=$B29)*$D$10:$D$26*J$10:J$26)/$D29,0) -> 63.12119 | K29: =IFERROR(SUMPRODUCT(($C$10:$C$26=$B29)*$D$10:$D$26*K$10:K$26)/$D29,0) -> 71.494331 | L29: =IFERROR(SUMPRODUCT(($C$10:$C$26=$B29)*$D$10:$D$26*L$10:L$26)/$D29,0) -> 80.69987
B30: Liquidity | D30: =SUMIFS($D$10:$D$26,$C$10:$C$26,B30) -> 25 | J30: =IFERROR(SUMPRODUCT(($C$10:$C$26=$B30)*$D$10:$D$26*J$10:J$26)/$D30,0) -> 73.018048 | K30: =IFERROR(SUMPRODUCT(($C$10:$C$26=$B30)*$D$10:$D$26*K$10:K$26)/$D30,0) -> 86.620796 | L30: =IFERROR(SUMPRODUCT(($C$10:$C$26=$B30)*$D$10:$D$26*L$10:L$26)/$D30,0) -> 89.208854
B31: Solvency | D31: =SUMIFS($D$10:$D$26,$C$10:$C$26,B31) -> 25 | J31: =IFERROR(SUMPRODUCT(($C$10:$C$26=$B31)*$D$10:$D$26*J$10:J$26)/$D31,0) -> 69.716919 | K31: =IFERROR(SUMPRODUCT(($C$10:$C$26=$B31)*$D$10:$D$26*K$10:K$26)/$D31,0) -> 73.605286 | L31: =IFERROR(SUMPRODUCT(($C$10:$C$26=$B31)*$D$10:$D$26*L$10:L$26)/$D31,0) -> 85.833957
B32: Efficiency | D32: =SUMIFS($D$10:$D$26,$C$10:$C$26,B32) -> 20 | J32: =IFERROR(SUMPRODUCT(($C$10:$C$26=$B32)*$D$10:$D$26*J$10:J$26)/$D32,0) -> 78.366164 | K32: =IFERROR(SUMPRODUCT(($C$10:$C$26=$B32)*$D$10:$D$26*K$10:K$26)/$D32,0) -> 79.909891 | L32: =IFERROR(SUMPRODUCT(($C$10:$C$26=$B32)*$D$10:$D$26*L$10:L$26)/$D32,0) -> 81.80119
B33: Overall health score | D33: =SUM(D29:D32) -> 100 | J33: =SUMPRODUCT($D$10:$D$26,J$10:J$26)/SUM($D$10:$D$26) -> 70.293332 | K33: =SUMPRODUCT($D$10:$D$26,K$10:K$26)/SUM($D$10:$D$26) -> 77.486798 | L33: =SUMPRODUCT($D$10:$D$26,L$10:L$26)/SUM($D$10:$D$26) -> 84.330902
B34: Letter grade | J34: =INDEX(Grade_Letter,MATCH(J33,Grade_Floor,1)) -> C | K34: =INDEX(Grade_Letter,MATCH(K33,Grade_Floor,1)) -> C | L34: =INDEX(Grade_Letter,MATCH(L33,Grade_Floor,1)) -> B
B35: Rating | J35: =INDEX(Grade_Desc,MATCH(J33,Grade_Floor,1)) -> Adequate | K35: =INDEX(Grade_Desc,MATCH(K33,Grade_Floor,1)) -> Adequate | L35: =INDEX(Grade_Desc,MATCH(L33,Grade_Floor,1)) -> Good

Sheet DuPont
B1: DuPont Analysis (five-step)
B2: Sampaguita Foods & Distribution Corporation (SFDC) | PHP in thousands | ROE = tax burden x interest burden x EBIT margin x asset turnover x equity multiplier
B3: =HYPERLINK("#Cover!A1","◄ Back to Cover") -> ◄ Back to Cover
B5: Driver | D5: =FS_Data!D$5 -> 2023 | E5: =FS_Data!E$5 -> 2024 | F5: =FS_Data!F$5 -> 2025
B6: Tax burden (net profit / profit before tax) | D6: =IFERROR(FS_Data!D22/FS_Data!D20,0) -> 0.74136851 | E6: =IFERROR(FS_Data!E22/FS_Data!E20,0) -> 0.74246884 | F6: =IFERROR(FS_Data!F22/FS_Data!F20,0) -> 0.74374677
B7: Interest burden (profit before tax / EBIT) | D7: =IFERROR(FS_Data!D20/FS_Data!D16,0) -> 0.75867504 | E7: =IFERROR(FS_Data!E20/FS_Data!E16,0) -> 0.78656413 | F7: =IFERROR(FS_Data!F20/FS_Data!F16,0) -> 0.8274353
B8: EBIT margin (EBIT / net sales) | D8: =IFERROR(FS_Data!D16/FS_Data!D7,0) -> 0.048678753 | E8: =IFERROR(FS_Data!E16/FS_Data!E7,0) -> 0.055362122 | F8: =IFERROR(FS_Data!F16/FS_Data!F7,0) -> 0.062505527
B9: Asset turnover (net sales / average assets) | D9: =IFERROR(FS_Data!D7/AVERAGE(FS_Data!C32,FS_Data!D32),0) -> 2.0067035 | E9: =IFERROR(FS_Data!E7/AVERAGE(FS_Data!D32,FS_Data!E32),0) -> 2.0459918 | F9: =IFERROR(FS_Data!F7/AVERAGE(FS_Data!E32,FS_Data!F32),0) -> 2.0682356
B10: Equity multiplier (average assets / average equity) | D10: =IFERROR(AVERAGE(FS_Data!C32,FS_Data!D32)/AVERAGE(FS_Data!C44,FS_Data!D44),0) -> 2.1750195 | E10: =IFERROR(AVERAGE(FS_Data!D32,FS_Data!E32)/AVERAGE(FS_Data!D44,FS_Data!E44),0) -> 2.1140357 | F10: =IFERROR(AVERAGE(FS_Data!E32,FS_Data!F32)/AVERAGE(FS_Data!E44,FS_Data!F44),0) -> 2.0318029
B11: Return on equity (product of drivers) | D11: =PRODUCT(D6:D10) -> 0.11950215 | E11: =PRODUCT(E6:E10) -> 0.13984318 | F11: =PRODUCT(F6:F10) -> 0.16164384
B12: ROE per Ratios sheet | D12: =Ratios!D12 -> 0.11950215 | E12: =Ratios!E12 -> 0.13984318 | F12: =Ratios!F12 -> 0.16164384
B13: Difference (should be 0) | D13: =ROUND(D11-D12,6) -> 0 | E13: =ROUND(E11-E12,6) -> 0 | F13: =ROUND(F11-F12,6) -> 0
B15: ATTRIBUTION OF THE CHANGE IN ROE (log-decomposition, sums exactly to the change)
B16: From year | D16: 2024
B17: To year | D17: 2025
B19: Driver | D19: From | E19: To | F19: Contribution to change in ROE (pts)
B20: Tax burden | D20: =INDEX($D6:$F6,MATCH(Dp_From,FY_List,0)) -> 0.74246884 | E20: =INDEX($D6:$F6,MATCH(Dp_To,FY_List,0)) -> 0.74374677 | F20: =IFERROR(LN(E20/D20)/LN($E$25/$D$25)*($E$25-$D$25),0) -> 0.00025878278
B21: Interest burden | D21: =INDEX($D7:$F7,MATCH(Dp_From,FY_List,0)) -> 0.78656413 | E21: =INDEX($D7:$F7,MATCH(Dp_To,FY_List,0)) -> 0.8274353 | F21: =IFERROR(LN(E21/D21)/LN($E$25/$D$25)*($E$25-$D$25),0) -> 0.0076228353
B22: EBIT margin | D22: =INDEX($D8:$F8,MATCH(Dp_From,FY_List,0)) -> 0.055362122 | E22: =INDEX($D8:$F8,MATCH(Dp_To,FY_List,0)) -> 0.062505527 | F22: =IFERROR(LN(E22/D22)/LN($E$25/$D$25)*($E$25-$D$25),0) -> 0.018262203
B23: Asset turnover | D23: =INDEX($D9:$F9,MATCH(Dp_From,FY_List,0)) -> 2.0459918 | E23: =INDEX($D9:$F9,MATCH(Dp_To,FY_List,0)) -> 2.0682356 | F23: =IFERROR(LN(E23/D23)/LN($E$25/$D$25)*($E$25-$D$25),0) -> 0.0016271788
B24: Equity multiplier | D24: =INDEX($D10:$F10,MATCH(Dp_From,FY_List,0)) -> 2.1140357 | E24: =INDEX($D10:$F10,MATCH(Dp_To,FY_List,0)) -> 2.0318029 | F24: =IFERROR(LN(E24/D24)/LN($E$25/$D$25)*($E$25-$D$25),0) -> -0.0059703474
B25: Return on equity | D25: =INDEX($D$11:$F$11,MATCH(Dp_From,FY_List,0)) -> 0.13984318 | E25: =INDEX($D$11:$F$11,MATCH(Dp_To,FY_List,0)) -> 0.16164384 | F25: =SUM(F20:F24) -> 0.021800652
B26: Change in ROE | F26: =E25-D25 -> 0.021800652
B27: Attribution check (should be 0) | F27: =ROUND(F25-F26,8) -> 0
B29: ="Return on equity moved from "&TEXT(D25,"0.0%")&" to "&TEXT(E25,"0.0%")&"; the largest driver was "&INDEX(B20:B24,MATCH(MAX(F20:F24),F20:F24,0))&" ("&TEXT(MAX(F20:F24),"+0.0%;-0.0%")&" pts) and the largest drag was "&INDEX(B20:B24,MATCH(MIN(F20:F24),F20:F24,0))&" ("&TEXT(MIN(F20:F24),"+0.0%;-0.0%")&" pts)." -> Return on equity moved from 14.0% to 16.2%; the largest driver was EBIT margin (+1.8% pts) and the largest drag was Equity multiplier (-0.6% pts).

Sheet Credit_Risk
B1: Credit Risk: Altman Z''-Score and Covenant Compliance
B2: Sampaguita Foods & Distribution Corporation (SFDC) | PHP in thousands
B3: =HYPERLINK("#Cover!A1","◄ Back to Cover") -> ◄ Back to Cover
B5: A. Altman Z''-score (emerging-market model) | C5: Coefficient | D5: =FS_Data!D$5 -> 2023 | E5: =FS_Data!E$5 -> 2024 | F5: =FS_Data!F$5 -> 2025
B6: X1 Working capital / total assets | C6: 6.56 | D6: =IFERROR((FS_Data!D29-FS_Data!D38)/FS_Data!D32,0) -> 0.19907268 | E6: =IFERROR((FS_Data!E29-FS_Data!E38)/FS_Data!E32,0) -> 0.24476828 | F6: =IFERROR((FS_Data!F29-FS_Data!F38)/FS_Data!F32,0) -> 0.24536382
B7: X2 Retained earnings / total assets | C7: 3.26 | D7: =IFERROR(FS_Data!D43/FS_Data!D32,0) -> 0.14105136 | E7: =IFERROR(FS_Data!E43/FS_Data!E32,0) -> 0.17388838 | F7: =IFERROR(FS_Data!F43/FS_Data!F32,0) -> 0.22259099
B8: X3 EBIT / total assets | C8: 6.72 | D8: =IFERROR(FS_Data!D16/FS_Data!D32,0) -> 0.096275065 | E8: =IFERROR(FS_Data!E16/FS_Data!E32,0) -> 0.10754199 | F8: =IFERROR(FS_Data!F16/FS_Data!F32,0) -> 0.12703751
B9: X4 Equity / total liabilities | C9: 1.05 | D9: =IFERROR(FS_Data!D44/FS_Data!D40,0) -> 0.89912357 | E9: =IFERROR(FS_Data!E44/FS_Data!E40,0) -> 0.89630341 | F9: =IFERROR(FS_Data!F44/FS_Data!F40,0) -> 1.0450456
B10: Constant (emerging markets) | C10: 3.25
B11: Z''-score | D11: =$C$10+SUMPRODUCT($C$6:$C$9,D6:D9) -> 6.6067924 | E11: =$C$10+SUMPRODUCT($C$6:$C$9,E6:E9) -> 7.0863568 | F11: =$C$10+SUMPRODUCT($C$6:$C$9,F6:F9) -> 7.5362232 | H11: Z'' = 3.25 + 6.56 X1 + 3.26 X2 + 6.72 X3 + 1.05 X4. Zones: above 5.85 safe; 4.15-5.85 grey; below 4.15 distress.
B12: Zone | D12: =IF(D11>$C$13,"Safe",IF(D11>=$D$13,"Grey","Distress")) -> Safe | E12: =IF(E11>$C$13,"Safe",IF(E11>=$D$13,"Grey","Distress")) -> Safe | F12: =IF(F11>$C$13,"Safe",IF(F11>=$D$13,"Grey","Distress")) -> Safe
B13: Safe-zone floor / distress ceiling | C13: 5.85 | D13: 4.15
B16: B. Bank covenant compliance (illustrative terms) | C16: Threshold | D16: =FS_Data!D$5 -> 2023 | E16: =FS_Data!E$5 -> 2024 | F16: =FS_Data!F$5 -> 2025 | H16: Test
B17: Current ratio (at least) | C17: 1.2 | D17: =Ratios!D15 -> 1.575501 | E17: =Ratios!E15 -> 1.7609372 | F17: =Ratios!F15 -> 1.7551507 | H17: Min
B18: Borrowings-to-equity (at most) | C18: 1.5 | D18: =Ratios!D21 -> 0.69189717 | E18: =Ratios!E21 -> 0.6962321 | F18: =Ratios!F21 -> 0.54396283 | H18: Max
B19: Interest cover (at least) | C19: 3 | D19: =Ratios!D25 -> 3.8356204 | E19: =Ratios!E25 -> 4.3288017 | F19: =Ratios!F25 -> 5.1969049 | H19: Min
B20: Debt service cover ratio (at least) | C20: 1.25 | D20: =Ratios!D28 -> 2.5583159 | E20: =Ratios!E28 -> 2.8160572 | F20: =Ratios!F28 -> 3.0731196 | H20: Min
B22: Headroom vs covenant (positive = compliant) | D22: =FS_Data!D$5 -> 2023 | E22: =FS_Data!E$5 -> 2024 | F22: =FS_Data!F$5 -> 2025 | H22: Status FY2025
B23: Current ratio | D23: =IFERROR(IF($H17="Min",(D17-$C17)/$C17,($C17-D17)/$C17),0) -> 0.3129175 | E23: =IFERROR(IF($H17="Min",(E17-$C17)/$C17,($C17-E17)/$C17),0) -> 0.46744764 | F23: =IFERROR(IF($H17="Min",(F17-$C17)/$C17,($C17-F17)/$C17),0) -> 0.46262562 | H23: =IF(F23>=0,"✔ Compliant - headroom "&TEXT(F23,"0%"),"✖ Breach by "&TEXT(-F23,"0%")) -> ✔ Compliant - headroom 46%
B24: Borrowings-to-equity | D24: =IFERROR(IF($H18="Min",(D18-$C18)/$C18,($C18-D18)/$C18),0) -> 0.53873522 | E24: =IFERROR(IF($H18="Min",(E18-$C18)/$C18,($C18-E18)/$C18),0) -> 0.53584527 | F24: =IFERROR(IF($H18="Min",(F18-$C18)/$C18,($C18-F18)/$C18),0) -> 0.63735811 | H24: =IF(F24>=0,"✔ Compliant - headroom "&TEXT(F24,"0%"),"✖ Breach by "&TEXT(-F24,"0%")) -> ✔ Compliant - headroom 64%
B25: Interest cover | D25: =IFERROR(IF($H19="Min",(D19-$C19)/$C19,($C19-D19)/$C19),0) -> 0.27854013 | E25: =IFERROR(IF($H19="Min",(E19-$C19)/$C19,($C19-E19)/$C19),0) -> 0.44293391 | F25: =IFERROR(IF($H19="Min",(F19-$C19)/$C19,($C19-F19)/$C19),0) -> 0.73230164 | H25: =IF(F25>=0,"✔ Compliant - headroom "&TEXT(F25,"0%"),"✖ Breach by "&TEXT(-F25,"0%")) -> ✔ Compliant - headroom 73%
B26: Debt service cover ratio | D26: =IFERROR(IF($H20="Min",(D20-$C20)/$C20,($C20-D20)/$C20),0) -> 1.0466527 | E26: =IFERROR(IF($H20="Min",(E20-$C20)/$C20,($C20-E20)/$C20),0) -> 1.2528458 | F26: =IFERROR(IF($H20="Min",(F20-$C20)/$C20,($C20-F20)/$C20),0) -> 1.4584957 | H26: =IF(F26>=0,"✔ Compliant - headroom "&TEXT(F26,"0%"),"✖ Breach by "&TEXT(-F26,"0%")) -> ✔ Compliant - headroom 146%
B28: Colour key: green = more than 15% headroom; amber = 0-15% headroom (early-warning); red = breach.

Sheet Sensitivity
B1: What-if Sensitivity Analysis
B2: Sampaguita Foods & Distribution Corporation (SFDC) | PHP in thousands | Change the yellow cells; pro-forma results recalculate
B3: =HYPERLINK("#Cover!A1","◄ Back to Cover") -> ◄ Back to Cover
B5: Base year | C5: 2025
B7: SCENARIO SHOCKS (inputs)
B8: Change in net sales (%) | C8: 0 | G8: Example: -10% net sales, -1.0% gross margin points, +5 DSO days.
B9: Change in gross margin (percentage points) | C9: 0 | G9: Defaults are zero so the pro-forma equals the base case.
B10: Change in operating expenses, excl. depreciation (%) | C10: 0
B11: Change in days sales outstanding (days) | C11: 0
B12: Change in days inventory outstanding (days) | C12: 0
B13: Change in interest rate on borrowings (points) | C13: 0
B15: PHP '000 unless stated | C15: Base | D15: Pro-forma | E15: Change
B16: Net sales | C16: =INDEX(FS_Data!$C$7:$F$7,MATCH(Sens_Year,FS_Data!$C$5:$F$5,0)) -> 972442 | D16: =C16*(1+C8) -> 972442 | E16: =D16-C16 -> 0
B17: Gross profit | C17: =INDEX(FS_Data!$C$9:$F$9,MATCH(Sens_Year,FS_Data!$C$5:$F$5,0)) -> 249894 | D17: =D16*(C17/C16+C9) -> 249894 | E17: =D17-C17 -> 0
B18: Gross margin | C18: =C17/C16 -> 0.25697574 | D18: =D17/D16 -> 0.25697574 | E18: =D18-C18 -> 0
B19: Operating expenses (excl. depreciation) | C19: =-(INDEX(FS_Data!$C$10:$F$10,MATCH(Sens_Year,FS_Data!$C$5:$F$5,0))+INDEX(FS_Data!$C$11:$F$11,MATCH(Sens_Year,FS_Data!$C$5:$F$5,0))) -> 169904 | D19: =C19*(1+C10) -> 169904 | E19: =D19-C19 -> 0
B20: Depreciation | C20: =-INDEX(FS_Data!$C$12:$F$12,MATCH(Sens_Year,FS_Data!$C$5:$F$5,0)) -> 21257 | D20: =C20 -> 21257 | E20: =D20-C20 -> 0
B21: EBIT | C21: =INDEX(FS_Data!$C$16:$F$16,MATCH(Sens_Year,FS_Data!$C$5:$F$5,0)) -> 60783 | D21: =D17-D19-D20+INDEX(FS_Data!$C$15:$F$15,MATCH(Sens_Year,FS_Data!$C$5:$F$5,0))+INDEX(FS_Data!$C$14:$F$14,MATCH(Sens_Year,FS_Data!$C$5:$F$5,0)) -> 60783 | E21: =D21-C21 -> 0
B22: Finance costs | C22: =-INDEX(FS_Data!$C$19:$F$19,MATCH(Sens_Year,FS_Data!$C$5:$F$5,0)) -> 11696 | D22: =C22+INDEX(FS_Data!$C$46:$F$46,MATCH(Sens_Year,FS_Data!$C$5:$F$5,0))*C13 -> 11696 | E22: =D22-C22 -> 0
B23: Profit before tax | C23: =C21-C22+INDEX(FS_Data!$C$18:$F$18,MATCH(Sens_Year,FS_Data!$C$5:$F$5,0)) -> 50294 | D23: =D21-D22+INDEX(FS_Data!$C$18:$F$18,MATCH(Sens_Year,FS_Data!$C$5:$F$5,0)) -> 50294 | E23: =D23-C23 -> 0
B24: Income tax (at base effective rate) | C24: =-INDEX(FS_Data!$C$21:$F$21,MATCH(Sens_Year,FS_Data!$C$5:$F$5,0)) -> 12888 | D24: =IFERROR(D23*C24/C23,0) -> 12888 | E24: =D24-C24 -> 0
B25: Net profit | C25: =C23-C24 -> 37406 | D25: =D23-D24 -> 37406 | E25: =D25-C25 -> 0
B26: Trade receivables | C26: =INDEX(FS_Data!$C$26:$F$26,MATCH(Sens_Year,FS_Data!$C$5:$F$5,0)) -> 93248 | D26: =(IFERROR(C26/C16*365,0)+C11)*D16/365 -> 93248 | E26: =D26-C26 -> 0
B27: Inventories | C27: =INDEX(FS_Data!$C$27:$F$27,MATCH(Sens_Year,FS_Data!$C$5:$F$5,0)) -> 85122 | D27: =(IFERROR(C27/(C16-C17)*365,0)+C12)*(D16-D17)/365 -> 85122 | E27: =D27-C27 -> 0
B28: Cash (adjusted for profit and working capital) | C28: =INDEX(FS_Data!$C$25:$F$25,MATCH(Sens_Year,FS_Data!$C$5:$F$5,0)) -> 81748 | D28: =C28+(D25-C25)-(D26-C26)-(D27-C27) -> 81748 | E28: =D28-C28 -> 0
B29: Current assets | C29: =INDEX(FS_Data!$C$29:$F$29,MATCH(Sens_Year,FS_Data!$C$5:$F$5,0)) -> 272861 | D29: =C29+(D28-C28)+(D26-C26)+(D27-C27) -> 272861 | E29: =D29-C29 -> 0
B30: Current liabilities | C30: =INDEX(FS_Data!$C$38:$F$38,MATCH(Sens_Year,FS_Data!$C$5:$F$5,0)) -> 155463 | D30: =C30 -> 155463 | E30: =D30-C30 -> 0
B31: Total equity | C31: =INDEX(FS_Data!$C$44:$F$44,MATCH(Sens_Year,FS_Data!$C$5:$F$5,0)) -> 244502 | D31: =C31+(D25-C25) -> 244502 | E31: =D31-C31 -> 0
B32: Total borrowings | C32: =INDEX(FS_Data!$C$46:$F$46,MATCH(Sens_Year,FS_Data!$C$5:$F$5,0)) -> 133000 | D32: =C32 -> 133000 | E32: =D32-C32 -> 0
B34: PRO-FORMA RATIOS AND COVENANT TESTS
B35: Current ratio | C35: =IFERROR(C29/C30,0) -> 1.7551507 | D35: =IFERROR(D29/D30,0) -> 1.7551507 | E35: =D35-C35 -> 0
B36: Net profit margin | C36: =IFERROR(C25/C16,0) -> 0.038466047 | D36: =IFERROR(D25/D16,0) -> 0.038466047 | E36: =D36-C36 -> 0
B37: Return on equity (year-end equity) | C37: =IFERROR(C25/C31,0) -> 0.15298852 | D37: =IFERROR(D25/D31,0) -> 0.15298852 | E37: =D37-C37 -> 0
B38: Borrowings-to-equity | C38: =IFERROR(C32/C31,0) -> 0.54396283 | D38: =IFERROR(D32/D31,0) -> 0.54396283 | E38: =D38-C38 -> 0
B39: Interest cover (EBIT / finance costs) | C39: =IFERROR(C21/C22,0) -> 5.1969049 | D39: =IFERROR(D21/D22,0) -> 5.1969049 | E39: =D39-C39 -> 0
B41: Covenant: current ratio | D41: =IF(D35>=Credit_Risk!$C$17,"✔ Pass","✖ Breach") -> ✔ Pass
B42: Covenant: borrowings-to-equity | D42: =IF(D38<=Credit_Risk!$C$18,"✔ Pass","✖ Breach") -> ✔ Pass
B43: Covenant: interest cover | D43: =IF(D39>=Credit_Risk!$C$19,"✔ Pass","✖ Breach") -> ✔ Pass
B45: Simplifications: tax at the base effective rate; payables and equity move only through profit; current liabilities unchanged. Use as a directional stress test.

Sheet FS_Data
B1: Financial Statement Data (from Project 1)
B2: Sampaguita Foods & Distribution Corporation (SFDC) | PHP in thousands | Blue = hard-coded from the Project 1 workbook; totals are recalculated here
B3: =HYPERLINK("#Cover!A1","◄ Back to Cover") -> ◄ Back to Cover
B5: PHP '000 | C5: 2022 | D5: =C5+1 -> 2023 | E5: =D5+1 -> 2024 | F5: =E5+1 -> 2025
B6: INCOME STATEMENT
B7: Net sales | D7: 821118 | E7: 897238 | F7: 972442
B8: Cost of sales | D8: -613977 | E8: -668558 | F8: -722548
B9: Gross profit | D9: =D7+D8 -> 207141 | E9: =E7+E8 -> 228680 | F9: =F7+F8 -> 249894
B10: Selling and distribution expenses | D10: -93216 | E10: -99930 | F10: -106077
B11: General and administrative expenses | D11: -58315 | E11: -61197 | F11: -63827
B12: Depreciation | D12: -17389 | E12: -19250 | F12: -21257
B13: Operating profit | D13: =SUM(D9:D12) -> 38221 | E13: =SUM(E9:E12) -> 48303 | F13: =SUM(F9:F12) -> 58733
B14: Gain / (loss) on disposal | D14: 400 | E14: -150 | F14: 350
B15: Other income | D15: 1350 | E15: 1520 | F15: 1700
B16: EBIT | D16: =SUM(D13:D15) -> 39971 | E16: =SUM(E13:E15) -> 49673 | F16: =SUM(F13:F15) -> 60783
B17: EBITDA | D17: =D16-D12 -> 57360 | E17: =E16-E12 -> 68923 | F17: =F16-F12 -> 82040
B18: Interest income | D18: 775 | E18: 873 | F18: 1207
B19: Finance costs | D19: -10421 | E19: -11475 | F19: -11696
B20: Profit before income tax | D20: =D16+D18+D19 -> 30325 | E20: =E16+E18+E19 -> 39071 | F20: =F16+F18+F19 -> 50294
B21: Income tax expense | D21: -7843 | E21: -10062 | F21: -12888
B22: Net profit | D22: =D20+D21 -> 22482 | E22: =E20+E21 -> 29009 | F22: =F20+F21 -> 37406
B24: STATEMENT OF FINANCIAL POSITION
B25: Cash and cash equivalents | C25: 62000 | D25: 58216 | E25: 80460 | F25: 81748
B26: Trade and other receivables | C26: 71000 | D26: 80987 | E26: 88495 | F26: 93248
B27: Inventories | C27: 74500 | D27: 75696 | E27: 80593 | F27: 85122
B28: Prepayments and other current assets | C28: 11200 | D28: 11365 | E28: 12085 | F28: 12743
B29: Total current assets | C29: =SUM(C25:C28) -> 218700 | D29: =SUM(D25:D28) -> 226264 | E29: =SUM(E25:E28) -> 261633 | F29: =SUM(F25:F28) -> 272861
B30: Property, plant and equipment, net | C30: 174700 | D30: 178711 | E30: 189761 | F30: 194504
B31: Other non-current assets | C31: 9800 | D31: 10200 | E31: 10500 | F31: 11100
B32: Total assets | C32: =C29+C30+C31 -> 403200 | D32: =D29+D30+D31 -> 415175 | E32: =E29+E30+E31 -> 461894 | F32: =F29+F30+F31 -> 478465
B33: Trade and other payables | C33: 62300 | D33: 67285 | E33: 75098 | F33: 83143
B34: Accrued expenses | C34: 13400 | D34: 13638 | E34: 14501 | F34: 15291
B35: Income tax payable | C35: 2800 | D35: 1691 | E35: 1977 | F35: 2529
B36: Short-term loans | C36: 45000 | D36: 48000 | E36: 42000 | F36: 38000
B37: Current portion of long-term loans | C37: 12000 | D37: 13000 | E37: 15000 | F37: 16500
B38: Total current liabilities | C38: =SUM(C33:C37) -> 135500 | D38: =SUM(D33:D37) -> 143614 | E38: =SUM(E33:E37) -> 148576 | F38: =SUM(F33:F37) -> 155463
B39: Long-term loans, net of current portion | C39: 88000 | D39: 75000 | E39: 95000 | F39: 78500
B40: Total liabilities | C40: =C38+C39 -> 223500 | D40: =D38+D39 -> 218614 | E40: =E38+E39 -> 243576 | F40: =F38+F39 -> 233963
B41: Share capital | C41: 120000 | D41: 120000 | E41: 120000 | F41: 120000
B42: Additional paid-in capital | C42: 18000 | D42: 18000 | E42: 18000 | F42: 18000
...

Sheet Benchmarks
B1: Benchmarks, Weights and Direction
B2: Sampaguita Foods & Distribution Corporation (SFDC) | PHP in thousands | Illustrative reference points - replace with peer or lender data
B3: =HYPERLINK("#Cover!A1","◄ Back to Cover") -> ◄ Back to Cover
B5: Ratio | C5: Category | D5: Better if | E5: Weight | F5: Industry median | G5: Top quartile | H5: Lender view
B6: Gross profit margin | C6: Profitability | D6: Higher | E6: 6 | F6: 0.24 | G6: 0.3 | H6: 0.2
B7: Operating profit margin | C7: Profitability | D7: Higher | E7: 6 | F7: 0.045 | G7: 0.075 | H7: 0.03
B8: Net profit margin | C8: Profitability | D8: Higher | E8: 6 | F8: 0.03 | G8: 0.05 | H8: 0.02
B9: Return on assets (average) | C9: Profitability | D9: Higher | E9: 6 | F9: 0.06 | G9: 0.1 | H9: 0.04
B10: Return on equity (average) | C10: Profitability | D10: Higher | E10: 6 | F10: 0.14 | G10: 0.2 | H10: 0.1
B11: Current ratio | C11: Liquidity | D11: Higher | E11: 8 | F11: 1.5 | G11: 2 | H11: 1.2
B12: Quick ratio | C12: Liquidity | D12: Higher | E12: 7 | F12: 0.9 | G12: 1.2 | H12: 0.8
B13: Operating cash flow ratio | C13: Liquidity | D13: Higher | E13: 5 | F13: 0.35 | G13: 0.5 | H13: 0.25
B14: Cash ratio | C14: Liquidity | D14: Higher | E14: 5 | F14: 0.3 | G14: 0.5 | H14: 0.2
B15: Borrowings-to-equity | C15: Solvency | D15: Lower | E15: 7 | F15: 1 | G15: 0.5 | H15: 1.5
B16: Debt ratio | C16: Solvency | D16: Lower | E16: 4 | F16: 0.6 | G16: 0.45 | H16: 0.7
B17: Interest cover | C17: Solvency | D17: Higher | E17: 7 | F17: 4 | G17: 7 | H17: 3
... B22: Total asset turnover | C22: Efficiency | D22: Higher | E22: 5 | F22: 2 | G22: 2.4 | H22: 1.6
B23: Total weight | E23: =SUM(E6:E22) -> 100

Sheet Chart_Data
B1: Chart Data
B2: Sampaguita Foods & Distribution Corporation (SFDC) | PHP in thousands | Helper tables - all formulas
B3: =HYPERLINK("#Cover!A1","◄ Back to Cover") -> ◄ Back to Cover
B5: Margins | C5: ="FY"&FS_Data!D$5 -> FY2023 | D5: ="FY"&FS_Data!E$5 -> FY2024 | E5: ="FY"&FS_Data!F$5 -> FY2025
B6: Gross margin | C6: =Ratios!D7 -> 0.25226703 | D6: =Ratios!E7 -> 0.25487106 | E6: =Ratios!F7 -> 0.25697574
B7: EBITDA margin | C7: =Ratios!D8 -> 0.069855977 | D7: =Ratios!E8 -> 0.076816853 | E7: =Ratios!F8 -> 0.084364929
B8: Net margin | C8: =Ratios!D10 -> 0.027379743 | D8: =Ratios!E10 -> 0.032331444 | E8: =Ratios!F10 -> 0.038466047
B10: Returns | C10: ="FY"&FS_Data!D$5 -> FY2023 | D10: ="FY"&FS_Data!E$5 -> FY2024 | E10: ="FY"&FS_Data!F$5 -> FY2025
B11: Return on assets | C11: =Ratios!D11 -> 0.054943027 | D11: =Ratios!E11 -> 0.06614987 | E11: =Ratios!F11 -> 0.07955685
B12: Return on equity | C12: =Ratios!D12 -> 0.11950215 | D12: =Ratios!E12 -> 0.13984318 | E12: =Ratios!F12 -> 0.16164384
B14: Liquidity | C14: ="FY"&FS_Data!D$5 -> FY2023 | D14: ="FY"&FS_Data!E$5 -> FY2024 | E14: ="FY"&FS_Data!F$5 -> FY2025
B15: Current ratio | C15: =Ratios!D15 -> 1.575501 | D15: =Ratios!E15 -> 1.7609372 | E15: =Ratios!F15 -> 1.7551507
B16: Quick ratio | C16: =Ratios!D16 -> 0.96928572 | D16: =Ratios!E16 -> 1.1371621 | E16: =Ratios!F16 -> 1.125644
B17: Cash ratio | C17: =Ratios!D17 -> 0.40536438 | D17: =Ratios!E17 -> 0.54154103 | E17: =Ratios!F17 -> 0.52583573
B19: Leverage | C19: ="FY"&FS_Data!D$5 -> FY2023 | D19: ="FY"&FS_Data!E$5 -> FY2024 | E19: ="FY"&FS_Data!F$5 -> FY2025
B20: Borrowings-to-equity | C20: =Ratios!D21 -> 0.69189717 | D20: =Ratios!E21 -> 0.6962321 | E20: =Ratios!F21 -> 0.54396283
B21: Net debt / EBITDA | C21: =Ratios!D27 -> 1.3560669 | D21: =Ratios!E27 -> 1.0379699 | E21: =Ratios!F27 -> 0.62471965
B22: Interest cover | C22: =Ratios!D25 -> 3.8356204 | D22: =Ratios!E25 -> 4.3288017 | E22: =Ratios!F25 -> 5.1969049
B24: Working capital days | C24: ="FY"&FS_Data!D$5 -> FY2023 | D24: ="FY"&FS_Data!E$5 -> FY2024 | E24: ="FY"&FS_Data!F$5 -> FY2025
B25: DSO | C25: =Ratios!D31 -> 33.780318 | D25: =Ratios!E31 -> 34.472977 | E25: =Ratios!F31 -> 34.108047
B26: DIO | C26: =Ratios!D33 -> 44.64462 | D26: =Ratios!E33 -> 42.663079 | E26: =Ratios!F33 -> 41.856025
B27: DPO | C27: =Ratios!D35 -> 38.518157 | D27: =Ratios!E35 -> 38.86708 | E27: =Ratios!F35 -> 39.968255
B28: Cash conversion cycle | C28: =Ratios!D36 -> 39.906782 | D28: =Ratios!E36 -> 38.268975 | E28: =Ratios!F36 -> 35.995818
B30: Category scores (selected year) | C30: ="FY"&Dash_Year -> FY2025
B31: Profitability | C31: =INDEX(Scorecard!$J$29:$L$29,MATCH(Dash_Year,Scorecard!$J$9:$L$9,0)) -> 80.69987
B32: Liquidity | C32: =INDEX(Scorecard!$J$30:$L$30,MATCH(Dash_Year,Scorecard!$J$9:$L$9,0)) -> 89.208854
B33: Solvency | C33: =INDEX(Scorecard!$J$31:$L$31,MATCH(Dash_Year,Scorecard!$J$9:$L$9,0)) -> 85.833957
B34: Efficiency | C34: =INDEX(Scorecard!$J$32:$L$32,MATCH(Dash_Year,Scorecard!$J$9:$L$9,0)) -> 81.80119
B36: Covenant headroom (selected year) | C36: ="FY"&Dash_Year -> FY2025
B37: Current ratio | C37: =INDEX(Credit_Risk!$D$23:$F$23,MATCH(Dash_Year,Credit_Risk!$D$16:$F$16,0)) -> 0.46262562
B38: Borrowings-to-equity | C38: =INDEX(Credit_Risk!$D$24:$F$24,MATCH(Dash_Year,Credit_Risk!$D$16:$F$16,0)) -> 0.63735811
B39: Interest cover | C39: =INDEX(Credit_Risk!$D$25:$F$25,MATCH(Dash_Year,Credit_Risk!$D$16:$F$16,0)) -> 0.73230164
B40: Debt service cover ratio | C40: =INDEX(Credit_Risk!$D$26:$F$26,MATCH(Dash_Year,Credit_Risk!$D$16:$F$16,0)) -> 1.4584957
B42: DuPont attribution (pts of ROE) | C42: ="FY"&Dp_From&" to FY"&Dp_To -> FY2024 to FY2025
B43: =DuPont!B20 -> Tax burden | C43: =DuPont!F20 -> 0.00025878278
B44: =DuPont!B21 -> Interest burden | C44: =DuPont!F21 -> 0.0076228353
B45: =DuPont!B22 -> EBIT margin | C45: =DuPont!F22 -> 0.018262203
B46: =DuPont!B23 -> Asset turnover | C46: =DuPont!F23 -> 0.0016271788
B47: =DuPont!B24 -> Equity multiplier | C47: =DuPont!F24 -> -0.0059703474

Sheet Lists
B1: Lists
B2: Sampaguita Foods & Distribution Corporation (SFDC) | PHP in thousands
B3: =HYPERLINK("#Cover!A1","◄ Back to Cover") -> ◄ Back to Cover
A4: Fiscal years | C4: Benchmark sets | E4: Grade floor | F4: Grade | G4: Rating
A5: =FS_Data!D$5 -> 2023 | C5: Industry median | E5: 0 | F5: E | G5: Distressed
A6: =FS_Data!E$5 -> 2024 | C6: Top quartile | E6: 60 | F6: D | G6: Weak
A7: =FS_Data!F$5 -> 2025 | C7: Lender view | E7: 70 | F7: C | G7: Adequate
E8: 80 | F8: B | G8: Good
E9: 90 | F9: A | G9: Strong

Sheet Checks
B1: Model Integrity Checks
B2: Sampaguita Foods & Distribution Corporation (SFDC) | PHP in thousands
B3: =HYPERLINK("#Cover!A1","◄ Back to Cover") -> ◄ Back to Cover
B4: Overall status | C4: =IF(COUNTIF(D7:D26,"ERROR")=0,"✔ All "&COUNTA(D7:D26)&" integrity checks passed","✖ "&COUNTIF(D7:D26,"ERROR")&" check(s) failing - review the Checks sheet") -> ✔ All 20 integrity checks passed
B6: Check (difference should be zero) | C6: Difference | D6: Status | E6: What it proves
B7: Balance sheet balances - FY2022 | C7: =FS_Data!C32-FS_Data!C45 -> 0 | D7: =IF(ABS(C7)<0.5,"OK","ERROR") -> OK | E7: Assets = liabilities + equity in the imported statements
B8: Balance sheet balances - FY2023 | C8: =FS_Data!D32-FS_Data!D45 -> 0 | D8: =IF(ABS(C8)<0.5,"OK","ERROR") -> OK | E8: Assets = liabilities + equity in the imported statements
B9: Balance sheet balances - FY2024 | C9: =FS_Data!E32-FS_Data!E45 -> 0 | D9: =IF(ABS(C9)<0.5,"OK","ERROR") -> OK | E9: Assets = liabilities + equity in the imported statements
B10: Balance sheet balances - FY2025 | C10: =FS_Data!F32-FS_Data!F45 -> 0 | D10: =IF(ABS(C10)<0.5,"OK","ERROR") -> OK | E10: Assets = liabilities + equity in the imported statements
B11: Net profit agrees to Project 1 - FY2023 | C11: =FS_Data!D22-FS_Data!D57 -> 0 | D11: =IF(ABS(C11)<0.5,"OK","ERROR") -> OK | E11: Recalculated net profit equals the Project 1 figure
B12: Net profit agrees to Project 1 - FY2024 | C12: =FS_Data!E22-FS_Data!E57 -> 0 | D12: =IF(ABS(C12)<0.5,"OK","ERROR") -> OK | E12: Recalculated net profit equals the Project 1 figure
B13: Net profit agrees to Project 1 - FY2025 | C13: =FS_Data!F22-FS_Data!F57 -> 0 | D13: =IF(ABS(C13)<0.5,"OK","ERROR") -> OK | E13: Recalculated net profit equals the Project 1 figure
B14: Total assets agree to Project 1 - FY2022 | C14: =FS_Data!C32-FS_Data!C58 -> 0 | D14: =IF(ABS(C14)<0.5,"OK","ERROR") -> OK | E14: Recalculated total assets equal the Project 1 figure
B15: Total assets agree to Project 1 - FY2023 | C15: =FS_Data!D32-FS_Data!D58 -> 0 | D15: =IF(ABS(C15)<0.5,"OK","ERROR") -> OK | E15: Recalculated total assets equal the Project 1 figure
